Workbook

Sheet Final_Summary
A1: FINAL VALIDATION SUMMARY - 9 predicted split suppressor / Sec tRNA candidates, Methanosarcina barkeri str. Wiesmoor
A2: Scores = 199-record model (Supplementary_Data_S1_REV3_199). GC = canonical slots 1-72, missing slots excluded, recomputed from sheet "Cand+Decoy Sequences" (matches Final_Validation_Status workbook exactly). Blue = input value; black = formula; green = link to another sheet.
A4: DECISION PARAMETERS
A5: Decoy-calibrated cut (S >=) | D5: -0.0801 | E5: Midpoint: decoy max vs weakest real tRNA (S1, Threshold Analysis)
A6: Decoy maximum S | D6: -0.189 | E6: Highest of 13 randomised-genome decoys (S1)
A7: C1 overall GC (>=) | D7: 0.49227308 | E7: 5th percentile, 199 training tRNAs
A8: C2 GC_stem, G+C of 42 stem slots (>=) | D8: 24 | E8: 5th percentile, 199 training tRNAs (57.1%)
A9: C3 dGC = GC_stem - GC_nonstem (>=) | D9: 0.14924466 | E9: 5th percentile, 199 training tRNAs (+14.9 pts)
A10: Minimum attainable p vs 13 decoys | D10: =1/(13+1) -> 0.071428571 | E10: Power floor: no candidate can reach p < 0.05
A12: CANDIDATE STATUS (Stage A model -> Stage B structure, reported only -> Stage C GC criteria -> final)
A13: Candidate | B13: Type | C13: Anti-codon | D13: Length (nt) | E13: Combined score S | F13: p vs decoys | G13: Model status (Stage A) | H13: MFE (kcal/mol) | I13: Stem pairs | J13: Conserved positions | K13: T-loop | L13: G+C (72 slots) | M13: Present slots | N13: Overall GC | O13: GC_stem (of 42) | P13: GC_nonstem | Q13: dGC (pts) | R13: GC criteria met (of 3) | S13: FINAL STATUS | T13: G+C nonstem | U13: Nonstem slots
A14: trna64 | B14: Sec | C14: UCA | D14: 71 | E14: 0.0394 | F14: 0.071 | G14: =IF(E14>=$D$5,"SUPPORTED",IF(E14>$D$6,"BORDERLINE","NOT SUPPORTED")) -> SUPPORTED | H14: -32.9 | I14: 19/21 | J14: 10/12 | K14: 5/5 | L14: 46 | M14: 71 | N14: =L14/M14 -> 0.64788732 | O14: 34 | P14: =T14/U14 -> 0.4137931 | Q14: =(O14/42-P14)*100 -> 39.573071 | R14: =(N14>=$D$7)+(O14>=$D$8)+(Q14/100>=$D$9) -> 3 | S14: =IF(AND(G14="SUPPORTED",R14=3),"SUPPORTED",IF(G14<>"NOT SUPPORTED","BORDERLINE","NOT SUPPORTED")) -> SUPPORTED | T14: 12 | U14: 29
A15: trna958 | B15: Sup | C15: CUA | D15: 86 | E15: -0.1423 | F15: 0.071 | G15: =IF(E15>=$D$5,"SUPPORTED",IF(E15>$D$6,"BORDERLINE","NOT SUPPORTED")) -> BORDERLINE | H15: -20.3 | I15: 19/21 | J15: 10/12 | K15: 5/5 | L15: 32 | M15: 72 | N15: =L15/M15 -> 0.44444444 | O15: 21 | P15: =T15/U15 -> 0.36666667 | Q15: =(O15/42-P15)*100 -> 13.333333 | R15: =(N15>=$D$7)+(O15>=$D$8)+(Q15/100>=$D$9) -> 0 | S15: =IF(AND(G15="SUPPORTED",R15=3),"SUPPORTED",IF(G15<>"NOT SUPPORTED","BORDERLINE","NOT SUPPORTED")) -> BORDERLINE | T15: 11 | U15: 30
A16: trna1091 | B16: Sup | C16: CUA | D16: 88 | E16: -0.2388 | F16: 0.286 | G16: =IF(E16>=$D$5,"SUPPORTED",IF(E16>$D$6,"BORDERLINE","NOT SUPPORTED")) -> NOT SUPPORTED | H16: -29.4 | I16: 19/21 | J16: 6/12 | K16: 1/5 | L16: 33 | M16: 72 | N16: =L16/M16 -> 0.45833333 | O16: 20 | P16: =T16/U16 -> 0.43333333 | Q16: =(O16/42-P16)*100 -> 4.2857143 | R16: =(N16>=$D$7)+(O16>=$D$8)+(Q16/100>=$D$9) -> 0 | S16: =IF(AND(G16="SUPPORTED",R16=3),"SUPPORTED",IF(G16<>"NOT SUPPORTED","BORDERLINE","NOT SUPPORTED")) -> NOT SUPPORTED | T16: 13 | U16: 30
A17: trna1395 | B17: Sup | C17: CUA | D17: 92 | E17: -0.2469 | F17: 0.286 | G17: =IF(E17>=$D$5,"SUPPORTED",IF(E17>$D$6,"BORDERLINE","NOT SUPPORTED")) -> NOT SUPPORTED | H17: -20.6 | I17: 19/21 | J17: 7/12 | K17: 4/5 | L17: 39 | M17: 71 | N17: =L17/M17 -> 0.54929577 | O17: 24 | P17: =T17/U17 -> 0.51724138 | Q17: =(O17/42-P17)*100 -> 5.4187192 | R17: =(N17>=$D$7)+(O17>=$D$8)+(Q17/100>=$D$9) -> 2 | S17: =IF(AND(G17="SUPPORTED",R17=3),"SUPPORTED",IF(G17<>"NOT SUPPORTED","BORDERLINE","NOT SUPPORTED")) -> NOT SUPPORTED | T17: 15 | U17: 29
A18: trna1 | B18: Sec | C18: UCA | D18: 70 | E18: -0.2866 | F18: 0.357 | G18: =IF(E18>=$D$5,"SUPPORTED",IF(E18>$D$6,"BORDERLINE","NOT SUPPORTED")) -> NOT SUPPORTED | H18: -14.1 | I18: 19/21 | J18: 7/12 | K18: 2/5 | L18: 23 | M18: 70 | N18: =L18/M18 -> 0.32857143 | O18: 15 | P18: =T18/U18 -> 0.28571429 | Q18: =(O18/42-P18)*100 -> 7.1428571 | R18: =(N18>=$D$7)+(O18>=$D$8)+(Q18/100>=$D$9) -> 0 | S18: =IF(AND(G18="SUPPORTED",R18=3),"SUPPORTED",IF(G18<>"NOT SUPPORTED","BORDERLINE","NOT SUPPORTED")) -> NOT SUPPORTED | T18: 8 | U18: 28
A19: trna20 | B19: Sup | C19: UUA | D19: 70 | E19: -0.2905 | F19: 0.429 | G19: =IF(E19>=$D$5,"SUPPORTED",IF(E19>$D$6,"BORDERLINE","NOT SUPPORTED")) -> NOT SUPPORTED | H19: -16.5 | I19: 20/21 | J19: 7/12 | K19: 3/5 | L19: 31 | M19: 70 | N19: =L19/M19 -> 0.44285714 | O19: 20 | P19: =T19/U19 -> 0.39285714 | Q19: =(O19/42-P19)*100 -> 8.3333333 | R19: =(N19>=$D$7)+(O19>=$D$8)+(Q19/100>=$D$9) -> 0 | S19: =IF(AND(G19="SUPPORTED",R19=3),"SUPPORTED",IF(G19<>"NOT SUPPORTED","BORDERLINE","NOT SUPPORTED")) -> NOT SUPPORTED | T19: 11 | U19: 28
A20: trna9 | B20: Sup | C20: UUA | D20: 70 | E20: -0.3163 | F20: 0.429 | G20: =IF(E20>=$D$5,"SUPPORTED",IF(E20>$D$6,"BORDERLINE","NOT SUPPORTED")) -> NOT SUPPORTED | H20: -16.4 | I20: 19/21 | J20: 7/12 | K20: 2/5 | L20: 21 | M20: 70 | N20: =L20/M20 -> 0.3 | O20: 12 | P20: =T20/U20 -> 0.32142857 | Q20: =(O20/42-P20)*100 -> -3.5714286 | R20: =(N20>=$D$7)+(O20>=$D$8)+(Q20/100>=$D$9) -> 0 | S20: =IF(AND(G20="SUPPORTED",R20=3),"SUPPORTED",IF(G20<>"NOT SUPPORTED","BORDERLINE","NOT SUPPORTED")) -> NOT SUPPORTED | T20: 9 | U20: 28
A21: trna590 | B21: Sup | C21: UUA | D21: 80 | E21: -0.4643 | F21: 0.929 | G21: =IF(E21>=$D$5,"SUPPORTED",IF(E21>$D$6,"BORDERLINE","NOT SUPPORTED")) -> NOT SUPPORTED | H21: -19.3 | I21: 20/21 | J21: 6/12 | K21: 2/5 | L21: 24 | M21: 71 | N21: =L21/M21 -> 0.33802817 | O21: 16 | P21: =T21/U21 -> 0.27586207 | Q21: =(O21/42-P21)*100 -> 10.509031 | R21: =(N21>=$D$7)+(O21>=$D$8)+(Q21/100>=$D$9) -> 0 | S21: =IF(AND(G21="SUPPORTED",R21=3),"SUPPORTED",IF(G21<>"NOT SUPPORTED","BORDERLINE","NOT SUPPORTED")) -> NOT SUPPORTED | T21: 8 | U21: 29
A22: trna1470 | B22: Sup | C22: CUA | D22: 93 | E22: -0.4932 | F22: 1 | G22: =IF(E22>=$D$5,"SUPPORTED",IF(E22>$D$6,"BORDERLINE","NOT SUPPORTED")) -> NOT SUPPORTED | H22: -20.6 | I22: 19/21 | J22: 5/12 | K22: 1/5 | L22: 35 | M22: 72 | N22: =L22/M22 -> 0.48611111 | O22: 18 | P22: =T22/U22 -> 0.56666667 | Q22: =(O22/42-P22)*100 -> -13.809524 | R22: =(N22>=$D$7)+(O22>=$D$8)+(Q22/100>=$D$9) -> 0 | S22: =IF(AND(G22="SUPPORTED",R22=3),"SUPPORTED",IF(G22<>"NOT SUPPORTED","BORDERLINE","NOT SUPPORTED")) -> NOT SUPPORTED | T22: 17 | U22: 30
A23: Final rule (stated before application): SUPPORTED = S >= cut AND all 3 GC criteria; BORDERLINE = S above every decoy but not SUPPORTED; NOT SUPPORTED = S inside decoy range, whatever the GC profile (GC never rescues a candidate the model rejects).
A25: OUTCOME
A26: Status | B26: Stage A only (published) | D26: Final (model + GC) | F26: Candidates (final)
A27: SUPPORTED | B27: =COUNTIF($G$14:$G$22,A27) -> 1 | D27: =COUNTIF($S$14:$S$22,A27) -> 1 | F27: trna64
A28: BORDERLINE | B28: =COUNTIF($G$14:$G$22,A28) -> 1 | D28: =COUNTIF($S$14:$S$22,A28) -> 1 | F28: trna958 (above every decoy; meets 0/3 GC criteria)
A29: NOT SUPPORTED | B29: =COUNTIF($G$14:$G$22,A29) -> 7 | D29: =COUNTIF($S$14:$S$22,A29) -> 7 | F29: trna1091, trna1395*, trna1, trna20, trna9, trna590, trna1470
A30: * trna1395 meets 2 of 3 GC criteria (C1, C2) but its score lies inside the decoy range; flagged for re-examination in the revised search only.
A32: KEY EVIDENCE (one line each)
A33: Real tRNAs vs both negative controls | F33: AUC = 1.000 (158 real tRNAs vs 13 decoys and vs 960 shuffled)
A34: Candidates vs decoys, model score alone | F34: AUC 0.615 (p = 0.39): 7 of 9 candidates inside decoy score range
A35: Candidates vs decoys, GC alone | F35: Overall GC AUC 0.859 (p = 0.0055); GC_stem AUC 0.880 (p = 0.0032); dGC AUC 0.778 (p = 0.033)
A36: Model + GC composite | F36: S + overall GC + GC_stem + dGC: AUC 0.829 (p = 0.011) - GC is complementary to the positional model
A37: GC criteria C1-C3 (all three) | F37: Accept 92% training, 93% held-out, 98% M. barkeri tRNAs; accept 0/13 decoys; 1/9 candidates
A38: Effect on search output | F38: False positives 0.26 -> 0.00 per randomised genome; supported candidate trna64 retained
A39: Stem enrichment (dGC) in real tRNAs | F39: +30.0 to +31.6 pts in all three reference sets; positive in 357/357 (Wilcoxon p < 1e-30)
A40: Power limit | F40: 13 decoys -> min p = 0.071; ~99 decoys (~380 randomised genomes) needed for p < 0.01; GC-matched decoys planned
A42: TABLES FOR THE MANUSCRIPT (compact plan)
A43: Table | B43: Title | E43: Content (columns / panels) | L43: Built from | P43: Change vs previous
A44: Table 1 (REVISED) | B44: Final validation status of the nine predicted candidates | E44: Per candidate: type, anticodon, length | combined score S, p vs decoys | MFE, stem pairs, conserved positions, T-loop | overall GC, GC_stem, dGC, GC criteria met | final status | L44: Old Table 1 + Final_Status (GC workbook) | P44: GC (72-slot) + C1-C3 added; emission / transition columns moved to Suppl. S1; final status now model + GC
A45: Table 2 (REVISED) | B45: Score and GC composition of candidates against known tRNAs and both negative controls | E45: Per set (6 sets): role, n | S mean +/- SD, range of S | overall GC, GC_stem, dGC | pass all GC criteria | L45: Old Table 2 + Reference_GC + GC_Criteria | P45: GC columns + criteria pass rate added; M. barkeri set labelled as tRNAscan-SE annotations (not gold standard); stem / conserved columns moved to S1
...

Sheet Table 1
A1: Table 1. Final validation status of the nine predicted split suppressor-tRNA candidates.
A2: Candidates are ordered by combined score S. p values are empirical against the 13 randomised-genome sequences (minimum attainable 0.071). Decision threshold S = -0.0801. GC values use canonical slots 1-72; GC criteria: C1 overall GC >= 49.2%, C2 GC_stem >= 24/42, C3 dGC >= +14.9 points (5th percentiles of the 199 reference tRNAs).
A4: Candidate | B4: Type | C4: Anti- codon | D4: Length (nt) | E4: Combined score S | F4: p vs decoys | G4: MFE (kcal/mol) | H4: Stem pairs | I4: Conserved positions | J4: T-loop | K4: Overall GC (%) | L4: GC_stem (of 42) | M4: dGC (pts) | N4: GC criteria met | O4: Status
A5: =Final_Summary!A14 -> trna64 | B5: =Final_Summary!B14 -> Sec | C5: =Final_Summary!C14 -> UCA | D5: =Final_Summary!D14 -> 71 | E5: =Final_Summary!E14 -> 0.0394 | F5: =Final_Summary!F14 -> 0.071 | G5: =Final_Summary!H14 -> -32.9 | H5: =Final_Summary!I14 -> 19/21 | I5: =Final_Summary!J14 -> 10/12 | J5: =Final_Summary!K14 -> 5/5 | K5: =Final_Summary!N14*100 -> 64.788732 | L5: =Final_Summary!O14&"/42" -> 34/42 | M5: =Final_Summary!Q14 -> 39.573071 | N5: =Final_Summary!R14&"/3" -> 3/3 | O5: =IF(Final_Summary!S14="SUPPORTED","Supported",IF(Final_Summary!S14="BORDERLINE","Borderline","Not supported")) -> Supported
A6: =Final_Summary!A15 -> trna958 | B6: =Final_Summary!B15 -> Sup | C6: =Final_Summary!C15 -> CUA | D6: =Final_Summary!D15 -> 86 | E6: =Final_Summary!E15 -> -0.1423 | F6: =Final_Summary!F15 -> 0.071 | G6: =Final_Summary!H15 -> -20.3 | H6: =Final_Summary!I15 -> 19/21 | I6: =Final_Summary!J15 -> 10/12 | J6: =Final_Summary!K15 -> 5/5 | K6: =Final_Summary!N15*100 -> 44.444444 | L6: =Final_Summary!O15&"/42" -> 21/42 | M6: =Final_Summary!Q15 -> 13.333333 | N6: =Final_Summary!R15&"/3" -> 0/3 | O6: =IF(Final_Summary!S15="SUPPORTED","Supported",IF(Final_Summary!S15="BORDERLINE","Borderline","Not supported")) -> Borderline
A7: =Final_Summary!A16 -> trna1091 | B7: =Final_Summary!B16 -> Sup | C7: =Final_Summary!C16 -> CUA | D7: =Final_Summary!D16 -> 88 | E7: =Final_Summary!E16 -> -0.2388 | F7: =Final_Summary!F16 -> 0.286 | G7: =Final_Summary!H16 -> -29.4 | H7: =Final_Summary!I16 -> 19/21 | I7: =Final_Summary!J16 -> 6/12 | J7: =Final_Summary!K16 -> 1/5 | K7: =Final_Summary!N16*100 -> 45.833333 | L7: =Final_Summary!O16&"/42" -> 20/42 | M7: =Final_Summary!Q16 -> 4.2857143 | N7: =Final_Summary!R16&"/3" -> 0/3 | O7: =IF(Final_Summary!S16="SUPPORTED","Supported",IF(Final_Summary!S16="BORDERLINE","Borderline","Not supported")) -> Not supported
A8: =Final_Summary!A17 -> trna1395 | B8: =Final_Summary!B17 -> Sup | C8: =Final_Summary!C17 -> CUA | D8: =Final_Summary!D17 -> 92 | E8: =Final_Summary!E17 -> -0.2469 | F8: =Final_Summary!F17 -> 0.286 | G8: =Final_Summary!H17 -> -20.6 | H8: =Final_Summary!I17 -> 19/21 | I8: =Final_Summary!J17 -> 7/12 | J8: =Final_Summary!K17 -> 4/5 | K8: =Final_Summary!N17*100 -> 54.929577 | L8: =Final_Summary!O17&"/42" -> 24/42 | M8: =Final_Summary!Q17 -> 5.4187192 | N8: =Final_Summary!R17&"/3" -> 2/3 | O8: =IF(Final_Summary!S17="SUPPORTED","Supported",IF(Final_Summary!S17="BORDERLINE","Borderline","Not supported")) -> Not supported
A9: =Final_Summary!A18 -> trna1 | B9: =Final_Summary!B18 -> Sec | C9: =Final_Summary!C18 -> UCA | D9: =Final_Summary!D18 -> 70 | E9: =Final_Summary!E18 -> -0.2866 | F9: =Final_Summary!F18 -> 0.357 | G9: =Final_Summary!H18 -> -14.1 | H9: =Final_Summary!I18 -> 19/21 | I9: =Final_Summary!J18 -> 7/12 | J9: =Final_Summary!K18 -> 2/5 | K9: =Final_Summary!N18*100 -> 32.857143 | L9: =Final_Summary!O18&"/42" -> 15/42 | M9: =Final_Summary!Q18 -> 7.1428571 | N9: =Final_Summary!R18&"/3" -> 0/3 | O9: =IF(Final_Summary!S18="SUPPORTED","Supported",IF(Final_Summary!S18="BORDERLINE","Borderline","Not supported")) -> Not supported
A10: =Final_Summary!A19 -> trna20 | B10: =Final_Summary!B19 -> Sup | C10: =Final_Summary!C19 -> UUA | D10: =Final_Summary!D19 -> 70 | E10: =Final_Summary!E19 -> -0.2905 | F10: =Final_Summary!F19 -> 0.429 | G10: =Final_Summary!H19 -> -16.5 | H10: =Final_Summary!I19 -> 20/21 | I10: =Final_Summary!J19 -> 7/12 | J10: =Final_Summary!K19 -> 3/5 | K10: =Final_Summary!N19*100 -> 44.285714 | L10: =Final_Summary!O19&"/42" -> 20/42 | M10: =Final_Summary!Q19 -> 8.3333333 | N10: =Final_Summary!R19&"/3" -> 0/3 | O10: =IF(Final_Summary!S19="SUPPORTED","Supported",IF(Final_Summary!S19="BORDERLINE","Borderline","Not supported")) -> Not supported
A11: =Final_Summary!A20 -> trna9 | B11: =Final_Summary!B20 -> Sup | C11: =Final_Summary!C20 -> UUA | D11: =Final_Summary!D20 -> 70 | E11: =Final_Summary!E20 -> -0.3163 | F11: =Final_Summary!F20 -> 0.429 | G11: =Final_Summary!H20 -> -16.4 | H11: =Final_Summary!I20 -> 19/21 | I11: =Final_Summary!J20 -> 7/12 | J11: =Final_Summary!K20 -> 2/5 | K11: =Final_Summary!N20*100 -> 30 | L11: =Final_Summary!O20&"/42" -> 12/42 | M11: =Final_Summary!Q20 -> -3.5714286 | N11: =Final_Summary!R20&"/3" -> 0/3 | O11: =IF(Final_Summary!S20="SUPPORTED","Supported",IF(Final_Summary!S20="BORDERLINE","Borderline","Not supported")) -> Not supported
A12: =Final_Summary!A21 -> trna590 | B12: =Final_Summary!B21 -> Sup | C12: =Final_Summary!C21 -> UUA | D12: =Final_Summary!D21 -> 80 | E12: =Final_Summary!E21 -> -0.4643 | F12: =Final_Summary!F21 -> 0.929 | G12: =Final_Summary!H21 -> -19.3 | H12: =Final_Summary!I21 -> 20/21 | I12: =Final_Summary!J21 -> 6/12 | J12: =Final_Summary!K21 -> 2/5 | K12: =Final_Summary!N21*100 -> 33.802817 | L12: =Final_Summary!O21&"/42" -> 16/42 | M12: =Final_Summary!Q21 -> 10.509031 | N12: =Final_Summary!R21&"/3" -> 0/3 | O12: =IF(Final_Summary!S21="SUPPORTED","Supported",IF(Final_Summary!S21="BORDERLINE","Borderline","Not supported")) -> Not supported
A13: =Final_Summary!A22 -> trna1470 | B13: =Final_Summary!B22 -> Sup | C13: =Final_Summary!C22 -> CUA | D13: =Final_Summary!D22 -> 93 | E13: =Final_Summary!E22 -> -0.4932 | F13: =Final_Summary!F22 -> 1 | G13: =Final_Summary!H22 -> -20.6 | H13: =Final_Summary!I22 -> 19/21 | I13: =Final_Summary!J22 -> 5/12 | J13: =Final_Summary!K22 -> 1/5 | K13: =Final_Summary!N22*100 -> 48.611111 | L13: =Final_Summary!O22&"/42" -> 18/42 | M13: =Final_Summary!Q22 -> -13.809524 | N13: =Final_Summary!R22&"/3" -> 0/3 | O13: =IF(Final_Summary!S22="SUPPORTED","Supported",IF(Final_Summary!S22="BORDERLINE","Borderline","Not supported")) -> Not supported
A15: Supported: S above the decision threshold and all three GC criteria met. Borderline: S above every randomised-genome sequence but not supported. Not supported: S within the randomised-genome range; GC is an additional requirement and is never used to rescue a candidate the model rejects. Stem pairing, conserved positions and T-loop are reported but were not used in the decision. Emission and transition log-odds are given in Supplementary Data S1.

Sheet Table 2
A1: Table 2. Probabilistic score and GC composition of the predicted candidates compared with known tRNAs and with both negative controls.
A2: All sequences were scored with the same position-specific model estimated from the 199 reference tRNAs (reference set scored leave-one-out). Scores are means +/- SD; GC values are set means over canonical slots 1-72.
A4: Sequence set | B4: Role | C4: n | D4: Combined score S | E4: Range of S | F4: Overall GC (%) | G4: GC_stem (%) | H4: dGC (pts) | I4: Pass C1-C3 (all three)
A5: T-psi-C reference | B5: Model construction | C5: 199 | D5: +0.506 ± 0.135 | E5: -0.207 to +0.759 | F5: 60.1 | G5: 73 | H5: 31.3 | I5: ="183/199 ("&TEXT(183/199,"0%")&")" -> 183/199 (92%)
A6: T-psi-C held out | B6: Positive control | C6: 96 | D6: +0.494 ± 0.117 | E6: +0.029 to +0.687 | F6: 58.7 | G6: 71.1 | H6: 30 | I6: ="89/96 ("&TEXT(89/96,"0%")&")" -> 89/96 (93%)
A7: M. barkeri annotated (tRNAscan-SE) | B7: Organism-specific reference | C7: 62 | D7: +0.422 ± 0.111 | E7: +0.241 to +0.698 | F7: 61.5 | G7: 74.5 | H7: 31.6 | I7: ="61/62 ("&TEXT(61/62,"0%")&")" -> 61/62 (98%)
A8: Predicted candidates | B8: Under test | C8: 9 | D8: -0.271 ± 0.151 | E8: -0.493 to +0.039 | F8: 44.4 | G8: 47.6 | H8: 7.9 | I8: =COUNTIF(Final_Summary!R14:R22,3)&"/9 ("&TEXT(COUNTIF(Final_Summary!R14:R22,3)/9,"0%")&")" -> 1/9 (11%)
A9: Randomised genome | B9: Negative control | C9: 13 | D9: -0.338 ± 0.094 | E9: -0.476 to -0.189 | F9: 31.3 | G9: 30.4 | H9: -2.1 | I9: ="0/13 ("&TEXT(0/13,"0%")&")" -> 0/13 (0%)
A10: Base-shuffled tRNAs | B10: Negative control | C10: 960 | D10: -0.603 ± 0.113 | E10: -0.915 to -0.208 | F10: as held-out set | G10: – | H10: – | I10: n.a.
A11: Separation between known tRNAs and both negative controls was complete (AUC = 1.000). Decision threshold S = -0.0801, midway between the highest randomised-genome score and the lowest known-tRNA score. GC criteria (C1 overall GC >= 49.2%, C2 GC_stem >= 24/42, C3 dGC >= +14.9 pts) are the 5th percentiles of the 199 reference tRNAs and were not tuned on candidates or decoys. dGC = GC_stem - GC_nonstem; it is positive in all 357 reference tRNAs. The 62 M. barkeri sequences are tRNAscan-SE computational annotations, not experimentally confirmed tRNAs, and are used as an organism-specific reference distribution, not as ground truth. Base-shuffled tRNAs retain the composition of the held-out set.

Sheet Table 3
A1: Table 3. Contribution of GC composition to the selection of split-tRNA candidates.
A3: A. Discrimination of the 9 predicted candidates from the 13 randomised-genome sequences
A4: Feature | B4: Type | C4: AUC | D4: p | E4: Significant (p < 0.05)
A5: Combined score S | B5: Positional model alone | C5: 0.615 | D5: 0.385 | E5: =IF(D5<0.05,"yes","no") -> no
A6: Overall GC | B6: Composition alone | C6: 0.859 | D6: 0.0055 | E6: =IF(D6<0.05,"yes","no") -> yes
A7: GC_stem | B7: Composition alone | C7: 0.88 | D7: 0.0032 | E7: =IF(D7<0.05,"yes","no") -> yes
A8: dGC | B8: Composition alone | C8: 0.778 | D8: 0.033 | E8: =IF(D8<0.05,"yes","no") -> yes
A9: S + GC_stem | B9: Model + composition | C9: 0.795 | D9: 0.023 | E9: =IF(D9<0.05,"yes","no") -> yes
A10: S + overall GC + GC_stem + dGC | B10: Model + composition | C10: 0.829 | D10: 0.011 | E10: =IF(D10<0.05,"yes","no") -> yes
A12: B. Search output before and after adding the GC criteria
A13: Screening procedure | B13: Candidates from real genome | C13: Sequences from 50 randomised genomes | D13: False positives per randomised genome | E13: Model-supported candidate retained
A14: Published (probabilistic model only) | B14: 9 | C14: 13 | D14: =C14/50 -> 0.26 | E14: yes (trna64)
A15: Revised (model + GC criteria C1-C3) | B15: =COUNTIF(Final_Summary!R14:R22,3) -> 1 | C15: 0 | D15: =C15/50 -> 0 | E15: yes (trna64)
A17: AUC from the two-sided Mann-Whitney U test (normal approximation with tie and continuity correction). Composite features are sums of z-scores standardised over all 22 sequences. With n = 9 vs 13 the tests have limited power and the composite was evaluated on the same sequences; it is reported as evidence that composition is informative, not as a tuned classifier. Panel B applies C1-C3 to the complete output of the existing search; the GC criteria retain 92-98% of real tRNAs (Table 2).

Sheet Corrections
A1: Consistency check - fix these before submitting S3 and the response letter
A3: # | B3: Where | C3: Current text / value | D3: Correct value | E3: Why
A4: 1 | B4: Final_Status (S3) col E, F, G, H; Reply point 8 | C4: Scores of an earlier model run: trna64 S = +0.0382; cut -0.0795; decoy max -0.1879 | D4: trna64 S = +0.0394; cut -0.0801; decoy max -0.1890 (all 9 S values as in Table 1) | E4: Manuscript Tables 1-2 and S1 use the corrected 199-record model. All statuses are unchanged.
A5: 2 | B5: Final_Status (S3) cell H11 | C5: trna20 p vs decoys = 0.357 | D5: 0.429 | E5: With S = -0.2905, five decoys score higher -> (5+1)/14 = 0.429.
A6: 3 | B6: Composite_AUC (S3) row "Combined score S"; Reply point 5 | C6: S alone AUC 0.624, p = 0.349 | D6: AUC 0.615, p = 0.385 | E6: Recomputed with 199-record scores. Composite rows unchanged (0.735 / 0.786 / 0.795 / 0.795 / 0.829). S1 Decoy Discrimination gives p = 0.367 without continuity correction.
A7: 4 | B7: Old Table 1 "GC (%)" column; GC_Definition (S3) | C7: trna958 45.35, trna1091 43.18, trna1395 47.83, trna590 35.00, trna1470 47.83 (all-nucleotide GC) | D7: 44.4, 45.8, 54.9, 33.8, 48.6 (72-slot GC, as in the new Table 1) | E7: GC_Definition says Table 1 shows the 72-slot value 44.4%. That is true only for the revised Table 1.
A8: 5 | B8: Reply point 2 | C8: "the three agree to within 1.6 percentage points on every measure" | D8: "agree to within 3.4 percentage points on every measure (dGC within 1.6)" | E8: Overall GC 58.7-61.5 (2.8 pts); GC_stem 71.1-74.5 (3.4 pts); dGC 30.0-31.6 (1.6 pts).
A9: 6 | B9: Reply point 7; Revised_Screen note | C9: "the search has been rerun ... reported in [Section X / Table Y]"; GC-matched decoys "generated" | D9: Give the real section / table, or remove the claim | E9: Neither file contains a rerun search or GC-matched decoy results. Do not claim them until they exist.
A10: 7 | B10: Old Table 1 footnote | C10: "a compositional contribution to its score cannot be excluded" (trna64) | D10: Delete; replaced by GC criteria in the new Table 1 legend | E10: trna64 now passes all three reference-derived GC criteria.
A11: 8 | B11: Table 2 rows: held-out 96, M. barkeri 62, shuffled 960 | C11: Scores still from the 200-record model (S1 Read Me, item 8: PROVISIONAL) | D11: Rescore with the 199-record model, or say so in the legend | E11: Only these three rows were not re-derived after the duplicate was removed.
A12: 9 | B12: Reply intro and points 1, 5 | C12: Cites Supplementary Data S2 (per-tRNA GC by region) | D12: Attach S2 | E12: S2 is not among the files provided.
