Workbook

Sheet Table 1 (manuscript)
A1: Table 1. Structural and probabilistic assessment of the nine predicted split-tRNA candidates.
A2: Candidates are ordered by combined score. p values are empirical, against the 13 randomised-genome sequences; the smallest attainable value with that control is 0.071. The decision threshold was -0.0801. Stem pairing is reported but was not used in the decision.
A4: Candidate | B4: Type | C4: Anti- codon | D4: Length (nt) | E4: GC (%) | F4: MFE (kcal/mol) | G4: Emission log-odds | H4: Transition log-odds | I4: Combined score S | J4: p vs decoys | K4: Stem pairs | L4: Conserved positions | M4: T-loop | N4: Status
A5: trna64 | B5: Sec | C5: UCA | D5: 71 | E5: 64.79 | F5: -32.9 | G5: 0.0381 | H5: 0.0406 | I5: 0.0394 | J5: 0.071 | K5: 19/21 | L5: 10/12 | M5: 5/5 | N5: Supported
A6: trna958 | B6: Sup | C6: CUA | D6: 86 | E6: 45.35 | F6: -20.3 | G6: -0.1879 | H6: -0.0968 | I6: -0.1423 | J6: 0.071 | K6: 19/21 | L6: 10/12 | M6: 5/5 | N6: Borderline
A7: trna1091 | B7: Sup | C7: CUA | D7: 88 | E7: 43.18 | F7: -29.4 | G7: -0.3172 | H7: -0.1605 | I7: -0.2388 | J7: 0.286 | K7: 19/21 | L7: 6/12 | M7: 1/5 | N7: Not supported
A8: trna1395 | B8: Sup | C8: CUA | D8: 92 | E8: 47.83 | F8: -20.6 | G8: -0.3044 | H8: -0.1894 | I8: -0.2469 | J8: 0.286 | K8: 19/21 | L8: 7/12 | M8: 4/5 | N8: Not supported
A9: trna1 | B9: Sec | C9: UCA | D9: 70 | E9: 32.86 | F9: -14.1 | G9: -0.3449 | H9: -0.2284 | I9: -0.2866 | J9: 0.357 | K9: 19/21 | L9: 7/12 | M9: 2/5 | N9: Not supported
A10: trna20 | B10: Sup | C10: UUA | D10: 70 | E10: 44.29 | F10: -16.5 | G10: -0.2854 | H10: -0.2955 | I10: -0.2905 | J10: 0.429 | K10: 20/21 | L10: 7/12 | M10: 3/5 | N10: Not supported
A11: trna9 | B11: Sup | C11: UUA | D11: 70 | E11: 30 | F11: -16.4 | G11: -0.3702 | H11: -0.2624 | I11: -0.3163 | J11: 0.429 | K11: 19/21 | L11: 7/12 | M11: 2/5 | N11: Not supported
A12: trna590 | B12: Sup | C12: UUA | D12: 80 | E12: 35 | F12: -19.3 | G12: -0.5245 | H12: -0.4042 | I12: -0.4643 | J12: 0.929 | K12: 20/21 | L12: 6/12 | M12: 2/5 | N12: Not supported
A13: trna1470 | B13: Sup | C13: CUA | D13: 93 | E13: 47.83 | F13: -20.6 | G13: -0.5057 | H13: -0.4807 | I13: -0.4932 | J13: 1 | K13: 19/21 | L13: 5/12 | M13: 1/5 | N13: Not supported
A15: Supported: combined score above the threshold, with conserved positions and T-loop within the range of known tRNAs. Borderline: above every randomised-genome sequence but below the threshold. Not supported: within the randomised-genome range.
A18: Note: the GC content of trna64 lies above the range of the randomised-genome sequences (21.1-45.1%), so a compositional contribution to its score cannot be excluded.

Sheet Table 2 (manuscript)
A1: Table 2. Probabilistic scores of the predicted candidates compared with known tRNAs and with both negative controls.
A2: All sequences were scored with the same position-specific model estimated from the 199 reference tRNAs. Values are means with standard deviations. The reference set was scored leave-one-out.
A4: Sequence set | B4: Role | C4: n | D4: Emission log-odds | E4: Transition log-odds | F4: Combined score S | G4: Range of S | H4: Stem pairing | I4: Conserved positions
A5: T-psi-C reference | B5: Model construction | C5: 199 | D5: +0.502 ± 0.143 | E5: +0.511 ± 0.133 | F5: +0.506 ± 0.135 | G5: -0.207 to +0.759 | H5: 0.978 | I5: 0.936
A6: T-psi-C held out | B6: Positive control | C6: 96 | D6: +0.489 ± 0.120 | E6: +0.499 ± 0.117 | F6: +0.494 ± 0.117 | G6: +0.029 to +0.687 | H6: 0.983 | I6: 0.941
A7: M. barkeri annotated | B7: Positive control | C7: 62 | D7: +0.421 ± 0.118 | E7: +0.424 ± 0.108 | F7: +0.422 ± 0.111 | G7: +0.241 to +0.698 | H7: 0.959 | I7: 0.952
A8: Predicted candidates | B8: Under test | C8: 9 | D8: -0.311 ± 0.158 | E8: -0.231 ± 0.148 | F8: -0.271 ± 0.151 | G8: -0.493 to +0.039 | H8: 0.915 | I8: 0.602
A9: Randomised genome | B9: Negative control | C9: 13 | D9: -0.364 ± 0.116 | E9: -0.312 ± 0.088 | F9: -0.338 ± 0.094 | G9: -0.476 to -0.189 | H9: 0.919 | I9: 0.667
A10: Base-shuffled tRNAs | B10: Negative control | C10: 960 | D10: -0.778 ± 0.155 | E10: -0.427 ± 0.103 | F10: -0.603 ± 0.113 | G10: -0.915 to -0.208 | H10: 0.400 | I10: 0.241
A12: Separation between known tRNAs and both negative controls was complete (AUC = 1.000 in each case). The decision threshold, set midway between the highest randomised-genome score and the lowest known-tRNA score, was -0.0801.

Sheet Read Me
A1: tRNA MODEL v5 — VALIDATION OF 9 PREDICTED CANDIDATES AGAINST A REALISTIC NEGATIVE CONTROL
A3: CHECKS ON THIS BATCH
A4: 1. Reference corrected to 199 | B4: The reference database now holds 199 records. The earlier version listed tdbR00000504 (Mycoplasma mycoides, Ile, CAU) twice; one of the two entries was removed. Frequencies, emission and transition matrices, background frequencies, the leave-one-out reference scores and every score and statistic that depends on the model were re-derived from the 199 records.
A5: 2. T-Psi-C OTHER 100 unchanged | B5: Byte-identical to the previous round. 101 rows, 96 unique records, 5 exact duplicate rows removed (4 Lys, 1 Tyr). Zero overlap with the reference 199.
A6: 3. MBSW 62 unchanged | B6: Byte-identical to the previous round. 62 mature archaeal tRNAs from tRNAscan-SE.
A7: 4. The 13 random-genome file is a true legacy .xls | B7: tRNA_randomgenome_13_positions_1-72.xls is a BIFF Composite Document, not a renamed .xlsx. It was converted to .xlsx before reading. It holds the same 13 sequences as the previous round: same names, same anticodons, same lengths, same gap counts.
A8: 5. The 9 pasted candidates were verified | B8: The 9 predicted candidates supplied in the message body were transcribed and compared cell by cell against the candidate file used previously: 0 differing cells across all 9 x 72. The T to U change and the anticodon spelling (UUA / CUA / UCA rather than tta / cta / tca) are notation only.
A9: 6. Every figure reproduced | B9: Before the correction, the Python pipeline reproduced every statistic of the 200-record version exactly, to the last decimal place. The same pipeline was then rerun on the 199-record reference.
A10: 7. Roles of the sets | B10: The 13 random-genome sequences are the NEGATIVE control, not candidates. The 9 predicted candidates are what is being tested. Your message refers in one place to 'our 13 candidate tRNA'; that has been read as the random-genome decoy set, consistent with how it was described when first supplied.
A11: 8. Sets 2, 3 and the permutation null | B11: PROVISIONAL. The workbook holds only the scores, not the sequences, of the 96 T-Psi-C OTHER tRNAs, the 62 MBSW tRNAs and the 960 permutations, so their emission, transition and combined scores (and the statistics built on them: weakest real tRNA, AUCs against real tRNAs, z and p vs the permutation null, the real-tRNA column of Position Deficit) are still those of the 200-record model. Everything else has been re-derived from the 199 records.
A12: WHY THE DECOY SET MATTERS
A13: The gap it closes | B13: Up to v4 the only negative control was a positional permutation of a real tRNA. That is an easy negative: a scrambled tRNA has no reason to fold at all. The realistic false positive for a split-tRNA search is genomic sequence that already folds like a tRNA, which is exactly what your predictor returns when run on randomized genome.
A14: How well matched it is | B14: The 13 decoys carry the same anticodons as the real candidates (UUA and CUA), the same declared type (Sup), and overlapping lengths (71-95 against 70-93). They are therefore a properly matched hard negative.
A15: Predictor false-positive yield | B15: 13 candidates from 50 randomized genomes = 0.26 per genome.
A17: HEADLINE RESULT
A18: Against real tRNAs | B18: Separation stays perfect: AUC = 1.000. Every one of the 158 real tRNAs outscores every decoy and every permutation.
A19: Against the decoys | B19: The combined score separates the 9 predicted from the 13 decoys only weakly: predicted -0.2711 against decoy -0.3381, Mann-Whitney p = 0.367, AUC = 0.615. Seven of the nine fall inside the decoy range.
A20: The GC confound | B20: GC content separates predicted from decoy far better than the model does (AUC 0.859, p = 0.005). After the linear GC effect is removed the difference disappears completely (p = 0.973, AUC = 0.504). On this evidence the positional model adds nothing beyond base composition when the task is telling a real candidate from a randomized-genome decoy.
A21: Identity features run the wrong way | B21: The decoys score HIGHER than the predicted candidates on invariant match (0.667 against 0.602) and on the T-loop (0.631 against 0.556). These features cannot be used to argue for the candidates.
A22: Stem pairing is uninformative here | B22: Predicted 0.915 against decoy 0.919. The predictor selects for foldability, so both sets fold. Stem pairing was used as a supporting criterion in v4; against this null it has no discriminating power and that v4 criterion is withdrawn.
A24: REVISED THRESHOLD
A25: Against the decoy null | B25: Decoy maximum -0.1890; weakest of the 158 real tRNAs +0.0288; recommended cut = midpoint -0.0801.
A26: Against the permutation null | B26: Cut against the permutation null = -0.0896. The decoy-calibrated cut is slightly stricter.
A27: Candidates clearing it | B27: 1 of 9.
A28: Candidates above the decoy maximum | B28: 2 of 9.
A30: STATISTICAL POWER — READ THIS BEFORE QUOTING ANY p VALUE
A31: The floor | B31: With 13 decoys the smallest empirical p any candidate can receive is 1/(13+1) = 0.0714. No candidate can reach p < 0.05 against this null, however good it is. The two best candidates both sit at this floor.
A32: What it would take | B32: About 99 decoys are needed before p < 0.01 is even reachable. At the observed yield of 0.26 decoys per randomized genome that means roughly 380 randomized genomes.
A33: The better experiment | B33: Generate the decoys GC-matched to the candidates, or draw them from GC-matched genomic windows. Because GC is doing all the discriminating work, a GC-matched decoy set is the test that would actually settle the question.
A35: WHAT THIS DOES AND DOES NOT SHOW
A36: Shown | B36: All 9 candidates are clearly distinguishable from real mature tRNAs, and clearly better than scrambled sequence. One candidate, trna64, also sits above every decoy and clears the decoy-calibrated threshold.
A37: Not shown | B37: That the 9 candidates as a group are distinguishable from what the predictor finds in randomized genome. On the present evidence they are not, once GC is accounted for.
A39: COMPUTED INPUTS
A40: Note | B40: Reference leave-one-out scores, the 96 T-Psi-C OTHER scores, the 62 MBSW scores, the 960 permutation scores and all ROC and Mann-Whitney statistics are computed in Python and entered as values, shown in blue. The 22 candidates and decoys are scored by live spreadsheet formula from the emission and transition tables so the chain can be audited end to end.

Sheet Database + Frequency
A1: T-PSI-C REFERENCE DATABASE (199 records, positions 1-72) WITH NUCLEOTIDE FREQUENCY BENEATH, HORIZONTAL
A2: Organism | B2: Trna No | C2: tRNA | D2: Anti codon | E2: 1 | F2: 2 | G2: 3 | H2: 4 | I2: 5 | J2: 6 | K2: 7 | L2: 8 | M2: 9 | N2: 10 | O2: 11 | P2: 12 | Q2: 13 | R2: 14 | S2: 15 | T2: 16 | U2: 17 | V2: 18 | W2: 19 | X2: 20 | Y2: 21 | Z2: 22 | AA2: 23 | AB2: 24 | AC2: 25 | AD2: 26 | AE2: 27 | AF2: 28 | AG2: 29 | AH2: 30 | AI2: 31 | AJ2: 32 | AK2: 33 | AL2: 34 | AM2: 35 | AN2: 36 | AO2: 37 | AP2: 38 | AQ2: 39 | AR2: 40 | AS2: 41 | AT2: 42 | AU2: 43 | AV2: 44 | AW2: 45 | AX2: 46 | AY2: 47 | AZ2: 48 | BA2: 49 | BB2: 50 | BC2: 51 | BD2: 52 | BE2: 53 | BF2: 54 | BG2: 55 | BH2: 56 | BI2: 57 | BJ2: 58 | BK2: 59 | BL2: 60 | BM2: 61 | BN2: 62 | BO2: 63 | BP2: 64 | BQ2: 65 | BR2: 66 | BS2: 67 | BT2: 68 | BU2: 69 | BV2: 70 | BW2: 71 | BX2: 72
A3: Aeropyrum pernix(A) | B3: tdbR00000589 | C3: ARG | D3: UCU | E3: G | F3: G | G3: G | H3: C | I3: C | J3: C | K3: G | L3: U | M3: A | N3: G | O3: C | P3: U | Q3: C | R3: A | S3: G | T3: C | U3: C | V3: G | W3: G | X3: A | Y3: A | Z3: G | AA3: A | AB3: G | AC3: C | AD3: G | AE3: C | AF3: C | AG3: G | AH3: G | AI3: C | AJ3: C | AK3: U | AL3: U | AM3: C | AN3: U | AO3: A | AP3: A | AQ3: G | AR3: C | AS3: C | AT3: G | AU3: G | AV3: U | AW3: G | AX3: C | AY3: U | AZ3: G | BA3: C | BB3: C | BC3: G | BD3: G | BE3: G | BF3: U | BG3: U | BH3: C | BI3: A | BJ3: A | BK3: A | BL3: U | BM3: C | BN3: C | BO3: C | BP3: G | BQ3: G | BR3: C | BS3: G | BT3: G | BU3: G | BV3: C | BW3: C | BX3: C
A4: Aeropyrum pernix(A) | B4: tdbR00000588 | C4: ASC | D4: GUC | E4: G | F4: C | G4: C | H4: G | I4: C | J4: G | K4: G | L4: U | M4: A | N4: G | O4: U | P4: A | Q4: U | R4: A | S4: G | T4: C | U4: C | V4: G | W4: G | X4: A | Y4: A | Z4: G | AA4: U | AB4: A | AC4: U | AD4: G | AE4: C | AF4: G | AG4: G | AH4: G | AI4: C | AJ4: C | AK4: U | AL4: G | AM4: U | AN4: C | AO4: A | AP4: A | AQ4: G | AR4: C | AS4: C | AT4: C | AU4: G | AV4: U | AW4: G | AX4: - | AY4: A | AZ4: C | BA4: C | BB4: C | BC4: G | BD4: G | BE4: G | BF4: U | BG4: U | BH4: C | BI4: A | BJ4: A | BK4: A | BL4: U | BM4: C | BN4: C | BO4: C | BP4: G | BQ4: G | BR4: C | BS4: C | BT4: G | BU4: C | BV4: G | BW4: G | BX4: C
A5: Aeropyrum pernix(A) | B5: tdbR00000583 | C5: CYS | D5: GCA | E5: G | F5: C | G5: C | H5: G | I5: G | J5: G | K5: G | L5: U | M5: G | N5: G | O5: C | P5: C | Q5: G | R5: A | S5: G | T5: - | U5: C | V5: G | W5: G | X5: U | Y5: A | Z5: A | AA5: G | AB5: G | AC5: C | AD5: G | AE5: G | AF5: C | AG5: G | AH5: G | AI5: G | AJ5: C | AK5: U | AL5: G | AM5: C | AN5: A | AO5: G | AP5: A | AQ5: C | AR5: C | AS5: C | AT5: G | AU5: U | AV5: U | AW5: A | AX5: G | AY5: U | AZ5: C | BA5: C | BB5: C | BC5: G | BD5: G | BE5: G | BF5: U | BG5: U | BH5: C | BI5: G | BJ5: A | BK5: A | BL5: U | BM5: C | BN5: C | BO5: C | BP5: G | BQ5: G | BR5: C | BS5: C | BT5: C | BU5: C | BV5: G | BW5: G | BX5: C
A6: Aeropyrum pernix(A) | B6: tdbR00000581 | C6: LYS | D6: CUU | E6: G | F6: G | G6: G | H6: C | I6: C | J6: C | K6: G | L6: U | M6: A | N6: G | O6: C | P6: U | Q6: C | R6: A | S6: G | T6: C | U6: C | V6: G | W6: G | X6: U | Y6: A | Z6: G | AA6: A | AB6: G | AC6: C | AD6: G | AE6: G | AF6: C | AG6: G | AH6: G | AI6: G | AJ6: C | AK6: U | AL6: C | AM6: U | AN6: U | AO6: A | AP6: A | AQ6: C | AR6: C | AS6: C | AT6: G | AU6: C | AV6: G | AW6: A | AX6: G | AY6: U | AZ6: C | BA6: C | BB6: C | BC6: G | BD6: G | BE6: G | BF6: U | BG6: U | BH6: C | BI6: A | BJ6: A | BK6: A | BL6: U | BM6: C | BN6: C | BO6: C | BP6: G | BQ6: G | BR6: C | BS6: G | BT6: G | BU6: G | BV6: C | BW6: C | BX6: C
A7: Aeropyrum pernix(A) | B7: tdbR00000580 | C7: LYS | D7: UUU | E7: G | F7: G | G7: G | H7: C | I7: C | J7: C | K7: G | L7: U | M7: A | N7: G | O7: C | P7: U | Q7: C | R7: A | S7: G | T7: C | U7: C | V7: G | W7: G | X7: C | Y7: A | Z7: G | AA7: A | AB7: G | AC7: C | AD7: G | AE7: G | AF7: C | AG7: G | AH7: G | AI7: G | AJ7: C | AK7: U | AL7: U | AM7: U | AN7: U | AO7: A | AP7: C | AQ7: C | AR7: C | AS7: C | AT7: G | AU7: C | AV7: G | AW7: G | AX7: A | AY7: U | AZ7: C | BA7: C | BB7: C | BC7: G | BD7: G | BE7: G | BF7: U | BG7: U | BH7: C | BI7: A | BJ7: A | BK7: A | BL7: U | BM7: C | BN7: C | BO7: C | BP7: G | BQ7: G | BR7: C | BS7: G | BT7: G | BU7: G | BV7: C | BW7: C | BX7: C
A8: Aeropyrum pernix(A) | B8: tdbR00000586 | C8: MET | D8: CAU | E8: G | F8: G | G8: G | H8: C | I8: C | J8: C | K8: G | L8: U | M8: A | N8: G | O8: C | P8: U | Q8: C | R8: A | S8: G | T8: C | U8: C | V8: G | W8: G | X8: U | Y8: A | Z8: G | AA8: A | AB8: G | AC8: C | AD8: G | AE8: C | AF8: C | AG8: C | AH8: G | AI8: G | AJ8: C | AK8: U | AL8: C | AM8: A | AN8: U | AO8: A | AP8: A | AQ8: C | AR8: C | AS8: G | AT8: G | AU8: G | AV8: U | AW8: G | AX8: G | AY8: U | AZ8: C | BA8: G | BB8: G | BC8: G | BD8: G | BE8: G | BF8: U | BG8: U | BH8: C | BI8: A | BJ8: A | BK8: A | BL8: U | BM8: C | BN8: C | BO8: C | BP8: C | BQ8: C | BR8: C | BS8: G | BT8: G | BU8: G | BV8: C | BW8: C | BX8: C
A9: Aeropyrum pernix(A) | B9: tdbR00000587 | C9: MET | D9: CAU | E9: G | F9: C | G9: C | H9: G | I9: C | J9: C | K9: G | L9: U | M9: A | N9: G | O9: C | P9: U | Q9: C | R9: A | S9: G | T9: C | U9: C | V9: G | W9: G | X9: C | Y9: A | Z9: G | AA9: A | AB9: G | AC9: C | AD9: G | AE9: C | AF9: C | AG9: G | AH9: G | AI9: A | AJ9: C | AK9: U | AL9: C | AM9: A | AN9: U | AO9: A | AP9: A | AQ9: U | AR9: C | AS9: C | AT9: G | AU9: G | AV9: A | AW9: G | AX9: G | AY9: U | AZ9: C | BA9: C | BB9: C | BC9: G | BD9: G | BE9: G | BF9: U | BG9: U | BH9: C | BI9: G | BJ9: A | BK9: A | BL9: U | BM9: C | BN9: C | BO9: C | BP9: G | BQ9: G | BR9: C | BS9: G | BT9: G | BU9: C | BV9: G | BW9: G | BX9: C
A10: Aeropyrum pernix(A) | B10: tdbR00000579 | C10: PRO | D10: CGG | E10: G | F10: G | G10: G | H10: C | I10: C | J10: C | K10: G | L10: G | M10: C | N10: G | O10: U | P10: C | Q10: U | R10: A | S10: G | T10: C | U10: C | V10: G | W10: G | X10: C | Y10: A | Z10: A | AA10: G | AB10: A | AC10: U | AD10: G | AE10: C | AF10: G | AG10: G | AH10: G | AI10: G | AJ10: U | AK10: A | AL10: C | AM10: G | AN10: G | AO10: G | AP10: A | AQ10: C | AR10: C | AS10: C | AT10: C | AU10: G | AV10: U | AW10: G | AX10: G | AY10: U | AZ10: C | BA10: C | BB10: G | BC10: G | BD10: G | BE10: G | BF10: U | BG10: U | BH10: C | BI10: A | BJ10: A | BK10: A | BL10: U | BM10: C | BN10: C | BO10: C | BP10: C | BQ10: G | BR10: C | BS10: G | BT10: G | BU10: G | BV10: C | BW10: C | BX10: C
A11: Aeropyrum pernix(A) | B11: tdbR00000584 | C11: PRO | D11: GGG | E11: G | F11: G | G11: G | H11: G | I11: C | J11: C | K11: G | L11: U | M11: C | N11: G | O11: U | P11: C | Q11: U | R11: A | S11: G | T11: C | U11: C | V11: G | W11: G | X11: C | Y11: A | Z11: G | AA11: G | AB11: A | AC11: U | AD11: G | AE11: C | AF11: C | AG11: A | AH11: G | AI11: C | AJ11: C | AK11: U | AL11: G | AM11: G | AN11: G | AO11: G | AP11: C | AQ11: G | AR11: C | AS11: U | AT11: G | AU11: G | AV11: U | AW11: G | AX11: G | AY11: U | AZ11: C | BA11: C | BB11: C | BC11: G | BD11: G | BE11: G | BF11: U | BG11: U | BH11: C | BI11: A | BJ11: A | BK11: A | BL11: U | BM11: C | BN11: C | BO11: C | BP11: G | BQ11: G | BR11: C | BS11: G | BT11: G | BU11: C | BV11: C | BW11: C | BX11: C
A12: Aeropyrum pernix(A) | B12: tdbR00000585 | C12: THR | D12: CGU | E12: G | F12: C | G12: C | H12: G | I12: C | J12: C | K12: G | L12: U | M12: A | N12: G | O12: C | P12: U | Q12: C | R12: A | S12: G | T12: - | U12: C | V12: G | W12: G | X12: U | Y12: A | Z12: G | AA12: A | AB12: G | AC12: C | AD12: G | AE12: C | AF12: C | AG12: G | AH12: G | AI12: C | AJ12: C | AK12: U | AL12: C | AM12: G | AN12: U | AO12: A | AP12: A | AQ12: G | AR12: C | AS12: C | AT12: G | AU12: G | AV12: U | AW12: G | AX12: G | AY12: U | AZ12: C | BA12: G | BB12: C | BC12: G | BD12: G | BE12: G | BF12: U | BG12: U | BH12: C | BI12: G | BJ12: A | BK12: A | BL12: U | BM12: C | BN12: C | BO12: C | BP12: G | BQ12: C | BR12: C | BS12: G | BT12: G | BU12: C | BV12: G | BW12: G | BX12: C
A13: Aeropyrum pernix(A) | B13: tdbR00000582 | C13: TYR | D13: GUA | E13: C | F13: C | G13: C | H13: G | I13: C | J13: C | K13: G | L13: U | M13: A | N13: G | O13: C | P13: U | Q13: C | R13: A | S13: G | T13: - | U13: C | V13: G | W13: G | X13: C | Y13: A | Z13: G | AA13: A | AB13: G | AC13: C | AD13: G | AE13: C | AF13: C | AG13: C | AH13: G | AI13: G | AJ13: C | AK13: U | AL13: G | AM13: U | AN13: A | AO13: C | AP13: A | AQ13: C | AR13: C | AS13: G | AT13: G | AU13: G | AV13: U | AW13: G | AX13: G | AY13: U | AZ13: C | BA13: C | BB13: G | BC13: G | BD13: G | BE13: G | BF13: U | BG13: U | BH13: C | BI13: G | BJ13: A | BK13: A | BL13: U | BM13: C | BN13: C | BO13: C | BP13: C | BQ13: G | BR13: C | BS13: G | BT13: G | BU13: C | BV13: G | BW13: G | BX13: G
A14: Escherichia coli(B) | B14: tdbR00000008 | C14: Ala | D14: GGC | E14: G | F14: G | G14: G | H14: G | I14: C | J14: U | K14: A | L14: U | M14: A | N14: G | O14: C | P14: U | Q14: C | R14: A | S14: G | T14: C | U14: U | V14: G | W14: G | X14: G | Y14: A | Z14: G | AA14: A | AB14: G | AC14: C | AD14: G | AE14: C | AF14: U | AG14: U | AH14: G | AI14: C | AJ14: A | AK14: U | AL14: G | AM14: G | AN14: C | AO14: A | AP14: U | AQ14: G | AR14: C | AS14: A | AT14: A | AU14: G | AV14: A | AW14: G | AX14: G | AY14: U | AZ14: C | BA14: A | BB14: G | BC14: C | BD14: G | BE14: G | BF14: U | BG14: U | BH14: C | BI14: G | BJ14: A | BK14: U | BL14: C | BM14: C | BN14: C | BO14: G | BP14: C | BQ14: U | BR14: U | BS14: A | BT14: G | BU14: C | BV14: U | BW14: C | BX14: C
... A201: Homo sapiens | B201: tdbR00000868 | C201: Thr | D201: AGU | E201: G | F201: C | G201: U | H201: C | I201: U | J201: U | K201: G | L201: U | M201: A | N201: G | O201: C | P201: U | Q201: C | R201: A | S201: G | T201: - | U201: U | V201: G | W201: G | X201: U | Y201: A | Z201: G | AA201: A | AB201: G | AC201: C | AD201: G | AE201: C | AF201: U | AG201: U | AH201: G | AI201: C | AJ201: C | AK201: U | AL201: A | AM201: G | AN201: U | AO201: A | AP201: A | AQ201: G | AR201: C | AS201: A | AT201: A | AU201: G | AV201: A | AW201: G | AX201: G | AY201: C | AZ201: C | BA201: C | BB201: A | BC201: G | BD201: U | BE201: G | BF201: U | BG201: U | BH201: C | BI201: A | BJ201: A | BK201: G | BL201: U | BM201: C | BN201: A | BO201: C | BP201: U | BQ201: G | BR201: C | BS201: U | BT201: G | BU201: G | BV201: A | BW201: G | BX201: C
A204: NUCLEOTIDE FREQUENCY — HORIZONTAL
A205: Counted over the 199 records above. Missing cells excluded from the valid total.
D206: Position | E206: 1 | F206: 2 | G206: 3 | H206: 4 | I206: 5 | J206: 6 | K206: 7 | L206: 8 | M206: 9 | N206: 10 | O206: 11 | P206: 12 | Q206: 13 | R206: 14 | S206: 15 | T206: 16 | U206: 17 | V206: 18 | W206: 19 | X206: 20 | Y206: 21 | Z206: 22 | AA206: 23 | AB206: 24 | AC206: 25 | AD206: 26 | AE206: 27 | AF206: 28 | AG206: 29 | AH206: 30 | AI206: 31 | AJ206: 32 | AK206: 33 | AL206: 34 | AM206: 35 | AN206: 36 | AO206: 37 | AP206: 38 | AQ206: 39 | AR206: 40 | AS206: 41 | AT206: 42 | AU206: 43 | AV206: 44 | AW206: 45 | AX206: 46 | AY206: 47 | AZ206: 48 | BA206: 49 | BB206: 50 | BC206: 51 | BD206: 52 | BE206: 53 | BF206: 54 | BG206: 55 | BH206: 56 | BI206: 57 | BJ206: 58 | BK206: 59 | BL206: 60 | BM206: 61 | BN206: 62 | BO206: 63 | BP206: 64 | BQ206: 65 | BR206: 66 | BS206: 67 | BT206: 68 | BU206: 69 | BV206: 70 | BW206: 71 | BX206: 72
D207: A | E207: 13 | F207: 6 | G207: 14 | H207: 15 | I207: 30 | J207: 34 | K207: 47 | L207: 1 | M207: 130 | N207: 0 | O207: 7 | P207: 13 | Q207: 13 | R207: 197 | S207: 33 | T207: 3 | U207: 12 | V207: 1 | W207: 1 | X207: 17 | Y207: 178 | Z207: 41 | AA207: 120 | AB207: 37 | AC207: 1 | AD207: 83 | AE207: 24 | AF207: 24 | AG207: 32 | AH207: 0 | AI207: 54 | AJ207: 6 | AK207: 1 | AL207: 9 | AM207: 61 | AN207: 43 | AO207: 150 | AP207: 146 | AQ207: 18 | AR207: 1 | AS207: 54 | AT207: 48 | AU207: 45 | AV207: 99 | AW207: 15 | AX207: 16 | AY207: 26 | AZ207: 1 | BA207: 31 | BB207: 23 | BC207: 28 | BD207: 26 | BE207: 1 | BF207: 2 | BG207: 1 | BH207: 2 | BI207: 76 | BJ207: 197 | BK207: 91 | BL207: 1 | BM207: 0 | BN207: 3 | BO207: 22 | BP207: 32 | BQ207: 9 | BR207: 43 | BS207: 41 | BT207: 15 | BU207: 25 | BV207: 23 | BW207: 5 | BX207: 16
D208: C | E208: 21 | F208: 82 | G208: 77 | H208: 61 | I208: 79 | J208: 65 | K208: 3 | L208: 0 | M208: 7 | N208: 8 | O208: 146 | P208: 29 | Q208: 129 | R208: 1 | S208: 2 | T208: 47 | U208: 63 | V208: 0 | W208: 0 | X208: 45 | Y208: 4 | Z208: 0 | AA208: 38 | AB208: 6 | AC208: 177 | AD208: 5 | AE208: 93 | AF208: 103 | AG208: 35 | AH208: 42 | AI208: 72 | AJ208: 134 | AK208: 1 | AL208: 66 | AM208: 46 | AN208: 53 | AO208: 1 | AP208: 29 | AQ208: 50 | AR208: 143 | AS208: 77 | AT208: 20 | AU208: 23 | AV208: 31 | AW208: 5 | AX208: 4 | AY208: 23 | AZ208: 167 | BA208: 57 | BB208: 87 | BC208: 41 | BD208: 2 | BE208: 1 | BF208: 0 | BG208: 1 | BH208: 195 | BI208: 0 | BJ208: 1 | BK208: 12 | BL208: 40 | BM208: 197 | BN208: 168 | BO208: 97 | BP208: 42 | BQ208: 63 | BR208: 105 | BS208: 45 | BT208: 62 | BU208: 88 | BV208: 71 | BW208: 103 | BX208: 145
D209: G | E209: 152 | F209: 105 | G209: 85 | H209: 89 | I209: 69 | J209: 48 | K209: 105 | L209: 1 | M209: 61 | N209: 191 | O209: 6 | P209: 38 | Q209: 19 | R209: 1 | S209: 161 | T209: 3 | U209: 8 | V209: 198 | W209: 196 | X209: 18 | Y209: 7 | Z209: 144 | AA209: 29 | AB209: 149 | AC209: 7 | AD209: 100 | AE209: 31 | AF209: 22 | AG209: 77 | AH209: 150 | AI209: 54 | AJ209: 0 | AK209: 0 | AL209: 66 | AM209: 51 | AN209: 32 | AO209: 48 | AP209: 1 | AQ209: 72 | AR209: 47 | AS209: 35 | AT209: 105 | AU209: 99 | AV209: 46 | AW209: 149 | AX209: 136 | AY209: 16 | AZ209: 2 | BA209: 100 | BB209: 54 | BC209: 99 | BD209: 167 | BE209: 195 | BF209: 0 | BG209: 1 | BH209: 1 | BI209: 121 | BJ209: 0 | BK209: 46 | BL209: 2 | BM209: 1 | BN209: 2 | BO209: 48 | BP209: 92 | BQ209: 57 | BR209: 2 | BS209: 75 | BT209: 87 | BU209: 70 | BV209: 75 | BW209: 82 | BX209: 17
D210: U | E210: 13 | F210: 6 | G210: 23 | H210: 34 | I210: 21 | J210: 52 | K210: 44 | L210: 197 | M210: 0 | N210: 0 | O210: 40 | P210: 119 | Q210: 38 | R210: 0 | S210: 2 | T210: 79 | U210: 113 | V210: 0 | W210: 2 | X210: 118 | Y210: 10 | Z210: 14 | AA210: 12 | AB210: 7 | AC210: 14 | AD210: 11 | AE210: 51 | AF210: 50 | AG210: 55 | AH210: 7 | AI210: 19 | AJ210: 59 | AK210: 197 | AL210: 58 | AM210: 41 | AN210: 71 | AO210: 0 | AP210: 23 | AQ210: 59 | AR210: 8 | AS210: 33 | AT210: 26 | AU210: 32 | AV210: 23 | AW210: 28 | AX210: 12 | AY210: 134 | AZ210: 29 | BA210: 11 | BB210: 35 | BC210: 30 | BD210: 4 | BE210: 2 | BF210: 197 | BG210: 196 | BH210: 1 | BI210: 1 | BJ210: 1 | BK210: 50 | BL210: 156 | BM210: 1 | BN210: 26 | BO210: 32 | BP210: 33 | BQ210: 69 | BR210: 49 | BS210: 38 | BT210: 35 | BU210: 16 | BV210: 30 | BW210: 9 | BX210: 21
D211: Missing | E211: 0 | F211: 0 | G211: 0 | H211: 0 | I211: 0 | J211: 0 | K211: 0 | L211: 0 | M211: 1 | N211: 0 | O211: 0 | P211: 0 | Q211: 0 | R211: 0 | S211: 1 | T211: 67 | U211: 3 | V211: 0 | W211: 0 | X211: 1 | Y211: 0 | Z211: 0 | AA211: 0 | AB211: 0 | AC211: 0 | AD211: 0 | AE211: 0 | AF211: 0 | AG211: 0 | AH211: 0 | AI211: 0 | AJ211: 0 | AK211: 0 | AL211: 0 | AM211: 0 | AN211: 0 | AO211: 0 | AP211: 0 | AQ211: 0 | AR211: 0 | AS211: 0 | AT211: 0 | AU211: 0 | AV211: 0 | AW211: 2 | AX211: 31 | AY211: 0 | AZ211: 0 | BA211: 0 | BB211: 0 | BC211: 1 | BD211: 0 | BE211: 0 | BF211: 0 | BG211: 0 | BH211: 0 | BI211: 1 | BJ211: 0 | BK211: 0 | BL211: 0 | BM211: 0 | BN211: 0 | BO211: 0 | BP211: 0 | BQ211: 1 | BR211: 0 | BS211: 0 | BT211: 0 | BU211: 0 | BV211: 0 | BW211: 0 | BX211: 0
D212: Valid total | E212: =SUM(E207:E210) -> 199 | F212: =SUM(F207:F210) -> 199 | G212: =SUM(G207:G210) -> 199 | H212: =SUM(H207:H210) -> 199 | I212: =SUM(I207:I210) -> 199 | J212: =SUM(J207:J210) -> 199 | K212: =SUM(K207:K210) -> 199 | L212: =SUM(L207:L210) -> 199 | ... BX212: =SUM(BX207:BX210) -> 199
D213: Check = 199 | E213: =E211+E212 -> 199 | F213: =F211+F212 -> 199 | G213: =G211+G212 -> 199 | H213: =H211+H212 -> 199 | I213: =I211+I212 -> 199 | J213: =J211+J212 -> 199 | K213: =K211+K212 -> 199 | L213: =L211+L212 -> 199 | ... BX213: =BX211+BX212 -> 199
D214: Most frequent | E214: G | F214: G | G214: G | H214: G | I214: C | J214: C | K214: G | L214: U | M214: A | N214: G | O214: C | P214: U | Q214: C | R214: A | S214: G | T214: U | U214: U | V214: G | W214: G | X214: U | Y214: A | Z214: G | AA214: A | AB214: G | AC214: C | AD214: G | AE214: C | AF214: C | AG214: G | AH214: G | AI214: C | AJ214: C | AK214: U | AL214: C/G | AM214: A | AN214: U | AO214: A | AP214: A | AQ214: G | AR214: C | AS214: C | AT214: G | AU214: G | AV214: A | AW214: G | AX214: G | AY214: U | AZ214: C | BA214: G | BB214: C | BC214: G | BD214: G | BE214: G | BF214: U | BG214: U | BH214: C | BI214: G | BJ214: A | BK214: A | BL214: U | BM214: C | BN214: C | BO214: C | BP214: G | BQ214: U | BR214: C | BS214: G | BT214: G | BU214: C | BV214: G | BW214: C | BX214: C
D215: Its share | E215: =MAX(E207:E210)/E212 -> 0.7638191 | F215: =MAX(F207:F210)/F212 -> 0.52763819 | G215: =MAX(G207:G210)/G212 -> 0.42713568 | H215: =MAX(H207:H210)/H212 -> 0.44723618 | I215: =MAX(I207:I210)/I212 -> 0.39698492 | J215: =MAX(J207:J210)/J212 -> 0.32663317 | K215: =MAX(K207:K210)/K212 -> 0.52763819 | L215: =MAX(L207:L210)/L212 -> 0.98994975 | ... BX215: =MAX(BX207:BX210)/BX212 -> 0.72864322

Sheet Frequency 1-72
A1: Position | B1: A | C1: C | D1: G | E1: U | F1: Missing | G1: Valid total | H1: Check total = 199
A2: 1 | B2: ='Database + Frequency'!E207 -> 13 | C2: ='Database + Frequency'!E208 -> 21 | D2: ='Database + Frequency'!E209 -> 152 | E2: ='Database + Frequency'!E210 -> 13 | F2: ='Database + Frequency'!E211 -> 0 | G2: =SUM(B2:E2) -> 199 | H2: =F2+G2 -> 199
A3: 2 | B3: ='Database + Frequency'!F207 -> 6 | C3: ='Database + Frequency'!F208 -> 82 | D3: ='Database + Frequency'!F209 -> 105 | E3: ='Database + Frequency'!F210 -> 6 | F3: ='Database + Frequency'!F211 -> 0 | G3: =SUM(B3:E3) -> 199 | H3: =F3+G3 -> 199
A4: 3 | B4: ='Database + Frequency'!G207 -> 14 | C4: ='Database + Frequency'!G208 -> 77 | D4: ='Database + Frequency'!G209 -> 85 | E4: ='Database + Frequency'!G210 -> 23 | F4: ='Database + Frequency'!G211 -> 0 | G4: =SUM(B4:E4) -> 199 | H4: =F4+G4 -> 199
A5: 4 | B5: ='Database + Frequency'!H207 -> 15 | C5: ='Database + Frequency'!H208 -> 61 | D5: ='Database + Frequency'!H209 -> 89 | E5: ='Database + Frequency'!H210 -> 34 | F5: ='Database + Frequency'!H211 -> 0 | G5: =SUM(B5:E5) -> 199 | H5: =F5+G5 -> 199
A6: 5 | B6: ='Database + Frequency'!I207 -> 30 | C6: ='Database + Frequency'!I208 -> 79 | D6: ='Database + Frequency'!I209 -> 69 | E6: ='Database + Frequency'!I210 -> 21 | F6: ='Database + Frequency'!I211 -> 0 | G6: =SUM(B6:E6) -> 199 | H6: =F6+G6 -> 199
A7: 6 | B7: ='Database + Frequency'!J207 -> 34 | C7: ='Database + Frequency'!J208 -> 65 | D7: ='Database + Frequency'!J209 -> 48 | E7: ='Database + Frequency'!J210 -> 52 | F7: ='Database + Frequency'!J211 -> 0 | G7: =SUM(B7:E7) -> 199 | H7: =F7+G7 -> 199
A8: 7 | B8: ='Database + Frequency'!K207 -> 47 | C8: ='Database + Frequency'!K208 -> 3 | D8: ='Database + Frequency'!K209 -> 105 | E8: ='Database + Frequency'!K210 -> 44 | F8: ='Database + Frequency'!K211 -> 0 | G8: =SUM(B8:E8) -> 199 | H8: =F8+G8 -> 199
A9: 8 | B9: ='Database + Frequency'!L207 -> 1 | C9: ='Database + Frequency'!L208 -> 0 | D9: ='Database + Frequency'!L209 -> 1 | E9: ='Database + Frequency'!L210 -> 197 | F9: ='Database + Frequency'!L211 -> 0 | G9: =SUM(B9:E9) -> 199 | H9: =F9+G9 -> 199
A10: 9 | B10: ='Database + Frequency'!M207 -> 130 | C10: ='Database + Frequency'!M208 -> 7 | D10: ='Database + Frequency'!M209 -> 61 | E10: ='Database + Frequency'!M210 -> 0 | F10: ='Database + Frequency'!M211 -> 1 | G10: =SUM(B10:E10) -> 198 | H10: =F10+G10 -> 199
A11: 10 | B11: ='Database + Frequency'!N207 -> 0 | C11: ='Database + Frequency'!N208 -> 8 | D11: ='Database + Frequency'!N209 -> 191 | E11: ='Database + Frequency'!N210 -> 0 | F11: ='Database + Frequency'!N211 -> 0 | G11: =SUM(B11:E11) -> 199 | H11: =F11+G11 -> 199
A12: 11 | B12: ='Database + Frequency'!O207 -> 7 | C12: ='Database + Frequency'!O208 -> 146 | D12: ='Database + Frequency'!O209 -> 6 | E12: ='Database + Frequency'!O210 -> 40 | F12: ='Database + Frequency'!O211 -> 0 | G12: =SUM(B12:E12) -> 199 | H12: =F12+G12 -> 199
A13: 12 | B13: ='Database + Frequency'!P207 -> 13 | C13: ='Database + Frequency'!P208 -> 29 | D13: ='Database + Frequency'!P209 -> 38 | E13: ='Database + Frequency'!P210 -> 119 | F13: ='Database + Frequency'!P211 -> 0 | G13: =SUM(B13:E13) -> 199 | H13: =F13+G13 -> 199
A14: 13 | B14: ='Database + Frequency'!Q207 -> 13 | C14: ='Database + Frequency'!Q208 -> 129 | D14: ='Database + Frequency'!Q209 -> 19 | E14: ='Database + Frequency'!Q210 -> 38 | F14: ='Database + Frequency'!Q211 -> 0 | G14: =SUM(B14:E14) -> 199 | H14: =F14+G14 -> 199
A15: 14 | B15: ='Database + Frequency'!R207 -> 197 | C15: ='Database + Frequency'!R208 -> 1 | D15: ='Database + Frequency'!R209 -> 1 | E15: ='Database + Frequency'!R210 -> 0 | F15: ='Database + Frequency'!R211 -> 0 | G15: =SUM(B15:E15) -> 199 | H15: =F15+G15 -> 199
A16: 15 | B16: ='Database + Frequency'!S207 -> 33 | C16: ='Database + Frequency'!S208 -> 2 | D16: ='Database + Frequency'!S209 -> 161 | E16: ='Database + Frequency'!S210 -> 2 | F16: ='Database + Frequency'!S211 -> 1 | G16: =SUM(B16:E16) -> 198 | H16: =F16+G16 -> 199
A17: 16 | B17: ='Database + Frequency'!T207 -> 3 | C17: ='Database + Frequency'!T208 -> 47 | D17: ='Database + Frequency'!T209 -> 3 | E17: ='Database + Frequency'!T210 -> 79 | F17: ='Database + Frequency'!T211 -> 67 | G17: =SUM(B17:E17) -> 132 | H17: =F17+G17 -> 199
A18: 17 | B18: ='Database + Frequency'!U207 -> 12 | C18: ='Database + Frequency'!U208 -> 63 | D18: ='Database + Frequency'!U209 -> 8 | E18: ='Database + Frequency'!U210 -> 113 | F18: ='Database + Frequency'!U211 -> 3 | G18: =SUM(B18:E18) -> 196 | H18: =F18+G18 -> 199
A19: 18 | B19: ='Database + Frequency'!V207 -> 1 | C19: ='Database + Frequency'!V208 -> 0 | D19: ='Database + Frequency'!V209 -> 198 | E19: ='Database + Frequency'!V210 -> 0 | F19: ='Database + Frequency'!V211 -> 0 | G19: =SUM(B19:E19) -> 199 | H19: =F19+G19 -> 199
A20: 19 | B20: ='Database + Frequency'!W207 -> 1 | C20: ='Database + Frequency'!W208 -> 0 | D20: ='Database + Frequency'!W209 -> 196 | E20: ='Database + Frequency'!W210 -> 2 | F20: ='Database + Frequency'!W211 -> 0 | G20: =SUM(B20:E20) -> 199 | H20: =F20+G20 -> 199
A21: 20 | B21: ='Database + Frequency'!X207 -> 17 | C21: ='Database + Frequency'!X208 -> 45 | D21: ='Database + Frequency'!X209 -> 18 | E21: ='Database + Frequency'!X210 -> 118 | F21: ='Database + Frequency'!X211 -> 1 | G21: =SUM(B21:E21) -> 198 | H21: =F21+G21 -> 199
A22: 21 | B22: ='Database + Frequency'!Y207 -> 178 | C22: ='Database + Frequency'!Y208 -> 4 | D22: ='Database + Frequency'!Y209 -> 7 | E22: ='Database + Frequency'!Y210 -> 10 | F22: ='Database + Frequency'!Y211 -> 0 | G22: =SUM(B22:E22) -> 199 | H22: =F22+G22 -> 199
A23: 22 | B23: ='Database + Frequency'!Z207 -> 41 | C23: ='Database + Frequency'!Z208 -> 0 | D23: ='Database + Frequency'!Z209 -> 144 | E23: ='Database + Frequency'!Z210 -> 14 | F23: ='Database + Frequency'!Z211 -> 0 | G23: =SUM(B23:E23) -> 199 | H23: =F23+G23 -> 199
A24: 23 | B24: ='Database + Frequency'!AA207 -> 120 | C24: ='Database + Frequency'!AA208 -> 38 | D24: ='Database + Frequency'!AA209 -> 29 | E24: ='Database + Frequency'!AA210 -> 12 | F24: ='Database + Frequency'!AA211 -> 0 | G24: =SUM(B24:E24) -> 199 | H24: =F24+G24 -> 199
A25: 24 | B25: ='Database + Frequency'!AB207 -> 37 | C25: ='Database + Frequency'!AB208 -> 6 | D25: ='Database + Frequency'!AB209 -> 149 | E25: ='Database + Frequency'!AB210 -> 7 | F25: ='Database + Frequency'!AB211 -> 0 | G25: =SUM(B25:E25) -> 199 | H25: =F25+G25 -> 199
A26: 25 | B26: ='Database + Frequency'!AC207 -> 1 | C26: ='Database + Frequency'!AC208 -> 177 | D26: ='Database + Frequency'!AC209 -> 7 | E26: ='Database + Frequency'!AC210 -> 14 | F26: ='Database + Frequency'!AC211 -> 0 | G26: =SUM(B26:E26) -> 199 | H26: =F26+G26 -> 199
A27: 26 | B27: ='Database + Frequency'!AD207 -> 83 | C27: ='Database + Frequency'!AD208 -> 5 | D27: ='Database + Frequency'!AD209 -> 100 | E27: ='Database + Frequency'!AD210 -> 11 | F27: ='Database + Frequency'!AD211 -> 0 | G27: =SUM(B27:E27) -> 199 | H27: =F27+G27 -> 199
A28: 27 | B28: ='Database + Frequency'!AE207 -> 24 | C28: ='Database + Frequency'!AE208 -> 93 | D28: ='Database + Frequency'!AE209 -> 31 | E28: ='Database + Frequency'!AE210 -> 51 | F28: ='Database + Frequency'!AE211 -> 0 | G28: =SUM(B28:E28) -> 199 | H28: =F28+G28 -> 199
A29: 28 | B29: ='Database + Frequency'!AF207 -> 24 | C29: ='Database + Frequency'!AF208 -> 103 | D29: ='Database + Frequency'!AF209 -> 22 | E29: ='Database + Frequency'!AF210 -> 50 | F29: ='Database + Frequency'!AF211 -> 0 | G29: =SUM(B29:E29) -> 199 | H29: =F29+G29 -> 199
A30: 29 | B30: ='Database + Frequency'!AG207 -> 32 | C30: ='Database + Frequency'!AG208 -> 35 | D30: ='Database + Frequency'!AG209 -> 77 | E30: ='Database + Frequency'!AG210 -> 55 | F30: ='Database + Frequency'!AG211 -> 0 | G30: =SUM(B30:E30) -> 199 | H30: =F30+G30 -> 199
A31: 30 | B31: ='Database + Frequency'!AH207 -> 0 | C31: ='Database + Frequency'!AH208 -> 42 | D31: ='Database + Frequency'!AH209 -> 150 | E31: ='Database + Frequency'!AH210 -> 7 | F31: ='Database + Frequency'!AH211 -> 0 | G31: =SUM(B31:E31) -> 199 | H31: =F31+G31 -> 199
A32: 31 | B32: ='Database + Frequency'!AI207 -> 54 | C32: ='Database + Frequency'!AI208 -> 72 | D32: ='Database + Frequency'!AI209 -> 54 | E32: ='Database + Frequency'!AI210 -> 19 | F32: ='Database + Frequency'!AI211 -> 0 | G32: =SUM(B32:E32) -> 199 | H32: =F32+G32 -> 199
A33: 32 | B33: ='Database + Frequency'!AJ207 -> 6 | C33: ='Database + Frequency'!AJ208 -> 134 | D33: ='Database + Frequency'!AJ209 -> 0 | E33: ='Database + Frequency'!AJ210 -> 59 | F33: ='Database + Frequency'!AJ211 -> 0 | G33: =SUM(B33:E33) -> 199 | H33: =F33+G33 -> 199
A34: 33 | B34: ='Database + Frequency'!AK207 -> 1 | C34: ='Database + Frequency'!AK208 -> 1 | D34: ='Database + Frequency'!AK209 -> 0 | E34: ='Database + Frequency'!AK210 -> 197 | F34: ='Database + Frequency'!AK211 -> 0 | G34: =SUM(B34:E34) -> 199 | H34: =F34+G34 -> 199
A35: 34 | B35: ='Database + Frequency'!AL207 -> 9 | C35: ='Database + Frequency'!AL208 -> 66 | D35: ='Database + Frequency'!AL209 -> 66 | E35: ='Database + Frequency'!AL210 -> 58 | F35: ='Database + Frequency'!AL211 -> 0 | G35: =SUM(B35:E35) -> 199 | H35: =F35+G35 -> 199
A36: 35 | B36: ='Database + Frequency'!AM207 -> 61 | C36: ='Database + Frequency'!AM208 -> 46 | D36: ='Database + Frequency'!AM209 -> 51 | E36: ='Database + Frequency'!AM210 -> 41 | F36: ='Database + Frequency'!AM211 -> 0 | G36: =SUM(B36:E36) -> 199 | H36: =F36+G36 -> 199
A37: 36 | B37: ='Database + Frequency'!AN207 -> 43 | C37: ='Database + Frequency'!AN208 -> 53 | D37: ='Database + Frequency'!AN209 -> 32 | E37: ='Database + Frequency'!AN210 -> 71 | F37: ='Database + Frequency'!AN211 -> 0 | G37: =SUM(B37:E37) -> 199 | H37: =F37+G37 -> 199
A38: 37 | B38: ='Database + Frequency'!AO207 -> 150 | C38: ='Database + Frequency'!AO208 -> 1 | D38: ='Database + Frequency'!AO209 -> 48 | E38: ='Database + Frequency'!AO210 -> 0 | F38: ='Database + Frequency'!AO211 -> 0 | G38: =SUM(B38:E38) -> 199 | H38: =F38+G38 -> 199
A39: 38 | B39: ='Database + Frequency'!AP207 -> 146 | C39: ='Database + Frequency'!AP208 -> 29 | D39: ='Database + Frequency'!AP209 -> 1 | E39: ='Database + Frequency'!AP210 -> 23 | F39: ='Database + Frequency'!AP211 -> 0 | G39: =SUM(B39:E39) -> 199 | H39: =F39+G39 -> 199
A40: 39 | B40: ='Database + Frequency'!AQ207 -> 18 | C40: ='Database + Frequency'!AQ208 -> 50 | D40: ='Database + Frequency'!AQ209 -> 72 | E40: ='Database + Frequency'!AQ210 -> 59 | F40: ='Database + Frequency'!AQ211 -> 0 | G40: =SUM(B40:E40) -> 199 | H40: =F40+G40 -> 199
...

Sheet Background
A1: BACKGROUND FREQUENCIES (reference set, pooled over all 72 positions)
A3: Base | B3: Total count | C3: Background p
A4: A | B4: =SUM('Frequency 1-72'!B2:B73) -> 2633 | C4: =B4/$B$8 -> 0.18517477
A5: C | B5: =SUM('Frequency 1-72'!C2:C73) -> 3936 | C5: =B5/$B$8 -> 0.27681272
A6: G | B6: =SUM('Frequency 1-72'!D2:D73) -> 4623 | C6: =B6/$B$8 -> 0.32512835
A7: U | B7: =SUM('Frequency 1-72'!E2:E73) -> 3027 | C7: =B7/$B$8 -> 0.21288417
A8: Total | B8: =SUM(B4:B7) -> 14219
A9: GC content | B9: =(B5+B6)/B8 -> 0.60194106
A11: From | B11: To | C11: Dinucleotide count | D11: Background p(Y|X) | E11: Key (From&To)
A12: A | B12: A | C12: =SUMIFS('Transition Stepwise'!$F$2:$F$1137,'Transition Stepwise'!$C$2:$C$1137,A12,'Transition Stepwise'!$D$2:$D$1137,B12) -> 569 | D12: =(C12+1)/(SUMIF($A$12:$A$27,A12,$C$12:$C$27)+4*1) -> 0.21956857 | E12: =A12&B12 -> AA
A13: A | B13: C | C13: =SUMIFS('Transition Stepwise'!$F$2:$F$1137,'Transition Stepwise'!$C$2:$C$1137,A13,'Transition Stepwise'!$D$2:$D$1137,B13) -> 417 | D13: =(C13+1)/(SUMIF($A$12:$A$27,A13,$C$12:$C$27)+4*1) -> 0.16101695 | E13: =A13&B13 -> AC
A14: A | B14: G | C14: =SUMIFS('Transition Stepwise'!$F$2:$F$1137,'Transition Stepwise'!$C$2:$C$1137,A14,'Transition Stepwise'!$D$2:$D$1137,B14) -> 1102 | D14: =(C14+1)/(SUMIF($A$12:$A$27,A14,$C$12:$C$27)+4*1) -> 0.42488444 | E14: =A14&B14 -> AG
A15: A | B15: U | C15: =SUMIFS('Transition Stepwise'!$F$2:$F$1137,'Transition Stepwise'!$C$2:$C$1137,A15,'Transition Stepwise'!$D$2:$D$1137,B15) -> 504 | D15: =(C15+1)/(SUMIF($A$12:$A$27,A15,$C$12:$C$27)+4*1) -> 0.19453005 | E15: =A15&B15 -> AU
A16: C | B16: A | C16: =SUMIFS('Transition Stepwise'!$F$2:$F$1137,'Transition Stepwise'!$C$2:$C$1137,A16,'Transition Stepwise'!$D$2:$D$1137,B16) -> 738 | D16: =(C16+1)/(SUMIF($A$12:$A$27,A16,$C$12:$C$27)+4*1) -> 0.19488397 | E16: =A16&B16 -> CA
A17: C | B17: C | C17: =SUMIFS('Transition Stepwise'!$F$2:$F$1137,'Transition Stepwise'!$C$2:$C$1137,A17,'Transition Stepwise'!$D$2:$D$1137,B17) -> 1183 | D17: =(C17+1)/(SUMIF($A$12:$A$27,A17,$C$12:$C$27)+4*1) -> 0.31223629 | E17: =A17&B17 -> CC
A18: C | B18: G | C18: =SUMIFS('Transition Stepwise'!$F$2:$F$1137,'Transition Stepwise'!$C$2:$C$1137,A18,'Transition Stepwise'!$D$2:$D$1137,B18) -> 1123 | D18: =(C18+1)/(SUMIF($A$12:$A$27,A18,$C$12:$C$27)+4*1) -> 0.2964135 | E18: =A18&B18 -> CG
A19: C | B19: U | C19: =SUMIFS('Transition Stepwise'!$F$2:$F$1137,'Transition Stepwise'!$C$2:$C$1137,A19,'Transition Stepwise'!$D$2:$D$1137,B19) -> 744 | D19: =(C19+1)/(SUMIF($A$12:$A$27,A19,$C$12:$C$27)+4*1) -> 0.19646624 | E19: =A19&B19 -> CU
A20: G | B20: A | C20: =SUMIFS('Transition Stepwise'!$F$2:$F$1137,'Transition Stepwise'!$C$2:$C$1137,A20,'Transition Stepwise'!$D$2:$D$1137,B20) -> 746 | D20: =(C20+1)/(SUMIF($A$12:$A$27,A20,$C$12:$C$27)+4*1) -> 0.16435644 | E20: =A20&B20 -> GA
A21: G | B21: C | C21: =SUMIFS('Transition Stepwise'!$F$2:$F$1137,'Transition Stepwise'!$C$2:$C$1137,A21,'Transition Stepwise'!$D$2:$D$1137,B21) -> 1163 | D21: =(C21+1)/(SUMIF($A$12:$A$27,A21,$C$12:$C$27)+4*1) -> 0.25610561 | E21: =A21&B21 -> GC
A22: G | B22: G | C22: =SUMIFS('Transition Stepwise'!$F$2:$F$1137,'Transition Stepwise'!$C$2:$C$1137,A22,'Transition Stepwise'!$D$2:$D$1137,B22) -> 1566 | D22: =(C22+1)/(SUMIF($A$12:$A$27,A22,$C$12:$C$27)+4*1) -> 0.34477448 | E22: =A22&B22 -> GG
A23: G | B23: U | C23: =SUMIFS('Transition Stepwise'!$F$2:$F$1137,'Transition Stepwise'!$C$2:$C$1137,A23,'Transition Stepwise'!$D$2:$D$1137,B23) -> 1066 | D23: =(C23+1)/(SUMIF($A$12:$A$27,A23,$C$12:$C$27)+4*1) -> 0.23476348 | E23: =A23&B23 -> GU
... A27: U | B27: U | C27: =SUMIFS('Transition Stepwise'!$F$2:$F$1137,'Transition Stepwise'!$C$2:$C$1137,A27,'Transition Stepwise'!$D$2:$D$1137,B27) -> 660 | D27: =(C27+1)/(SUMIF($A$12:$A$27,A27,$C$12:$C$27)+4*1) -> 0.22048032 | E27: =A27&B27 -> UU
A29: Column E is a plain concatenation key. It lets the dinucleotide background be looked up with an ordinary MATCH, which Excel 2007 evaluates without array entry (Ctrl+Shift+Enter).

Sheet Formulas
A1: EVERY FORMULA USED, STEP BY STEP
A2: All functions listed are available in Excel 2007.
A4: Step | B4: Quantity | C4: Algebra | D4: Spreadsheet implementation (without the leading = sign) | E4: Where
A5: 1 | B5: Frequency | C5: n(b,i) = records with base b at position i | D5: counted from the database block | E5: Database + Frequency
A6: 2 | B6: Valid total | C6: N(i) = n(A,i)+n(C,i)+n(G,i)+n(U,i) | D6: SUM over the four base rows | E6: Frequency 1-72 col G
A7: 3 | B7: Emission raw | C7: e_raw(b,i) = n(b,i) / N(i) | D7: D/E | E7: Emission Stepwise col G
A8: 4 | B8: Emission smoothed | C8: e(b,i) = ( n(b,i) + a ) / ( N(i) + 4a ) | D8: I/J | E8: Emission Stepwise col H
A9: 5 | B9: Emission check | C9: sum over b of e(b,i) = 1 | D9: ROUND(SUMIF(position,i,smoothed),9) | E9: Emission Stepwise col L
A10: 6 | B10: Background base | C10: q(b) = sum over i n(b,i) / grand total | D10: SUM(col)/total | E10: Background C4:C7
A11: 7 | B11: Transition count | C11: c(X->Y,i) = records with X at i and Y at i+1 | D11: counted from the database block | E11: Transition Stepwise col F
A12: 8 | B12: FROM total | C12: Cx(X,i) = sum over Y of c(X->Y,i) | D12: SUMIFS(count, step, i, from, X) | E12: Transition Stepwise col G
A13: 9 | B13: Transition raw | C13: t_raw(Y|X,i) = c(X->Y,i) / Cx(X,i) | D13: F/G | E13: Transition Stepwise col I
A14: 10 | B14: Transition smoothed | C14: t(Y|X,i) = ( c(X->Y,i) + a ) / ( Cx(X,i) + 4a ) | D14: K/L | E14: Transition Stepwise col J
A15: 11 | B15: Transition check | C15: sum over Y of t(Y|X,i) = 1 | D15: ROUND(SUMIFS(smoothed, step, i, from, X),9) | E15: Transition Stepwise col N
A16: 12 | B16: Background dinucleotide | C16: qd(Y|X) = ( sum over i c(X->Y,i) + a ) / ( sum over i,Y c(X->Y,i) + 4a ) | D16: (C+1)/(SUMIF+4) | E16: Background D12:D27
... A30: 26 | B30: GC-adjusted residual | C30: r = S - ( mean(S) + b*( GC - mean(GC) ) ) | D30: computed in Python | E30: GC Confound
A33: a = alpha = 1 (Laplace smoothing).

Sheet Emission Stepwise
A1: Position | B1: Base | C1: Key | D1: Count n | E1: Valid N | F1: Alpha | G1: Raw e_raw | H1: Smoothed e | I1: n+a | J1: N+4a | K1: Formula | L1: Check sum
A2: 1 | B2: A | C2: =A2&"|"&B2 -> 1|A | D2: =INDEX('Frequency 1-72'!$B$2:$E$73,A2,MATCH(B2,{"A","C","G","U"},0)) -> 13 | E2: ='Frequency 1-72'!G2 -> 199 | F2: 1 | G2: =IF(E2=0,"",D2/E2) -> 0.065326633 | H2: =I2/J2 -> 0.068965517 | I2: =D2+F2 -> 14 | J2: =E2+4*F2 -> 203 | K2: e = (n + a) / (N + 4a) | L2: =ROUND(SUMIF($A$2:$A$289,A2,$H$2:$H$289),9) -> 1
A3: 1 | B3: C | C3: =A3&"|"&B3 -> 1|C | D3: =INDEX('Frequency 1-72'!$B$2:$E$73,A3,MATCH(B3,{"A","C","G","U"},0)) -> 21 | E3: ='Frequency 1-72'!G2 -> 199 | F3: 1 | G3: =IF(E3=0,"",D3/E3) -> 0.10552764 | H3: =I3/J3 -> 0.10837438 | I3: =D3+F3 -> 22 | J3: =E3+4*F3 -> 203 | K3: e = (n + a) / (N + 4a) | L3: =ROUND(SUMIF($A$2:$A$289,A3,$H$2:$H$289),9) -> 1
A4: 1 | B4: G | C4: =A4&"|"&B4 -> 1|G | D4: =INDEX('Frequency 1-72'!$B$2:$E$73,A4,MATCH(B4,{"A","C","G","U"},0)) -> 152 | E4: ='Frequency 1-72'!G2 -> 199 | F4: 1 | G4: =IF(E4=0,"",D4/E4) -> 0.7638191 | H4: =I4/J4 -> 0.75369458 | I4: =D4+F4 -> 153 | J4: =E4+4*F4 -> 203 | K4: e = (n + a) / (N + 4a) | L4: =ROUND(SUMIF($A$2:$A$289,A4,$H$2:$H$289),9) -> 1
A5: 1 | B5: U | C5: =A5&"|"&B5 -> 1|U | D5: =INDEX('Frequency 1-72'!$B$2:$E$73,A5,MATCH(B5,{"A","C","G","U"},0)) -> 13 | E5: ='Frequency 1-72'!G2 -> 199 | F5: 1 | G5: =IF(E5=0,"",D5/E5) -> 0.065326633 | H5: =I5/J5 -> 0.068965517 | I5: =D5+F5 -> 14 | J5: =E5+4*F5 -> 203 | K5: e = (n + a) / (N + 4a) | L5: =ROUND(SUMIF($A$2:$A$289,A5,$H$2:$H$289),9) -> 1
A6: 2 | B6: A | C6: =A6&"|"&B6 -> 2|A | D6: =INDEX('Frequency 1-72'!$B$2:$E$73,A6,MATCH(B6,{"A","C","G","U"},0)) -> 6 | E6: ='Frequency 1-72'!G3 -> 199 | F6: 1 | G6: =IF(E6=0,"",D6/E6) -> 0.030150754 | H6: =I6/J6 -> 0.034482759 | I6: =D6+F6 -> 7 | J6: =E6+4*F6 -> 203 | K6: e = (n + a) / (N + 4a) | L6: =ROUND(SUMIF($A$2:$A$289,A6,$H$2:$H$289),9) -> 1
A7: 2 | B7: C | C7: =A7&"|"&B7 -> 2|C | D7: =INDEX('Frequency 1-72'!$B$2:$E$73,A7,MATCH(B7,{"A","C","G","U"},0)) -> 82 | E7: ='Frequency 1-72'!G3 -> 199 | F7: 1 | G7: =IF(E7=0,"",D7/E7) -> 0.4120603 | H7: =I7/J7 -> 0.408867 | I7: =D7+F7 -> 83 | J7: =E7+4*F7 -> 203 | K7: e = (n + a) / (N + 4a) | L7: =ROUND(SUMIF($A$2:$A$289,A7,$H$2:$H$289),9) -> 1
A8: 2 | B8: G | C8: =A8&"|"&B8 -> 2|G | D8: =INDEX('Frequency 1-72'!$B$2:$E$73,A8,MATCH(B8,{"A","C","G","U"},0)) -> 105 | E8: ='Frequency 1-72'!G3 -> 199 | F8: 1 | G8: =IF(E8=0,"",D8/E8) -> 0.52763819 | H8: =I8/J8 -> 0.52216749 | I8: =D8+F8 -> 106 | J8: =E8+4*F8 -> 203 | K8: e = (n + a) / (N + 4a) | L8: =ROUND(SUMIF($A$2:$A$289,A8,$H$2:$H$289),9) -> 1
A9: 2 | B9: U | C9: =A9&"|"&B9 -> 2|U | D9: =INDEX('Frequency 1-72'!$B$2:$E$73,A9,MATCH(B9,{"A","C","G","U"},0)) -> 6 | E9: ='Frequency 1-72'!G3 -> 199 | F9: 1 | G9: =IF(E9=0,"",D9/E9) -> 0.030150754 | H9: =I9/J9 -> 0.034482759 | I9: =D9+F9 -> 7 | J9: =E9+4*F9 -> 203 | K9: e = (n + a) / (N + 4a) | L9: =ROUND(SUMIF($A$2:$A$289,A9,$H$2:$H$289),9) -> 1
A10: 3 | B10: A | C10: =A10&"|"&B10 -> 3|A | D10: =INDEX('Frequency 1-72'!$B$2:$E$73,A10,MATCH(B10,{"A","C","G","U"},0)) -> 14 | E10: ='Frequency 1-72'!G4 -> 199 | F10: 1 | G10: =IF(E10=0,"",D10/E10) -> 0.070351759 | H10: =I10/J10 -> 0.073891626 | I10: =D10+F10 -> 15 | J10: =E10+4*F10 -> 203 | K10: e = (n + a) / (N + 4a) | L10: =ROUND(SUMIF($A$2:$A$289,A10,$H$2:$H$289),9) -> 1
A11: 3 | B11: C | C11: =A11&"|"&B11 -> 3|C | D11: =INDEX('Frequency 1-72'!$B$2:$E$73,A11,MATCH(B11,{"A","C","G","U"},0)) -> 77 | E11: ='Frequency 1-72'!G4 -> 199 | F11: 1 | G11: =IF(E11=0,"",D11/E11) -> 0.38693467 | H11: =I11/J11 -> 0.38423645 | I11: =D11+F11 -> 78 | J11: =E11+4*F11 -> 203 | K11: e = (n + a) / (N + 4a) | L11: =ROUND(SUMIF($A$2:$A$289,A11,$H$2:$H$289),9) -> 1
A12: 3 | B12: G | C12: =A12&"|"&B12 -> 3|G | D12: =INDEX('Frequency 1-72'!$B$2:$E$73,A12,MATCH(B12,{"A","C","G","U"},0)) -> 85 | E12: ='Frequency 1-72'!G4 -> 199 | F12: 1 | G12: =IF(E12=0,"",D12/E12) -> 0.42713568 | H12: =I12/J12 -> 0.42364532 | I12: =D12+F12 -> 86 | J12: =E12+4*F12 -> 203 | K12: e = (n + a) / (N + 4a) | L12: =ROUND(SUMIF($A$2:$A$289,A12,$H$2:$H$289),9) -> 1
A13: 3 | B13: U | C13: =A13&"|"&B13 -> 3|U | D13: =INDEX('Frequency 1-72'!$B$2:$E$73,A13,MATCH(B13,{"A","C","G","U"},0)) -> 23 | E13: ='Frequency 1-72'!G4 -> 199 | F13: 1 | G13: =IF(E13=0,"",D13/E13) -> 0.11557789 | H13: =I13/J13 -> 0.1182266 | I13: =D13+F13 -> 24 | J13: =E13+4*F13 -> 203 | K13: e = (n + a) / (N + 4a) | L13: =ROUND(SUMIF($A$2:$A$289,A13,$H$2:$H$289),9) -> 1
A14: 4 | B14: A | C14: =A14&"|"&B14 -> 4|A | D14: =INDEX('Frequency 1-72'!$B$2:$E$73,A14,MATCH(B14,{"A","C","G","U"},0)) -> 15 | E14: ='Frequency 1-72'!G5 -> 199 | F14: 1 | G14: =IF(E14=0,"",D14/E14) -> 0.075376884 | H14: =I14/J14 -> 0.078817734 | I14: =D14+F14 -> 16 | J14: =E14+4*F14 -> 203 | K14: e = (n + a) / (N + 4a) | L14: =ROUND(SUMIF($A$2:$A$289,A14,$H$2:$H$289),9) -> 1
A15: 4 | B15: C | C15: =A15&"|"&B15 -> 4|C | D15: =INDEX('Frequency 1-72'!$B$2:$E$73,A15,MATCH(B15,{"A","C","G","U"},0)) -> 61 | E15: ='Frequency 1-72'!G5 -> 199 | F15: 1 | G15: =IF(E15=0,"",D15/E15) -> 0.30653266 | H15: =I15/J15 -> 0.30541872 | I15: =D15+F15 -> 62 | J15: =E15+4*F15 -> 203 | K15: e = (n + a) / (N + 4a) | L15: =ROUND(SUMIF($A$2:$A$289,A15,$H$2:$H$289),9) -> 1
A16: 4 | B16: G | C16: =A16&"|"&B16 -> 4|G | D16: =INDEX('Frequency 1-72'!$B$2:$E$73,A16,MATCH(B16,{"A","C","G","U"},0)) -> 89 | E16: ='Frequency 1-72'!G5 -> 199 | F16: 1 | G16: =IF(E16=0,"",D16/E16) -> 0.44723618 | H16: =I16/J16 -> 0.44334975 | I16: =D16+F16 -> 90 | J16: =E16+4*F16 -> 203 | K16: e = (n + a) / (N + 4a) | L16: =ROUND(SUMIF($A$2:$A$289,A16,$H$2:$H$289),9) -> 1
A17: 4 | B17: U | C17: =A17&"|"&B17 -> 4|U | D17: =INDEX('Frequency 1-72'!$B$2:$E$73,A17,MATCH(B17,{"A","C","G","U"},0)) -> 34 | E17: ='Frequency 1-72'!G5 -> 199 | F17: 1 | G17: =IF(E17=0,"",D17/E17) -> 0.17085427 | H17: =I17/J17 -> 0.17241379 | I17: =D17+F17 -> 35 | J17: =E17+4*F17 -> 203 | K17: e = (n + a) / (N + 4a) | L17: =ROUND(SUMIF($A$2:$A$289,A17,$H$2:$H$289),9) -> 1
A18: 5 | B18: A | C18: =A18&"|"&B18 -> 5|A | D18: =INDEX('Frequency 1-72'!$B$2:$E$73,A18,MATCH(B18,{"A","C","G","U"},0)) -> 30 | E18: ='Frequency 1-72'!G6 -> 199 | F18: 1 | G18: =IF(E18=0,"",D18/E18) -> 0.15075377 | H18: =I18/J18 -> 0.15270936 | I18: =D18+F18 -> 31 | J18: =E18+4*F18 -> 203 | K18: e = (n + a) / (N + 4a) | L18: =ROUND(SUMIF($A$2:$A$289,A18,$H$2:$H$289),9) -> 1
A19: 5 | B19: C | C19: =A19&"|"&B19 -> 5|C | D19: =INDEX('Frequency 1-72'!$B$2:$E$73,A19,MATCH(B19,{"A","C","G","U"},0)) -> 79 | E19: ='Frequency 1-72'!G6 -> 199 | F19: 1 | G19: =IF(E19=0,"",D19/E19) -> 0.39698492 | H19: =I19/J19 -> 0.39408867 | I19: =D19+F19 -> 80 | J19: =E19+4*F19 -> 203 | K19: e = (n + a) / (N + 4a) | L19: =ROUND(SUMIF($A$2:$A$289,A19,$H$2:$H$289),9) -> 1
A20: 5 | B20: G | C20: =A20&"|"&B20 -> 5|G | D20: =INDEX('Frequency 1-72'!$B$2:$E$73,A20,MATCH(B20,{"A","C","G","U"},0)) -> 69 | E20: ='Frequency 1-72'!G6 -> 199 | F20: 1 | G20: =IF(E20=0,"",D20/E20) -> 0.34673367 | H20: =I20/J20 -> 0.34482759 | I20: =D20+F20 -> 70 | J20: =E20+4*F20 -> 203 | K20: e = (n + a) / (N + 4a) | L20: =ROUND(SUMIF($A$2:$A$289,A20,$H$2:$H$289),9) -> 1
A21: 5 | B21: U | C21: =A21&"|"&B21 -> 5|U | D21: =INDEX('Frequency 1-72'!$B$2:$E$73,A21,MATCH(B21,{"A","C","G","U"},0)) -> 21 | E21: ='Frequency 1-72'!G6 -> 199 | F21: 1 | G21: =IF(E21=0,"",D21/E21) -> 0.10552764 | H21: =I21/J21 -> 0.10837438 | I21: =D21+F21 -> 22 | J21: =E21+4*F21 -> 203 | K21: e = (n + a) / (N + 4a) | L21: =ROUND(SUMIF($A$2:$A$289,A21,$H$2:$H$289),9) -> 1
A22: 6 | B22: A | C22: =A22&"|"&B22 -> 6|A | D22: =INDEX('Frequency 1-72'!$B$2:$E$73,A22,MATCH(B22,{"A","C","G","U"},0)) -> 34 | E22: ='Frequency 1-72'!G7 -> 199 | F22: 1 | G22: =IF(E22=0,"",D22/E22) -> 0.17085427 | H22: =I22/J22 -> 0.17241379 | I22: =D22+F22 -> 35 | J22: =E22+4*F22 -> 203 | K22: e = (n + a) / (N + 4a) | L22: =ROUND(SUMIF($A$2:$A$289,A22,$H$2:$H$289),9) -> 1
A23: 6 | B23: C | C23: =A23&"|"&B23 -> 6|C | D23: =INDEX('Frequency 1-72'!$B$2:$E$73,A23,MATCH(B23,{"A","C","G","U"},0)) -> 65 | E23: ='Frequency 1-72'!G7 -> 199 | F23: 1 | G23: =IF(E23=0,"",D23/E23) -> 0.32663317 | H23: =I23/J23 -> 0.32512315 | I23: =D23+F23 -> 66 | J23: =E23+4*F23 -> 203 | K23: e = (n + a) / (N + 4a) | L23: =ROUND(SUMIF($A$2:$A$289,A23,$H$2:$H$289),9) -> 1
A24: 6 | B24: G | C24: =A24&"|"&B24 -> 6|G | D24: =INDEX('Frequency 1-72'!$B$2:$E$73,A24,MATCH(B24,{"A","C","G","U"},0)) -> 48 | E24: ='Frequency 1-72'!G7 -> 199 | F24: 1 | G24: =IF(E24=0,"",D24/E24) -> 0.24120603 | H24: =I24/J24 -> 0.24137931 | I24: =D24+F24 -> 49 | J24: =E24+4*F24 -> 203 | K24: e = (n + a) / (N + 4a) | L24: =ROUND(SUMIF($A$2:$A$289,A24,$H$2:$H$289),9) -> 1
A25: 6 | B25: U | C25: =A25&"|"&B25 -> 6|U | D25: =INDEX('Frequency 1-72'!$B$2:$E$73,A25,MATCH(B25,{"A","C","G","U"},0)) -> 52 | E25: ='Frequency 1-72'!G7 -> 199 | F25: 1 | G25: =IF(E25=0,"",D25/E25) -> 0.26130653 | H25: =I25/J25 -> 0.26108374 | I25: =D25+F25 -> 53 | J25: =E25+4*F25 -> 203 | K25: e = (n + a) / (N + 4a) | L25: =ROUND(SUMIF($A$2:$A$289,A25,$H$2:$H$289),9) -> 1
A26: 7 | B26: A | C26: =A26&"|"&B26 -> 7|A | D26: =INDEX('Frequency 1-72'!$B$2:$E$73,A26,MATCH(B26,{"A","C","G","U"},0)) -> 47 | E26: ='Frequency 1-72'!G8 -> 199 | F26: 1 | G26: =IF(E26=0,"",D26/E26) -> 0.2361809 | H26: =I26/J26 -> 0.2364532 | I26: =D26+F26 -> 48 | J26: =E26+4*F26 -> 203 | K26: e = (n + a) / (N + 4a) | L26: =ROUND(SUMIF($A$2:$A$289,A26,$H$2:$H$289),9) -> 1
A27: 7 | B27: C | C27: =A27&"|"&B27 -> 7|C | D27: =INDEX('Frequency 1-72'!$B$2:$E$73,A27,MATCH(B27,{"A","C","G","U"},0)) -> 3 | E27: ='Frequency 1-72'!G8 -> 199 | F27: 1 | G27: =IF(E27=0,"",D27/E27) -> 0.015075377 | H27: =I27/J27 -> 0.019704433 | I27: =D27+F27 -> 4 | J27: =E27+4*F27 -> 203 | K27: e = (n + a) / (N + 4a) | L27: =ROUND(SUMIF($A$2:$A$289,A27,$H$2:$H$289),9) -> 1
A28: 7 | B28: G | C28: =A28&"|"&B28 -> 7|G | D28: =INDEX('Frequency 1-72'!$B$2:$E$73,A28,MATCH(B28,{"A","C","G","U"},0)) -> 105 | E28: ='Frequency 1-72'!G8 -> 199 | F28: 1 | G28: =IF(E28=0,"",D28/E28) -> 0.52763819 | H28: =I28/J28 -> 0.52216749 | I28: =D28+F28 -> 106 | J28: =E28+4*F28 -> 203 | K28: e = (n + a) / (N + 4a) | L28: =ROUND(SUMIF($A$2:$A$289,A28,$H$2:$H$289),9) -> 1
A29: 7 | B29: U | C29: =A29&"|"&B29 -> 7|U | D29: =INDEX('Frequency 1-72'!$B$2:$E$73,A29,MATCH(B29,{"A","C","G","U"},0)) -> 44 | E29: ='Frequency 1-72'!G8 -> 199 | F29: 1 | G29: =IF(E29=0,"",D29/E29) -> 0.22110553 | H29: =I29/J29 -> 0.22167488 | I29: =D29+F29 -> 45 | J29: =E29+4*F29 -> 203 | K29: e = (n + a) / (N + 4a) | L29: =ROUND(SUMIF($A$2:$A$289,A29,$H$2:$H$289),9) -> 1
A30: 8 | B30: A | C30: =A30&"|"&B30 -> 8|A | D30: =INDEX('Frequency 1-72'!$B$2:$E$73,A30,MATCH(B30,{"A","C","G","U"},0)) -> 1 | E30: ='Frequency 1-72'!G9 -> 199 | F30: 1 | G30: =IF(E30=0,"",D30/E30) -> 0.0050251256 | H30: =I30/J30 -> 0.0098522167 | I30: =D30+F30 -> 2 | J30: =E30+4*F30 -> 203 | K30: e = (n + a) / (N + 4a) | L30: =ROUND(SUMIF($A$2:$A$289,A30,$H$2:$H$289),9) -> 1
A31: 8 | B31: C | C31: =A31&"|"&B31 -> 8|C | D31: =INDEX('Frequency 1-72'!$B$2:$E$73,A31,MATCH(B31,{"A","C","G","U"},0)) -> 0 | E31: ='Frequency 1-72'!G9 -> 199 | F31: 1 | G31: =IF(E31=0,"",D31/E31) -> 0 | H31: =I31/J31 -> 0.0049261084 | I31: =D31+F31 -> 1 | J31: =E31+4*F31 -> 203 | K31: e = (n + a) / (N + 4a) | L31: =ROUND(SUMIF($A$2:$A$289,A31,$H$2:$H$289),9) -> 1
A32: 8 | B32: G | C32: =A32&"|"&B32 -> 8|G | D32: =INDEX('Frequency 1-72'!$B$2:$E$73,A32,MATCH(B32,{"A","C","G","U"},0)) -> 1 | E32: ='Frequency 1-72'!G9 -> 199 | F32: 1 | G32: =IF(E32=0,"",D32/E32) -> 0.0050251256 | H32: =I32/J32 -> 0.0098522167 | I32: =D32+F32 -> 2 | J32: =E32+4*F32 -> 203 | K32: e = (n + a) / (N + 4a) | L32: =ROUND(SUMIF($A$2:$A$289,A32,$H$2:$H$289),9) -> 1
A33: 8 | B33: U | C33: =A33&"|"&B33 -> 8|U | D33: =INDEX('Frequency 1-72'!$B$2:$E$73,A33,MATCH(B33,{"A","C","G","U"},0)) -> 197 | E33: ='Frequency 1-72'!G9 -> 199 | F33: 1 | G33: =IF(E33=0,"",D33/E33) -> 0.98994975 | H33: =I33/J33 -> 0.97536946 | I33: =D33+F33 -> 198 | J33: =E33+4*F33 -> 203 | K33: e = (n + a) / (N + 4a) | L33: =ROUND(SUMIF($A$2:$A$289,A33,$H$2:$H$289),9) -> 1
A34: 9 | B34: A | C34: =A34&"|"&B34 -> 9|A | D34: =INDEX('Frequency 1-72'!$B$2:$E$73,A34,MATCH(B34,{"A","C","G","U"},0)) -> 130 | E34: ='Frequency 1-72'!G10 -> 198 | F34: 1 | G34: =IF(E34=0,"",D34/E34) -> 0.65656566 | H34: =I34/J34 -> 0.64851485 | I34: =D34+F34 -> 131 | J34: =E34+4*F34 -> 202 | K34: e = (n + a) / (N + 4a) | L34: =ROUND(SUMIF($A$2:$A$289,A34,$H$2:$H$289),9) -> 1
A35: 9 | B35: C | C35: =A35&"|"&B35 -> 9|C | D35: =INDEX('Frequency 1-72'!$B$2:$E$73,A35,MATCH(B35,{"A","C","G","U"},0)) -> 7 | E35: ='Frequency 1-72'!G10 -> 198 | F35: 1 | G35: =IF(E35=0,"",D35/E35) -> 0.035353535 | H35: =I35/J35 -> 0.03960396 | I35: =D35+F35 -> 8 | J35: =E35+4*F35 -> 202 | K35: e = (n + a) / (N + 4a) | L35: =ROUND(SUMIF($A$2:$A$289,A35,$H$2:$H$289),9) -> 1
A36: 9 | B36: G | C36: =A36&"|"&B36 -> 9|G | D36: =INDEX('Frequency 1-72'!$B$2:$E$73,A36,MATCH(B36,{"A","C","G","U"},0)) -> 61 | E36: ='Frequency 1-72'!G10 -> 198 | F36: 1 | G36: =IF(E36=0,"",D36/E36) -> 0.30808081 | H36: =I36/J36 -> 0.30693069 | I36: =D36+F36 -> 62 | J36: =E36+4*F36 -> 202 | K36: e = (n + a) / (N + 4a) | L36: =ROUND(SUMIF($A$2:$A$289,A36,$H$2:$H$289),9) -> 1
A37: 9 | B37: U | C37: =A37&"|"&B37 -> 9|U | D37: =INDEX('Frequency 1-72'!$B$2:$E$73,A37,MATCH(B37,{"A","C","G","U"},0)) -> 0 | E37: ='Frequency 1-72'!G10 -> 198 | F37: 1 | G37: =IF(E37=0,"",D37/E37) -> 0 | H37: =I37/J37 -> 0.004950495 | I37: =D37+F37 -> 1 | J37: =E37+4*F37 -> 202 | K37: e = (n + a) / (N + 4a) | L37: =ROUND(SUMIF($A$2:$A$289,A37,$H$2:$H$289),9) -> 1
A38: 10 | B38: A | C38: =A38&"|"&B38 -> 10|A | D38: =INDEX('Frequency 1-72'!$B$2:$E$73,A38,MATCH(B38,{"A","C","G","U"},0)) -> 0 | E38: ='Frequency 1-72'!G11 -> 199 | F38: 1 | G38: =IF(E38=0,"",D38/E38) -> 0 | H38: =I38/J38 -> 0.0049261084 | I38: =D38+F38 -> 1 | J38: =E38+4*F38 -> 203 | K38: e = (n + a) / (N + 4a) | L38: =ROUND(SUMIF($A$2:$A$289,A38,$H$2:$H$289),9) -> 1
A39: 10 | B39: C | C39: =A39&"|"&B39 -> 10|C | D39: =INDEX('Frequency 1-72'!$B$2:$E$73,A39,MATCH(B39,{"A","C","G","U"},0)) -> 8 | E39: ='Frequency 1-72'!G11 -> 199 | F39: 1 | G39: =IF(E39=0,"",D39/E39) -> 0.040201005 | H39: =I39/J39 -> 0.044334975 | I39: =D39+F39 -> 9 | J39: =E39+4*F39 -> 203 | K39: e = (n + a) / (N + 4a) | L39: =ROUND(SUMIF($A$2:$A$289,A39,$H$2:$H$289),9) -> 1
A40: 10 | B40: G | C40: =A40&"|"&B40 -> 10|G | D40: =INDEX('Frequency 1-72'!$B$2:$E$73,A40,MATCH(B40,{"A","C","G","U"},0)) -> 191 | E40: ='Frequency 1-72'!G11 -> 199 | F40: 1 | G40: =IF(E40=0,"",D40/E40) -> 0.95979899 | H40: =I40/J40 -> 0.94581281 | I40: =D40+F40 -> 192 | J40: =E40+4*F40 -> 203 | K40: e = (n + a) / (N + 4a) | L40: =ROUND(SUMIF($A$2:$A$289,A40,$H$2:$H$289),9) -> 1
...

Sheet Emission Matrix
A1: EMISSION PROBABILITY MATRIX (smoothed) — rows = base, columns = position
