Workbook

Sheet Read Me
A1: tRNA MODEL v5 — VALIDATION OF 9 PREDICTED CANDIDATES AGAINST A REALISTIC NEGATIVE CONTROL
A3: FILE FORMAT
A4: Compatibility | B4: Saved as .xlsx (Office Open XML), the native format of Excel 2007 and every later version. Only functions available in Excel 2007 are used (SUM, AVERAGE, MIN, MAX, ROUND, IF, AND, LN, INDEX, MATCH, CORREL, STDEVP, SUMIF, SUMIFS, COUNTIF, COUNTIFS, AVERAGEIFS). No post-2007 function, no array formula and no table feature is used, so every cell recalculates in Excel 2007.
A6: CHECKS ON THIS BATCH
A7: 1. Reference 200 unchanged | B7: tRNA_Database_T_Psi_C_200_1.xlsx is byte-identical to the file used in the previous round (same MD5). The reference model, and therefore the emission and transition matrices, are unchanged.
A8: 2. T-Psi-C OTHER 100 unchanged | B8: Byte-identical to the previous round. 101 rows, 96 unique records, 5 exact duplicate rows removed (4 Lys, 1 Tyr). Zero overlap with the reference 200.
A9: 3. MBSW 62 unchanged | B9: Byte-identical to the previous round. 62 mature archaeal tRNAs from tRNAscan-SE.
A10: 4. The 13 random-genome file is a true legacy .xls | B10: tRNA_randomgenome_13_positions_1-72.xls is a BIFF Composite Document, not a renamed .xlsx. It was converted to .xlsx before reading. It holds the same 13 sequences as the previous round: same names, same anticodons, same lengths, same gap counts.
A11: 5. The 9 pasted candidates were verified | B11: The 9 predicted candidates supplied in the message body were transcribed and compared cell by cell against the candidate file used previously: 0 differing cells across all 9 x 72. The T to U change and the anticodon spelling (UUA / CUA / UCA rather than tta / cta / tca) are notation only.
A12: 6. Every figure reproduced | B12: Because all inputs are unchanged, the whole analysis was re-derived from this new file set as an independent check. Every statistic reproduced exactly, to the last decimal place.
A13: 7. Roles of the sets | B13: The 13 random-genome sequences are the NEGATIVE control, not candidates. The 9 predicted candidates are what is being tested. Your message refers in one place to 'our 13 candidate tRNA'; that has been read as the random-genome decoy set, consistent with how it was described when first supplied.
A15: WHY THE DECOY SET MATTERS
A16: The gap it closes | B16: Up to v4 the only negative control was a positional permutation of a real tRNA. That is an easy negative: a scrambled tRNA has no reason to fold at all. The realistic false positive for a split-tRNA search is genomic sequence that already folds like a tRNA, which is exactly what your predictor returns when run on randomized genome.
A17: How well matched it is | B17: The 13 decoys carry the same anticodons as the real candidates (UUA and CUA), the same declared type (Sup), and overlapping lengths (71-95 against 70-93). They are therefore a properly matched hard negative.
A18: Predictor false-positive yield | B18: 13 candidates from 50 randomized genomes = 0.26 per genome.
A20: HEADLINE RESULT
A21: Against real tRNAs | B21: Separation stays perfect: AUC = 1.000. Every one of the 158 real tRNAs outscores every decoy and every permutation.
A22: Against the decoys | B22: The combined score separates the 9 predicted from the 13 decoys only weakly: predicted -0.2719 against decoy -0.3398, Mann-Whitney p = 0.333, AUC = 0.624. Seven of the nine fall inside the decoy range.
A23: The GC confound | B23: GC content separates predicted from decoy far better than the model does (AUC 0.859, p = 0.005). After the linear GC effect is removed the difference disappears completely (p = 0.973, AUC = 0.496). On this evidence the positional model adds nothing beyond base composition when the task is telling a real candidate from a randomized-genome decoy.
A24: Identity features run the wrong way | B24: The decoys score HIGHER than the predicted candidates on invariant match (0.667 against 0.602) and on the T-loop (0.631 against 0.556). These features cannot be used to argue for the candidates.
A25: Stem pairing is uninformative here | B25: Predicted 0.915 against decoy 0.919. The predictor selects for foldability, so both sets fold. Stem pairing was used as a supporting criterion in v4; against this null it has no discriminating power and that v4 criterion is withdrawn.
A27: REVISED THRESHOLD
A28: Against the decoy null | B28: Decoy maximum -0.1879; weakest of the 158 real tRNAs +0.0288; recommended cut = midpoint -0.0795.
A29: Against the permutation null | B29: Cut was -0.0896 in v4. The decoy-calibrated cut is slightly stricter.
A30: Candidates clearing it | B30: 1 of 9.
A31: Candidates above the decoy maximum | B31: 2 of 9.
A33: STATISTICAL POWER — READ THIS BEFORE QUOTING ANY p VALUE
A34: The floor | B34: With 13 decoys the smallest empirical p any candidate can receive is 1/(13+1) = 0.0714. No candidate can reach p < 0.05 against this null, however good it is. The two best candidates both sit at this floor.
A35: What it would take | B35: About 99 decoys are needed before p < 0.01 is even reachable. At the observed yield of 0.26 decoys per randomized genome that means roughly 380 randomized genomes.
A36: The better experiment | B36: Generate the decoys GC-matched to the candidates, or draw them from GC-matched genomic windows. Because GC is doing all the discriminating work, a GC-matched decoy set is the test that would actually settle the question.
A38: WHAT THIS DOES AND DOES NOT SHOW
A39: Shown | B39: All 9 candidates are clearly distinguishable from real mature tRNAs, and clearly better than scrambled sequence. One candidate, trna64, also sits above every decoy and clears the decoy-calibrated threshold.
A40: Not shown | B40: That the 9 candidates as a group are distinguishable from what the predictor finds in randomized genome. On the present evidence they are not, once GC is accounted for.
A42: COMPUTED INPUTS
A43: Note | B43: Reference leave-one-out scores, the 96 T-Psi-C OTHER scores, the 62 MBSW scores, the 960 permutation scores and all ROC and Mann-Whitney statistics are computed in Python and entered as values, shown in blue. The 22 candidates and decoys are scored by live spreadsheet formula from the emission and transition tables so the chain can be audited end to end.

Sheet Database + Frequency
A1: T-PSI-C REFERENCE DATABASE (200 records, positions 1-72) WITH NUCLEOTIDE FREQUENCY BENEATH, HORIZONTAL
A2: Organism | B2: Trna No | C2: tRNA | D2: Anti codon | E2: 1 | F2: 2 | G2: 3 | H2: 4 | I2: 5 | J2: 6 | K2: 7 | L2: 8 | M2: 9 | N2: 10 | O2: 11 | P2: 12 | Q2: 13 | R2: 14 | S2: 15 | T2: 16 | U2: 17 | V2: 18 | W2: 19 | X2: 20 | Y2: 21 | Z2: 22 | AA2: 23 | AB2: 24 | AC2: 25 | AD2: 26 | AE2: 27 | AF2: 28 | AG2: 29 | AH2: 30 | AI2: 31 | AJ2: 32 | AK2: 33 | AL2: 34 | AM2: 35 | AN2: 36 | AO2: 37 | AP2: 38 | AQ2: 39 | AR2: 40 | AS2: 41 | AT2: 42 | AU2: 43 | AV2: 44 | AW2: 45 | AX2: 46 | AY2: 47 | AZ2: 48 | BA2: 49 | BB2: 50 | BC2: 51 | BD2: 52 | BE2: 53 | BF2: 54 | BG2: 55 | BH2: 56 | BI2: 57 | BJ2: 58 | BK2: 59 | BL2: 60 | BM2: 61 | BN2: 62 | BO2: 63 | BP2: 64 | BQ2: 65 | BR2: 66 | BS2: 67 | BT2: 68 | BU2: 69 | BV2: 70 | BW2: 71 | BX2: 72
A3: Aeropyrum pernix(A) | B3: tdbR00000589 | C3: ARG | D3: UCU | E3: G | F3: G | G3: G | H3: C | I3: C | J3: C | K3: G | L3: U | M3: A | N3: G | O3: C | P3: U | Q3: C | R3: A | S3: G | T3: C | U3: C | V3: G | W3: G | X3: A | Y3: A | Z3: G | AA3: A | AB3: G | AC3: C | AD3: G | AE3: C | AF3: C | AG3: G | AH3: G | AI3: C | AJ3: C | AK3: U | AL3: U | AM3: C | AN3: U | AO3: A | AP3: A | AQ3: G | AR3: C | AS3: C | AT3: G | AU3: G | AV3: U | AW3: G | AX3: C | AY3: U | AZ3: G | BA3: C | BB3: C | BC3: G | BD3: G | BE3: G | BF3: U | BG3: U | BH3: C | BI3: A | BJ3: A | BK3: A | BL3: U | BM3: C | BN3: C | BO3: C | BP3: G | BQ3: G | BR3: C | BS3: G | BT3: G | BU3: G | BV3: C | BW3: C | BX3: C
A4: Aeropyrum pernix(A) | B4: tdbR00000588 | C4: ASC | D4: GUC | E4: G | F4: C | G4: C | H4: G | I4: C | J4: G | K4: G | L4: U | M4: A | N4: G | O4: U | P4: A | Q4: U | R4: A | S4: G | T4: C | U4: C | V4: G | W4: G | X4: A | Y4: A | Z4: G | AA4: U | AB4: A | AC4: U | AD4: G | AE4: C | AF4: G | AG4: G | AH4: G | AI4: C | AJ4: C | AK4: U | AL4: G | AM4: U | AN4: C | AO4: A | AP4: A | AQ4: G | AR4: C | AS4: C | AT4: C | AU4: G | AV4: U | AW4: G | AX4: - | AY4: A | AZ4: C | BA4: C | BB4: C | BC4: G | BD4: G | BE4: G | BF4: U | BG4: U | BH4: C | BI4: A | BJ4: A | BK4: A | BL4: U | BM4: C | BN4: C | BO4: C | BP4: G | BQ4: G | BR4: C | BS4: C | BT4: G | BU4: C | BV4: G | BW4: G | BX4: C
A5: Aeropyrum pernix(A) | B5: tdbR00000583 | C5: CYS | D5: GCA | E5: G | F5: C | G5: C | H5: G | I5: G | J5: G | K5: G | L5: U | M5: G | N5: G | O5: C | P5: C | Q5: G | R5: A | S5: G | T5: - | U5: C | V5: G | W5: G | X5: U | Y5: A | Z5: A | AA5: G | AB5: G | AC5: C | AD5: G | AE5: G | AF5: C | AG5: G | AH5: G | AI5: G | AJ5: C | AK5: U | AL5: G | AM5: C | AN5: A | AO5: G | AP5: A | AQ5: C | AR5: C | AS5: C | AT5: G | AU5: U | AV5: U | AW5: A | AX5: G | AY5: U | AZ5: C | BA5: C | BB5: C | BC5: G | BD5: G | BE5: G | BF5: U | BG5: U | BH5: C | BI5: G | BJ5: A | BK5: A | BL5: U | BM5: C | BN5: C | BO5: C | BP5: G | BQ5: G | BR5: C | BS5: C | BT5: C | BU5: C | BV5: G | BW5: G | BX5: C
A6: Aeropyrum pernix(A) | B6: tdbR00000581 | C6: LYS | D6: CUU | E6: G | F6: G | G6: G | H6: C | I6: C | J6: C | K6: G | L6: U | M6: A | N6: G | O6: C | P6: U | Q6: C | R6: A | S6: G | T6: C | U6: C | V6: G | W6: G | X6: U | Y6: A | Z6: G | AA6: A | AB6: G | AC6: C | AD6: G | AE6: G | AF6: C | AG6: G | AH6: G | AI6: G | AJ6: C | AK6: U | AL6: C | AM6: U | AN6: U | AO6: A | AP6: A | AQ6: C | AR6: C | AS6: C | AT6: G | AU6: C | AV6: G | AW6: A | AX6: G | AY6: U | AZ6: C | BA6: C | BB6: C | BC6: G | BD6: G | BE6: G | BF6: U | BG6: U | BH6: C | BI6: A | BJ6: A | BK6: A | BL6: U | BM6: C | BN6: C | BO6: C | BP6: G | BQ6: G | BR6: C | BS6: G | BT6: G | BU6: G | BV6: C | BW6: C | BX6: C
A7: Aeropyrum pernix(A) | B7: tdbR00000580 | C7: LYS | D7: UUU | E7: G | F7: G | G7: G | H7: C | I7: C | J7: C | K7: G | L7: U | M7: A | N7: G | O7: C | P7: U | Q7: C | R7: A | S7: G | T7: C | U7: C | V7: G | W7: G | X7: C | Y7: A | Z7: G | AA7: A | AB7: G | AC7: C | AD7: G | AE7: G | AF7: C | AG7: G | AH7: G | AI7: G | AJ7: C | AK7: U | AL7: U | AM7: U | AN7: U | AO7: A | AP7: C | AQ7: C | AR7: C | AS7: C | AT7: G | AU7: C | AV7: G | AW7: G | AX7: A | AY7: U | AZ7: C | BA7: C | BB7: C | BC7: G | BD7: G | BE7: G | BF7: U | BG7: U | BH7: C | BI7: A | BJ7: A | BK7: A | BL7: U | BM7: C | BN7: C | BO7: C | BP7: G | BQ7: G | BR7: C | BS7: G | BT7: G | BU7: G | BV7: C | BW7: C | BX7: C
A8: Aeropyrum pernix(A) | B8: tdbR00000586 | C8: MET | D8: CAU | E8: G | F8: G | G8: G | H8: C | I8: C | J8: C | K8: G | L8: U | M8: A | N8: G | O8: C | P8: U | Q8: C | R8: A | S8: G | T8: C | U8: C | V8: G | W8: G | X8: U | Y8: A | Z8: G | AA8: A | AB8: G | AC8: C | AD8: G | AE8: C | AF8: C | AG8: C | AH8: G | AI8: G | AJ8: C | AK8: U | AL8: C | AM8: A | AN8: U | AO8: A | AP8: A | AQ8: C | AR8: C | AS8: G | AT8: G | AU8: G | AV8: U | AW8: G | AX8: G | AY8: U | AZ8: C | BA8: G | BB8: G | BC8: G | BD8: G | BE8: G | BF8: U | BG8: U | BH8: C | BI8: A | BJ8: A | BK8: A | BL8: U | BM8: C | BN8: C | BO8: C | BP8: C | BQ8: C | BR8: C | BS8: G | BT8: G | BU8: G | BV8: C | BW8: C | BX8: C
A9: Aeropyrum pernix(A) | B9: tdbR00000587 | C9: MET | D9: CAU | E9: G | F9: C | G9: C | H9: G | I9: C | J9: C | K9: G | L9: U | M9: A | N9: G | O9: C | P9: U | Q9: C | R9: A | S9: G | T9: C | U9: C | V9: G | W9: G | X9: C | Y9: A | Z9: G | AA9: A | AB9: G | AC9: C | AD9: G | AE9: C | AF9: C | AG9: G | AH9: G | AI9: A | AJ9: C | AK9: U | AL9: C | AM9: A | AN9: U | AO9: A | AP9: A | AQ9: U | AR9: C | AS9: C | AT9: G | AU9: G | AV9: A | AW9: G | AX9: G | AY9: U | AZ9: C | BA9: C | BB9: C | BC9: G | BD9: G | BE9: G | BF9: U | BG9: U | BH9: C | BI9: G | BJ9: A | BK9: A | BL9: U | BM9: C | BN9: C | BO9: C | BP9: G | BQ9: G | BR9: C | BS9: G | BT9: G | BU9: C | BV9: G | BW9: G | BX9: C
A10: Aeropyrum pernix(A) | B10: tdbR00000579 | C10: PRO | D10: CGG | E10: G | F10: G | G10: G | H10: C | I10: C | J10: C | K10: G | L10: G | M10: C | N10: G | O10: U | P10: C | Q10: U | R10: A | S10: G | T10: C | U10: C | V10: G | W10: G | X10: C | Y10: A | Z10: A | AA10: G | AB10: A | AC10: U | AD10: G | AE10: C | AF10: G | AG10: G | AH10: G | AI10: G | AJ10: U | AK10: A | AL10: C | AM10: G | AN10: G | AO10: G | AP10: A | AQ10: C | AR10: C | AS10: C | AT10: C | AU10: G | AV10: U | AW10: G | AX10: G | AY10: U | AZ10: C | BA10: C | BB10: G | BC10: G | BD10: G | BE10: G | BF10: U | BG10: U | BH10: C | BI10: A | BJ10: A | BK10: A | BL10: U | BM10: C | BN10: C | BO10: C | BP10: C | BQ10: G | BR10: C | BS10: G | BT10: G | BU10: G | BV10: C | BW10: C | BX10: C
A11: Aeropyrum pernix(A) | B11: tdbR00000584 | C11: PRO | D11: GGG | E11: G | F11: G | G11: G | H11: G | I11: C | J11: C | K11: G | L11: U | M11: C | N11: G | O11: U | P11: C | Q11: U | R11: A | S11: G | T11: C | U11: C | V11: G | W11: G | X11: C | Y11: A | Z11: G | AA11: G | AB11: A | AC11: U | AD11: G | AE11: C | AF11: C | AG11: A | AH11: G | AI11: C | AJ11: C | AK11: U | AL11: G | AM11: G | AN11: G | AO11: G | AP11: C | AQ11: G | AR11: C | AS11: U | AT11: G | AU11: G | AV11: U | AW11: G | AX11: G | AY11: U | AZ11: C | BA11: C | BB11: C | BC11: G | BD11: G | BE11: G | BF11: U | BG11: U | BH11: C | BI11: A | BJ11: A | BK11: A | BL11: U | BM11: C | BN11: C | BO11: C | BP11: G | BQ11: G | BR11: C | BS11: G | BT11: G | BU11: C | BV11: C | BW11: C | BX11: C
A12: Aeropyrum pernix(A) | B12: tdbR00000585 | C12: THR | D12: CGU | E12: G | F12: C | G12: C | H12: G | I12: C | J12: C | K12: G | L12: U | M12: A | N12: G | O12: C | P12: U | Q12: C | R12: A | S12: G | T12: - | U12: C | V12: G | W12: G | X12: U | Y12: A | Z12: G | AA12: A | AB12: G | AC12: C | AD12: G | AE12: C | AF12: C | AG12: G | AH12: G | AI12: C | AJ12: C | AK12: U | AL12: C | AM12: G | AN12: U | AO12: A | AP12: A | AQ12: G | AR12: C | AS12: C | AT12: G | AU12: G | AV12: U | AW12: G | AX12: G | AY12: U | AZ12: C | BA12: G | BB12: C | BC12: G | BD12: G | BE12: G | BF12: U | BG12: U | BH12: C | BI12: G | BJ12: A | BK12: A | BL12: U | BM12: C | BN12: C | BO12: C | BP12: G | BQ12: C | BR12: C | BS12: G | BT12: G | BU12: C | BV12: G | BW12: G | BX12: C
A13: Aeropyrum pernix(A) | B13: tdbR00000582 | C13: TYR | D13: GUA | E13: C | F13: C | G13: C | H13: G | I13: C | J13: C | K13: G | L13: U | M13: A | N13: G | O13: C | P13: U | Q13: C | R13: A | S13: G | T13: - | U13: C | V13: G | W13: G | X13: C | Y13: A | Z13: G | AA13: A | AB13: G | AC13: C | AD13: G | AE13: C | AF13: C | AG13: C | AH13: G | AI13: G | AJ13: C | AK13: U | AL13: G | AM13: U | AN13: A | AO13: C | AP13: A | AQ13: C | AR13: C | AS13: G | AT13: G | AU13: G | AV13: U | AW13: G | AX13: G | AY13: U | AZ13: C | BA13: C | BB13: G | BC13: G | BD13: G | BE13: G | BF13: U | BG13: U | BH13: C | BI13: G | BJ13: A | BK13: A | BL13: U | BM13: C | BN13: C | BO13: C | BP13: C | BQ13: G | BR13: C | BS13: G | BT13: G | BU13: C | BV13: G | BW13: G | BX13: G
A14: Escherichia coli(B) | B14: tdbR00000008 | C14: Ala | D14: GGC | E14: G | F14: G | G14: G | H14: G | I14: C | J14: U | K14: A | L14: U | M14: A | N14: G | O14: C | P14: U | Q14: C | R14: A | S14: G | T14: C | U14: U | V14: G | W14: G | X14: G | Y14: A | Z14: G | AA14: A | AB14: G | AC14: C | AD14: G | AE14: C | AF14: U | AG14: U | AH14: G | AI14: C | AJ14: A | AK14: U | AL14: G | AM14: G | AN14: C | AO14: A | AP14: U | AQ14: G | AR14: C | AS14: A | AT14: A | AU14: G | AV14: A | AW14: G | AX14: G | AY14: U | AZ14: C | BA14: A | BB14: G | BC14: C | BD14: G | BE14: G | BF14: U | BG14: U | BH14: C | BI14: G | BJ14: A | BK14: U | BL14: C | BM14: C | BN14: C | BO14: G | BP14: C | BQ14: U | BR14: U | BS14: A | BT14: G | BU14: C | BV14: U | BW14: C | BX14: C
... A202: Homo sapiens | B202: tdbR00000868 | C202: Thr | D202: AGU | E202: G | F202: C | G202: U | H202: C | I202: U | J202: U | K202: G | L202: U | M202: A | N202: G | O202: C | P202: U | Q202: C | R202: A | S202: G | T202: - | U202: U | V202: G | W202: G | X202: U | Y202: A | Z202: G | AA202: A | AB202: G | AC202: C | AD202: G | AE202: C | AF202: U | AG202: U | AH202: G | AI202: C | AJ202: C | AK202: U | AL202: A | AM202: G | AN202: U | AO202: A | AP202: A | AQ202: G | AR202: C | AS202: A | AT202: A | AU202: G | AV202: A | AW202: G | AX202: G | AY202: C | AZ202: C | BA202: C | BB202: A | BC202: G | BD202: U | BE202: G | BF202: U | BG202: U | BH202: C | BI202: A | BJ202: A | BK202: G | BL202: U | BM202: C | BN202: A | BO202: C | BP202: U | BQ202: G | BR202: C | BS202: U | BT202: G | BU202: G | BV202: A | BW202: G | BX202: C
A205: NUCLEOTIDE FREQUENCY — HORIZONTAL
A206: Counted over the 200 records above. Missing cells excluded from the valid total.
D207: Position | E207: 1 | F207: 2 | G207: 3 | H207: 4 | I207: 5 | J207: 6 | K207: 7 | L207: 8 | M207: 9 | N207: 10 | O207: 11 | P207: 12 | Q207: 13 | R207: 14 | S207: 15 | T207: 16 | U207: 17 | V207: 18 | W207: 19 | X207: 20 | Y207: 21 | Z207: 22 | AA207: 23 | AB207: 24 | AC207: 25 | AD207: 26 | AE207: 27 | AF207: 28 | AG207: 29 | AH207: 30 | AI207: 31 | AJ207: 32 | AK207: 33 | AL207: 34 | AM207: 35 | AN207: 36 | AO207: 37 | AP207: 38 | AQ207: 39 | AR207: 40 | AS207: 41 | AT207: 42 | AU207: 43 | AV207: 44 | AW207: 45 | AX207: 46 | AY207: 47 | AZ207: 48 | BA207: 49 | BB207: 50 | BC207: 51 | BD207: 52 | BE207: 53 | BF207: 54 | BG207: 55 | BH207: 56 | BI207: 57 | BJ207: 58 | BK207: 59 | BL207: 60 | BM207: 61 | BN207: 62 | BO207: 63 | BP207: 64 | BQ207: 65 | BR207: 66 | BS207: 67 | BT207: 68 | BU207: 69 | BV207: 70 | BW207: 71 | BX207: 72
D208: A | E208: 13 | F208: 6 | G208: 14 | H208: 16 | I208: 31 | J208: 34 | K208: 48 | L208: 1 | M208: 131 | N208: 0 | O208: 7 | P208: 13 | Q208: 13 | R208: 198 | S208: 33 | T208: 3 | U208: 12 | V208: 1 | W208: 1 | X208: 17 | Y208: 179 | Z208: 41 | AA208: 121 | AB208: 37 | AC208: 1 | AD208: 84 | AE208: 24 | AF208: 24 | AG208: 32 | AH208: 0 | AI208: 54 | AJ208: 6 | AK208: 1 | AL208: 9 | AM208: 62 | AN208: 43 | AO208: 151 | AP208: 147 | AQ208: 18 | AR208: 1 | AS208: 54 | AT208: 49 | AU208: 45 | AV208: 100 | AW208: 15 | AX208: 16 | AY208: 26 | AZ208: 1 | BA208: 31 | BB208: 23 | BC208: 28 | BD208: 26 | BE208: 1 | BF208: 2 | BG208: 1 | BH208: 2 | BI208: 77 | BJ208: 198 | BK208: 91 | BL208: 1 | BM208: 0 | BN208: 3 | BO208: 23 | BP208: 33 | BQ208: 9 | BR208: 43 | BS208: 42 | BT208: 15 | BU208: 25 | BV208: 23 | BW208: 5 | BX208: 16
D209: C | E209: 22 | F209: 82 | G209: 77 | H209: 61 | I209: 79 | J209: 65 | K209: 3 | L209: 0 | M209: 7 | N209: 8 | O209: 147 | P209: 29 | Q209: 130 | R209: 1 | S209: 2 | T209: 48 | U209: 63 | V209: 0 | W209: 0 | X209: 45 | Y209: 4 | Z209: 0 | AA209: 38 | AB209: 6 | AC209: 178 | AD209: 5 | AE209: 93 | AF209: 103 | AG209: 36 | AH209: 43 | AI209: 72 | AJ209: 135 | AK209: 1 | AL209: 66 | AM209: 46 | AN209: 53 | AO209: 1 | AP209: 29 | AQ209: 51 | AR209: 143 | AS209: 77 | AT209: 20 | AU209: 23 | AV209: 31 | AW209: 5 | AX209: 4 | AY209: 23 | AZ209: 168 | BA209: 57 | BB209: 87 | BC209: 41 | BD209: 2 | BE209: 1 | BF209: 0 | BG209: 1 | BH209: 196 | BI209: 0 | BJ209: 1 | BK209: 12 | BL209: 40 | BM209: 198 | BN209: 169 | BO209: 97 | BP209: 42 | BQ209: 63 | BR209: 105 | BS209: 45 | BT209: 62 | BU209: 88 | BV209: 72 | BW209: 104 | BX209: 145
D210: G | E210: 152 | F210: 106 | G210: 86 | H210: 89 | I210: 69 | J210: 48 | K210: 105 | L210: 1 | M210: 61 | N210: 192 | O210: 6 | P210: 38 | Q210: 19 | R210: 1 | S210: 162 | T210: 3 | U210: 8 | V210: 199 | W210: 197 | X210: 18 | Y210: 7 | Z210: 145 | AA210: 29 | AB210: 150 | AC210: 7 | AD210: 100 | AE210: 31 | AF210: 22 | AG210: 77 | AH210: 150 | AI210: 55 | AJ210: 0 | AK210: 0 | AL210: 67 | AM210: 51 | AN210: 32 | AO210: 48 | AP210: 1 | AQ210: 72 | AR210: 48 | AS210: 36 | AT210: 105 | AU210: 100 | AV210: 46 | AW210: 150 | AX210: 137 | AY210: 16 | AZ210: 2 | BA210: 101 | BB210: 54 | BC210: 99 | BD210: 168 | BE210: 196 | BF210: 0 | BG210: 1 | BH210: 1 | BI210: 121 | BJ210: 0 | BK210: 47 | BL210: 2 | BM210: 1 | BN210: 2 | BO210: 48 | BP210: 92 | BQ210: 57 | BR210: 2 | BS210: 75 | BT210: 87 | BU210: 70 | BV210: 75 | BW210: 82 | BX210: 18
D211: U | E211: 13 | F211: 6 | G211: 23 | H211: 34 | I211: 21 | J211: 53 | K211: 44 | L211: 198 | M211: 0 | N211: 0 | O211: 40 | P211: 120 | Q211: 38 | R211: 0 | S211: 2 | T211: 79 | U211: 114 | V211: 0 | W211: 2 | X211: 119 | Y211: 10 | Z211: 14 | AA211: 12 | AB211: 7 | AC211: 14 | AD211: 11 | AE211: 52 | AF211: 51 | AG211: 55 | AH211: 7 | AI211: 19 | AJ211: 59 | AK211: 198 | AL211: 58 | AM211: 41 | AN211: 72 | AO211: 0 | AP211: 23 | AQ211: 59 | AR211: 8 | AS211: 33 | AT211: 26 | AU211: 32 | AV211: 23 | AW211: 28 | AX211: 12 | AY211: 135 | AZ211: 29 | BA211: 11 | BB211: 36 | BC211: 31 | BD211: 4 | BE211: 2 | BF211: 198 | BG211: 197 | BH211: 1 | BI211: 1 | BJ211: 1 | BK211: 50 | BL211: 157 | BM211: 1 | BN211: 26 | BO211: 32 | BP211: 33 | BQ211: 70 | BR211: 50 | BS211: 38 | BT211: 36 | BU211: 17 | BV211: 30 | BW211: 9 | BX211: 21
D212: Missing | E212: 0 | F212: 0 | G212: 0 | H212: 0 | I212: 0 | J212: 0 | K212: 0 | L212: 0 | M212: 1 | N212: 0 | O212: 0 | P212: 0 | Q212: 0 | R212: 0 | S212: 1 | T212: 67 | U212: 3 | V212: 0 | W212: 0 | X212: 1 | Y212: 0 | Z212: 0 | AA212: 0 | AB212: 0 | AC212: 0 | AD212: 0 | AE212: 0 | AF212: 0 | AG212: 0 | AH212: 0 | AI212: 0 | AJ212: 0 | AK212: 0 | AL212: 0 | AM212: 0 | AN212: 0 | AO212: 0 | AP212: 0 | AQ212: 0 | AR212: 0 | AS212: 0 | AT212: 0 | AU212: 0 | AV212: 0 | AW212: 2 | AX212: 31 | AY212: 0 | AZ212: 0 | BA212: 0 | BB212: 0 | BC212: 1 | BD212: 0 | BE212: 0 | BF212: 0 | BG212: 0 | BH212: 0 | BI212: 1 | BJ212: 0 | BK212: 0 | BL212: 0 | BM212: 0 | BN212: 0 | BO212: 0 | BP212: 0 | BQ212: 1 | BR212: 0 | BS212: 0 | BT212: 0 | BU212: 0 | BV212: 0 | BW212: 0 | BX212: 0
D213: Valid total | E213: =SUM(E208:E211) -> 200 | F213: =SUM(F208:F211) -> 200 | G213: =SUM(G208:G211) -> 200 | H213: =SUM(H208:H211) -> 200 | I213: =SUM(I208:I211) -> 200 | J213: =SUM(J208:J211) -> 200 | K213: =SUM(K208:K211) -> 200 | L213: =SUM(L208:L211) -> 200 | ... BX213: =SUM(BX208:BX211) -> 200
D214: Check = 200 | E214: =E212+E213 -> 200 | F214: =F212+F213 -> 200 | G214: =G212+G213 -> 200 | H214: =H212+H213 -> 200 | I214: =I212+I213 -> 200 | J214: =J212+J213 -> 200 | K214: =K212+K213 -> 200 | L214: =L212+L213 -> 200 | ... BX214: =BX212+BX213 -> 200
D215: Most frequent | E215: G | F215: G | G215: G | H215: G | I215: C | J215: C | K215: G | L215: U | M215: A | N215: G | O215: C | P215: U | Q215: C | R215: A | S215: G | T215: U | U215: U | V215: G | W215: G | X215: U | Y215: A | Z215: G | AA215: A | AB215: G | AC215: C | AD215: G | AE215: C | AF215: C | AG215: G | AH215: G | AI215: C | AJ215: C | AK215: U | AL215: G | AM215: A | AN215: U | AO215: A | AP215: A | AQ215: G | AR215: C | AS215: C | AT215: G | AU215: G | AV215: A | AW215: G | AX215: G | AY215: U | AZ215: C | BA215: G | BB215: C | BC215: G | BD215: G | BE215: G | BF215: U | BG215: U | BH215: C | BI215: G | BJ215: A | BK215: A | BL215: U | BM215: C | BN215: C | BO215: C | BP215: G | BQ215: U | BR215: C | BS215: G | BT215: G | BU215: C | BV215: G | BW215: C | BX215: C
D216: Its share | E216: =MAX(E208:E211)/E213 -> 0.76 | F216: =MAX(F208:F211)/F213 -> 0.53 | G216: =MAX(G208:G211)/G213 -> 0.43 | H216: =MAX(H208:H211)/H213 -> 0.445 | I216: =MAX(I208:I211)/I213 -> 0.395 | J216: =MAX(J208:J211)/J213 -> 0.325 | K216: =MAX(K208:K211)/K213 -> 0.525 | L216: =MAX(L208:L211)/L213 -> 0.99 | ... BX216: =MAX(BX208:BX211)/BX213 -> 0.725

Sheet Frequency 1-72
A1: Position | B1: A | C1: C | D1: G | E1: U | F1: Missing | G1: Valid total | H1: Check total = 200
A2: 1 | B2: ='Database + Frequency'!E208 -> 13 | C2: ='Database + Frequency'!E209 -> 22 | D2: ='Database + Frequency'!E210 -> 152 | E2: ='Database + Frequency'!E211 -> 13 | F2: ='Database + Frequency'!E212 -> 0 | G2: =SUM(B2:E2) -> 200 | H2: =F2+G2 -> 200
A3: 2 | B3: ='Database + Frequency'!F208 -> 6 | C3: ='Database + Frequency'!F209 -> 82 | D3: ='Database + Frequency'!F210 -> 106 | E3: ='Database + Frequency'!F211 -> 6 | F3: ='Database + Frequency'!F212 -> 0 | G3: =SUM(B3:E3) -> 200 | H3: =F3+G3 -> 200
A4: 3 | B4: ='Database + Frequency'!G208 -> 14 | C4: ='Database + Frequency'!G209 -> 77 | D4: ='Database + Frequency'!G210 -> 86 | E4: ='Database + Frequency'!G211 -> 23 | F4: ='Database + Frequency'!G212 -> 0 | G4: =SUM(B4:E4) -> 200 | H4: =F4+G4 -> 200
A5: 4 | B5: ='Database + Frequency'!H208 -> 16 | C5: ='Database + Frequency'!H209 -> 61 | D5: ='Database + Frequency'!H210 -> 89 | E5: ='Database + Frequency'!H211 -> 34 | F5: ='Database + Frequency'!H212 -> 0 | G5: =SUM(B5:E5) -> 200 | H5: =F5+G5 -> 200
A6: 5 | B6: ='Database + Frequency'!I208 -> 31 | C6: ='Database + Frequency'!I209 -> 79 | D6: ='Database + Frequency'!I210 -> 69 | E6: ='Database + Frequency'!I211 -> 21 | F6: ='Database + Frequency'!I212 -> 0 | G6: =SUM(B6:E6) -> 200 | H6: =F6+G6 -> 200
A7: 6 | B7: ='Database + Frequency'!J208 -> 34 | C7: ='Database + Frequency'!J209 -> 65 | D7: ='Database + Frequency'!J210 -> 48 | E7: ='Database + Frequency'!J211 -> 53 | F7: ='Database + Frequency'!J212 -> 0 | G7: =SUM(B7:E7) -> 200 | H7: =F7+G7 -> 200
A8: 7 | B8: ='Database + Frequency'!K208 -> 48 | C8: ='Database + Frequency'!K209 -> 3 | D8: ='Database + Frequency'!K210 -> 105 | E8: ='Database + Frequency'!K211 -> 44 | F8: ='Database + Frequency'!K212 -> 0 | G8: =SUM(B8:E8) -> 200 | H8: =F8+G8 -> 200
A9: 8 | B9: ='Database + Frequency'!L208 -> 1 | C9: ='Database + Frequency'!L209 -> 0 | D9: ='Database + Frequency'!L210 -> 1 | E9: ='Database + Frequency'!L211 -> 198 | F9: ='Database + Frequency'!L212 -> 0 | G9: =SUM(B9:E9) -> 200 | H9: =F9+G9 -> 200
A10: 9 | B10: ='Database + Frequency'!M208 -> 131 | C10: ='Database + Frequency'!M209 -> 7 | D10: ='Database + Frequency'!M210 -> 61 | E10: ='Database + Frequency'!M211 -> 0 | F10: ='Database + Frequency'!M212 -> 1 | G10: =SUM(B10:E10) -> 199 | H10: =F10+G10 -> 200
A11: 10 | B11: ='Database + Frequency'!N208 -> 0 | C11: ='Database + Frequency'!N209 -> 8 | D11: ='Database + Frequency'!N210 -> 192 | E11: ='Database + Frequency'!N211 -> 0 | F11: ='Database + Frequency'!N212 -> 0 | G11: =SUM(B11:E11) -> 200 | H11: =F11+G11 -> 200
A12: 11 | B12: ='Database + Frequency'!O208 -> 7 | C12: ='Database + Frequency'!O209 -> 147 | D12: ='Database + Frequency'!O210 -> 6 | E12: ='Database + Frequency'!O211 -> 40 | F12: ='Database + Frequency'!O212 -> 0 | G12: =SUM(B12:E12) -> 200 | H12: =F12+G12 -> 200
A13: 12 | B13: ='Database + Frequency'!P208 -> 13 | C13: ='Database + Frequency'!P209 -> 29 | D13: ='Database + Frequency'!P210 -> 38 | E13: ='Database + Frequency'!P211 -> 120 | F13: ='Database + Frequency'!P212 -> 0 | G13: =SUM(B13:E13) -> 200 | H13: =F13+G13 -> 200
A14: 13 | B14: ='Database + Frequency'!Q208 -> 13 | C14: ='Database + Frequency'!Q209 -> 130 | D14: ='Database + Frequency'!Q210 -> 19 | E14: ='Database + Frequency'!Q211 -> 38 | F14: ='Database + Frequency'!Q212 -> 0 | G14: =SUM(B14:E14) -> 200 | H14: =F14+G14 -> 200
A15: 14 | B15: ='Database + Frequency'!R208 -> 198 | C15: ='Database + Frequency'!R209 -> 1 | D15: ='Database + Frequency'!R210 -> 1 | E15: ='Database + Frequency'!R211 -> 0 | F15: ='Database + Frequency'!R212 -> 0 | G15: =SUM(B15:E15) -> 200 | H15: =F15+G15 -> 200
A16: 15 | B16: ='Database + Frequency'!S208 -> 33 | C16: ='Database + Frequency'!S209 -> 2 | D16: ='Database + Frequency'!S210 -> 162 | E16: ='Database + Frequency'!S211 -> 2 | F16: ='Database + Frequency'!S212 -> 1 | G16: =SUM(B16:E16) -> 199 | H16: =F16+G16 -> 200
A17: 16 | B17: ='Database + Frequency'!T208 -> 3 | C17: ='Database + Frequency'!T209 -> 48 | D17: ='Database + Frequency'!T210 -> 3 | E17: ='Database + Frequency'!T211 -> 79 | F17: ='Database + Frequency'!T212 -> 67 | G17: =SUM(B17:E17) -> 133 | H17: =F17+G17 -> 200
A18: 17 | B18: ='Database + Frequency'!U208 -> 12 | C18: ='Database + Frequency'!U209 -> 63 | D18: ='Database + Frequency'!U210 -> 8 | E18: ='Database + Frequency'!U211 -> 114 | F18: ='Database + Frequency'!U212 -> 3 | G18: =SUM(B18:E18) -> 197 | H18: =F18+G18 -> 200
A19: 18 | B19: ='Database + Frequency'!V208 -> 1 | C19: ='Database + Frequency'!V209 -> 0 | D19: ='Database + Frequency'!V210 -> 199 | E19: ='Database + Frequency'!V211 -> 0 | F19: ='Database + Frequency'!V212 -> 0 | G19: =SUM(B19:E19) -> 200 | H19: =F19+G19 -> 200
A20: 19 | B20: ='Database + Frequency'!W208 -> 1 | C20: ='Database + Frequency'!W209 -> 0 | D20: ='Database + Frequency'!W210 -> 197 | E20: ='Database + Frequency'!W211 -> 2 | F20: ='Database + Frequency'!W212 -> 0 | G20: =SUM(B20:E20) -> 200 | H20: =F20+G20 -> 200
A21: 20 | B21: ='Database + Frequency'!X208 -> 17 | C21: ='Database + Frequency'!X209 -> 45 | D21: ='Database + Frequency'!X210 -> 18 | E21: ='Database + Frequency'!X211 -> 119 | F21: ='Database + Frequency'!X212 -> 1 | G21: =SUM(B21:E21) -> 199 | H21: =F21+G21 -> 200
A22: 21 | B22: ='Database + Frequency'!Y208 -> 179 | C22: ='Database + Frequency'!Y209 -> 4 | D22: ='Database + Frequency'!Y210 -> 7 | E22: ='Database + Frequency'!Y211 -> 10 | F22: ='Database + Frequency'!Y212 -> 0 | G22: =SUM(B22:E22) -> 200 | H22: =F22+G22 -> 200
A23: 22 | B23: ='Database + Frequency'!Z208 -> 41 | C23: ='Database + Frequency'!Z209 -> 0 | D23: ='Database + Frequency'!Z210 -> 145 | E23: ='Database + Frequency'!Z211 -> 14 | F23: ='Database + Frequency'!Z212 -> 0 | G23: =SUM(B23:E23) -> 200 | H23: =F23+G23 -> 200
A24: 23 | B24: ='Database + Frequency'!AA208 -> 121 | C24: ='Database + Frequency'!AA209 -> 38 | D24: ='Database + Frequency'!AA210 -> 29 | E24: ='Database + Frequency'!AA211 -> 12 | F24: ='Database + Frequency'!AA212 -> 0 | G24: =SUM(B24:E24) -> 200 | H24: =F24+G24 -> 200
A25: 24 | B25: ='Database + Frequency'!AB208 -> 37 | C25: ='Database + Frequency'!AB209 -> 6 | D25: ='Database + Frequency'!AB210 -> 150 | E25: ='Database + Frequency'!AB211 -> 7 | F25: ='Database + Frequency'!AB212 -> 0 | G25: =SUM(B25:E25) -> 200 | H25: =F25+G25 -> 200
A26: 25 | B26: ='Database + Frequency'!AC208 -> 1 | C26: ='Database + Frequency'!AC209 -> 178 | D26: ='Database + Frequency'!AC210 -> 7 | E26: ='Database + Frequency'!AC211 -> 14 | F26: ='Database + Frequency'!AC212 -> 0 | G26: =SUM(B26:E26) -> 200 | H26: =F26+G26 -> 200
A27: 26 | B27: ='Database + Frequency'!AD208 -> 84 | C27: ='Database + Frequency'!AD209 -> 5 | D27: ='Database + Frequency'!AD210 -> 100 | E27: ='Database + Frequency'!AD211 -> 11 | F27: ='Database + Frequency'!AD212 -> 0 | G27: =SUM(B27:E27) -> 200 | H27: =F27+G27 -> 200
A28: 27 | B28: ='Database + Frequency'!AE208 -> 24 | C28: ='Database + Frequency'!AE209 -> 93 | D28: ='Database + Frequency'!AE210 -> 31 | E28: ='Database + Frequency'!AE211 -> 52 | F28: ='Database + Frequency'!AE212 -> 0 | G28: =SUM(B28:E28) -> 200 | H28: =F28+G28 -> 200
A29: 28 | B29: ='Database + Frequency'!AF208 -> 24 | C29: ='Database + Frequency'!AF209 -> 103 | D29: ='Database + Frequency'!AF210 -> 22 | E29: ='Database + Frequency'!AF211 -> 51 | F29: ='Database + Frequency'!AF212 -> 0 | G29: =SUM(B29:E29) -> 200 | H29: =F29+G29 -> 200
A30: 29 | B30: ='Database + Frequency'!AG208 -> 32 | C30: ='Database + Frequency'!AG209 -> 36 | D30: ='Database + Frequency'!AG210 -> 77 | E30: ='Database + Frequency'!AG211 -> 55 | F30: ='Database + Frequency'!AG212 -> 0 | G30: =SUM(B30:E30) -> 200 | H30: =F30+G30 -> 200
A31: 30 | B31: ='Database + Frequency'!AH208 -> 0 | C31: ='Database + Frequency'!AH209 -> 43 | D31: ='Database + Frequency'!AH210 -> 150 | E31: ='Database + Frequency'!AH211 -> 7 | F31: ='Database + Frequency'!AH212 -> 0 | G31: =SUM(B31:E31) -> 200 | H31: =F31+G31 -> 200
A32: 31 | B32: ='Database + Frequency'!AI208 -> 54 | C32: ='Database + Frequency'!AI209 -> 72 | D32: ='Database + Frequency'!AI210 -> 55 | E32: ='Database + Frequency'!AI211 -> 19 | F32: ='Database + Frequency'!AI212 -> 0 | G32: =SUM(B32:E32) -> 200 | H32: =F32+G32 -> 200
A33: 32 | B33: ='Database + Frequency'!AJ208 -> 6 | C33: ='Database + Frequency'!AJ209 -> 135 | D33: ='Database + Frequency'!AJ210 -> 0 | E33: ='Database + Frequency'!AJ211 -> 59 | F33: ='Database + Frequency'!AJ212 -> 0 | G33: =SUM(B33:E33) -> 200 | H33: =F33+G33 -> 200
A34: 33 | B34: ='Database + Frequency'!AK208 -> 1 | C34: ='Database + Frequency'!AK209 -> 1 | D34: ='Database + Frequency'!AK210 -> 0 | E34: ='Database + Frequency'!AK211 -> 198 | F34: ='Database + Frequency'!AK212 -> 0 | G34: =SUM(B34:E34) -> 200 | H34: =F34+G34 -> 200
A35: 34 | B35: ='Database + Frequency'!AL208 -> 9 | C35: ='Database + Frequency'!AL209 -> 66 | D35: ='Database + Frequency'!AL210 -> 67 | E35: ='Database + Frequency'!AL211 -> 58 | F35: ='Database + Frequency'!AL212 -> 0 | G35: =SUM(B35:E35) -> 200 | H35: =F35+G35 -> 200
A36: 35 | B36: ='Database + Frequency'!AM208 -> 62 | C36: ='Database + Frequency'!AM209 -> 46 | D36: ='Database + Frequency'!AM210 -> 51 | E36: ='Database + Frequency'!AM211 -> 41 | F36: ='Database + Frequency'!AM212 -> 0 | G36: =SUM(B36:E36) -> 200 | H36: =F36+G36 -> 200
A37: 36 | B37: ='Database + Frequency'!AN208 -> 43 | C37: ='Database + Frequency'!AN209 -> 53 | D37: ='Database + Frequency'!AN210 -> 32 | E37: ='Database + Frequency'!AN211 -> 72 | F37: ='Database + Frequency'!AN212 -> 0 | G37: =SUM(B37:E37) -> 200 | H37: =F37+G37 -> 200
A38: 37 | B38: ='Database + Frequency'!AO208 -> 151 | C38: ='Database + Frequency'!AO209 -> 1 | D38: ='Database + Frequency'!AO210 -> 48 | E38: ='Database + Frequency'!AO211 -> 0 | F38: ='Database + Frequency'!AO212 -> 0 | G38: =SUM(B38:E38) -> 200 | H38: =F38+G38 -> 200
A39: 38 | B39: ='Database + Frequency'!AP208 -> 147 | C39: ='Database + Frequency'!AP209 -> 29 | D39: ='Database + Frequency'!AP210 -> 1 | E39: ='Database + Frequency'!AP211 -> 23 | F39: ='Database + Frequency'!AP212 -> 0 | G39: =SUM(B39:E39) -> 200 | H39: =F39+G39 -> 200
A40: 39 | B40: ='Database + Frequency'!AQ208 -> 18 | C40: ='Database + Frequency'!AQ209 -> 51 | D40: ='Database + Frequency'!AQ210 -> 72 | E40: ='Database + Frequency'!AQ211 -> 59 | F40: ='Database + Frequency'!AQ212 -> 0 | G40: =SUM(B40:E40) -> 200 | H40: =F40+G40 -> 200
...

Sheet Background
A1: BACKGROUND FREQUENCIES (reference set, pooled over all 72 positions)
A3: Base | B3: Total count | C3: Background p
A4: A | B4: =SUM('Frequency 1-72'!B2:B73) -> 2651 | C4: =B4/$B$8 -> 0.18550136
A5: C | B5: =SUM('Frequency 1-72'!C2:C73) -> 3951 | C5: =B5/$B$8 -> 0.27646771
A6: G | B6: =SUM('Frequency 1-72'!D2:D73) -> 4643 | C6: =B6/$B$8 -> 0.32488979
A7: U | B7: =SUM('Frequency 1-72'!E2:E73) -> 3046 | C7: =B7/$B$8 -> 0.21314114
A8: Total | B8: =SUM(B4:B7) -> 14291
A9: GC content | B9: =(B5+B6)/B8 -> 0.6013575
A11: From | B11: To | C11: Dinucleotide count | D11: Background p(Y|X)
A12: A | B12: A | C12: =SUMIFS('Transition Stepwise'!$F$2:$F$1137,'Transition Stepwise'!$C$2:$C$1137,A12,'Transition Stepwise'!$D$2:$D$1137,B12) -> 573 | D12: =(C12+1)/(SUMIF($A$12:$A$27,A12,$C$12:$C$27)+4*1) -> 0.21958684
A13: A | B13: C | C13: =SUMIFS('Transition Stepwise'!$F$2:$F$1137,'Transition Stepwise'!$C$2:$C$1137,A13,'Transition Stepwise'!$D$2:$D$1137,B13) -> 418 | D13: =(C13+1)/(SUMIF($A$12:$A$27,A13,$C$12:$C$27)+4*1) -> 0.16029074
A14: A | B14: G | C14: =SUMIFS('Transition Stepwise'!$F$2:$F$1137,'Transition Stepwise'!$C$2:$C$1137,A14,'Transition Stepwise'!$D$2:$D$1137,B14) -> 1109 | D14: =(C14+1)/(SUMIF($A$12:$A$27,A14,$C$12:$C$27)+4*1) -> 0.42463657
A15: A | B15: U | C15: =SUMIFS('Transition Stepwise'!$F$2:$F$1137,'Transition Stepwise'!$C$2:$C$1137,A15,'Transition Stepwise'!$D$2:$D$1137,B15) -> 510 | D15: =(C15+1)/(SUMIF($A$12:$A$27,A15,$C$12:$C$27)+4*1) -> 0.19548585
A16: C | B16: A | C16: =SUMIFS('Transition Stepwise'!$F$2:$F$1137,'Transition Stepwise'!$C$2:$C$1137,A16,'Transition Stepwise'!$D$2:$D$1137,B16) -> 742 | D16: =(C16+1)/(SUMIF($A$12:$A$27,A16,$C$12:$C$27)+4*1) -> 0.1951668
A17: C | B17: C | C17: =SUMIFS('Transition Stepwise'!$F$2:$F$1137,'Transition Stepwise'!$C$2:$C$1137,A17,'Transition Stepwise'!$D$2:$D$1137,B17) -> 1186 | D17: =(C17+1)/(SUMIF($A$12:$A$27,A17,$C$12:$C$27)+4*1) -> 0.31179406
A18: C | B18: G | C18: =SUMIFS('Transition Stepwise'!$F$2:$F$1137,'Transition Stepwise'!$C$2:$C$1137,A18,'Transition Stepwise'!$D$2:$D$1137,B18) -> 1128 | D18: =(C18+1)/(SUMIF($A$12:$A$27,A18,$C$12:$C$27)+4*1) -> 0.29655897
A19: C | B19: U | C19: =SUMIFS('Transition Stepwise'!$F$2:$F$1137,'Transition Stepwise'!$C$2:$C$1137,A19,'Transition Stepwise'!$D$2:$D$1137,B19) -> 747 | D19: =(C19+1)/(SUMIF($A$12:$A$27,A19,$C$12:$C$27)+4*1) -> 0.19648017
A20: G | B20: A | C20: =SUMIFS('Transition Stepwise'!$F$2:$F$1137,'Transition Stepwise'!$C$2:$C$1137,A20,'Transition Stepwise'!$D$2:$D$1137,B20) -> 751 | D20: =(C20+1)/(SUMIF($A$12:$A$27,A20,$C$12:$C$27)+4*1) -> 0.16476775
A21: G | B21: C | C21: =SUMIFS('Transition Stepwise'!$F$2:$F$1137,'Transition Stepwise'!$C$2:$C$1137,A21,'Transition Stepwise'!$D$2:$D$1137,B21) -> 1167 | D21: =(C21+1)/(SUMIF($A$12:$A$27,A21,$C$12:$C$27)+4*1) -> 0.25591586
A22: G | B22: G | C22: =SUMIFS('Transition Stepwise'!$F$2:$F$1137,'Transition Stepwise'!$C$2:$C$1137,A22,'Transition Stepwise'!$D$2:$D$1137,B22) -> 1571 | D22: =(C22+1)/(SUMIF($A$12:$A$27,A22,$C$12:$C$27)+4*1) -> 0.34443471
A23: G | B23: U | C23: =SUMIFS('Transition Stepwise'!$F$2:$F$1137,'Transition Stepwise'!$C$2:$C$1137,A23,'Transition Stepwise'!$D$2:$D$1137,B23) -> 1071 | D23: =(C23+1)/(SUMIF($A$12:$A$27,A23,$C$12:$C$27)+4*1) -> 0.23488168
... A27: U | B27: U | C27: =SUMIFS('Transition Stepwise'!$F$2:$F$1137,'Transition Stepwise'!$C$2:$C$1137,A27,'Transition Stepwise'!$D$2:$D$1137,B27) -> 665 | D27: =(C27+1)/(SUMIF($A$12:$A$27,A27,$C$12:$C$27)+4*1) -> 0.22074909

Sheet Formulas
A1: EVERY FORMULA USED, STEP BY STEP
A2: All functions listed are available in Excel 2007.
A4: Step | B4: Quantity | C4: Algebra | D4: Spreadsheet implementation (without the leading = sign) | E4: Where
A5: 1 | B5: Frequency | C5: n(b,i) = records with base b at position i | D5: counted from the database block | E5: Database + Frequency
A6: 2 | B6: Valid total | C6: N(i) = n(A,i)+n(C,i)+n(G,i)+n(U,i) | D6: SUM over the four base rows | E6: Frequency 1-72 col G
A7: 3 | B7: Emission raw | C7: e_raw(b,i) = n(b,i) / N(i) | D7: D/E | E7: Emission Stepwise col G
A8: 4 | B8: Emission smoothed | C8: e(b,i) = ( n(b,i) + a ) / ( N(i) + 4a ) | D8: I/J | E8: Emission Stepwise col H
A9: 5 | B9: Emission check | C9: sum over b of e(b,i) = 1 | D9: ROUND(SUMIF(position,i,smoothed),9) | E9: Emission Stepwise col L
A10: 6 | B10: Background base | C10: q(b) = sum over i n(b,i) / grand total | D10: SUM(col)/total | E10: Background C4:C7
A11: 7 | B11: Transition count | C11: c(X->Y,i) = records with X at i and Y at i+1 | D11: counted from the database block | E11: Transition Stepwise col F
A12: 8 | B12: FROM total | C12: Cx(X,i) = sum over Y of c(X->Y,i) | D12: SUMIFS(count, step, i, from, X) | E12: Transition Stepwise col G
A13: 9 | B13: Transition raw | C13: t_raw(Y|X,i) = c(X->Y,i) / Cx(X,i) | D13: F/G | E13: Transition Stepwise col I
A14: 10 | B14: Transition smoothed | C14: t(Y|X,i) = ( c(X->Y,i) + a ) / ( Cx(X,i) + 4a ) | D14: K/L | E14: Transition Stepwise col J
A15: 11 | B15: Transition check | C15: sum over Y of t(Y|X,i) = 1 | D15: ROUND(SUMIFS(smoothed, step, i, from, X),9) | E15: Transition Stepwise col N
A16: 12 | B16: Background dinucleotide | C16: qd(Y|X) = ( sum over i c(X->Y,i) + a ) / ( sum over i,Y c(X->Y,i) + 4a ) | D16: (C+1)/(SUMIF+4) | E16: Background D12:D27
... A30: 26 | B30: GC-adjusted residual | C30: r = S - ( mean(S) + b*( GC - mean(GC) ) ) | D30: computed in Python | E30: GC Confound
A33: a = alpha = 1 (Laplace smoothing).

Sheet Emission Stepwise
A1: Position | B1: Base | C1: Key | D1: Count n | E1: Valid N | F1: Alpha | G1: Raw e_raw | H1: Smoothed e | I1: n+a | J1: N+4a | K1: Formula | L1: Check sum
A2: 1 | B2: A | C2: =A2&"|"&B2 -> 1|A | D2: =INDEX('Frequency 1-72'!$B$2:$E$73,A2,MATCH(B2,{"A","C","G","U"},0)) -> 13 | E2: ='Frequency 1-72'!G2 -> 200 | F2: 1 | G2: =IF(E2=0,"",D2/E2) -> 0.065 | H2: =I2/J2 -> 0.068627451 | I2: =D2+F2 -> 14 | J2: =E2+4*F2 -> 204 | K2: e = (n + a) / (N + 4a) | L2: =ROUND(SUMIF($A$2:$A$289,A2,$H$2:$H$289),9) -> 1
A3: 1 | B3: C | C3: =A3&"|"&B3 -> 1|C | D3: =INDEX('Frequency 1-72'!$B$2:$E$73,A3,MATCH(B3,{"A","C","G","U"},0)) -> 22 | E3: ='Frequency 1-72'!G2 -> 200 | F3: 1 | G3: =IF(E3=0,"",D3/E3) -> 0.11 | H3: =I3/J3 -> 0.1127451 | I3: =D3+F3 -> 23 | J3: =E3+4*F3 -> 204 | K3: e = (n + a) / (N + 4a) | L3: =ROUND(SUMIF($A$2:$A$289,A3,$H$2:$H$289),9) -> 1
A4: 1 | B4: G | C4: =A4&"|"&B4 -> 1|G | D4: =INDEX('Frequency 1-72'!$B$2:$E$73,A4,MATCH(B4,{"A","C","G","U"},0)) -> 152 | E4: ='Frequency 1-72'!G2 -> 200 | F4: 1 | G4: =IF(E4=0,"",D4/E4) -> 0.76 | H4: =I4/J4 -> 0.75 | I4: =D4+F4 -> 153 | J4: =E4+4*F4 -> 204 | K4: e = (n + a) / (N + 4a) | L4: =ROUND(SUMIF($A$2:$A$289,A4,$H$2:$H$289),9) -> 1
A5: 1 | B5: U | C5: =A5&"|"&B5 -> 1|U | D5: =INDEX('Frequency 1-72'!$B$2:$E$73,A5,MATCH(B5,{"A","C","G","U"},0)) -> 13 | E5: ='Frequency 1-72'!G2 -> 200 | F5: 1 | G5: =IF(E5=0,"",D5/E5) -> 0.065 | H5: =I5/J5 -> 0.068627451 | I5: =D5+F5 -> 14 | J5: =E5+4*F5 -> 204 | K5: e = (n + a) / (N + 4a) | L5: =ROUND(SUMIF($A$2:$A$289,A5,$H$2:$H$289),9) -> 1
A6: 2 | B6: A | C6: =A6&"|"&B6 -> 2|A | D6: =INDEX('Frequency 1-72'!$B$2:$E$73,A6,MATCH(B6,{"A","C","G","U"},0)) -> 6 | E6: ='Frequency 1-72'!G3 -> 200 | F6: 1 | G6: =IF(E6=0,"",D6/E6) -> 0.03 | H6: =I6/J6 -> 0.034313725 | I6: =D6+F6 -> 7 | J6: =E6+4*F6 -> 204 | K6: e = (n + a) / (N + 4a) | L6: =ROUND(SUMIF($A$2:$A$289,A6,$H$2:$H$289),9) -> 1
A7: 2 | B7: C | C7: =A7&"|"&B7 -> 2|C | D7: =INDEX('Frequency 1-72'!$B$2:$E$73,A7,MATCH(B7,{"A","C","G","U"},0)) -> 82 | E7: ='Frequency 1-72'!G3 -> 200 | F7: 1 | G7: =IF(E7=0,"",D7/E7) -> 0.41 | H7: =I7/J7 -> 0.40686275 | I7: =D7+F7 -> 83 | J7: =E7+4*F7 -> 204 | K7: e = (n + a) / (N + 4a) | L7: =ROUND(SUMIF($A$2:$A$289,A7,$H$2:$H$289),9) -> 1
A8: 2 | B8: G | C8: =A8&"|"&B8 -> 2|G | D8: =INDEX('Frequency 1-72'!$B$2:$E$73,A8,MATCH(B8,{"A","C","G","U"},0)) -> 106 | E8: ='Frequency 1-72'!G3 -> 200 | F8: 1 | G8: =IF(E8=0,"",D8/E8) -> 0.53 | H8: =I8/J8 -> 0.5245098 | I8: =D8+F8 -> 107 | J8: =E8+4*F8 -> 204 | K8: e = (n + a) / (N + 4a) | L8: =ROUND(SUMIF($A$2:$A$289,A8,$H$2:$H$289),9) -> 1
A9: 2 | B9: U | C9: =A9&"|"&B9 -> 2|U | D9: =INDEX('Frequency 1-72'!$B$2:$E$73,A9,MATCH(B9,{"A","C","G","U"},0)) -> 6 | E9: ='Frequency 1-72'!G3 -> 200 | F9: 1 | G9: =IF(E9=0,"",D9/E9) -> 0.03 | H9: =I9/J9 -> 0.034313725 | I9: =D9+F9 -> 7 | J9: =E9+4*F9 -> 204 | K9: e = (n + a) / (N + 4a) | L9: =ROUND(SUMIF($A$2:$A$289,A9,$H$2:$H$289),9) -> 1
A10: 3 | B10: A | C10: =A10&"|"&B10 -> 3|A | D10: =INDEX('Frequency 1-72'!$B$2:$E$73,A10,MATCH(B10,{"A","C","G","U"},0)) -> 14 | E10: ='Frequency 1-72'!G4 -> 200 | F10: 1 | G10: =IF(E10=0,"",D10/E10) -> 0.07 | H10: =I10/J10 -> 0.073529412 | I10: =D10+F10 -> 15 | J10: =E10+4*F10 -> 204 | K10: e = (n + a) / (N + 4a) | L10: =ROUND(SUMIF($A$2:$A$289,A10,$H$2:$H$289),9) -> 1
A11: 3 | B11: C | C11: =A11&"|"&B11 -> 3|C | D11: =INDEX('Frequency 1-72'!$B$2:$E$73,A11,MATCH(B11,{"A","C","G","U"},0)) -> 77 | E11: ='Frequency 1-72'!G4 -> 200 | F11: 1 | G11: =IF(E11=0,"",D11/E11) -> 0.385 | H11: =I11/J11 -> 0.38235294 | I11: =D11+F11 -> 78 | J11: =E11+4*F11 -> 204 | K11: e = (n + a) / (N + 4a) | L11: =ROUND(SUMIF($A$2:$A$289,A11,$H$2:$H$289),9) -> 1
A12: 3 | B12: G | C12: =A12&"|"&B12 -> 3|G | D12: =INDEX('Frequency 1-72'!$B$2:$E$73,A12,MATCH(B12,{"A","C","G","U"},0)) -> 86 | E12: ='Frequency 1-72'!G4 -> 200 | F12: 1 | G12: =IF(E12=0,"",D12/E12) -> 0.43 | H12: =I12/J12 -> 0.42647059 | I12: =D12+F12 -> 87 | J12: =E12+4*F12 -> 204 | K12: e = (n + a) / (N + 4a) | L12: =ROUND(SUMIF($A$2:$A$289,A12,$H$2:$H$289),9) -> 1
A13: 3 | B13: U | C13: =A13&"|"&B13 -> 3|U | D13: =INDEX('Frequency 1-72'!$B$2:$E$73,A13,MATCH(B13,{"A","C","G","U"},0)) -> 23 | E13: ='Frequency 1-72'!G4 -> 200 | F13: 1 | G13: =IF(E13=0,"",D13/E13) -> 0.115 | H13: =I13/J13 -> 0.11764706 | I13: =D13+F13 -> 24 | J13: =E13+4*F13 -> 204 | K13: e = (n + a) / (N + 4a) | L13: =ROUND(SUMIF($A$2:$A$289,A13,$H$2:$H$289),9) -> 1
A14: 4 | B14: A | C14: =A14&"|"&B14 -> 4|A | D14: =INDEX('Frequency 1-72'!$B$2:$E$73,A14,MATCH(B14,{"A","C","G","U"},0)) -> 16 | E14: ='Frequency 1-72'!G5 -> 200 | F14: 1 | G14: =IF(E14=0,"",D14/E14) -> 0.08 | H14: =I14/J14 -> 0.083333333 | I14: =D14+F14 -> 17 | J14: =E14+4*F14 -> 204 | K14: e = (n + a) / (N + 4a) | L14: =ROUND(SUMIF($A$2:$A$289,A14,$H$2:$H$289),9) -> 1
A15: 4 | B15: C | C15: =A15&"|"&B15 -> 4|C | D15: =INDEX('Frequency 1-72'!$B$2:$E$73,A15,MATCH(B15,{"A","C","G","U"},0)) -> 61 | E15: ='Frequency 1-72'!G5 -> 200 | F15: 1 | G15: =IF(E15=0,"",D15/E15) -> 0.305 | H15: =I15/J15 -> 0.30392157 | I15: =D15+F15 -> 62 | J15: =E15+4*F15 -> 204 | K15: e = (n + a) / (N + 4a) | L15: =ROUND(SUMIF($A$2:$A$289,A15,$H$2:$H$289),9) -> 1
A16: 4 | B16: G | C16: =A16&"|"&B16 -> 4|G | D16: =INDEX('Frequency 1-72'!$B$2:$E$73,A16,MATCH(B16,{"A","C","G","U"},0)) -> 89 | E16: ='Frequency 1-72'!G5 -> 200 | F16: 1 | G16: =IF(E16=0,"",D16/E16) -> 0.445 | H16: =I16/J16 -> 0.44117647 | I16: =D16+F16 -> 90 | J16: =E16+4*F16 -> 204 | K16: e = (n + a) / (N + 4a) | L16: =ROUND(SUMIF($A$2:$A$289,A16,$H$2:$H$289),9) -> 1
A17: 4 | B17: U | C17: =A17&"|"&B17 -> 4|U | D17: =INDEX('Frequency 1-72'!$B$2:$E$73,A17,MATCH(B17,{"A","C","G","U"},0)) -> 34 | E17: ='Frequency 1-72'!G5 -> 200 | F17: 1 | G17: =IF(E17=0,"",D17/E17) -> 0.17 | H17: =I17/J17 -> 0.17156863 | I17: =D17+F17 -> 35 | J17: =E17+4*F17 -> 204 | K17: e = (n + a) / (N + 4a) | L17: =ROUND(SUMIF($A$2:$A$289,A17,$H$2:$H$289),9) -> 1
A18: 5 | B18: A | C18: =A18&"|"&B18 -> 5|A | D18: =INDEX('Frequency 1-72'!$B$2:$E$73,A18,MATCH(B18,{"A","C","G","U"},0)) -> 31 | E18: ='Frequency 1-72'!G6 -> 200 | F18: 1 | G18: =IF(E18=0,"",D18/E18) -> 0.155 | H18: =I18/J18 -> 0.15686275 | I18: =D18+F18 -> 32 | J18: =E18+4*F18 -> 204 | K18: e = (n + a) / (N + 4a) | L18: =ROUND(SUMIF($A$2:$A$289,A18,$H$2:$H$289),9) -> 1
A19: 5 | B19: C | C19: =A19&"|"&B19 -> 5|C | D19: =INDEX('Frequency 1-72'!$B$2:$E$73,A19,MATCH(B19,{"A","C","G","U"},0)) -> 79 | E19: ='Frequency 1-72'!G6 -> 200 | F19: 1 | G19: =IF(E19=0,"",D19/E19) -> 0.395 | H19: =I19/J19 -> 0.39215686 | I19: =D19+F19 -> 80 | J19: =E19+4*F19 -> 204 | K19: e = (n + a) / (N + 4a) | L19: =ROUND(SUMIF($A$2:$A$289,A19,$H$2:$H$289),9) -> 1
A20: 5 | B20: G | C20: =A20&"|"&B20 -> 5|G | D20: =INDEX('Frequency 1-72'!$B$2:$E$73,A20,MATCH(B20,{"A","C","G","U"},0)) -> 69 | E20: ='Frequency 1-72'!G6 -> 200 | F20: 1 | G20: =IF(E20=0,"",D20/E20) -> 0.345 | H20: =I20/J20 -> 0.34313725 | I20: =D20+F20 -> 70 | J20: =E20+4*F20 -> 204 | K20: e = (n + a) / (N + 4a) | L20: =ROUND(SUMIF($A$2:$A$289,A20,$H$2:$H$289),9) -> 1
A21: 5 | B21: U | C21: =A21&"|"&B21 -> 5|U | D21: =INDEX('Frequency 1-72'!$B$2:$E$73,A21,MATCH(B21,{"A","C","G","U"},0)) -> 21 | E21: ='Frequency 1-72'!G6 -> 200 | F21: 1 | G21: =IF(E21=0,"",D21/E21) -> 0.105 | H21: =I21/J21 -> 0.10784314 | I21: =D21+F21 -> 22 | J21: =E21+4*F21 -> 204 | K21: e = (n + a) / (N + 4a) | L21: =ROUND(SUMIF($A$2:$A$289,A21,$H$2:$H$289),9) -> 1
A22: 6 | B22: A | C22: =A22&"|"&B22 -> 6|A | D22: =INDEX('Frequency 1-72'!$B$2:$E$73,A22,MATCH(B22,{"A","C","G","U"},0)) -> 34 | E22: ='Frequency 1-72'!G7 -> 200 | F22: 1 | G22: =IF(E22=0,"",D22/E22) -> 0.17 | H22: =I22/J22 -> 0.17156863 | I22: =D22+F22 -> 35 | J22: =E22+4*F22 -> 204 | K22: e = (n + a) / (N + 4a) | L22: =ROUND(SUMIF($A$2:$A$289,A22,$H$2:$H$289),9) -> 1
A23: 6 | B23: C | C23: =A23&"|"&B23 -> 6|C | D23: =INDEX('Frequency 1-72'!$B$2:$E$73,A23,MATCH(B23,{"A","C","G","U"},0)) -> 65 | E23: ='Frequency 1-72'!G7 -> 200 | F23: 1 | G23: =IF(E23=0,"",D23/E23) -> 0.325 | H23: =I23/J23 -> 0.32352941 | I23: =D23+F23 -> 66 | J23: =E23+4*F23 -> 204 | K23: e = (n + a) / (N + 4a) | L23: =ROUND(SUMIF($A$2:$A$289,A23,$H$2:$H$289),9) -> 1
A24: 6 | B24: G | C24: =A24&"|"&B24 -> 6|G | D24: =INDEX('Frequency 1-72'!$B$2:$E$73,A24,MATCH(B24,{"A","C","G","U"},0)) -> 48 | E24: ='Frequency 1-72'!G7 -> 200 | F24: 1 | G24: =IF(E24=0,"",D24/E24) -> 0.24 | H24: =I24/J24 -> 0.24019608 | I24: =D24+F24 -> 49 | J24: =E24+4*F24 -> 204 | K24: e = (n + a) / (N + 4a) | L24: =ROUND(SUMIF($A$2:$A$289,A24,$H$2:$H$289),9) -> 1
A25: 6 | B25: U | C25: =A25&"|"&B25 -> 6|U | D25: =INDEX('Frequency 1-72'!$B$2:$E$73,A25,MATCH(B25,{"A","C","G","U"},0)) -> 53 | E25: ='Frequency 1-72'!G7 -> 200 | F25: 1 | G25: =IF(E25=0,"",D25/E25) -> 0.265 | H25: =I25/J25 -> 0.26470588 | I25: =D25+F25 -> 54 | J25: =E25+4*F25 -> 204 | K25: e = (n + a) / (N + 4a) | L25: =ROUND(SUMIF($A$2:$A$289,A25,$H$2:$H$289),9) -> 1
A26: 7 | B26: A | C26: =A26&"|"&B26 -> 7|A | D26: =INDEX('Frequency 1-72'!$B$2:$E$73,A26,MATCH(B26,{"A","C","G","U"},0)) -> 48 | E26: ='Frequency 1-72'!G8 -> 200 | F26: 1 | G26: =IF(E26=0,"",D26/E26) -> 0.24 | H26: =I26/J26 -> 0.24019608 | I26: =D26+F26 -> 49 | J26: =E26+4*F26 -> 204 | K26: e = (n + a) / (N + 4a) | L26: =ROUND(SUMIF($A$2:$A$289,A26,$H$2:$H$289),9) -> 1
A27: 7 | B27: C | C27: =A27&"|"&B27 -> 7|C | D27: =INDEX('Frequency 1-72'!$B$2:$E$73,A27,MATCH(B27,{"A","C","G","U"},0)) -> 3 | E27: ='Frequency 1-72'!G8 -> 200 | F27: 1 | G27: =IF(E27=0,"",D27/E27) -> 0.015 | H27: =I27/J27 -> 0.019607843 | I27: =D27+F27 -> 4 | J27: =E27+4*F27 -> 204 | K27: e = (n + a) / (N + 4a) | L27: =ROUND(SUMIF($A$2:$A$289,A27,$H$2:$H$289),9) -> 1
A28: 7 | B28: G | C28: =A28&"|"&B28 -> 7|G | D28: =INDEX('Frequency 1-72'!$B$2:$E$73,A28,MATCH(B28,{"A","C","G","U"},0)) -> 105 | E28: ='Frequency 1-72'!G8 -> 200 | F28: 1 | G28: =IF(E28=0,"",D28/E28) -> 0.525 | H28: =I28/J28 -> 0.51960784 | I28: =D28+F28 -> 106 | J28: =E28+4*F28 -> 204 | K28: e = (n + a) / (N + 4a) | L28: =ROUND(SUMIF($A$2:$A$289,A28,$H$2:$H$289),9) -> 1
A29: 7 | B29: U | C29: =A29&"|"&B29 -> 7|U | D29: =INDEX('Frequency 1-72'!$B$2:$E$73,A29,MATCH(B29,{"A","C","G","U"},0)) -> 44 | E29: ='Frequency 1-72'!G8 -> 200 | F29: 1 | G29: =IF(E29=0,"",D29/E29) -> 0.22 | H29: =I29/J29 -> 0.22058824 | I29: =D29+F29 -> 45 | J29: =E29+4*F29 -> 204 | K29: e = (n + a) / (N + 4a) | L29: =ROUND(SUMIF($A$2:$A$289,A29,$H$2:$H$289),9) -> 1
A30: 8 | B30: A | C30: =A30&"|"&B30 -> 8|A | D30: =INDEX('Frequency 1-72'!$B$2:$E$73,A30,MATCH(B30,{"A","C","G","U"},0)) -> 1 | E30: ='Frequency 1-72'!G9 -> 200 | F30: 1 | G30: =IF(E30=0,"",D30/E30) -> 0.005 | H30: =I30/J30 -> 0.0098039216 | I30: =D30+F30 -> 2 | J30: =E30+4*F30 -> 204 | K30: e = (n + a) / (N + 4a) | L30: =ROUND(SUMIF($A$2:$A$289,A30,$H$2:$H$289),9) -> 1
A31: 8 | B31: C | C31: =A31&"|"&B31 -> 8|C | D31: =INDEX('Frequency 1-72'!$B$2:$E$73,A31,MATCH(B31,{"A","C","G","U"},0)) -> 0 | E31: ='Frequency 1-72'!G9 -> 200 | F31: 1 | G31: =IF(E31=0,"",D31/E31) -> 0 | H31: =I31/J31 -> 0.0049019608 | I31: =D31+F31 -> 1 | J31: =E31+4*F31 -> 204 | K31: e = (n + a) / (N + 4a) | L31: =ROUND(SUMIF($A$2:$A$289,A31,$H$2:$H$289),9) -> 1
A32: 8 | B32: G | C32: =A32&"|"&B32 -> 8|G | D32: =INDEX('Frequency 1-72'!$B$2:$E$73,A32,MATCH(B32,{"A","C","G","U"},0)) -> 1 | E32: ='Frequency 1-72'!G9 -> 200 | F32: 1 | G32: =IF(E32=0,"",D32/E32) -> 0.005 | H32: =I32/J32 -> 0.0098039216 | I32: =D32+F32 -> 2 | J32: =E32+4*F32 -> 204 | K32: e = (n + a) / (N + 4a) | L32: =ROUND(SUMIF($A$2:$A$289,A32,$H$2:$H$289),9) -> 1
A33: 8 | B33: U | C33: =A33&"|"&B33 -> 8|U | D33: =INDEX('Frequency 1-72'!$B$2:$E$73,A33,MATCH(B33,{"A","C","G","U"},0)) -> 198 | E33: ='Frequency 1-72'!G9 -> 200 | F33: 1 | G33: =IF(E33=0,"",D33/E33) -> 0.99 | H33: =I33/J33 -> 0.9754902 | I33: =D33+F33 -> 199 | J33: =E33+4*F33 -> 204 | K33: e = (n + a) / (N + 4a) | L33: =ROUND(SUMIF($A$2:$A$289,A33,$H$2:$H$289),9) -> 1
A34: 9 | B34: A | C34: =A34&"|"&B34 -> 9|A | D34: =INDEX('Frequency 1-72'!$B$2:$E$73,A34,MATCH(B34,{"A","C","G","U"},0)) -> 131 | E34: ='Frequency 1-72'!G10 -> 199 | F34: 1 | G34: =IF(E34=0,"",D34/E34) -> 0.65829146 | H34: =I34/J34 -> 0.65024631 | I34: =D34+F34 -> 132 | J34: =E34+4*F34 -> 203 | K34: e = (n + a) / (N + 4a) | L34: =ROUND(SUMIF($A$2:$A$289,A34,$H$2:$H$289),9) -> 1
A35: 9 | B35: C | C35: =A35&"|"&B35 -> 9|C | D35: =INDEX('Frequency 1-72'!$B$2:$E$73,A35,MATCH(B35,{"A","C","G","U"},0)) -> 7 | E35: ='Frequency 1-72'!G10 -> 199 | F35: 1 | G35: =IF(E35=0,"",D35/E35) -> 0.035175879 | H35: =I35/J35 -> 0.039408867 | I35: =D35+F35 -> 8 | J35: =E35+4*F35 -> 203 | K35: e = (n + a) / (N + 4a) | L35: =ROUND(SUMIF($A$2:$A$289,A35,$H$2:$H$289),9) -> 1
A36: 9 | B36: G | C36: =A36&"|"&B36 -> 9|G | D36: =INDEX('Frequency 1-72'!$B$2:$E$73,A36,MATCH(B36,{"A","C","G","U"},0)) -> 61 | E36: ='Frequency 1-72'!G10 -> 199 | F36: 1 | G36: =IF(E36=0,"",D36/E36) -> 0.30653266 | H36: =I36/J36 -> 0.30541872 | I36: =D36+F36 -> 62 | J36: =E36+4*F36 -> 203 | K36: e = (n + a) / (N + 4a) | L36: =ROUND(SUMIF($A$2:$A$289,A36,$H$2:$H$289),9) -> 1
A37: 9 | B37: U | C37: =A37&"|"&B37 -> 9|U | D37: =INDEX('Frequency 1-72'!$B$2:$E$73,A37,MATCH(B37,{"A","C","G","U"},0)) -> 0 | E37: ='Frequency 1-72'!G10 -> 199 | F37: 1 | G37: =IF(E37=0,"",D37/E37) -> 0 | H37: =I37/J37 -> 0.0049261084 | I37: =D37+F37 -> 1 | J37: =E37+4*F37 -> 203 | K37: e = (n + a) / (N + 4a) | L37: =ROUND(SUMIF($A$2:$A$289,A37,$H$2:$H$289),9) -> 1
A38: 10 | B38: A | C38: =A38&"|"&B38 -> 10|A | D38: =INDEX('Frequency 1-72'!$B$2:$E$73,A38,MATCH(B38,{"A","C","G","U"},0)) -> 0 | E38: ='Frequency 1-72'!G11 -> 200 | F38: 1 | G38: =IF(E38=0,"",D38/E38) -> 0 | H38: =I38/J38 -> 0.0049019608 | I38: =D38+F38 -> 1 | J38: =E38+4*F38 -> 204 | K38: e = (n + a) / (N + 4a) | L38: =ROUND(SUMIF($A$2:$A$289,A38,$H$2:$H$289),9) -> 1
A39: 10 | B39: C | C39: =A39&"|"&B39 -> 10|C | D39: =INDEX('Frequency 1-72'!$B$2:$E$73,A39,MATCH(B39,{"A","C","G","U"},0)) -> 8 | E39: ='Frequency 1-72'!G11 -> 200 | F39: 1 | G39: =IF(E39=0,"",D39/E39) -> 0.04 | H39: =I39/J39 -> 0.044117647 | I39: =D39+F39 -> 9 | J39: =E39+4*F39 -> 204 | K39: e = (n + a) / (N + 4a) | L39: =ROUND(SUMIF($A$2:$A$289,A39,$H$2:$H$289),9) -> 1
A40: 10 | B40: G | C40: =A40&"|"&B40 -> 10|G | D40: =INDEX('Frequency 1-72'!$B$2:$E$73,A40,MATCH(B40,{"A","C","G","U"},0)) -> 192 | E40: ='Frequency 1-72'!G11 -> 200 | F40: 1 | G40: =IF(E40=0,"",D40/E40) -> 0.96 | H40: =I40/J40 -> 0.94607843 | I40: =D40+F40 -> 193 | J40: =E40+4*F40 -> 204 | K40: e = (n + a) / (N + 4a) | L40: =ROUND(SUMIF($A$2:$A$289,A40,$H$2:$H$289),9) -> 1
...

Sheet Emission Matrix
A1: EMISSION PROBABILITY MATRIX (smoothed) — rows = base, columns = position
A2: Base / position | B2: 1 | C2: 2 | D2: 3 | E2: 4 | F2: 5 | G2: 6 | H2: 7 | I2: 8 | J2: 9 | K2: 10 | L2: 11 | M2: 12 | N2: 13 | O2: 14 | P2: 15 | Q2: 16 | R2: 17 | S2: 18 | T2: 19 | U2: 20 | V2: 21 | W2: 22 | X2: 23 | Y2: 24 | Z2: 25 | AA2: 26 | AB2: 27 | AC2: 28 | AD2: 29 | AE2: 30 | AF2: 31 | AG2: 32 | AH2: 33 | AI2: 34 | AJ2: 35 | AK2: 36 | AL2: 37 | AM2: 38 | AN2: 39 | AO2: 40 | AP2: 41 | AQ2: 42 | AR2: 43 | AS2: 44 | AT2: 45 | AU2: 46 | AV2: 47 | AW2: 48 | AX2: 49 | AY2: 50 | AZ2: 51 | BA2: 52 | BB2: 53 | BC2: 54 | BD2: 55 | BE2: 56 | BF2: 57 | BG2: 58 | BH2: 59 | BI2: 60 | BJ2: 61 | BK2: 62 | BL2: 63 | BM2: 64 | BN2: 65 | BO2: 66 | BP2: 67 | BQ2: 68 | BR2: 69 | BS2: 70 | BT2: 71 | BU2: 72
