Workbook

Sheet GC_Summary
A1: Methanosarcina barkeri str. Wiesmoor (MBSW) genomic tRNAs - G+C content of tRNA sequence, 4 stems + 3D base pairs, and 4 loops
A3: tRNA | B3: Length (nt) | C3: Total G | D3: Total C | E3: Total G+C | F3: Overall G+C % | G3: Acceptor stem G+C | H3: D-stem G+C | I3: AC-stem G+C | J3: T-stem G+C | K3: 4 stems G+C (of 42 nt) | L3: 4 stems G+C % | M3: 3D BP G+C (of 14 nt) | N3: 3D BP G+C % | O3: 4 stems + 3D G+C (of 56 nt) | P3: 4 stems + 3D G+C % | Q3: D-loop G+C | R3: AC-loop G+C | S3: Variable loop G+C | T3: TΨC-loop G+C | U3: 4 loops length (nt) | V3: 4 loops G+C | W3: 4 loops G+C % | X3: Pos 8 nt | Y3: Pos 9 nt | Z3: Pos 26 nt | AA3: G in 8, 9, 26 | AB3: C in 8, 9, 26 | AC3: G+C in 8, 9, 26 (of 3 nt) | AD3: 8, 9, 26 G+C % | AE3: Check: stems + loops + 8,9,26 G+C = total G+C | AF3: Non-stem nt (4 loops + 8, 9, 26) | AG3: Non-stem G+C | AH3: GC_nonstem % | AI3: GC_stem % (4 stems, 42 nt) | AJ3: ΔGC = GC_stem − GC_nonstem
A4: tRNA-Ala-CGC-1-1 | B4: =COUNTIF(Positions!$B$2:$B$4694,A4) -> 71 | C4: =COUNTIFS(Positions!$B$2:$B$4694,A4,Positions!$E$2:$E$4694,"G") -> 23 | D4: =COUNTIFS(Positions!$B$2:$B$4694,A4,Positions!$E$2:$E$4694,"C") -> 19 | E4: =C4+D4 -> 42 | F4: =E4/B4 -> 0.5915493 | G4: =SUMIFS(Stems_3D_BP!$K$2:$K$1765,Stems_3D_BP!$A$2:$A$1765,$A4,Stems_3D_BP!$B$2:$B$1765,"Acceptor stem") -> 11 | H4: =SUMIFS(Stems_3D_BP!$K$2:$K$1765,Stems_3D_BP!$A$2:$A$1765,$A4,Stems_3D_BP!$B$2:$B$1765,"D-stem") -> 4 | I4: =SUMIFS(Stems_3D_BP!$K$2:$K$1765,Stems_3D_BP!$A$2:$A$1765,$A4,Stems_3D_BP!$B$2:$B$1765,"Anticodon stem") -> 4 | J4: =SUMIFS(Stems_3D_BP!$K$2:$K$1765,Stems_3D_BP!$A$2:$A$1765,$A4,Stems_3D_BP!$B$2:$B$1765,"T-stem") -> 10 | K4: =SUM(G4:J4) -> 29 | L4: =K4/42 -> 0.69047619 | M4: =SUMIFS(Stems_3D_BP!$K$2:$K$1765,Stems_3D_BP!$A$2:$A$1765,$A4,Stems_3D_BP!$B$2:$B$1765,"3D (tertiary) BP") -> 6 | N4: =M4/14 -> 0.42857143 | O4: =K4+M4 -> 35 | P4: =O4/56 -> 0.625 | Q4: =SUMIFS(Loops!$I$2:$I$316,Loops!$A$2:$A$316,$A4,Loops!$B$2:$B$316,"D-loop") -> 4 | R4: =SUMIFS(Loops!$I$2:$I$316,Loops!$A$2:$A$316,$A4,Loops!$B$2:$B$316,"Anticodon loop") -> 3 | S4: =SUMIFS(Loops!$I$2:$I$316,Loops!$A$2:$A$316,$A4,Loops!$B$2:$B$316,"Variable loop") -> 4 | T4: =SUMIFS(Loops!$I$2:$I$316,Loops!$A$2:$A$316,$A4,Loops!$B$2:$B$316,"TΨC-loop") -> 1 | U4: =SUMIFS(Loops!$F$2:$F$316,Loops!$A$2:$A$316,$A4)-SUMIFS(Loops!$F$2:$F$316,Loops!$A$2:$A$316,$A4,Loops!$B$2:$B$316,"Positions 8, 9, 26") -> 26 | V4: =SUM(Q4:T4) -> 12 | W4: =V4/U4 -> 0.46153846 | X4: =INDEX(Positions!$E$2:$E$4694,MATCH($A4&"|8",Positions!$A$2:$A$4694,0)) -> U | Y4: =INDEX(Positions!$E$2:$E$4694,MATCH($A4&"|9",Positions!$A$2:$A$4694,0)) -> A | Z4: =INDEX(Positions!$E$2:$E$4694,MATCH($A4&"|26",Positions!$A$2:$A$4694,0)) -> G | AA4: =(X4="G")+(Y4="G")+(Z4="G") -> 1 | AB4: =(X4="C")+(Y4="C")+(Z4="C") -> 0 | AC4: =AA4+AB4 -> 1 | AD4: =AC4/3 -> 0.33333333 | AE4: =IF(K4+V4+AC4=E4,"OK","MISMATCH") -> OK | AF4: =B4-42 -> 29 | AG4: =V4+AC4 -> 13 | AH4: =AG4/AF4 -> 0.44827586 | AI4: =L4 -> 0.69047619 | AJ4: =AI4-AH4 -> 0.24220033
A5: tRNA-Ala-GGC-1-1 | B5: =COUNTIF(Positions!$B$2:$B$4694,A5) -> 71 | C5: =COUNTIFS(Positions!$B$2:$B$4694,A5,Positions!$E$2:$E$4694,"G") -> 25 | D5: =COUNTIFS(Positions!$B$2:$B$4694,A5,Positions!$E$2:$E$4694,"C") -> 19 | E5: =C5+D5 -> 44 | F5: =E5/B5 -> 0.61971831 | G5: =SUMIFS(Stems_3D_BP!$K$2:$K$1765,Stems_3D_BP!$A$2:$A$1765,$A5,Stems_3D_BP!$B$2:$B$1765,"Acceptor stem") -> 13 | H5: =SUMIFS(Stems_3D_BP!$K$2:$K$1765,Stems_3D_BP!$A$2:$A$1765,$A5,Stems_3D_BP!$B$2:$B$1765,"D-stem") -> 4 | I5: =SUMIFS(Stems_3D_BP!$K$2:$K$1765,Stems_3D_BP!$A$2:$A$1765,$A5,Stems_3D_BP!$B$2:$B$1765,"Anticodon stem") -> 6 | J5: =SUMIFS(Stems_3D_BP!$K$2:$K$1765,Stems_3D_BP!$A$2:$A$1765,$A5,Stems_3D_BP!$B$2:$B$1765,"T-stem") -> 8 | K5: =SUM(G5:J5) -> 31 | L5: =K5/42 -> 0.73809524 | M5: =SUMIFS(Stems_3D_BP!$K$2:$K$1765,Stems_3D_BP!$A$2:$A$1765,$A5,Stems_3D_BP!$B$2:$B$1765,"3D (tertiary) BP") -> 6 | N5: =M5/14 -> 0.42857143 | O5: =K5+M5 -> 37 | P5: =O5/56 -> 0.66071429 | Q5: =SUMIFS(Loops!$I$2:$I$316,Loops!$A$2:$A$316,$A5,Loops!$B$2:$B$316,"D-loop") -> 4 | R5: =SUMIFS(Loops!$I$2:$I$316,Loops!$A$2:$A$316,$A5,Loops!$B$2:$B$316,"Anticodon loop") -> 3 | S5: =SUMIFS(Loops!$I$2:$I$316,Loops!$A$2:$A$316,$A5,Loops!$B$2:$B$316,"Variable loop") -> 4 | T5: =SUMIFS(Loops!$I$2:$I$316,Loops!$A$2:$A$316,$A5,Loops!$B$2:$B$316,"TΨC-loop") -> 1 | U5: =SUMIFS(Loops!$F$2:$F$316,Loops!$A$2:$A$316,$A5)-SUMIFS(Loops!$F$2:$F$316,Loops!$A$2:$A$316,$A5,Loops!$B$2:$B$316,"Positions 8, 9, 26") -> 26 | V5: =SUM(Q5:T5) -> 12 | W5: =V5/U5 -> 0.46153846 | X5: =INDEX(Positions!$E$2:$E$4694,MATCH($A5&"|8",Positions!$A$2:$A$4694,0)) -> U | Y5: =INDEX(Positions!$E$2:$E$4694,MATCH($A5&"|9",Positions!$A$2:$A$4694,0)) -> A | Z5: =INDEX(Positions!$E$2:$E$4694,MATCH($A5&"|26",Positions!$A$2:$A$4694,0)) -> G | AA5: =(X5="G")+(Y5="G")+(Z5="G") -> 1 | AB5: =(X5="C")+(Y5="C")+(Z5="C") -> 0 | AC5: =AA5+AB5 -> 1 | AD5: =AC5/3 -> 0.33333333 | AE5: =IF(K5+V5+AC5=E5,"OK","MISMATCH") -> OK | AF5: =B5-42 -> 29 | AG5: =V5+AC5 -> 13 | AH5: =AG5/AF5 -> 0.44827586 | AI5: =L5 -> 0.73809524 | AJ5: =AI5-AH5 -> 0.28981938
A6: tRNA-Ala-TGC-1-1 | B6: =COUNTIF(Positions!$B$2:$B$4694,A6) -> 72 | C6: =COUNTIFS(Positions!$B$2:$B$4694,A6,Positions!$E$2:$E$4694,"G") -> 23 | D6: =COUNTIFS(Positions!$B$2:$B$4694,A6,Positions!$E$2:$E$4694,"C") -> 18 | E6: =C6+D6 -> 41 | F6: =E6/B6 -> 0.56944444 | G6: =SUMIFS(Stems_3D_BP!$K$2:$K$1765,Stems_3D_BP!$A$2:$A$1765,$A6,Stems_3D_BP!$B$2:$B$1765,"Acceptor stem") -> 9 | H6: =SUMIFS(Stems_3D_BP!$K$2:$K$1765,Stems_3D_BP!$A$2:$A$1765,$A6,Stems_3D_BP!$B$2:$B$1765,"D-stem") -> 4 | I6: =SUMIFS(Stems_3D_BP!$K$2:$K$1765,Stems_3D_BP!$A$2:$A$1765,$A6,Stems_3D_BP!$B$2:$B$1765,"Anticodon stem") -> 8 | J6: =SUMIFS(Stems_3D_BP!$K$2:$K$1765,Stems_3D_BP!$A$2:$A$1765,$A6,Stems_3D_BP!$B$2:$B$1765,"T-stem") -> 8 | K6: =SUM(G6:J6) -> 29 | L6: =K6/42 -> 0.69047619 | M6: =SUMIFS(Stems_3D_BP!$K$2:$K$1765,Stems_3D_BP!$A$2:$A$1765,$A6,Stems_3D_BP!$B$2:$B$1765,"3D (tertiary) BP") -> 6 | N6: =M6/14 -> 0.42857143 | O6: =K6+M6 -> 35 | P6: =O6/56 -> 0.625 | Q6: =SUMIFS(Loops!$I$2:$I$316,Loops!$A$2:$A$316,$A6,Loops!$B$2:$B$316,"D-loop") -> 3 | R6: =SUMIFS(Loops!$I$2:$I$316,Loops!$A$2:$A$316,$A6,Loops!$B$2:$B$316,"Anticodon loop") -> 2 | S6: =SUMIFS(Loops!$I$2:$I$316,Loops!$A$2:$A$316,$A6,Loops!$B$2:$B$316,"Variable loop") -> 4 | T6: =SUMIFS(Loops!$I$2:$I$316,Loops!$A$2:$A$316,$A6,Loops!$B$2:$B$316,"TΨC-loop") -> 2 | U6: =SUMIFS(Loops!$F$2:$F$316,Loops!$A$2:$A$316,$A6)-SUMIFS(Loops!$F$2:$F$316,Loops!$A$2:$A$316,$A6,Loops!$B$2:$B$316,"Positions 8, 9, 26") -> 27 | V6: =SUM(Q6:T6) -> 11 | W6: =V6/U6 -> 0.40740741 | X6: =INDEX(Positions!$E$2:$E$4694,MATCH($A6&"|8",Positions!$A$2:$A$4694,0)) -> U | Y6: =INDEX(Positions!$E$2:$E$4694,MATCH($A6&"|9",Positions!$A$2:$A$4694,0)) -> A | Z6: =INDEX(Positions!$E$2:$E$4694,MATCH($A6&"|26",Positions!$A$2:$A$4694,0)) -> G | AA6: =(X6="G")+(Y6="G")+(Z6="G") -> 1 | AB6: =(X6="C")+(Y6="C")+(Z6="C") -> 0 | AC6: =AA6+AB6 -> 1 | AD6: =AC6/3 -> 0.33333333 | AE6: =IF(K6+V6+AC6=E6,"OK","MISMATCH") -> OK | AF6: =B6-42 -> 30 | AG6: =V6+AC6 -> 12 | AH6: =AG6/AF6 -> 0.4 | AI6: =L6 -> 0.69047619 | AJ6: =AI6-AH6 -> 0.29047619
A7: tRNA-Arg-CCG-1-1 | B7: =COUNTIF(Positions!$B$2:$B$4694,A7) -> 71 | C7: =COUNTIFS(Positions!$B$2:$B$4694,A7,Positions!$E$2:$E$4694,"G") -> 21 | D7: =COUNTIFS(Positions!$B$2:$B$4694,A7,Positions!$E$2:$E$4694,"C") -> 19 | E7: =C7+D7 -> 40 | F7: =E7/B7 -> 0.56338028 | G7: =SUMIFS(Stems_3D_BP!$K$2:$K$1765,Stems_3D_BP!$A$2:$A$1765,$A7,Stems_3D_BP!$B$2:$B$1765,"Acceptor stem") -> 8 | H7: =SUMIFS(Stems_3D_BP!$K$2:$K$1765,Stems_3D_BP!$A$2:$A$1765,$A7,Stems_3D_BP!$B$2:$B$1765,"D-stem") -> 4 | I7: =SUMIFS(Stems_3D_BP!$K$2:$K$1765,Stems_3D_BP!$A$2:$A$1765,$A7,Stems_3D_BP!$B$2:$B$1765,"Anticodon stem") -> 8 | J7: =SUMIFS(Stems_3D_BP!$K$2:$K$1765,Stems_3D_BP!$A$2:$A$1765,$A7,Stems_3D_BP!$B$2:$B$1765,"T-stem") -> 8 | K7: =SUM(G7:J7) -> 28 | L7: =K7/42 -> 0.66666667 | M7: =SUMIFS(Stems_3D_BP!$K$2:$K$1765,Stems_3D_BP!$A$2:$A$1765,$A7,Stems_3D_BP!$B$2:$B$1765,"3D (tertiary) BP") -> 7 | N7: =M7/14 -> 0.5 | O7: =K7+M7 -> 35 | P7: =O7/56 -> 0.625 | Q7: =SUMIFS(Loops!$I$2:$I$316,Loops!$A$2:$A$316,$A7,Loops!$B$2:$B$316,"D-loop") -> 3 | R7: =SUMIFS(Loops!$I$2:$I$316,Loops!$A$2:$A$316,$A7,Loops!$B$2:$B$316,"Anticodon loop") -> 5 | S7: =SUMIFS(Loops!$I$2:$I$316,Loops!$A$2:$A$316,$A7,Loops!$B$2:$B$316,"Variable loop") -> 2 | T7: =SUMIFS(Loops!$I$2:$I$316,Loops!$A$2:$A$316,$A7,Loops!$B$2:$B$316,"TΨC-loop") -> 2 | U7: =SUMIFS(Loops!$F$2:$F$316,Loops!$A$2:$A$316,$A7)-SUMIFS(Loops!$F$2:$F$316,Loops!$A$2:$A$316,$A7,Loops!$B$2:$B$316,"Positions 8, 9, 26") -> 26 | V7: =SUM(Q7:T7) -> 12 | W7: =V7/U7 -> 0.46153846 | X7: =INDEX(Positions!$E$2:$E$4694,MATCH($A7&"|8",Positions!$A$2:$A$4694,0)) -> U | Y7: =INDEX(Positions!$E$2:$E$4694,MATCH($A7&"|9",Positions!$A$2:$A$4694,0)) -> A | Z7: =INDEX(Positions!$E$2:$E$4694,MATCH($A7&"|26",Positions!$A$2:$A$4694,0)) -> U | AA7: =(X7="G")+(Y7="G")+(Z7="G") -> 0 | AB7: =(X7="C")+(Y7="C")+(Z7="C") -> 0 | AC7: =AA7+AB7 -> 0 | AD7: =AC7/3 -> 0 | AE7: =IF(K7+V7+AC7=E7,"OK","MISMATCH") -> OK | AF7: =B7-42 -> 29 | AG7: =V7+AC7 -> 12 | AH7: =AG7/AF7 -> 0.4137931 | AI7: =L7 -> 0.66666667 | AJ7: =AI7-AH7 -> 0.25287356
A8: tRNA-Arg-CCT-1-1 | B8: =COUNTIF(Positions!$B$2:$B$4694,A8) -> 74 | C8: =COUNTIFS(Positions!$B$2:$B$4694,A8,Positions!$E$2:$E$4694,"G") -> 24 | D8: =COUNTIFS(Positions!$B$2:$B$4694,A8,Positions!$E$2:$E$4694,"C") -> 23 | E8: =C8+D8 -> 47 | F8: =E8/B8 -> 0.63513514 | G8: =SUMIFS(Stems_3D_BP!$K$2:$K$1765,Stems_3D_BP!$A$2:$A$1765,$A8,Stems_3D_BP!$B$2:$B$1765,"Acceptor stem") -> 14 | H8: =SUMIFS(Stems_3D_BP!$K$2:$K$1765,Stems_3D_BP!$A$2:$A$1765,$A8,Stems_3D_BP!$B$2:$B$1765,"D-stem") -> 6 | I8: =SUMIFS(Stems_3D_BP!$K$2:$K$1765,Stems_3D_BP!$A$2:$A$1765,$A8,Stems_3D_BP!$B$2:$B$1765,"Anticodon stem") -> 7 | J8: =SUMIFS(Stems_3D_BP!$K$2:$K$1765,Stems_3D_BP!$A$2:$A$1765,$A8,Stems_3D_BP!$B$2:$B$1765,"T-stem") -> 8 | K8: =SUM(G8:J8) -> 35 | L8: =K8/42 -> 0.83333333 | M8: =SUMIFS(Stems_3D_BP!$K$2:$K$1765,Stems_3D_BP!$A$2:$A$1765,$A8,Stems_3D_BP!$B$2:$B$1765,"3D (tertiary) BP") -> 7 | N8: =M8/14 -> 0.5 | O8: =K8+M8 -> 42 | P8: =O8/56 -> 0.75 | Q8: =SUMIFS(Loops!$I$2:$I$316,Loops!$A$2:$A$316,$A8,Loops!$B$2:$B$316,"D-loop") -> 5 | R8: =SUMIFS(Loops!$I$2:$I$316,Loops!$A$2:$A$316,$A8,Loops!$B$2:$B$316,"Anticodon loop") -> 3 | S8: =SUMIFS(Loops!$I$2:$I$316,Loops!$A$2:$A$316,$A8,Loops!$B$2:$B$316,"Variable loop") -> 1 | T8: =SUMIFS(Loops!$I$2:$I$316,Loops!$A$2:$A$316,$A8,Loops!$B$2:$B$316,"TΨC-loop") -> 1 | U8: =SUMIFS(Loops!$F$2:$F$316,Loops!$A$2:$A$316,$A8)-SUMIFS(Loops!$F$2:$F$316,Loops!$A$2:$A$316,$A8,Loops!$B$2:$B$316,"Positions 8, 9, 26") -> 29 | V8: =SUM(Q8:T8) -> 10 | W8: =V8/U8 -> 0.34482759 | X8: =INDEX(Positions!$E$2:$E$4694,MATCH($A8&"|8",Positions!$A$2:$A$4694,0)) -> U | Y8: =INDEX(Positions!$E$2:$E$4694,MATCH($A8&"|9",Positions!$A$2:$A$4694,0)) -> G | Z8: =INDEX(Positions!$E$2:$E$4694,MATCH($A8&"|26",Positions!$A$2:$A$4694,0)) -> G | AA8: =(X8="G")+(Y8="G")+(Z8="G") -> 2 | AB8: =(X8="C")+(Y8="C")+(Z8="C") -> 0 | AC8: =AA8+AB8 -> 2 | AD8: =AC8/3 -> 0.66666667 | AE8: =IF(K8+V8+AC8=E8,"OK","MISMATCH") -> OK | AF8: =B8-42 -> 32 | AG8: =V8+AC8 -> 12 | AH8: =AG8/AF8 -> 0.375 | AI8: =L8 -> 0.83333333 | AJ8: =AI8-AH8 -> 0.45833333
A9: tRNA-Arg-GCG-1-1 | B9: =COUNTIF(Positions!$B$2:$B$4694,A9) -> 71 | C9: =COUNTIFS(Positions!$B$2:$B$4694,A9,Positions!$E$2:$E$4694,"G") -> 23 | D9: =COUNTIFS(Positions!$B$2:$B$4694,A9,Positions!$E$2:$E$4694,"C") -> 17 | E9: =C9+D9 -> 40 | F9: =E9/B9 -> 0.56338028 | G9: =SUMIFS(Stems_3D_BP!$K$2:$K$1765,Stems_3D_BP!$A$2:$A$1765,$A9,Stems_3D_BP!$B$2:$B$1765,"Acceptor stem") -> 10 | H9: =SUMIFS(Stems_3D_BP!$K$2:$K$1765,Stems_3D_BP!$A$2:$A$1765,$A9,Stems_3D_BP!$B$2:$B$1765,"D-stem") -> 5 | I9: =SUMIFS(Stems_3D_BP!$K$2:$K$1765,Stems_3D_BP!$A$2:$A$1765,$A9,Stems_3D_BP!$B$2:$B$1765,"Anticodon stem") -> 7 | J9: =SUMIFS(Stems_3D_BP!$K$2:$K$1765,Stems_3D_BP!$A$2:$A$1765,$A9,Stems_3D_BP!$B$2:$B$1765,"T-stem") -> 6 | K9: =SUM(G9:J9) -> 28 | L9: =K9/42 -> 0.66666667 | M9: =SUMIFS(Stems_3D_BP!$K$2:$K$1765,Stems_3D_BP!$A$2:$A$1765,$A9,Stems_3D_BP!$B$2:$B$1765,"3D (tertiary) BP") -> 6 | N9: =M9/14 -> 0.42857143 | O9: =K9+M9 -> 34 | P9: =O9/56 -> 0.60714286 | Q9: =SUMIFS(Loops!$I$2:$I$316,Loops!$A$2:$A$316,$A9,Loops!$B$2:$B$316,"D-loop") -> 3 | R9: =SUMIFS(Loops!$I$2:$I$316,Loops!$A$2:$A$316,$A9,Loops!$B$2:$B$316,"Anticodon loop") -> 5 | S9: =SUMIFS(Loops!$I$2:$I$316,Loops!$A$2:$A$316,$A9,Loops!$B$2:$B$316,"Variable loop") -> 2 | T9: =SUMIFS(Loops!$I$2:$I$316,Loops!$A$2:$A$316,$A9,Loops!$B$2:$B$316,"TΨC-loop") -> 2 | U9: =SUMIFS(Loops!$F$2:$F$316,Loops!$A$2:$A$316,$A9)-SUMIFS(Loops!$F$2:$F$316,Loops!$A$2:$A$316,$A9,Loops!$B$2:$B$316,"Positions 8, 9, 26") -> 26 | V9: =SUM(Q9:T9) -> 12 | W9: =V9/U9 -> 0.46153846 | X9: =INDEX(Positions!$E$2:$E$4694,MATCH($A9&"|8",Positions!$A$2:$A$4694,0)) -> U | Y9: =INDEX(Positions!$E$2:$E$4694,MATCH($A9&"|9",Positions!$A$2:$A$4694,0)) -> A | Z9: =INDEX(Positions!$E$2:$E$4694,MATCH($A9&"|26",Positions!$A$2:$A$4694,0)) -> U | AA9: =(X9="G")+(Y9="G")+(Z9="G") -> 0 | AB9: =(X9="C")+(Y9="C")+(Z9="C") -> 0 | AC9: =AA9+AB9 -> 0 | AD9: =AC9/3 -> 0 | AE9: =IF(K9+V9+AC9=E9,"OK","MISMATCH") -> OK | AF9: =B9-42 -> 29 | AG9: =V9+AC9 -> 12 | AH9: =AG9/AF9 -> 0.4137931 | AI9: =L9 -> 0.66666667 | AJ9: =AI9-AH9 -> 0.25287356
A10: tRNA-Arg-TCG-1-1 | B10: =COUNTIF(Positions!$B$2:$B$4694,A10) -> 73 | C10: =COUNTIFS(Positions!$B$2:$B$4694,A10,Positions!$E$2:$E$4694,"G") -> 24 | D10: =COUNTIFS(Positions!$B$2:$B$4694,A10,Positions!$E$2:$E$4694,"C") -> 20 | E10: =C10+D10 -> 44 | F10: =E10/B10 -> 0.60273973 | G10: =SUMIFS(Stems_3D_BP!$K$2:$K$1765,Stems_3D_BP!$A$2:$A$1765,$A10,Stems_3D_BP!$B$2:$B$1765,"Acceptor stem") -> 13 | H10: =SUMIFS(Stems_3D_BP!$K$2:$K$1765,Stems_3D_BP!$A$2:$A$1765,$A10,Stems_3D_BP!$B$2:$B$1765,"D-stem") -> 5 | I10: =SUMIFS(Stems_3D_BP!$K$2:$K$1765,Stems_3D_BP!$A$2:$A$1765,$A10,Stems_3D_BP!$B$2:$B$1765,"Anticodon stem") -> 6 | J10: =SUMIFS(Stems_3D_BP!$K$2:$K$1765,Stems_3D_BP!$A$2:$A$1765,$A10,Stems_3D_BP!$B$2:$B$1765,"T-stem") -> 8 | K10: =SUM(G10:J10) -> 32 | L10: =K10/42 -> 0.76190476 | M10: =SUMIFS(Stems_3D_BP!$K$2:$K$1765,Stems_3D_BP!$A$2:$A$1765,$A10,Stems_3D_BP!$B$2:$B$1765,"3D (tertiary) BP") -> 6 | N10: =M10/14 -> 0.42857143 | O10: =K10+M10 -> 38 | P10: =O10/56 -> 0.67857143 | Q10: =SUMIFS(Loops!$I$2:$I$316,Loops!$A$2:$A$316,$A10,Loops!$B$2:$B$316,"D-loop") -> 5 | R10: =SUMIFS(Loops!$I$2:$I$316,Loops!$A$2:$A$316,$A10,Loops!$B$2:$B$316,"Anticodon loop") -> 3 | S10: =SUMIFS(Loops!$I$2:$I$316,Loops!$A$2:$A$316,$A10,Loops!$B$2:$B$316,"Variable loop") -> 2 | T10: =SUMIFS(Loops!$I$2:$I$316,Loops!$A$2:$A$316,$A10,Loops!$B$2:$B$316,"TΨC-loop") -> 2 | U10: =SUMIFS(Loops!$F$2:$F$316,Loops!$A$2:$A$316,$A10)-SUMIFS(Loops!$F$2:$F$316,Loops!$A$2:$A$316,$A10,Loops!$B$2:$B$316,"Positions 8, 9, 26") -> 28 | V10: =SUM(Q10:T10) -> 12 | W10: =V10/U10 -> 0.42857143 | X10: =INDEX(Positions!$E$2:$E$4694,MATCH($A10&"|8",Positions!$A$2:$A$4694,0)) -> U | Y10: =INDEX(Positions!$E$2:$E$4694,MATCH($A10&"|9",Positions!$A$2:$A$4694,0)) -> A | Z10: =INDEX(Positions!$E$2:$E$4694,MATCH($A10&"|26",Positions!$A$2:$A$4694,0)) -> A | AA10: =(X10="G")+(Y10="G")+(Z10="G") -> 0 | AB10: =(X10="C")+(Y10="C")+(Z10="C") -> 0 | AC10: =AA10+AB10 -> 0 | AD10: =AC10/3 -> 0 | AE10: =IF(K10+V10+AC10=E10,"OK","MISMATCH") -> OK | AF10: =B10-42 -> 31 | AG10: =V10+AC10 -> 12 | AH10: =AG10/AF10 -> 0.38709677 | AI10: =L10 -> 0.76190476 | AJ10: =AI10-AH10 -> 0.37480799
A11: tRNA-Arg-TCT-1-1 | B11: =COUNTIF(Positions!$B$2:$B$4694,A11) -> 74 | C11: =COUNTIFS(Positions!$B$2:$B$4694,A11,Positions!$E$2:$E$4694,"G") -> 23 | D11: =COUNTIFS(Positions!$B$2:$B$4694,A11,Positions!$E$2:$E$4694,"C") -> 22 | E11: =C11+D11 -> 45 | F11: =E11/B11 -> 0.60810811 | G11: =SUMIFS(Stems_3D_BP!$K$2:$K$1765,Stems_3D_BP!$A$2:$A$1765,$A11,Stems_3D_BP!$B$2:$B$1765,"Acceptor stem") -> 12 | H11: =SUMIFS(Stems_3D_BP!$K$2:$K$1765,Stems_3D_BP!$A$2:$A$1765,$A11,Stems_3D_BP!$B$2:$B$1765,"D-stem") -> 4 | I11: =SUMIFS(Stems_3D_BP!$K$2:$K$1765,Stems_3D_BP!$A$2:$A$1765,$A11,Stems_3D_BP!$B$2:$B$1765,"Anticodon stem") -> 8 | J11: =SUMIFS(Stems_3D_BP!$K$2:$K$1765,Stems_3D_BP!$A$2:$A$1765,$A11,Stems_3D_BP!$B$2:$B$1765,"T-stem") -> 8 | K11: =SUM(G11:J11) -> 32 | L11: =K11/42 -> 0.76190476 | M11: =SUMIFS(Stems_3D_BP!$K$2:$K$1765,Stems_3D_BP!$A$2:$A$1765,$A11,Stems_3D_BP!$B$2:$B$1765,"3D (tertiary) BP") -> 7 | N11: =M11/14 -> 0.5 | O11: =K11+M11 -> 39 | P11: =O11/56 -> 0.69642857 | Q11: =SUMIFS(Loops!$I$2:$I$316,Loops!$A$2:$A$316,$A11,Loops!$B$2:$B$316,"D-loop") -> 5 | R11: =SUMIFS(Loops!$I$2:$I$316,Loops!$A$2:$A$316,$A11,Loops!$B$2:$B$316,"Anticodon loop") -> 2 | S11: =SUMIFS(Loops!$I$2:$I$316,Loops!$A$2:$A$316,$A11,Loops!$B$2:$B$316,"Variable loop") -> 3 | T11: =SUMIFS(Loops!$I$2:$I$316,Loops!$A$2:$A$316,$A11,Loops!$B$2:$B$316,"TΨC-loop") -> 1 | U11: =SUMIFS(Loops!$F$2:$F$316,Loops!$A$2:$A$316,$A11)-SUMIFS(Loops!$F$2:$F$316,Loops!$A$2:$A$316,$A11,Loops!$B$2:$B$316,"Positions 8, 9, 26") -> 29 | V11: =SUM(Q11:T11) -> 11 | W11: =V11/U11 -> 0.37931034 | X11: =INDEX(Positions!$E$2:$E$4694,MATCH($A11&"|8",Positions!$A$2:$A$4694,0)) -> U | Y11: =INDEX(Positions!$E$2:$E$4694,MATCH($A11&"|9",Positions!$A$2:$A$4694,0)) -> G | Z11: =INDEX(Positions!$E$2:$E$4694,MATCH($A11&"|26",Positions!$A$2:$A$4694,0)) -> G | AA11: =(X11="G")+(Y11="G")+(Z11="G") -> 2 | AB11: =(X11="C")+(Y11="C")+(Z11="C") -> 0 | AC11: =AA11+AB11 -> 2 | AD11: =AC11/3 -> 0.66666667 | AE11: =IF(K11+V11+AC11=E11,"OK","MISMATCH") -> OK | AF11: =B11-42 -> 32 | AG11: =V11+AC11 -> 13 | AH11: =AG11/AF11 -> 0.40625 | AI11: =L11 -> 0.76190476 | AJ11: =AI11-AH11 -> 0.35565476
A12: tRNA-Asn-GTT-1-1 | B12: =COUNTIF(Positions!$B$2:$B$4694,A12) -> 72 | C12: =COUNTIFS(Positions!$B$2:$B$4694,A12,Positions!$E$2:$E$4694,"G") -> 22 | D12: =COUNTIFS(Positions!$B$2:$B$4694,A12,Positions!$E$2:$E$4694,"C") -> 17 | E12: =C12+D12 -> 39 | F12: =E12/B12 -> 0.54166667 | G12: =SUMIFS(Stems_3D_BP!$K$2:$K$1765,Stems_3D_BP!$A$2:$A$1765,$A12,Stems_3D_BP!$B$2:$B$1765,"Acceptor stem") -> 10 | H12: =SUMIFS(Stems_3D_BP!$K$2:$K$1765,Stems_3D_BP!$A$2:$A$1765,$A12,Stems_3D_BP!$B$2:$B$1765,"D-stem") -> 4 | I12: =SUMIFS(Stems_3D_BP!$K$2:$K$1765,Stems_3D_BP!$A$2:$A$1765,$A12,Stems_3D_BP!$B$2:$B$1765,"Anticodon stem") -> 6 | J12: =SUMIFS(Stems_3D_BP!$K$2:$K$1765,Stems_3D_BP!$A$2:$A$1765,$A12,Stems_3D_BP!$B$2:$B$1765,"T-stem") -> 7 | K12: =SUM(G12:J12) -> 27 | L12: =K12/42 -> 0.64285714 | M12: =SUMIFS(Stems_3D_BP!$K$2:$K$1765,Stems_3D_BP!$A$2:$A$1765,$A12,Stems_3D_BP!$B$2:$B$1765,"3D (tertiary) BP") -> 7 | N12: =M12/14 -> 0.5 | O12: =K12+M12 -> 34 | P12: =O12/56 -> 0.60714286 | Q12: =SUMIFS(Loops!$I$2:$I$316,Loops!$A$2:$A$316,$A12,Loops!$B$2:$B$316,"D-loop") -> 3 | R12: =SUMIFS(Loops!$I$2:$I$316,Loops!$A$2:$A$316,$A12,Loops!$B$2:$B$316,"Anticodon loop") -> 2 | S12: =SUMIFS(Loops!$I$2:$I$316,Loops!$A$2:$A$316,$A12,Loops!$B$2:$B$316,"Variable loop") -> 2 | T12: =SUMIFS(Loops!$I$2:$I$316,Loops!$A$2:$A$316,$A12,Loops!$B$2:$B$316,"TΨC-loop") -> 4 | U12: =SUMIFS(Loops!$F$2:$F$316,Loops!$A$2:$A$316,$A12)-SUMIFS(Loops!$F$2:$F$316,Loops!$A$2:$A$316,$A12,Loops!$B$2:$B$316,"Positions 8, 9, 26") -> 27 | V12: =SUM(Q12:T12) -> 11 | W12: =V12/U12 -> 0.40740741 | X12: =INDEX(Positions!$E$2:$E$4694,MATCH($A12&"|8",Positions!$A$2:$A$4694,0)) -> U | Y12: =INDEX(Positions!$E$2:$E$4694,MATCH($A12&"|9",Positions!$A$2:$A$4694,0)) -> A | Z12: =INDEX(Positions!$E$2:$E$4694,MATCH($A12&"|26",Positions!$A$2:$A$4694,0)) -> G | AA12: =(X12="G")+(Y12="G")+(Z12="G") -> 1 | AB12: =(X12="C")+(Y12="C")+(Z12="C") -> 0 | AC12: =AA12+AB12 -> 1 | AD12: =AC12/3 -> 0.33333333 | AE12: =IF(K12+V12+AC12=E12,"OK","MISMATCH") -> OK | AF12: =B12-42 -> 30 | AG12: =V12+AC12 -> 12 | AH12: =AG12/AF12 -> 0.4 | AI12: =L12 -> 0.64285714 | AJ12: =AI12-AH12 -> 0.24285714
A13: tRNA-Asn-GTT-1-2 | B13: =COUNTIF(Positions!$B$2:$B$4694,A13) -> 72 | C13: =COUNTIFS(Positions!$B$2:$B$4694,A13,Positions!$E$2:$E$4694,"G") -> 22 | D13: =COUNTIFS(Positions!$B$2:$B$4694,A13,Positions!$E$2:$E$4694,"C") -> 17 | E13: =C13+D13 -> 39 | F13: =E13/B13 -> 0.54166667 | G13: =SUMIFS(Stems_3D_BP!$K$2:$K$1765,Stems_3D_BP!$A$2:$A$1765,$A13,Stems_3D_BP!$B$2:$B$1765,"Acceptor stem") -> 10 | H13: =SUMIFS(Stems_3D_BP!$K$2:$K$1765,Stems_3D_BP!$A$2:$A$1765,$A13,Stems_3D_BP!$B$2:$B$1765,"D-stem") -> 4 | I13: =SUMIFS(Stems_3D_BP!$K$2:$K$1765,Stems_3D_BP!$A$2:$A$1765,$A13,Stems_3D_BP!$B$2:$B$1765,"Anticodon stem") -> 6 | J13: =SUMIFS(Stems_3D_BP!$K$2:$K$1765,Stems_3D_BP!$A$2:$A$1765,$A13,Stems_3D_BP!$B$2:$B$1765,"T-stem") -> 7 | K13: =SUM(G13:J13) -> 27 | L13: =K13/42 -> 0.64285714 | M13: =SUMIFS(Stems_3D_BP!$K$2:$K$1765,Stems_3D_BP!$A$2:$A$1765,$A13,Stems_3D_BP!$B$2:$B$1765,"3D (tertiary) BP") -> 7 | N13: =M13/14 -> 0.5 | O13: =K13+M13 -> 34 | P13: =O13/56 -> 0.60714286 | Q13: =SUMIFS(Loops!$I$2:$I$316,Loops!$A$2:$A$316,$A13,Loops!$B$2:$B$316,"D-loop") -> 3 | R13: =SUMIFS(Loops!$I$2:$I$316,Loops!$A$2:$A$316,$A13,Loops!$B$2:$B$316,"Anticodon loop") -> 2 | S13: =SUMIFS(Loops!$I$2:$I$316,Loops!$A$2:$A$316,$A13,Loops!$B$2:$B$316,"Variable loop") -> 2 | T13: =SUMIFS(Loops!$I$2:$I$316,Loops!$A$2:$A$316,$A13,Loops!$B$2:$B$316,"TΨC-loop") -> 4 | U13: =SUMIFS(Loops!$F$2:$F$316,Loops!$A$2:$A$316,$A13)-SUMIFS(Loops!$F$2:$F$316,Loops!$A$2:$A$316,$A13,Loops!$B$2:$B$316,"Positions 8, 9, 26") -> 27 | V13: =SUM(Q13:T13) -> 11 | W13: =V13/U13 -> 0.40740741 | X13: =INDEX(Positions!$E$2:$E$4694,MATCH($A13&"|8",Positions!$A$2:$A$4694,0)) -> U | Y13: =INDEX(Positions!$E$2:$E$4694,MATCH($A13&"|9",Positions!$A$2:$A$4694,0)) -> A | Z13: =INDEX(Positions!$E$2:$E$4694,MATCH($A13&"|26",Positions!$A$2:$A$4694,0)) -> G | AA13: =(X13="G")+(Y13="G")+(Z13="G") -> 1 | AB13: =(X13="C")+(Y13="C")+(Z13="C") -> 0 | AC13: =AA13+AB13 -> 1 | AD13: =AC13/3 -> 0.33333333 | AE13: =IF(K13+V13+AC13=E13,"OK","MISMATCH") -> OK | AF13: =B13-42 -> 30 | AG13: =V13+AC13 -> 12 | AH13: =AG13/AF13 -> 0.4 | AI13: =L13 -> 0.64285714 | AJ13: =AI13-AH13 -> 0.24285714
A14: tRNA-Asp-GTC-1-1 | B14: =COUNTIF(Positions!$B$2:$B$4694,A14) -> 72 | C14: =COUNTIFS(Positions!$B$2:$B$4694,A14,Positions!$E$2:$E$4694,"G") -> 25 | D14: =COUNTIFS(Positions!$B$2:$B$4694,A14,Positions!$E$2:$E$4694,"C") -> 21 | E14: =C14+D14 -> 46 | F14: =E14/B14 -> 0.63888889 | G14: =SUMIFS(Stems_3D_BP!$K$2:$K$1765,Stems_3D_BP!$A$2:$A$1765,$A14,Stems_3D_BP!$B$2:$B$1765,"Acceptor stem") -> 11 | H14: =SUMIFS(Stems_3D_BP!$K$2:$K$1765,Stems_3D_BP!$A$2:$A$1765,$A14,Stems_3D_BP!$B$2:$B$1765,"D-stem") -> 3 | I14: =SUMIFS(Stems_3D_BP!$K$2:$K$1765,Stems_3D_BP!$A$2:$A$1765,$A14,Stems_3D_BP!$B$2:$B$1765,"Anticodon stem") -> 8 | J14: =SUMIFS(Stems_3D_BP!$K$2:$K$1765,Stems_3D_BP!$A$2:$A$1765,$A14,Stems_3D_BP!$B$2:$B$1765,"T-stem") -> 9 | K14: =SUM(G14:J14) -> 31 | L14: =K14/42 -> 0.73809524 | M14: =SUMIFS(Stems_3D_BP!$K$2:$K$1765,Stems_3D_BP!$A$2:$A$1765,$A14,Stems_3D_BP!$B$2:$B$1765,"3D (tertiary) BP") -> 8 | N14: =M14/14 -> 0.57142857 | O14: =K14+M14 -> 39 | P14: =O14/56 -> 0.69642857 | Q14: =SUMIFS(Loops!$I$2:$I$316,Loops!$A$2:$A$316,$A14,Loops!$B$2:$B$316,"D-loop") -> 5 | R14: =SUMIFS(Loops!$I$2:$I$316,Loops!$A$2:$A$316,$A14,Loops!$B$2:$B$316,"Anticodon loop") -> 4 | S14: =SUMIFS(Loops!$I$2:$I$316,Loops!$A$2:$A$316,$A14,Loops!$B$2:$B$316,"Variable loop") -> 3 | T14: =SUMIFS(Loops!$I$2:$I$316,Loops!$A$2:$A$316,$A14,Loops!$B$2:$B$316,"TΨC-loop") -> 2 | U14: =SUMIFS(Loops!$F$2:$F$316,Loops!$A$2:$A$316,$A14)-SUMIFS(Loops!$F$2:$F$316,Loops!$A$2:$A$316,$A14,Loops!$B$2:$B$316,"Positions 8, 9, 26") -> 27 | V14: =SUM(Q14:T14) -> 14 | W14: =V14/U14 -> 0.51851852 | X14: =INDEX(Positions!$E$2:$E$4694,MATCH($A14&"|8",Positions!$A$2:$A$4694,0)) -> U | Y14: =INDEX(Positions!$E$2:$E$4694,MATCH($A14&"|9",Positions!$A$2:$A$4694,0)) -> A | Z14: =INDEX(Positions!$E$2:$E$4694,MATCH($A14&"|26",Positions!$A$2:$A$4694,0)) -> G | AA14: =(X14="G")+(Y14="G")+(Z14="G") -> 1 | AB14: =(X14="C")+(Y14="C")+(Z14="C") -> 0 | AC14: =AA14+AB14 -> 1 | AD14: =AC14/3 -> 0.33333333 | AE14: =IF(K14+V14+AC14=E14,"OK","MISMATCH") -> OK | AF14: =B14-42 -> 30 | AG14: =V14+AC14 -> 15 | AH14: =AG14/AF14 -> 0.5 | AI14: =L14 -> 0.73809524 | AJ14: =AI14-AH14 -> 0.23809524
A15: tRNA-Cys-GCA-1-1 | B15: =COUNTIF(Positions!$B$2:$B$4694,A15) -> 71 | C15: =COUNTIFS(Positions!$B$2:$B$4694,A15,Positions!$E$2:$E$4694,"G") -> 22 | D15: =COUNTIFS(Positions!$B$2:$B$4694,A15,Positions!$E$2:$E$4694,"C") -> 21 | E15: =C15+D15 -> 43 | F15: =E15/B15 -> 0.6056338 | G15: =SUMIFS(Stems_3D_BP!$K$2:$K$1765,Stems_3D_BP!$A$2:$A$1765,$A15,Stems_3D_BP!$B$2:$B$1765,"Acceptor stem") -> 8 | H15: =SUMIFS(Stems_3D_BP!$K$2:$K$1765,Stems_3D_BP!$A$2:$A$1765,$A15,Stems_3D_BP!$B$2:$B$1765,"D-stem") -> 7 | I15: =SUMIFS(Stems_3D_BP!$K$2:$K$1765,Stems_3D_BP!$A$2:$A$1765,$A15,Stems_3D_BP!$B$2:$B$1765,"Anticodon stem") -> 6 | J15: =SUMIFS(Stems_3D_BP!$K$2:$K$1765,Stems_3D_BP!$A$2:$A$1765,$A15,Stems_3D_BP!$B$2:$B$1765,"T-stem") -> 8 | K15: =SUM(G15:J15) -> 29 | L15: =K15/42 -> 0.69047619 | M15: =SUMIFS(Stems_3D_BP!$K$2:$K$1765,Stems_3D_BP!$A$2:$A$1765,$A15,Stems_3D_BP!$B$2:$B$1765,"3D (tertiary) BP") -> 5 | N15: =M15/14 -> 0.35714286 | O15: =K15+M15 -> 34 | P15: =O15/56 -> 0.60714286 | Q15: =SUMIFS(Loops!$I$2:$I$316,Loops!$A$2:$A$316,$A15,Loops!$B$2:$B$316,"D-loop") -> 5 | R15: =SUMIFS(Loops!$I$2:$I$316,Loops!$A$2:$A$316,$A15,Loops!$B$2:$B$316,"Anticodon loop") -> 4 | S15: =SUMIFS(Loops!$I$2:$I$316,Loops!$A$2:$A$316,$A15,Loops!$B$2:$B$316,"Variable loop") -> 2 | T15: =SUMIFS(Loops!$I$2:$I$316,Loops!$A$2:$A$316,$A15,Loops!$B$2:$B$316,"TΨC-loop") -> 2 | U15: =SUMIFS(Loops!$F$2:$F$316,Loops!$A$2:$A$316,$A15)-SUMIFS(Loops!$F$2:$F$316,Loops!$A$2:$A$316,$A15,Loops!$B$2:$B$316,"Positions 8, 9, 26") -> 26 | V15: =SUM(Q15:T15) -> 13 | W15: =V15/U15 -> 0.5 | X15: =INDEX(Positions!$E$2:$E$4694,MATCH($A15&"|8",Positions!$A$2:$A$4694,0)) -> U | Y15: =INDEX(Positions!$E$2:$E$4694,MATCH($A15&"|9",Positions!$A$2:$A$4694,0)) -> G | Z15: =INDEX(Positions!$E$2:$E$4694,MATCH($A15&"|26",Positions!$A$2:$A$4694,0)) -> A | AA15: =(X15="G")+(Y15="G")+(Z15="G") -> 1 | AB15: =(X15="C")+(Y15="C")+(Z15="C") -> 0 | AC15: =AA15+AB15 -> 1 | AD15: =AC15/3 -> 0.33333333 | AE15: =IF(K15+V15+AC15=E15,"OK","MISMATCH") -> OK | AF15: =B15-42 -> 29 | AG15: =V15+AC15 -> 14 | AH15: =AG15/AF15 -> 0.48275862 | AI15: =L15 -> 0.69047619 | AJ15: =AI15-AH15 -> 0.20771757
... A66: tRNA-Val-TAC-1-1 | B66: =COUNTIF(Positions!$B$2:$B$4694,A66) -> 73 | C66: =COUNTIFS(Positions!$B$2:$B$4694,A66,Positions!$E$2:$E$4694,"G") -> 24 | D66: =COUNTIFS(Positions!$B$2:$B$4694,A66,Positions!$E$2:$E$4694,"C") -> 20 | E66: =C66+D66 -> 44 | F66: =E66/B66 -> 0.60273973 | G66: =SUMIFS(Stems_3D_BP!$K$2:$K$1765,Stems_3D_BP!$A$2:$A$1765,$A66,Stems_3D_BP!$B$2:$B$1765,"Acceptor stem") -> 13 | H66: =SUMIFS(Stems_3D_BP!$K$2:$K$1765,Stems_3D_BP!$A$2:$A$1765,$A66,Stems_3D_BP!$B$2:$B$1765,"D-stem") -> 4 | I66: =SUMIFS(Stems_3D_BP!$K$2:$K$1765,Stems_3D_BP!$A$2:$A$1765,$A66,Stems_3D_BP!$B$2:$B$1765,"Anticodon stem") -> 9 | J66: =SUMIFS(Stems_3D_BP!$K$2:$K$1765,Stems_3D_BP!$A$2:$A$1765,$A66,Stems_3D_BP!$B$2:$B$1765,"T-stem") -> 6 | K66: =SUM(G66:J66) -> 32 | L66: =K66/42 -> 0.76190476 | M66: =SUMIFS(Stems_3D_BP!$K$2:$K$1765,Stems_3D_BP!$A$2:$A$1765,$A66,Stems_3D_BP!$B$2:$B$1765,"3D (tertiary) BP") -> 7 | N66: =M66/14 -> 0.5 | O66: =K66+M66 -> 39 | P66: =O66/56 -> 0.69642857 | Q66: =SUMIFS(Loops!$I$2:$I$316,Loops!$A$2:$A$316,$A66,Loops!$B$2:$B$316,"D-loop") -> 4 | R66: =SUMIFS(Loops!$I$2:$I$316,Loops!$A$2:$A$316,$A66,Loops!$B$2:$B$316,"Anticodon loop") -> 2 | S66: =SUMIFS(Loops!$I$2:$I$316,Loops!$A$2:$A$316,$A66,Loops!$B$2:$B$316,"Variable loop") -> 3 | T66: =SUMIFS(Loops!$I$2:$I$316,Loops!$A$2:$A$316,$A66,Loops!$B$2:$B$316,"TΨC-loop") -> 2 | U66: =SUMIFS(Loops!$F$2:$F$316,Loops!$A$2:$A$316,$A66)-SUMIFS(Loops!$F$2:$F$316,Loops!$A$2:$A$316,$A66,Loops!$B$2:$B$316,"Positions 8, 9, 26") -> 28 | V66: =SUM(Q66:T66) -> 11 | W66: =V66/U66 -> 0.39285714 | X66: =INDEX(Positions!$E$2:$E$4694,MATCH($A66&"|8",Positions!$A$2:$A$4694,0)) -> U | Y66: =INDEX(Positions!$E$2:$E$4694,MATCH($A66&"|9",Positions!$A$2:$A$4694,0)) -> G | Z66: =INDEX(Positions!$E$2:$E$4694,MATCH($A66&"|26",Positions!$A$2:$A$4694,0)) -> A | AA66: =(X66="G")+(Y66="G")+(Z66="G") -> 1 | AB66: =(X66="C")+(Y66="C")+(Z66="C") -> 0 | AC66: =AA66+AB66 -> 1 | AD66: =AC66/3 -> 0.33333333 | AE66: =IF(K66+V66+AC66=E66,"OK","MISMATCH") -> OK | AF66: =B66-42 -> 31 | AG66: =V66+AC66 -> 12 | AH66: =AG66/AF66 -> 0.38709677 | AI66: =L66 -> 0.76190476 | AJ66: =AI66-AH66 -> 0.37480799
A67: Mean | B67: =AVERAGE(B4:B66) -> 74.492063 | C67: =AVERAGE(C4:C66) -> 24.111111 | D67: =AVERAGE(D4:D66) -> 21.238095 | E67: =AVERAGE(E4:E66) -> 45.349206 | F67: =AVERAGE(F4:F66) -> 0.60898275 | G67: =AVERAGE(G4:G66) -> 11.079365 | H67: =AVERAGE(H4:H66) -> 5.1428571 | I67: =AVERAGE(I4:I66) -> 7.1428571 | ... W67: =AVERAGE(W4:W66) -> 0.44204871 | AA67: =AVERAGE(AA4:AA66) -> 1.015873 | AB67: =AVERAGE(AB4:AB66) -> 0.079365079 | AC67: =AVERAGE(AC4:AC66) -> 1.0952381 | AD67: =AVERAGE(AD4:AD66) -> 0.36507937 | AF67: =AVERAGE(AF4:AF66) -> 32.492063 | AG67: =AVERAGE(AG4:AG66) -> 14.126984 | AH67: =AVERAGE(AH4:AH66) -> 0.43492327 | AI67: =AVERAGE(AI4:AI66) -> 0.74338624 | AJ67: =AVERAGE(AJ4:AJ66) -> 0.30846297
A69: Percentages: overall = G+C / full length; stems = /42 nt (21 bp); 3D = /14 nt (7 tertiary pairs); stems+3D = /56 nt; positions 8, 9, 26 = /3 nt; loops = / total nt of D, AC, variable and TΨC loops.
A70: 3D pairs 14, 15, 18, 19, 32, 38, 44, 48, 54, 55, 58 lie inside loops, so "4 stems + 3D" and "4 loops" share those nucleotides. 4 stems + 4 loops + positions 8, 9, 26 together cover every nucleotide once together cover every nucleotide once (column AE checks this).
A72: * one unidentified isotypes as per database

Sheet Positions
A1: Key | B1: tRNA | C1: Canonical position | D1: Actual position | E1: Nucleotide | F1: Region
A2: =B2&"|"&C2 -> tRNA-Ala-CGC-1-1|1 | B2: tRNA-Ala-CGC-1-1 | C2: 1 | D2: 1 | E2: G | F2: Acceptor stem
A3: =B3&"|"&C3 -> tRNA-Ala-CGC-1-1|2 | B3: tRNA-Ala-CGC-1-1 | C3: 2 | D3: 2 | E3: G | F3: Acceptor stem
A4: =B4&"|"&C4 -> tRNA-Ala-CGC-1-1|3 | B4: tRNA-Ala-CGC-1-1 | C4: 3 | D4: 3 | E4: G | F4: Acceptor stem
A5: =B5&"|"&C5 -> tRNA-Ala-CGC-1-1|4 | B5: tRNA-Ala-CGC-1-1 | C5: 4 | D5: 4 | E5: C | F5: Acceptor stem
A6: =B6&"|"&C6 -> tRNA-Ala-CGC-1-1|5 | B6: tRNA-Ala-CGC-1-1 | C6: 5 | D6: 5 | E6: U | F6: Acceptor stem
A7: =B7&"|"&C7 -> tRNA-Ala-CGC-1-1|6 | B7: tRNA-Ala-CGC-1-1 | C7: 6 | D7: 6 | E7: C | F7: Acceptor stem
A8: =B8&"|"&C8 -> tRNA-Ala-CGC-1-1|7 | B8: tRNA-Ala-CGC-1-1 | C8: 7 | D8: 7 | E8: G | F8: Acceptor stem
A9: =B9&"|"&C9 -> tRNA-Ala-CGC-1-1|8 | B9: tRNA-Ala-CGC-1-1 | C9: 8 | D9: 8 | E9: U | F9: Position 8
A10: =B10&"|"&C10 -> tRNA-Ala-CGC-1-1|9 | B10: tRNA-Ala-CGC-1-1 | C10: 9 | D10: 9 | E10: A | F10: Position 9
A11: =B11&"|"&C11 -> tRNA-Ala-CGC-1-1|10 | B11: tRNA-Ala-CGC-1-1 | C11: 10 | D11: 10 | E11: G | F11: D-stem
A12: =B12&"|"&C12 -> tRNA-Ala-CGC-1-1|11 | B12: tRNA-Ala-CGC-1-1 | C12: 11 | D12: 11 | E12: A | F12: D-stem
A13: =B13&"|"&C13 -> tRNA-Ala-CGC-1-1|12 | B13: tRNA-Ala-CGC-1-1 | C13: 12 | D13: 12 | E13: U | F13: D-stem
... A4694: =B4694&"|"&C4694 -> tRNA-Val-TAC-1-1|72 | B4694: tRNA-Val-TAC-1-1 | C4694: 72 | D4694: 73 | E4694: C | F4694: Acceptor stem

Sheet Stems_3D_BP
A1: tRNA | B1: Element | C1: Canonical pair | D1: Actual pos (5′) | E1: Actual pos (3′) | F1: Nt (5′) | G1: Nt (3′) | H1: Pair | I1: G count | J1: C count | K1: G+C count
A2: tRNA-Ala-CGC-1-1 | B2: Acceptor stem | C2: 1-72 | D2: =INDEX(Positions!$D$2:$D$4694,MATCH($A2&"|1",Positions!$A$2:$A$4694,0)) -> 1 | E2: =INDEX(Positions!$D$2:$D$4694,MATCH($A2&"|72",Positions!$A$2:$A$4694,0)) -> 71 | F2: =INDEX(Positions!$E$2:$E$4694,MATCH($A2&"|1",Positions!$A$2:$A$4694,0)) -> G | G2: =INDEX(Positions!$E$2:$E$4694,MATCH($A2&"|72",Positions!$A$2:$A$4694,0)) -> C | H2: =F2&"-"&G2 -> G-C | I2: =(F2="G")+(G2="G") -> 1 | J2: =(F2="C")+(G2="C") -> 1 | K2: =I2+J2 -> 2
A3: tRNA-Ala-CGC-1-1 | B3: Acceptor stem | C3: 2-71 | D3: =INDEX(Positions!$D$2:$D$4694,MATCH($A3&"|2",Positions!$A$2:$A$4694,0)) -> 2 | E3: =INDEX(Positions!$D$2:$D$4694,MATCH($A3&"|71",Positions!$A$2:$A$4694,0)) -> 70 | F3: =INDEX(Positions!$E$2:$E$4694,MATCH($A3&"|2",Positions!$A$2:$A$4694,0)) -> G | G3: =INDEX(Positions!$E$2:$E$4694,MATCH($A3&"|71",Positions!$A$2:$A$4694,0)) -> C | H3: =F3&"-"&G3 -> G-C | I3: =(F3="G")+(G3="G") -> 1 | J3: =(F3="C")+(G3="C") -> 1 | K3: =I3+J3 -> 2
A4: tRNA-Ala-CGC-1-1 | B4: Acceptor stem | C4: 3-70 | D4: =INDEX(Positions!$D$2:$D$4694,MATCH($A4&"|3",Positions!$A$2:$A$4694,0)) -> 3 | E4: =INDEX(Positions!$D$2:$D$4694,MATCH($A4&"|70",Positions!$A$2:$A$4694,0)) -> 69 | F4: =INDEX(Positions!$E$2:$E$4694,MATCH($A4&"|3",Positions!$A$2:$A$4694,0)) -> G | G4: =INDEX(Positions!$E$2:$E$4694,MATCH($A4&"|70",Positions!$A$2:$A$4694,0)) -> U | H4: =F4&"-"&G4 -> G-U | I4: =(F4="G")+(G4="G") -> 1 | J4: =(F4="C")+(G4="C") -> 0 | K4: =I4+J4 -> 1
A5: tRNA-Ala-CGC-1-1 | B5: Acceptor stem | C5: 4-69 | D5: =INDEX(Positions!$D$2:$D$4694,MATCH($A5&"|4",Positions!$A$2:$A$4694,0)) -> 4 | E5: =INDEX(Positions!$D$2:$D$4694,MATCH($A5&"|69",Positions!$A$2:$A$4694,0)) -> 68 | F5: =INDEX(Positions!$E$2:$E$4694,MATCH($A5&"|4",Positions!$A$2:$A$4694,0)) -> C | G5: =INDEX(Positions!$E$2:$E$4694,MATCH($A5&"|69",Positions!$A$2:$A$4694,0)) -> G | H5: =F5&"-"&G5 -> C-G | I5: =(F5="G")+(G5="G") -> 1 | J5: =(F5="C")+(G5="C") -> 1 | K5: =I5+J5 -> 2
A6: tRNA-Ala-CGC-1-1 | B6: Acceptor stem | C6: 5-68 | D6: =INDEX(Positions!$D$2:$D$4694,MATCH($A6&"|5",Positions!$A$2:$A$4694,0)) -> 5 | E6: =INDEX(Positions!$D$2:$D$4694,MATCH($A6&"|68",Positions!$A$2:$A$4694,0)) -> 67 | F6: =INDEX(Positions!$E$2:$E$4694,MATCH($A6&"|5",Positions!$A$2:$A$4694,0)) -> U | G6: =INDEX(Positions!$E$2:$E$4694,MATCH($A6&"|68",Positions!$A$2:$A$4694,0)) -> A | H6: =F6&"-"&G6 -> U-A | I6: =(F6="G")+(G6="G") -> 0 | J6: =(F6="C")+(G6="C") -> 0 | K6: =I6+J6 -> 0
A7: tRNA-Ala-CGC-1-1 | B7: Acceptor stem | C7: 6-67 | D7: =INDEX(Positions!$D$2:$D$4694,MATCH($A7&"|6",Positions!$A$2:$A$4694,0)) -> 6 | E7: =INDEX(Positions!$D$2:$D$4694,MATCH($A7&"|67",Positions!$A$2:$A$4694,0)) -> 66 | F7: =INDEX(Positions!$E$2:$E$4694,MATCH($A7&"|6",Positions!$A$2:$A$4694,0)) -> C | G7: =INDEX(Positions!$E$2:$E$4694,MATCH($A7&"|67",Positions!$A$2:$A$4694,0)) -> G | H7: =F7&"-"&G7 -> C-G | I7: =(F7="G")+(G7="G") -> 1 | J7: =(F7="C")+(G7="C") -> 1 | K7: =I7+J7 -> 2
A8: tRNA-Ala-CGC-1-1 | B8: Acceptor stem | C8: 7-66 | D8: =INDEX(Positions!$D$2:$D$4694,MATCH($A8&"|7",Positions!$A$2:$A$4694,0)) -> 7 | E8: =INDEX(Positions!$D$2:$D$4694,MATCH($A8&"|66",Positions!$A$2:$A$4694,0)) -> 65 | F8: =INDEX(Positions!$E$2:$E$4694,MATCH($A8&"|7",Positions!$A$2:$A$4694,0)) -> G | G8: =INDEX(Positions!$E$2:$E$4694,MATCH($A8&"|66",Positions!$A$2:$A$4694,0)) -> C | H8: =F8&"-"&G8 -> G-C | I8: =(F8="G")+(G8="G") -> 1 | J8: =(F8="C")+(G8="C") -> 1 | K8: =I8+J8 -> 2
A9: tRNA-Ala-CGC-1-1 | B9: D-stem | C9: 10-25 | D9: =INDEX(Positions!$D$2:$D$4694,MATCH($A9&"|10",Positions!$A$2:$A$4694,0)) -> 10 | E9: =INDEX(Positions!$D$2:$D$4694,MATCH($A9&"|25",Positions!$A$2:$A$4694,0)) -> 24 | F9: =INDEX(Positions!$E$2:$E$4694,MATCH($A9&"|10",Positions!$A$2:$A$4694,0)) -> G | G9: =INDEX(Positions!$E$2:$E$4694,MATCH($A9&"|25",Positions!$A$2:$A$4694,0)) -> C | H9: =F9&"-"&G9 -> G-C | I9: =(F9="G")+(G9="G") -> 1 | J9: =(F9="C")+(G9="C") -> 1 | K9: =I9+J9 -> 2
A10: tRNA-Ala-CGC-1-1 | B10: D-stem | C10: 11-24 | D10: =INDEX(Positions!$D$2:$D$4694,MATCH($A10&"|11",Positions!$A$2:$A$4694,0)) -> 11 | E10: =INDEX(Positions!$D$2:$D$4694,MATCH($A10&"|24",Positions!$A$2:$A$4694,0)) -> 23 | F10: =INDEX(Positions!$E$2:$E$4694,MATCH($A10&"|11",Positions!$A$2:$A$4694,0)) -> A | G10: =INDEX(Positions!$E$2:$E$4694,MATCH($A10&"|24",Positions!$A$2:$A$4694,0)) -> U | H10: =F10&"-"&G10 -> A-U | I10: =(F10="G")+(G10="G") -> 0 | J10: =(F10="C")+(G10="C") -> 0 | K10: =I10+J10 -> 0
A11: tRNA-Ala-CGC-1-1 | B11: D-stem | C11: 12-23 | D11: =INDEX(Positions!$D$2:$D$4694,MATCH($A11&"|12",Positions!$A$2:$A$4694,0)) -> 12 | E11: =INDEX(Positions!$D$2:$D$4694,MATCH($A11&"|23",Positions!$A$2:$A$4694,0)) -> 22 | F11: =INDEX(Positions!$E$2:$E$4694,MATCH($A11&"|12",Positions!$A$2:$A$4694,0)) -> U | G11: =INDEX(Positions!$E$2:$E$4694,MATCH($A11&"|23",Positions!$A$2:$A$4694,0)) -> A | H11: =F11&"-"&G11 -> U-A | I11: =(F11="G")+(G11="G") -> 0 | J11: =(F11="C")+(G11="C") -> 0 | K11: =I11+J11 -> 0
A12: tRNA-Ala-CGC-1-1 | B12: D-stem | C12: 13-22 | D12: =INDEX(Positions!$D$2:$D$4694,MATCH($A12&"|13",Positions!$A$2:$A$4694,0)) -> 13 | E12: =INDEX(Positions!$D$2:$D$4694,MATCH($A12&"|22",Positions!$A$2:$A$4694,0)) -> 21 | F12: =INDEX(Positions!$E$2:$E$4694,MATCH($A12&"|13",Positions!$A$2:$A$4694,0)) -> C | G12: =INDEX(Positions!$E$2:$E$4694,MATCH($A12&"|22",Positions!$A$2:$A$4694,0)) -> G | H12: =F12&"-"&G12 -> C-G | I12: =(F12="G")+(G12="G") -> 1 | J12: =(F12="C")+(G12="C") -> 1 | K12: =I12+J12 -> 2
A13: tRNA-Ala-CGC-1-1 | B13: Anticodon stem | C13: 27-43 | D13: =INDEX(Positions!$D$2:$D$4694,MATCH($A13&"|27",Positions!$A$2:$A$4694,0)) -> 26 | E13: =INDEX(Positions!$D$2:$D$4694,MATCH($A13&"|43",Positions!$A$2:$A$4694,0)) -> 42 | F13: =INDEX(Positions!$E$2:$E$4694,MATCH($A13&"|27",Positions!$A$2:$A$4694,0)) -> U | G13: =INDEX(Positions!$E$2:$E$4694,MATCH($A13&"|43",Positions!$A$2:$A$4694,0)) -> A | H13: =F13&"-"&G13 -> U-A | I13: =(F13="G")+(G13="G") -> 0 | J13: =(F13="C")+(G13="C") -> 0 | K13: =I13+J13 -> 0
A14: tRNA-Ala-CGC-1-1 | B14: Anticodon stem | C14: 28-42 | D14: =INDEX(Positions!$D$2:$D$4694,MATCH($A14&"|28",Positions!$A$2:$A$4694,0)) -> 27 | E14: =INDEX(Positions!$D$2:$D$4694,MATCH($A14&"|42",Positions!$A$2:$A$4694,0)) -> 41 | F14: =INDEX(Positions!$E$2:$E$4694,MATCH($A14&"|28",Positions!$A$2:$A$4694,0)) -> U | G14: =INDEX(Positions!$E$2:$E$4694,MATCH($A14&"|42",Positions!$A$2:$A$4694,0)) -> A | H14: =F14&"-"&G14 -> U-A | I14: =(F14="G")+(G14="G") -> 0 | J14: =(F14="C")+(G14="C") -> 0 | K14: =I14+J14 -> 0
A15: tRNA-Ala-CGC-1-1 | B15: Anticodon stem | C15: 29-41 | D15: =INDEX(Positions!$D$2:$D$4694,MATCH($A15&"|29",Positions!$A$2:$A$4694,0)) -> 28 | E15: =INDEX(Positions!$D$2:$D$4694,MATCH($A15&"|41",Positions!$A$2:$A$4694,0)) -> 40 | F15: =INDEX(Positions!$E$2:$E$4694,MATCH($A15&"|29",Positions!$A$2:$A$4694,0)) -> A | G15: =INDEX(Positions!$E$2:$E$4694,MATCH($A15&"|41",Positions!$A$2:$A$4694,0)) -> U | H15: =F15&"-"&G15 -> A-U | I15: =(F15="G")+(G15="G") -> 0 | J15: =(F15="C")+(G15="C") -> 0 | K15: =I15+J15 -> 0
A16: tRNA-Ala-CGC-1-1 | B16: Anticodon stem | C16: 30-40 | D16: =INDEX(Positions!$D$2:$D$4694,MATCH($A16&"|30",Positions!$A$2:$A$4694,0)) -> 29 | E16: =INDEX(Positions!$D$2:$D$4694,MATCH($A16&"|40",Positions!$A$2:$A$4694,0)) -> 39 | F16: =INDEX(Positions!$E$2:$E$4694,MATCH($A16&"|30",Positions!$A$2:$A$4694,0)) -> C | G16: =INDEX(Positions!$E$2:$E$4694,MATCH($A16&"|40",Positions!$A$2:$A$4694,0)) -> G | H16: =F16&"-"&G16 -> C-G | I16: =(F16="G")+(G16="G") -> 1 | J16: =(F16="C")+(G16="C") -> 1 | K16: =I16+J16 -> 2
A17: tRNA-Ala-CGC-1-1 | B17: Anticodon stem | C17: 31-39 | D17: =INDEX(Positions!$D$2:$D$4694,MATCH($A17&"|31",Positions!$A$2:$A$4694,0)) -> 30 | E17: =INDEX(Positions!$D$2:$D$4694,MATCH($A17&"|39",Positions!$A$2:$A$4694,0)) -> 38 | F17: =INDEX(Positions!$E$2:$E$4694,MATCH($A17&"|31",Positions!$A$2:$A$4694,0)) -> G | G17: =INDEX(Positions!$E$2:$E$4694,MATCH($A17&"|39",Positions!$A$2:$A$4694,0)) -> C | H17: =F17&"-"&G17 -> G-C | I17: =(F17="G")+(G17="G") -> 1 | J17: =(F17="C")+(G17="C") -> 1 | K17: =I17+J17 -> 2
A18: tRNA-Ala-CGC-1-1 | B18: T-stem | C18: 49-65 | D18: =INDEX(Positions!$D$2:$D$4694,MATCH($A18&"|49",Positions!$A$2:$A$4694,0)) -> 48 | E18: =INDEX(Positions!$D$2:$D$4694,MATCH($A18&"|65",Positions!$A$2:$A$4694,0)) -> 64 | F18: =INDEX(Positions!$E$2:$E$4694,MATCH($A18&"|49",Positions!$A$2:$A$4694,0)) -> G | G18: =INDEX(Positions!$E$2:$E$4694,MATCH($A18&"|65",Positions!$A$2:$A$4694,0)) -> C | H18: =F18&"-"&G18 -> G-C | I18: =(F18="G")+(G18="G") -> 1 | J18: =(F18="C")+(G18="C") -> 1 | K18: =I18+J18 -> 2
A19: tRNA-Ala-CGC-1-1 | B19: T-stem | C19: 50-64 | D19: =INDEX(Positions!$D$2:$D$4694,MATCH($A19&"|50",Positions!$A$2:$A$4694,0)) -> 49 | E19: =INDEX(Positions!$D$2:$D$4694,MATCH($A19&"|64",Positions!$A$2:$A$4694,0)) -> 63 | F19: =INDEX(Positions!$E$2:$E$4694,MATCH($A19&"|50",Positions!$A$2:$A$4694,0)) -> C | G19: =INDEX(Positions!$E$2:$E$4694,MATCH($A19&"|64",Positions!$A$2:$A$4694,0)) -> G | H19: =F19&"-"&G19 -> C-G | I19: =(F19="G")+(G19="G") -> 1 | J19: =(F19="C")+(G19="C") -> 1 | K19: =I19+J19 -> 2
A20: tRNA-Ala-CGC-1-1 | B20: T-stem | C20: 51-63 | D20: =INDEX(Positions!$D$2:$D$4694,MATCH($A20&"|51",Positions!$A$2:$A$4694,0)) -> 50 | E20: =INDEX(Positions!$D$2:$D$4694,MATCH($A20&"|63",Positions!$A$2:$A$4694,0)) -> 62 | F20: =INDEX(Positions!$E$2:$E$4694,MATCH($A20&"|51",Positions!$A$2:$A$4694,0)) -> G | G20: =INDEX(Positions!$E$2:$E$4694,MATCH($A20&"|63",Positions!$A$2:$A$4694,0)) -> C | H20: =F20&"-"&G20 -> G-C | I20: =(F20="G")+(G20="G") -> 1 | J20: =(F20="C")+(G20="C") -> 1 | K20: =I20+J20 -> 2
A21: tRNA-Ala-CGC-1-1 | B21: T-stem | C21: 52-62 | D21: =INDEX(Positions!$D$2:$D$4694,MATCH($A21&"|52",Positions!$A$2:$A$4694,0)) -> 51 | E21: =INDEX(Positions!$D$2:$D$4694,MATCH($A21&"|62",Positions!$A$2:$A$4694,0)) -> 61 | F21: =INDEX(Positions!$E$2:$E$4694,MATCH($A21&"|52",Positions!$A$2:$A$4694,0)) -> G | G21: =INDEX(Positions!$E$2:$E$4694,MATCH($A21&"|62",Positions!$A$2:$A$4694,0)) -> C | H21: =F21&"-"&G21 -> G-C | I21: =(F21="G")+(G21="G") -> 1 | J21: =(F21="C")+(G21="C") -> 1 | K21: =I21+J21 -> 2
A22: tRNA-Ala-CGC-1-1 | B22: T-stem | C22: 53-61 | D22: =INDEX(Positions!$D$2:$D$4694,MATCH($A22&"|53",Positions!$A$2:$A$4694,0)) -> 52 | E22: =INDEX(Positions!$D$2:$D$4694,MATCH($A22&"|61",Positions!$A$2:$A$4694,0)) -> 60 | F22: =INDEX(Positions!$E$2:$E$4694,MATCH($A22&"|53",Positions!$A$2:$A$4694,0)) -> G | G22: =INDEX(Positions!$E$2:$E$4694,MATCH($A22&"|61",Positions!$A$2:$A$4694,0)) -> C | H22: =F22&"-"&G22 -> G-C | I22: =(F22="G")+(G22="G") -> 1 | J22: =(F22="C")+(G22="C") -> 1 | K22: =I22+J22 -> 2
A23: tRNA-Ala-CGC-1-1 | B23: 3D (tertiary) BP | C23: 8-14 | D23: =INDEX(Positions!$D$2:$D$4694,MATCH($A23&"|8",Positions!$A$2:$A$4694,0)) -> 8 | E23: =INDEX(Positions!$D$2:$D$4694,MATCH($A23&"|14",Positions!$A$2:$A$4694,0)) -> 14 | F23: =INDEX(Positions!$E$2:$E$4694,MATCH($A23&"|8",Positions!$A$2:$A$4694,0)) -> U | G23: =INDEX(Positions!$E$2:$E$4694,MATCH($A23&"|14",Positions!$A$2:$A$4694,0)) -> A | H23: =F23&"-"&G23 -> U-A | I23: =(F23="G")+(G23="G") -> 0 | J23: =(F23="C")+(G23="C") -> 0 | K23: =I23+J23 -> 0
A24: tRNA-Ala-CGC-1-1 | B24: 3D (tertiary) BP | C24: 15-48 | D24: =INDEX(Positions!$D$2:$D$4694,MATCH($A24&"|15",Positions!$A$2:$A$4694,0)) -> 15 | E24: =INDEX(Positions!$D$2:$D$4694,MATCH($A24&"|48",Positions!$A$2:$A$4694,0)) -> 47 | F24: =INDEX(Positions!$E$2:$E$4694,MATCH($A24&"|15",Positions!$A$2:$A$4694,0)) -> G | G24: =INDEX(Positions!$E$2:$E$4694,MATCH($A24&"|48",Positions!$A$2:$A$4694,0)) -> C | H24: =F24&"-"&G24 -> G-C | I24: =(F24="G")+(G24="G") -> 1 | J24: =(F24="C")+(G24="C") -> 1 | K24: =I24+J24 -> 2
A25: tRNA-Ala-CGC-1-1 | B25: 3D (tertiary) BP | C25: 18-55 | D25: =INDEX(Positions!$D$2:$D$4694,MATCH($A25&"|18",Positions!$A$2:$A$4694,0)) -> 16 | E25: =INDEX(Positions!$D$2:$D$4694,MATCH($A25&"|55",Positions!$A$2:$A$4694,0)) -> 54 | F25: =INDEX(Positions!$E$2:$E$4694,MATCH($A25&"|18",Positions!$A$2:$A$4694,0)) -> G | G25: =INDEX(Positions!$E$2:$E$4694,MATCH($A25&"|55",Positions!$A$2:$A$4694,0)) -> U | H25: =F25&"-"&G25 -> G-U | I25: =(F25="G")+(G25="G") -> 1 | J25: =(F25="C")+(G25="C") -> 0 | K25: =I25+J25 -> 1
A26: tRNA-Ala-CGC-1-1 | B26: 3D (tertiary) BP | C26: 19-56 | D26: =INDEX(Positions!$D$2:$D$4694,MATCH($A26&"|19",Positions!$A$2:$A$4694,0)) -> 17 | E26: =INDEX(Positions!$D$2:$D$4694,MATCH($A26&"|56",Positions!$A$2:$A$4694,0)) -> 55 | F26: =INDEX(Positions!$E$2:$E$4694,MATCH($A26&"|19",Positions!$A$2:$A$4694,0)) -> G | G26: =INDEX(Positions!$E$2:$E$4694,MATCH($A26&"|56",Positions!$A$2:$A$4694,0)) -> C | H26: =F26&"-"&G26 -> G-C | I26: =(F26="G")+(G26="G") -> 1 | J26: =(F26="C")+(G26="C") -> 1 | K26: =I26+J26 -> 2
A27: tRNA-Ala-CGC-1-1 | B27: 3D (tertiary) BP | C27: 26-44 | D27: =INDEX(Positions!$D$2:$D$4694,MATCH($A27&"|26",Positions!$A$2:$A$4694,0)) -> 25 | E27: =INDEX(Positions!$D$2:$D$4694,MATCH($A27&"|44",Positions!$A$2:$A$4694,0)) -> 43 | F27: =INDEX(Positions!$E$2:$E$4694,MATCH($A27&"|26",Positions!$A$2:$A$4694,0)) -> G | G27: =INDEX(Positions!$E$2:$E$4694,MATCH($A27&"|44",Positions!$A$2:$A$4694,0)) -> A | H27: =F27&"-"&G27 -> G-A | I27: =(F27="G")+(G27="G") -> 1 | J27: =(F27="C")+(G27="C") -> 0 | K27: =I27+J27 -> 1
A28: tRNA-Ala-CGC-1-1 | B28: 3D (tertiary) BP | C28: 32-38 | D28: =INDEX(Positions!$D$2:$D$4694,MATCH($A28&"|32",Positions!$A$2:$A$4694,0)) -> 31 | E28: =INDEX(Positions!$D$2:$D$4694,MATCH($A28&"|38",Positions!$A$2:$A$4694,0)) -> 37 | F28: =INDEX(Positions!$E$2:$E$4694,MATCH($A28&"|32",Positions!$A$2:$A$4694,0)) -> U | G28: =INDEX(Positions!$E$2:$E$4694,MATCH($A28&"|38",Positions!$A$2:$A$4694,0)) -> A | H28: =F28&"-"&G28 -> U-A | I28: =(F28="G")+(G28="G") -> 0 | J28: =(F28="C")+(G28="C") -> 0 | K28: =I28+J28 -> 0
A29: tRNA-Ala-CGC-1-1 | B29: 3D (tertiary) BP | C29: 54-58 | D29: =INDEX(Positions!$D$2:$D$4694,MATCH($A29&"|54",Positions!$A$2:$A$4694,0)) -> 53 | E29: =INDEX(Positions!$D$2:$D$4694,MATCH($A29&"|58",Positions!$A$2:$A$4694,0)) -> 57 | F29: =INDEX(Positions!$E$2:$E$4694,MATCH($A29&"|54",Positions!$A$2:$A$4694,0)) -> U | G29: =INDEX(Positions!$E$2:$E$4694,MATCH($A29&"|58",Positions!$A$2:$A$4694,0)) -> A | H29: =F29&"-"&G29 -> U-A | I29: =(F29="G")+(G29="G") -> 0 | J29: =(F29="C")+(G29="C") -> 0 | K29: =I29+J29 -> 0
A30: tRNA-Ala-GGC-1-1 | B30: Acceptor stem | C30: 1-72 | D30: =INDEX(Positions!$D$2:$D$4694,MATCH($A30&"|1",Positions!$A$2:$A$4694,0)) -> 1 | E30: =INDEX(Positions!$D$2:$D$4694,MATCH($A30&"|72",Positions!$A$2:$A$4694,0)) -> 71 | F30: =INDEX(Positions!$E$2:$E$4694,MATCH($A30&"|1",Positions!$A$2:$A$4694,0)) -> G | G30: =INDEX(Positions!$E$2:$E$4694,MATCH($A30&"|72",Positions!$A$2:$A$4694,0)) -> C | H30: =F30&"-"&G30 -> G-C | I30: =(F30="G")+(G30="G") -> 1 | J30: =(F30="C")+(G30="C") -> 1 | K30: =I30+J30 -> 2
A31: tRNA-Ala-GGC-1-1 | B31: Acceptor stem | C31: 2-71 | D31: =INDEX(Positions!$D$2:$D$4694,MATCH($A31&"|2",Positions!$A$2:$A$4694,0)) -> 2 | E31: =INDEX(Positions!$D$2:$D$4694,MATCH($A31&"|71",Positions!$A$2:$A$4694,0)) -> 70 | F31: =INDEX(Positions!$E$2:$E$4694,MATCH($A31&"|2",Positions!$A$2:$A$4694,0)) -> G | G31: =INDEX(Positions!$E$2:$E$4694,MATCH($A31&"|71",Positions!$A$2:$A$4694,0)) -> C | H31: =F31&"-"&G31 -> G-C | I31: =(F31="G")+(G31="G") -> 1 | J31: =(F31="C")+(G31="C") -> 1 | K31: =I31+J31 -> 2
A32: tRNA-Ala-GGC-1-1 | B32: Acceptor stem | C32: 3-70 | D32: =INDEX(Positions!$D$2:$D$4694,MATCH($A32&"|3",Positions!$A$2:$A$4694,0)) -> 3 | E32: =INDEX(Positions!$D$2:$D$4694,MATCH($A32&"|70",Positions!$A$2:$A$4694,0)) -> 69 | F32: =INDEX(Positions!$E$2:$E$4694,MATCH($A32&"|3",Positions!$A$2:$A$4694,0)) -> G | G32: =INDEX(Positions!$E$2:$E$4694,MATCH($A32&"|70",Positions!$A$2:$A$4694,0)) -> U | H32: =F32&"-"&G32 -> G-U | I32: =(F32="G")+(G32="G") -> 1 | J32: =(F32="C")+(G32="C") -> 0 | K32: =I32+J32 -> 1
A33: tRNA-Ala-GGC-1-1 | B33: Acceptor stem | C33: 4-69 | D33: =INDEX(Positions!$D$2:$D$4694,MATCH($A33&"|4",Positions!$A$2:$A$4694,0)) -> 4 | E33: =INDEX(Positions!$D$2:$D$4694,MATCH($A33&"|69",Positions!$A$2:$A$4694,0)) -> 68 | F33: =INDEX(Positions!$E$2:$E$4694,MATCH($A33&"|4",Positions!$A$2:$A$4694,0)) -> C | G33: =INDEX(Positions!$E$2:$E$4694,MATCH($A33&"|69",Positions!$A$2:$A$4694,0)) -> G | H33: =F33&"-"&G33 -> C-G | I33: =(F33="G")+(G33="G") -> 1 | J33: =(F33="C")+(G33="C") -> 1 | K33: =I33+J33 -> 2
A34: tRNA-Ala-GGC-1-1 | B34: Acceptor stem | C34: 5-68 | D34: =INDEX(Positions!$D$2:$D$4694,MATCH($A34&"|5",Positions!$A$2:$A$4694,0)) -> 5 | E34: =INDEX(Positions!$D$2:$D$4694,MATCH($A34&"|68",Positions!$A$2:$A$4694,0)) -> 67 | F34: =INDEX(Positions!$E$2:$E$4694,MATCH($A34&"|5",Positions!$A$2:$A$4694,0)) -> C | G34: =INDEX(Positions!$E$2:$E$4694,MATCH($A34&"|68",Positions!$A$2:$A$4694,0)) -> G | H34: =F34&"-"&G34 -> C-G | I34: =(F34="G")+(G34="G") -> 1 | J34: =(F34="C")+(G34="C") -> 1 | K34: =I34+J34 -> 2
A35: tRNA-Ala-GGC-1-1 | B35: Acceptor stem | C35: 6-67 | D35: =INDEX(Positions!$D$2:$D$4694,MATCH($A35&"|6",Positions!$A$2:$A$4694,0)) -> 6 | E35: =INDEX(Positions!$D$2:$D$4694,MATCH($A35&"|67",Positions!$A$2:$A$4694,0)) -> 66 | F35: =INDEX(Positions!$E$2:$E$4694,MATCH($A35&"|6",Positions!$A$2:$A$4694,0)) -> G | G35: =INDEX(Positions!$E$2:$E$4694,MATCH($A35&"|67",Positions!$A$2:$A$4694,0)) -> C | H35: =F35&"-"&G35 -> G-C | I35: =(F35="G")+(G35="G") -> 1 | J35: =(F35="C")+(G35="C") -> 1 | K35: =I35+J35 -> 2
A36: tRNA-Ala-GGC-1-1 | B36: Acceptor stem | C36: 7-66 | D36: =INDEX(Positions!$D$2:$D$4694,MATCH($A36&"|7",Positions!$A$2:$A$4694,0)) -> 7 | E36: =INDEX(Positions!$D$2:$D$4694,MATCH($A36&"|66",Positions!$A$2:$A$4694,0)) -> 65 | F36: =INDEX(Positions!$E$2:$E$4694,MATCH($A36&"|7",Positions!$A$2:$A$4694,0)) -> G | G36: =INDEX(Positions!$E$2:$E$4694,MATCH($A36&"|66",Positions!$A$2:$A$4694,0)) -> C | H36: =F36&"-"&G36 -> G-C | I36: =(F36="G")+(G36="G") -> 1 | J36: =(F36="C")+(G36="C") -> 1 | K36: =I36+J36 -> 2
A37: tRNA-Ala-GGC-1-1 | B37: D-stem | C37: 10-25 | D37: =INDEX(Positions!$D$2:$D$4694,MATCH($A37&"|10",Positions!$A$2:$A$4694,0)) -> 10 | E37: =INDEX(Positions!$D$2:$D$4694,MATCH($A37&"|25",Positions!$A$2:$A$4694,0)) -> 24 | F37: =INDEX(Positions!$E$2:$E$4694,MATCH($A37&"|10",Positions!$A$2:$A$4694,0)) -> G | G37: =INDEX(Positions!$E$2:$E$4694,MATCH($A37&"|25",Positions!$A$2:$A$4694,0)) -> C | H37: =F37&"-"&G37 -> G-C | I37: =(F37="G")+(G37="G") -> 1 | J37: =(F37="C")+(G37="C") -> 1 | K37: =I37+J37 -> 2
A38: tRNA-Ala-GGC-1-1 | B38: D-stem | C38: 11-24 | D38: =INDEX(Positions!$D$2:$D$4694,MATCH($A38&"|11",Positions!$A$2:$A$4694,0)) -> 11 | E38: =INDEX(Positions!$D$2:$D$4694,MATCH($A38&"|24",Positions!$A$2:$A$4694,0)) -> 23 | F38: =INDEX(Positions!$E$2:$E$4694,MATCH($A38&"|11",Positions!$A$2:$A$4694,0)) -> A | G38: =INDEX(Positions!$E$2:$E$4694,MATCH($A38&"|24",Positions!$A$2:$A$4694,0)) -> U | H38: =F38&"-"&G38 -> A-U | I38: =(F38="G")+(G38="G") -> 0 | J38: =(F38="C")+(G38="C") -> 0 | K38: =I38+J38 -> 0
A39: tRNA-Ala-GGC-1-1 | B39: D-stem | C39: 12-23 | D39: =INDEX(Positions!$D$2:$D$4694,MATCH($A39&"|12",Positions!$A$2:$A$4694,0)) -> 12 | E39: =INDEX(Positions!$D$2:$D$4694,MATCH($A39&"|23",Positions!$A$2:$A$4694,0)) -> 22 | F39: =INDEX(Positions!$E$2:$E$4694,MATCH($A39&"|12",Positions!$A$2:$A$4694,0)) -> U | G39: =INDEX(Positions!$E$2:$E$4694,MATCH($A39&"|23",Positions!$A$2:$A$4694,0)) -> A | H39: =F39&"-"&G39 -> U-A | I39: =(F39="G")+(G39="G") -> 0 | J39: =(F39="C")+(G39="C") -> 0 | K39: =I39+J39 -> 0
A40: tRNA-Ala-GGC-1-1 | B40: D-stem | C40: 13-22 | D40: =INDEX(Positions!$D$2:$D$4694,MATCH($A40&"|13",Positions!$A$2:$A$4694,0)) -> 13 | E40: =INDEX(Positions!$D$2:$D$4694,MATCH($A40&"|22",Positions!$A$2:$A$4694,0)) -> 21 | F40: =INDEX(Positions!$E$2:$E$4694,MATCH($A40&"|13",Positions!$A$2:$A$4694,0)) -> C | G40: =INDEX(Positions!$E$2:$E$4694,MATCH($A40&"|22",Positions!$A$2:$A$4694,0)) -> G | H40: =F40&"-"&G40 -> C-G | I40: =(F40="G")+(G40="G") -> 1 | J40: =(F40="C")+(G40="C") -> 1 | K40: =I40+J40 -> 2
...

Sheet Loops
A1: tRNA | B1: Loop / region | C1: Canonical positions | D1: Actual positions | E1: Loop sequence (5′→3′) | F1: Length | G1: G count | H1: C count | I1: G+C count | J1: G+C %
A2: tRNA-Ala-CGC-1-1 | B2: D-loop | C2: 14–21 | D2: 14–20 | E2: AGGGGAA | F2: =COUNTIFS(Positions!$B$2:$B$4694,A2,Positions!$F$2:$F$4694,B2) -> 7 | G2: =COUNTIFS(Positions!$B$2:$B$4694,A2,Positions!$F$2:$F$4694,B2,Positions!$E$2:$E$4694,"G") -> 4 | H2: =COUNTIFS(Positions!$B$2:$B$4694,A2,Positions!$F$2:$F$4694,B2,Positions!$E$2:$E$4694,"C") -> 0 | I2: =G2+H2 -> 4 | J2: =IF(F2=0,0,I2/F2) -> 0.57142857
A3: tRNA-Ala-CGC-1-1 | B3: Anticodon loop | C3: 32–38 | D3: 31–37 | E3: UUCGCAA | F3: =COUNTIFS(Positions!$B$2:$B$4694,A3,Positions!$F$2:$F$4694,B3) -> 7 | G3: =COUNTIFS(Positions!$B$2:$B$4694,A3,Positions!$F$2:$F$4694,B3,Positions!$E$2:$E$4694,"G") -> 1 | H3: =COUNTIFS(Positions!$B$2:$B$4694,A3,Positions!$F$2:$F$4694,B3,Positions!$E$2:$E$4694,"C") -> 2 | I3: =G3+H3 -> 3 | J3: =IF(F3=0,0,I3/F3) -> 0.42857143
A4: tRNA-Ala-CGC-1-1 | B4: Variable loop | C4: 44–48 | D4: 43–47 | E4: AGGCC | F4: =COUNTIFS(Positions!$B$2:$B$4694,A4,Positions!$F$2:$F$4694,B4) -> 5 | G4: =COUNTIFS(Positions!$B$2:$B$4694,A4,Positions!$F$2:$F$4694,B4,Positions!$E$2:$E$4694,"G") -> 2 | H4: =COUNTIFS(Positions!$B$2:$B$4694,A4,Positions!$F$2:$F$4694,B4,Positions!$E$2:$E$4694,"C") -> 2 | I4: =G4+H4 -> 4 | J4: =IF(F4=0,0,I4/F4) -> 0.8
A5: tRNA-Ala-CGC-1-1 | B5: TΨC-loop | C5: 54–60 | D5: 53–59 | E5: UUCAAAU | F5: =COUNTIFS(Positions!$B$2:$B$4694,A5,Positions!$F$2:$F$4694,B5) -> 7 | G5: =COUNTIFS(Positions!$B$2:$B$4694,A5,Positions!$F$2:$F$4694,B5,Positions!$E$2:$E$4694,"G") -> 0 | H5: =COUNTIFS(Positions!$B$2:$B$4694,A5,Positions!$F$2:$F$4694,B5,Positions!$E$2:$E$4694,"C") -> 1 | I5: =G5+H5 -> 1 | J5: =IF(F5=0,0,I5/F5) -> 0.14285714
A6: tRNA-Ala-CGC-1-1 | B6: Positions 8, 9, 26 | C6: 8, 9, 26 | D6: 8, 9, 25 | E6: UAG | F6: =COUNTIFS(Positions!$B$2:$B$4694,A6,Positions!$F$2:$F$4694,"Position 8")+COUNTIFS(Positions!$B$2:$B$4694,A6,Positions!$F$2:$F$4694,"Position 9")+COUNTIFS(Positions!$B$2:$B$4694,A6,Positions!$F$2:$F$4694,"Position 26") -> 3 | G6: =COUNTIFS(Positions!$B$2:$B$4694,A6,Positions!$F$2:$F$4694,"Position 8",Positions!$E$2:$E$4694,"G")+COUNTIFS(Positions!$B$2:$B$4694,A6,Positions!$F$2:$F$4694,"Position 9",Positions!$E$2:$E$4694,"G")+COUNTIFS(Positions!$B$2:$B$4694,A6,Positions!$F$2:$F$4694,"Position 26",Positions!$E$2:$E$4694,"G") -> 1 | H6: =COUNTIFS(Positions!$B$2:$B$4694,A6,Positions!$F$2:$F$4694,"Position 8",Positions!$E$2:$E$4694,"C")+COUNTIFS(Positions!$B$2:$B$4694,A6,Positions!$F$2:$F$4694,"Position 9",Positions!$E$2:$E$4694,"C")+COUNTIFS(Positions!$B$2:$B$4694,A6,Positions!$F$2:$F$4694,"Position 26",Positions!$E$2:$E$4694,"C") -> 0 | I6: =G6+H6 -> 1 | J6: =IF(F6=0,0,I6/F6) -> 0.33333333
A7: tRNA-Ala-GGC-1-1 | B7: D-loop | C7: 14–21 | D7: 14–20 | E7: AGGGGAA | F7: =COUNTIFS(Positions!$B$2:$B$4694,A7,Positions!$F$2:$F$4694,B7) -> 7 | G7: =COUNTIFS(Positions!$B$2:$B$4694,A7,Positions!$F$2:$F$4694,B7,Positions!$E$2:$E$4694,"G") -> 4 | H7: =COUNTIFS(Positions!$B$2:$B$4694,A7,Positions!$F$2:$F$4694,B7,Positions!$E$2:$E$4694,"C") -> 0 | I7: =G7+H7 -> 4 | J7: =IF(F7=0,0,I7/F7) -> 0.57142857
A8: tRNA-Ala-GGC-1-1 | B8: Anticodon loop | C8: 32–38 | D8: 31–37 | E8: UUGGCAU | F8: =COUNTIFS(Positions!$B$2:$B$4694,A8,Positions!$F$2:$F$4694,B8) -> 7 | G8: =COUNTIFS(Positions!$B$2:$B$4694,A8,Positions!$F$2:$F$4694,B8,Positions!$E$2:$E$4694,"G") -> 2 | H8: =COUNTIFS(Positions!$B$2:$B$4694,A8,Positions!$F$2:$F$4694,B8,Positions!$E$2:$E$4694,"C") -> 1 | I8: =G8+H8 -> 3 | J8: =IF(F8=0,0,I8/F8) -> 0.42857143
A9: tRNA-Ala-GGC-1-1 | B9: Variable loop | C9: 44–48 | D9: 43–47 | E9: AGGCC | F9: =COUNTIFS(Positions!$B$2:$B$4694,A9,Positions!$F$2:$F$4694,B9) -> 5 | G9: =COUNTIFS(Positions!$B$2:$B$4694,A9,Positions!$F$2:$F$4694,B9,Positions!$E$2:$E$4694,"G") -> 2 | H9: =COUNTIFS(Positions!$B$2:$B$4694,A9,Positions!$F$2:$F$4694,B9,Positions!$E$2:$E$4694,"C") -> 2 | I9: =G9+H9 -> 4 | J9: =IF(F9=0,0,I9/F9) -> 0.8
A10: tRNA-Ala-GGC-1-1 | B10: TΨC-loop | C10: 54–60 | D10: 53–59 | E10: UUCAAUU | F10: =COUNTIFS(Positions!$B$2:$B$4694,A10,Positions!$F$2:$F$4694,B10) -> 7 | G10: =COUNTIFS(Positions!$B$2:$B$4694,A10,Positions!$F$2:$F$4694,B10,Positions!$E$2:$E$4694,"G") -> 0 | H10: =COUNTIFS(Positions!$B$2:$B$4694,A10,Positions!$F$2:$F$4694,B10,Positions!$E$2:$E$4694,"C") -> 1 | I10: =G10+H10 -> 1 | J10: =IF(F10=0,0,I10/F10) -> 0.14285714
A11: tRNA-Ala-GGC-1-1 | B11: Positions 8, 9, 26 | C11: 8, 9, 26 | D11: 8, 9, 25 | E11: UAG | F11: =COUNTIFS(Positions!$B$2:$B$4694,A11,Positions!$F$2:$F$4694,"Position 8")+COUNTIFS(Positions!$B$2:$B$4694,A11,Positions!$F$2:$F$4694,"Position 9")+COUNTIFS(Positions!$B$2:$B$4694,A11,Positions!$F$2:$F$4694,"Position 26") -> 3 | G11: =COUNTIFS(Positions!$B$2:$B$4694,A11,Positions!$F$2:$F$4694,"Position 8",Positions!$E$2:$E$4694,"G")+COUNTIFS(Positions!$B$2:$B$4694,A11,Positions!$F$2:$F$4694,"Position 9",Positions!$E$2:$E$4694,"G")+COUNTIFS(Positions!$B$2:$B$4694,A11,Positions!$F$2:$F$4694,"Position 26",Positions!$E$2:$E$4694,"G") -> 1 | H11: =COUNTIFS(Positions!$B$2:$B$4694,A11,Positions!$F$2:$F$4694,"Position 8",Positions!$E$2:$E$4694,"C")+COUNTIFS(Positions!$B$2:$B$4694,A11,Positions!$F$2:$F$4694,"Position 9",Positions!$E$2:$E$4694,"C")+COUNTIFS(Positions!$B$2:$B$4694,A11,Positions!$F$2:$F$4694,"Position 26",Positions!$E$2:$E$4694,"C") -> 0 | I11: =G11+H11 -> 1 | J11: =IF(F11=0,0,I11/F11) -> 0.33333333
A12: tRNA-Ala-TGC-1-1 | B12: D-loop | C12: 14–21 | D12: 14–21 | E12: AGAUGGAA | F12: =COUNTIFS(Positions!$B$2:$B$4694,A12,Positions!$F$2:$F$4694,B12) -> 8 | G12: =COUNTIFS(Positions!$B$2:$B$4694,A12,Positions!$F$2:$F$4694,B12,Positions!$E$2:$E$4694,"G") -> 3 | H12: =COUNTIFS(Positions!$B$2:$B$4694,A12,Positions!$F$2:$F$4694,B12,Positions!$E$2:$E$4694,"C") -> 0 | I12: =G12+H12 -> 3 | J12: =IF(F12=0,0,I12/F12) -> 0.375
A13: tRNA-Ala-TGC-1-1 | B13: Anticodon loop | C13: 32–38 | D13: 32–38 | E13: UUUGCAA | F13: =COUNTIFS(Positions!$B$2:$B$4694,A13,Positions!$F$2:$F$4694,B13) -> 7 | G13: =COUNTIFS(Positions!$B$2:$B$4694,A13,Positions!$F$2:$F$4694,B13,Positions!$E$2:$E$4694,"G") -> 1 | H13: =COUNTIFS(Positions!$B$2:$B$4694,A13,Positions!$F$2:$F$4694,B13,Positions!$E$2:$E$4694,"C") -> 1 | I13: =G13+H13 -> 2 | J13: =IF(F13=0,0,I13/F13) -> 0.28571429
A14: tRNA-Ala-TGC-1-1 | B14: Variable loop | C14: 44–48 | D14: 44–48 | E14: AGGCC | F14: =COUNTIFS(Positions!$B$2:$B$4694,A14,Positions!$F$2:$F$4694,B14) -> 5 | G14: =COUNTIFS(Positions!$B$2:$B$4694,A14,Positions!$F$2:$F$4694,B14,Positions!$E$2:$E$4694,"G") -> 2 | H14: =COUNTIFS(Positions!$B$2:$B$4694,A14,Positions!$F$2:$F$4694,B14,Positions!$E$2:$E$4694,"C") -> 2 | I14: =G14+H14 -> 4 | J14: =IF(F14=0,0,I14/F14) -> 0.8
A15: tRNA-Ala-TGC-1-1 | B15: TΨC-loop | C15: 54–60 | D15: 54–60 | E15: UUCGAAU | F15: =COUNTIFS(Positions!$B$2:$B$4694,A15,Positions!$F$2:$F$4694,B15) -> 7 | G15: =COUNTIFS(Positions!$B$2:$B$4694,A15,Positions!$F$2:$F$4694,B15,Positions!$E$2:$E$4694,"G") -> 1 | H15: =COUNTIFS(Positions!$B$2:$B$4694,A15,Positions!$F$2:$F$4694,B15,Positions!$E$2:$E$4694,"C") -> 1 | I15: =G15+H15 -> 2 | J15: =IF(F15=0,0,I15/F15) -> 0.28571429
A16: tRNA-Ala-TGC-1-1 | B16: Positions 8, 9, 26 | C16: 8, 9, 26 | D16: 8, 9, 26 | E16: UAG | F16: =COUNTIFS(Positions!$B$2:$B$4694,A16,Positions!$F$2:$F$4694,"Position 8")+COUNTIFS(Positions!$B$2:$B$4694,A16,Positions!$F$2:$F$4694,"Position 9")+COUNTIFS(Positions!$B$2:$B$4694,A16,Positions!$F$2:$F$4694,"Position 26") -> 3 | G16: =COUNTIFS(Positions!$B$2:$B$4694,A16,Positions!$F$2:$F$4694,"Position 8",Positions!$E$2:$E$4694,"G")+COUNTIFS(Positions!$B$2:$B$4694,A16,Positions!$F$2:$F$4694,"Position 9",Positions!$E$2:$E$4694,"G")+COUNTIFS(Positions!$B$2:$B$4694,A16,Positions!$F$2:$F$4694,"Position 26",Positions!$E$2:$E$4694,"G") -> 1 | H16: =COUNTIFS(Positions!$B$2:$B$4694,A16,Positions!$F$2:$F$4694,"Position 8",Positions!$E$2:$E$4694,"C")+COUNTIFS(Positions!$B$2:$B$4694,A16,Positions!$F$2:$F$4694,"Position 9",Positions!$E$2:$E$4694,"C")+COUNTIFS(Positions!$B$2:$B$4694,A16,Positions!$F$2:$F$4694,"Position 26",Positions!$E$2:$E$4694,"C") -> 0 | I16: =G16+H16 -> 1 | J16: =IF(F16=0,0,I16/F16) -> 0.33333333
A17: tRNA-Arg-CCG-1-1 | B17: D-loop | C17: 14–21 | D17: 14–21 | E17: AGAGGAUA | F17: =COUNTIFS(Positions!$B$2:$B$4694,A17,Positions!$F$2:$F$4694,B17) -> 8 | G17: =COUNTIFS(Positions!$B$2:$B$4694,A17,Positions!$F$2:$F$4694,B17,Positions!$E$2:$E$4694,"G") -> 3 | H17: =COUNTIFS(Positions!$B$2:$B$4694,A17,Positions!$F$2:$F$4694,B17,Positions!$E$2:$E$4694,"C") -> 0 | I17: =G17+H17 -> 3 | J17: =IF(F17=0,0,I17/F17) -> 0.375
