Workbook

Sheet GC_Summary
A1: T-psi-C database tRNAs (22 species, trna_data_rev3_200) - G+C content of tRNA sequence, 4 stems + 3D base pairs, and 4 loops
A3: tRNA | B3: Length (nt) | C3: Total G | D3: Total C | E3: Total G+C | F3: Overall G+C % | G3: Acceptor stem G+C | H3: D-stem G+C | I3: AC-stem G+C | J3: T-stem G+C | K3: 4 stems G+C (of 42 nt) | L3: 4 stems G+C % | M3: 3D BP G+C (of 14 nt) | N3: 3D BP G+C % | O3: 4 stems + 3D G+C (of 56 nt) | P3: 4 stems + 3D G+C % | Q3: D-loop G+C | R3: AC-loop G+C | S3: Variable loop G+C | T3: TΨC-loop G+C | U3: 4 loops length (nt) | V3: 4 loops G+C | W3: 4 loops G+C % | X3: Pos 8 nt | Y3: Pos 9 nt | Z3: Pos 26 nt | AA3: G in 8, 9, 26 | AB3: C in 8, 9, 26 | AC3: G+C in 8, 9, 26 (of 3 nt) | AD3: 8, 9, 26 G+C % | AE3: Check: stems + loops + 8,9,26 G+C = total G+C | AF3: Non-stem nt (4 loops + 8, 9, 26) | AG3: Non-stem G+C | AH3: GC_nonstem % | AI3: GC_stem % (4 stems, 42 nt) | AJ3: ΔGC = GC_stem − GC_nonstem
A4: tdbR00000589 Arg-UCU | B4: =COUNTIF(Positions!$B$2:$B$14531,A4) -> 74 | C4: =COUNTIFS(Positions!$B$2:$B$14531,A4,Positions!$E$2:$E$14531,"G") -> 26 | D4: =COUNTIFS(Positions!$B$2:$B$14531,A4,Positions!$E$2:$E$14531,"C") -> 27 | E4: =C4+D4 -> 53 | F4: =E4/B4 -> 0.71621622 | G4: =SUMIFS(Stems_3D_BP!$K$2:$K$5573,Stems_3D_BP!$A$2:$A$5573,$A4,Stems_3D_BP!$B$2:$B$5573,"Acceptor stem") -> 14 | H4: =SUMIFS(Stems_3D_BP!$K$2:$K$5573,Stems_3D_BP!$A$2:$A$5573,$A4,Stems_3D_BP!$B$2:$B$5573,"D-stem") -> 6 | I4: =SUMIFS(Stems_3D_BP!$K$2:$K$5573,Stems_3D_BP!$A$2:$A$5573,$A4,Stems_3D_BP!$B$2:$B$5573,"Anticodon stem") -> 10 | J4: =SUMIFS(Stems_3D_BP!$K$2:$K$5573,Stems_3D_BP!$A$2:$A$5573,$A4,Stems_3D_BP!$B$2:$B$5573,"T-stem") -> 10 | K4: =SUM(G4:J4) -> 40 | L4: =K4/42 -> 0.95238095 | M4: =SUMIFS(Stems_3D_BP!$K$2:$K$5573,Stems_3D_BP!$A$2:$A$5573,$A4,Stems_3D_BP!$B$2:$B$5573,"3D (tertiary) BP") -> 7 | N4: =M4/14 -> 0.5 | O4: =K4+M4 -> 47 | P4: =O4/56 -> 0.83928571 | Q4: =SUMIFS(Loops!$I$2:$I$996,Loops!$A$2:$A$996,$A4,Loops!$B$2:$B$996,"D-loop") -> 6 | R4: =SUMIFS(Loops!$I$2:$I$996,Loops!$A$2:$A$996,$A4,Loops!$B$2:$B$996,"Anticodon loop") -> 2 | S4: =SUMIFS(Loops!$I$2:$I$996,Loops!$A$2:$A$996,$A4,Loops!$B$2:$B$996,"Variable loop") -> 3 | T4: =SUMIFS(Loops!$I$2:$I$996,Loops!$A$2:$A$996,$A4,Loops!$B$2:$B$996,"TΨC-loop") -> 1 | U4: =SUMIFS(Loops!$F$2:$F$996,Loops!$A$2:$A$996,$A4)-SUMIFS(Loops!$F$2:$F$996,Loops!$A$2:$A$996,$A4,Loops!$B$2:$B$996,"Positions 8, 9, 26") -> 29 | V4: =SUM(Q4:T4) -> 12 | W4: =V4/U4 -> 0.4137931 | X4: =INDEX(Positions!$E$2:$E$14531,MATCH($A4&"|8",Positions!$A$2:$A$14531,0)) -> U | Y4: =INDEX(Positions!$E$2:$E$14531,MATCH($A4&"|9",Positions!$A$2:$A$14531,0)) -> A | Z4: =INDEX(Positions!$E$2:$E$14531,MATCH($A4&"|26",Positions!$A$2:$A$14531,0)) -> G | AA4: =(X4="G")+(Y4="G")+(Z4="G") -> 1 | AB4: =(X4="C")+(Y4="C")+(Z4="C") -> 0 | AC4: =AA4+AB4 -> 1 | AD4: =AC4/3 -> 0.33333333 | AE4: =IF(K4+V4+AC4=E4,"OK","MISMATCH") -> OK | AF4: =B4-42 -> 32 | AG4: =V4+AC4 -> 13 | AH4: =AG4/AF4 -> 0.40625 | AI4: =L4 -> 0.95238095 | AJ4: =AI4-AH4 -> 0.54613095
A5: tdbR00000588 Asp-GUC | B5: =COUNTIF(Positions!$B$2:$B$14531,A5) -> 74 | C5: =COUNTIFS(Positions!$B$2:$B$14531,A5,Positions!$E$2:$E$14531,"G") -> 25 | D5: =COUNTIFS(Positions!$B$2:$B$14531,A5,Positions!$E$2:$E$14531,"C") -> 24 | E5: =C5+D5 -> 49 | F5: =E5/B5 -> 0.66216216 | G5: =SUMIFS(Stems_3D_BP!$K$2:$K$5573,Stems_3D_BP!$A$2:$A$5573,$A5,Stems_3D_BP!$B$2:$B$5573,"Acceptor stem") -> 14 | H5: =SUMIFS(Stems_3D_BP!$K$2:$K$5573,Stems_3D_BP!$A$2:$A$5573,$A5,Stems_3D_BP!$B$2:$B$5573,"D-stem") -> 2 | I5: =SUMIFS(Stems_3D_BP!$K$2:$K$5573,Stems_3D_BP!$A$2:$A$5573,$A5,Stems_3D_BP!$B$2:$B$5573,"Anticodon stem") -> 10 | J5: =SUMIFS(Stems_3D_BP!$K$2:$K$5573,Stems_3D_BP!$A$2:$A$5573,$A5,Stems_3D_BP!$B$2:$B$5573,"T-stem") -> 10 | K5: =SUM(G5:J5) -> 36 | L5: =K5/42 -> 0.85714286 | M5: =SUMIFS(Stems_3D_BP!$K$2:$K$5573,Stems_3D_BP!$A$2:$A$5573,$A5,Stems_3D_BP!$B$2:$B$5573,"3D (tertiary) BP") -> 7 | N5: =M5/14 -> 0.5 | O5: =K5+M5 -> 43 | P5: =O5/56 -> 0.76785714 | Q5: =SUMIFS(Loops!$I$2:$I$996,Loops!$A$2:$A$996,$A5,Loops!$B$2:$B$996,"D-loop") -> 6 | R5: =SUMIFS(Loops!$I$2:$I$996,Loops!$A$2:$A$996,$A5,Loops!$B$2:$B$996,"Anticodon loop") -> 3 | S5: =SUMIFS(Loops!$I$2:$I$996,Loops!$A$2:$A$996,$A5,Loops!$B$2:$B$996,"Variable loop") -> 2 | T5: =SUMIFS(Loops!$I$2:$I$996,Loops!$A$2:$A$996,$A5,Loops!$B$2:$B$996,"TΨC-loop") -> 1 | U5: =SUMIFS(Loops!$F$2:$F$996,Loops!$A$2:$A$996,$A5)-SUMIFS(Loops!$F$2:$F$996,Loops!$A$2:$A$996,$A5,Loops!$B$2:$B$996,"Positions 8, 9, 26") -> 29 | V5: =SUM(Q5:T5) -> 12 | W5: =V5/U5 -> 0.4137931 | X5: =INDEX(Positions!$E$2:$E$14531,MATCH($A5&"|8",Positions!$A$2:$A$14531,0)) -> U | Y5: =INDEX(Positions!$E$2:$E$14531,MATCH($A5&"|9",Positions!$A$2:$A$14531,0)) -> A | Z5: =INDEX(Positions!$E$2:$E$14531,MATCH($A5&"|26",Positions!$A$2:$A$14531,0)) -> G | AA5: =(X5="G")+(Y5="G")+(Z5="G") -> 1 | AB5: =(X5="C")+(Y5="C")+(Z5="C") -> 0 | AC5: =AA5+AB5 -> 1 | AD5: =AC5/3 -> 0.33333333 | AE5: =IF(K5+V5+AC5=E5,"OK","MISMATCH") -> OK | AF5: =B5-42 -> 32 | AG5: =V5+AC5 -> 13 | AH5: =AG5/AF5 -> 0.40625 | AI5: =L5 -> 0.85714286 | AJ5: =AI5-AH5 -> 0.45089286
A6: tdbR00000583 Cys-GCA | B6: =COUNTIF(Positions!$B$2:$B$14531,A6) -> 74 | C6: =COUNTIFS(Positions!$B$2:$B$14531,A6,Positions!$E$2:$E$14531,"G") -> 30 | D6: =COUNTIFS(Positions!$B$2:$B$14531,A6,Positions!$E$2:$E$14531,"C") -> 25 | E6: =C6+D6 -> 55 | F6: =E6/B6 -> 0.74324324 | G6: =SUMIFS(Stems_3D_BP!$K$2:$K$5573,Stems_3D_BP!$A$2:$A$5573,$A6,Stems_3D_BP!$B$2:$B$5573,"Acceptor stem") -> 14 | H6: =SUMIFS(Stems_3D_BP!$K$2:$K$5573,Stems_3D_BP!$A$2:$A$5573,$A6,Stems_3D_BP!$B$2:$B$5573,"D-stem") -> 7 | I6: =SUMIFS(Stems_3D_BP!$K$2:$K$5573,Stems_3D_BP!$A$2:$A$5573,$A6,Stems_3D_BP!$B$2:$B$5573,"Anticodon stem") -> 9 | J6: =SUMIFS(Stems_3D_BP!$K$2:$K$5573,Stems_3D_BP!$A$2:$A$5573,$A6,Stems_3D_BP!$B$2:$B$5573,"T-stem") -> 10 | K6: =SUM(G6:J6) -> 40 | L6: =K6/42 -> 0.95238095 | M6: =SUMIFS(Stems_3D_BP!$K$2:$K$5573,Stems_3D_BP!$A$2:$A$5573,$A6,Stems_3D_BP!$B$2:$B$5573,"3D (tertiary) BP") -> 7 | N6: =M6/14 -> 0.5 | O6: =K6+M6 -> 47 | P6: =O6/56 -> 0.83928571 | Q6: =SUMIFS(Loops!$I$2:$I$996,Loops!$A$2:$A$996,$A6,Loops!$B$2:$B$996,"D-loop") -> 5 | R6: =SUMIFS(Loops!$I$2:$I$996,Loops!$A$2:$A$996,$A6,Loops!$B$2:$B$996,"Anticodon loop") -> 4 | S6: =SUMIFS(Loops!$I$2:$I$996,Loops!$A$2:$A$996,$A6,Loops!$B$2:$B$996,"Variable loop") -> 2 | T6: =SUMIFS(Loops!$I$2:$I$996,Loops!$A$2:$A$996,$A6,Loops!$B$2:$B$996,"TΨC-loop") -> 2 | U6: =SUMIFS(Loops!$F$2:$F$996,Loops!$A$2:$A$996,$A6)-SUMIFS(Loops!$F$2:$F$996,Loops!$A$2:$A$996,$A6,Loops!$B$2:$B$996,"Positions 8, 9, 26") -> 29 | V6: =SUM(Q6:T6) -> 13 | W6: =V6/U6 -> 0.44827586 | X6: =INDEX(Positions!$E$2:$E$14531,MATCH($A6&"|8",Positions!$A$2:$A$14531,0)) -> U | Y6: =INDEX(Positions!$E$2:$E$14531,MATCH($A6&"|9",Positions!$A$2:$A$14531,0)) -> G | Z6: =INDEX(Positions!$E$2:$E$14531,MATCH($A6&"|26",Positions!$A$2:$A$14531,0)) -> G | AA6: =(X6="G")+(Y6="G")+(Z6="G") -> 2 | AB6: =(X6="C")+(Y6="C")+(Z6="C") -> 0 | AC6: =AA6+AB6 -> 2 | AD6: =AC6/3 -> 0.66666667 | AE6: =IF(K6+V6+AC6=E6,"OK","MISMATCH") -> OK | AF6: =B6-42 -> 32 | AG6: =V6+AC6 -> 15 | AH6: =AG6/AF6 -> 0.46875 | AI6: =L6 -> 0.95238095 | AJ6: =AI6-AH6 -> 0.48363095
A7: tdbR00000581 Lys-CUU | B7: =COUNTIF(Positions!$B$2:$B$14531,A7) -> 81 | C7: =COUNTIFS(Positions!$B$2:$B$14531,A7,Positions!$E$2:$E$14531,"G") -> 31 | D7: =COUNTIFS(Positions!$B$2:$B$14531,A7,Positions!$E$2:$E$14531,"C") -> 26 | E7: =C7+D7 -> 57 | F7: =E7/B7 -> 0.7037037 | G7: =SUMIFS(Stems_3D_BP!$K$2:$K$5573,Stems_3D_BP!$A$2:$A$5573,$A7,Stems_3D_BP!$B$2:$B$5573,"Acceptor stem") -> 14 | H7: =SUMIFS(Stems_3D_BP!$K$2:$K$5573,Stems_3D_BP!$A$2:$A$5573,$A7,Stems_3D_BP!$B$2:$B$5573,"D-stem") -> 6 | I7: =SUMIFS(Stems_3D_BP!$K$2:$K$5573,Stems_3D_BP!$A$2:$A$5573,$A7,Stems_3D_BP!$B$2:$B$5573,"Anticodon stem") -> 10 | J7: =SUMIFS(Stems_3D_BP!$K$2:$K$5573,Stems_3D_BP!$A$2:$A$5573,$A7,Stems_3D_BP!$B$2:$B$5573,"T-stem") -> 10 | K7: =SUM(G7:J7) -> 40 | L7: =K7/42 -> 0.95238095 | M7: =SUMIFS(Stems_3D_BP!$K$2:$K$5573,Stems_3D_BP!$A$2:$A$5573,$A7,Stems_3D_BP!$B$2:$B$5573,"3D (tertiary) BP") -> 8 | N7: =M7/14 -> 0.57142857 | O7: =K7+M7 -> 48 | P7: =O7/56 -> 0.85714286 | Q7: =SUMIFS(Loops!$I$2:$I$996,Loops!$A$2:$A$996,$A7,Loops!$B$2:$B$996,"D-loop") -> 5 | R7: =SUMIFS(Loops!$I$2:$I$996,Loops!$A$2:$A$996,$A7,Loops!$B$2:$B$996,"Anticodon loop") -> 2 | S7: =SUMIFS(Loops!$I$2:$I$996,Loops!$A$2:$A$996,$A7,Loops!$B$2:$B$996,"Variable loop") -> 8 | T7: =SUMIFS(Loops!$I$2:$I$996,Loops!$A$2:$A$996,$A7,Loops!$B$2:$B$996,"TΨC-loop") -> 1 | U7: =SUMIFS(Loops!$F$2:$F$996,Loops!$A$2:$A$996,$A7)-SUMIFS(Loops!$F$2:$F$996,Loops!$A$2:$A$996,$A7,Loops!$B$2:$B$996,"Positions 8, 9, 26") -> 36 | V7: =SUM(Q7:T7) -> 16 | W7: =V7/U7 -> 0.44444444 | X7: =INDEX(Positions!$E$2:$E$14531,MATCH($A7&"|8",Positions!$A$2:$A$14531,0)) -> U | Y7: =INDEX(Positions!$E$2:$E$14531,MATCH($A7&"|9",Positions!$A$2:$A$14531,0)) -> A | Z7: =INDEX(Positions!$E$2:$E$14531,MATCH($A7&"|26",Positions!$A$2:$A$14531,0)) -> G | AA7: =(X7="G")+(Y7="G")+(Z7="G") -> 1 | AB7: =(X7="C")+(Y7="C")+(Z7="C") -> 0 | AC7: =AA7+AB7 -> 1 | AD7: =AC7/3 -> 0.33333333 | AE7: =IF(K7+V7+AC7=E7,"OK","MISMATCH") -> OK | AF7: =B7-42 -> 39 | AG7: =V7+AC7 -> 17 | AH7: =AG7/AF7 -> 0.43589744 | AI7: =L7 -> 0.95238095 | AJ7: =AI7-AH7 -> 0.51648352
A8: tdbR00000580 Lys-UUU | B8: =COUNTIF(Positions!$B$2:$B$14531,A8) -> 76 | C8: =COUNTIFS(Positions!$B$2:$B$14531,A8,Positions!$E$2:$E$14531,"G") -> 28 | D8: =COUNTIFS(Positions!$B$2:$B$14531,A8,Positions!$E$2:$E$14531,"C") -> 28 | E8: =C8+D8 -> 56 | F8: =E8/B8 -> 0.73684211 | G8: =SUMIFS(Stems_3D_BP!$K$2:$K$5573,Stems_3D_BP!$A$2:$A$5573,$A8,Stems_3D_BP!$B$2:$B$5573,"Acceptor stem") -> 14 | H8: =SUMIFS(Stems_3D_BP!$K$2:$K$5573,Stems_3D_BP!$A$2:$A$5573,$A8,Stems_3D_BP!$B$2:$B$5573,"D-stem") -> 6 | I8: =SUMIFS(Stems_3D_BP!$K$2:$K$5573,Stems_3D_BP!$A$2:$A$5573,$A8,Stems_3D_BP!$B$2:$B$5573,"Anticodon stem") -> 10 | J8: =SUMIFS(Stems_3D_BP!$K$2:$K$5573,Stems_3D_BP!$A$2:$A$5573,$A8,Stems_3D_BP!$B$2:$B$5573,"T-stem") -> 10 | K8: =SUM(G8:J8) -> 40 | L8: =K8/42 -> 0.95238095 | M8: =SUMIFS(Stems_3D_BP!$K$2:$K$5573,Stems_3D_BP!$A$2:$A$5573,$A8,Stems_3D_BP!$B$2:$B$5573,"3D (tertiary) BP") -> 9 | N8: =M8/14 -> 0.64285714 | O8: =K8+M8 -> 49 | P8: =O8/56 -> 0.875 | Q8: =SUMIFS(Loops!$I$2:$I$996,Loops!$A$2:$A$996,$A8,Loops!$B$2:$B$996,"D-loop") -> 7 | R8: =SUMIFS(Loops!$I$2:$I$996,Loops!$A$2:$A$996,$A8,Loops!$B$2:$B$996,"Anticodon loop") -> 2 | S8: =SUMIFS(Loops!$I$2:$I$996,Loops!$A$2:$A$996,$A8,Loops!$B$2:$B$996,"Variable loop") -> 5 | T8: =SUMIFS(Loops!$I$2:$I$996,Loops!$A$2:$A$996,$A8,Loops!$B$2:$B$996,"TΨC-loop") -> 1 | U8: =SUMIFS(Loops!$F$2:$F$996,Loops!$A$2:$A$996,$A8)-SUMIFS(Loops!$F$2:$F$996,Loops!$A$2:$A$996,$A8,Loops!$B$2:$B$996,"Positions 8, 9, 26") -> 31 | V8: =SUM(Q8:T8) -> 15 | W8: =V8/U8 -> 0.48387097 | X8: =INDEX(Positions!$E$2:$E$14531,MATCH($A8&"|8",Positions!$A$2:$A$14531,0)) -> U | Y8: =INDEX(Positions!$E$2:$E$14531,MATCH($A8&"|9",Positions!$A$2:$A$14531,0)) -> A | Z8: =INDEX(Positions!$E$2:$E$14531,MATCH($A8&"|26",Positions!$A$2:$A$14531,0)) -> G | AA8: =(X8="G")+(Y8="G")+(Z8="G") -> 1 | AB8: =(X8="C")+(Y8="C")+(Z8="C") -> 0 | AC8: =AA8+AB8 -> 1 | AD8: =AC8/3 -> 0.33333333 | AE8: =IF(K8+V8+AC8=E8,"OK","MISMATCH") -> OK | AF8: =B8-42 -> 34 | AG8: =V8+AC8 -> 16 | AH8: =AG8/AF8 -> 0.47058824 | AI8: =L8 -> 0.95238095 | AJ8: =AI8-AH8 -> 0.48179272
A9: tdbR00000586 Met-CAU | B9: =COUNTIF(Positions!$B$2:$B$14531,A9) -> 73 | C9: =COUNTIFS(Positions!$B$2:$B$14531,A9,Positions!$E$2:$E$14531,"G") -> 26 | D9: =COUNTIFS(Positions!$B$2:$B$14531,A9,Positions!$E$2:$E$14531,"C") -> 26 | E9: =C9+D9 -> 52 | F9: =E9/B9 -> 0.71232877 | G9: =SUMIFS(Stems_3D_BP!$K$2:$K$5573,Stems_3D_BP!$A$2:$A$5573,$A9,Stems_3D_BP!$B$2:$B$5573,"Acceptor stem") -> 14 | H9: =SUMIFS(Stems_3D_BP!$K$2:$K$5573,Stems_3D_BP!$A$2:$A$5573,$A9,Stems_3D_BP!$B$2:$B$5573,"D-stem") -> 6 | I9: =SUMIFS(Stems_3D_BP!$K$2:$K$5573,Stems_3D_BP!$A$2:$A$5573,$A9,Stems_3D_BP!$B$2:$B$5573,"Anticodon stem") -> 10 | J9: =SUMIFS(Stems_3D_BP!$K$2:$K$5573,Stems_3D_BP!$A$2:$A$5573,$A9,Stems_3D_BP!$B$2:$B$5573,"T-stem") -> 10 | K9: =SUM(G9:J9) -> 40 | L9: =K9/42 -> 0.95238095 | M9: =SUMIFS(Stems_3D_BP!$K$2:$K$5573,Stems_3D_BP!$A$2:$A$5573,$A9,Stems_3D_BP!$B$2:$B$5573,"3D (tertiary) BP") -> 7 | N9: =M9/14 -> 0.5 | O9: =K9+M9 -> 47 | P9: =O9/56 -> 0.83928571 | Q9: =SUMIFS(Loops!$I$2:$I$996,Loops!$A$2:$A$996,$A9,Loops!$B$2:$B$996,"D-loop") -> 5 | R9: =SUMIFS(Loops!$I$2:$I$996,Loops!$A$2:$A$996,$A9,Loops!$B$2:$B$996,"Anticodon loop") -> 2 | S9: =SUMIFS(Loops!$I$2:$I$996,Loops!$A$2:$A$996,$A9,Loops!$B$2:$B$996,"Variable loop") -> 3 | T9: =SUMIFS(Loops!$I$2:$I$996,Loops!$A$2:$A$996,$A9,Loops!$B$2:$B$996,"TΨC-loop") -> 1 | U9: =SUMIFS(Loops!$F$2:$F$996,Loops!$A$2:$A$996,$A9)-SUMIFS(Loops!$F$2:$F$996,Loops!$A$2:$A$996,$A9,Loops!$B$2:$B$996,"Positions 8, 9, 26") -> 28 | V9: =SUM(Q9:T9) -> 11 | W9: =V9/U9 -> 0.39285714 | X9: =INDEX(Positions!$E$2:$E$14531,MATCH($A9&"|8",Positions!$A$2:$A$14531,0)) -> U | Y9: =INDEX(Positions!$E$2:$E$14531,MATCH($A9&"|9",Positions!$A$2:$A$14531,0)) -> A | Z9: =INDEX(Positions!$E$2:$E$14531,MATCH($A9&"|26",Positions!$A$2:$A$14531,0)) -> G | AA9: =(X9="G")+(Y9="G")+(Z9="G") -> 1 | AB9: =(X9="C")+(Y9="C")+(Z9="C") -> 0 | AC9: =AA9+AB9 -> 1 | AD9: =AC9/3 -> 0.33333333 | AE9: =IF(K9+V9+AC9=E9,"OK","MISMATCH") -> OK | AF9: =B9-42 -> 31 | AG9: =V9+AC9 -> 12 | AH9: =AG9/AF9 -> 0.38709677 | AI9: =L9 -> 0.95238095 | AJ9: =AI9-AH9 -> 0.56528418
A10: tdbR00000587 Met-CAU | B10: =COUNTIF(Positions!$B$2:$B$14531,A10) -> 73 | C10: =COUNTIFS(Positions!$B$2:$B$14531,A10,Positions!$E$2:$E$14531,"G") -> 26 | D10: =COUNTIFS(Positions!$B$2:$B$14531,A10,Positions!$E$2:$E$14531,"C") -> 26 | E10: =C10+D10 -> 52 | F10: =E10/B10 -> 0.71232877 | G10: =SUMIFS(Stems_3D_BP!$K$2:$K$5573,Stems_3D_BP!$A$2:$A$5573,$A10,Stems_3D_BP!$B$2:$B$5573,"Acceptor stem") -> 14 | H10: =SUMIFS(Stems_3D_BP!$K$2:$K$5573,Stems_3D_BP!$A$2:$A$5573,$A10,Stems_3D_BP!$B$2:$B$5573,"D-stem") -> 6 | I10: =SUMIFS(Stems_3D_BP!$K$2:$K$5573,Stems_3D_BP!$A$2:$A$5573,$A10,Stems_3D_BP!$B$2:$B$5573,"Anticodon stem") -> 8 | J10: =SUMIFS(Stems_3D_BP!$K$2:$K$5573,Stems_3D_BP!$A$2:$A$5573,$A10,Stems_3D_BP!$B$2:$B$5573,"T-stem") -> 10 | K10: =SUM(G10:J10) -> 38 | L10: =K10/42 -> 0.9047619 | M10: =SUMIFS(Stems_3D_BP!$K$2:$K$5573,Stems_3D_BP!$A$2:$A$5573,$A10,Stems_3D_BP!$B$2:$B$5573,"3D (tertiary) BP") -> 7 | N10: =M10/14 -> 0.5 | O10: =K10+M10 -> 45 | P10: =O10/56 -> 0.80357143 | Q10: =SUMIFS(Loops!$I$2:$I$996,Loops!$A$2:$A$996,$A10,Loops!$B$2:$B$996,"D-loop") -> 6 | R10: =SUMIFS(Loops!$I$2:$I$996,Loops!$A$2:$A$996,$A10,Loops!$B$2:$B$996,"Anticodon loop") -> 2 | S10: =SUMIFS(Loops!$I$2:$I$996,Loops!$A$2:$A$996,$A10,Loops!$B$2:$B$996,"Variable loop") -> 3 | T10: =SUMIFS(Loops!$I$2:$I$996,Loops!$A$2:$A$996,$A10,Loops!$B$2:$B$996,"TΨC-loop") -> 2 | U10: =SUMIFS(Loops!$F$2:$F$996,Loops!$A$2:$A$996,$A10)-SUMIFS(Loops!$F$2:$F$996,Loops!$A$2:$A$996,$A10,Loops!$B$2:$B$996,"Positions 8, 9, 26") -> 28 | V10: =SUM(Q10:T10) -> 13 | W10: =V10/U10 -> 0.46428571 | X10: =INDEX(Positions!$E$2:$E$14531,MATCH($A10&"|8",Positions!$A$2:$A$14531,0)) -> U | Y10: =INDEX(Positions!$E$2:$E$14531,MATCH($A10&"|9",Positions!$A$2:$A$14531,0)) -> A | Z10: =INDEX(Positions!$E$2:$E$14531,MATCH($A10&"|26",Positions!$A$2:$A$14531,0)) -> G | AA10: =(X10="G")+(Y10="G")+(Z10="G") -> 1 | AB10: =(X10="C")+(Y10="C")+(Z10="C") -> 0 | AC10: =AA10+AB10 -> 1 | AD10: =AC10/3 -> 0.33333333 | AE10: =IF(K10+V10+AC10=E10,"OK","MISMATCH") -> OK | AF10: =B10-42 -> 31 | AG10: =V10+AC10 -> 14 | AH10: =AG10/AF10 -> 0.4516129 | AI10: =L10 -> 0.9047619 | AJ10: =AI10-AH10 -> 0.453149
A11: tdbR00000579 Pro-CGG | B11: =COUNTIF(Positions!$B$2:$B$14531,A11) -> 74 | C11: =COUNTIFS(Positions!$B$2:$B$14531,A11,Positions!$E$2:$E$14531,"G") -> 28 | D11: =COUNTIFS(Positions!$B$2:$B$14531,A11,Positions!$E$2:$E$14531,"C") -> 25 | E11: =C11+D11 -> 53 | F11: =E11/B11 -> 0.71621622 | G11: =SUMIFS(Stems_3D_BP!$K$2:$K$5573,Stems_3D_BP!$A$2:$A$5573,$A11,Stems_3D_BP!$B$2:$B$5573,"Acceptor stem") -> 14 | H11: =SUMIFS(Stems_3D_BP!$K$2:$K$5573,Stems_3D_BP!$A$2:$A$5573,$A11,Stems_3D_BP!$B$2:$B$5573,"D-stem") -> 3 | I11: =SUMIFS(Stems_3D_BP!$K$2:$K$5573,Stems_3D_BP!$A$2:$A$5573,$A11,Stems_3D_BP!$B$2:$B$5573,"Anticodon stem") -> 10 | J11: =SUMIFS(Stems_3D_BP!$K$2:$K$5573,Stems_3D_BP!$A$2:$A$5573,$A11,Stems_3D_BP!$B$2:$B$5573,"T-stem") -> 10 | K11: =SUM(G11:J11) -> 37 | L11: =K11/42 -> 0.88095238 | M11: =SUMIFS(Stems_3D_BP!$K$2:$K$5573,Stems_3D_BP!$A$2:$A$5573,$A11,Stems_3D_BP!$B$2:$B$5573,"3D (tertiary) BP") -> 6 | N11: =M11/14 -> 0.42857143 | O11: =K11+M11 -> 43 | P11: =O11/56 -> 0.76785714 | Q11: =SUMIFS(Loops!$I$2:$I$996,Loops!$A$2:$A$996,$A11,Loops!$B$2:$B$996,"D-loop") -> 6 | R11: =SUMIFS(Loops!$I$2:$I$996,Loops!$A$2:$A$996,$A11,Loops!$B$2:$B$996,"Anticodon loop") -> 4 | S11: =SUMIFS(Loops!$I$2:$I$996,Loops!$A$2:$A$996,$A11,Loops!$B$2:$B$996,"Variable loop") -> 3 | T11: =SUMIFS(Loops!$I$2:$I$996,Loops!$A$2:$A$996,$A11,Loops!$B$2:$B$996,"TΨC-loop") -> 1 | U11: =SUMIFS(Loops!$F$2:$F$996,Loops!$A$2:$A$996,$A11)-SUMIFS(Loops!$F$2:$F$996,Loops!$A$2:$A$996,$A11,Loops!$B$2:$B$996,"Positions 8, 9, 26") -> 29 | V11: =SUM(Q11:T11) -> 14 | W11: =V11/U11 -> 0.48275862 | X11: =INDEX(Positions!$E$2:$E$14531,MATCH($A11&"|8",Positions!$A$2:$A$14531,0)) -> U | Y11: =INDEX(Positions!$E$2:$E$14531,MATCH($A11&"|9",Positions!$A$2:$A$14531,0)) -> C | Z11: =INDEX(Positions!$E$2:$E$14531,MATCH($A11&"|26",Positions!$A$2:$A$14531,0)) -> G | AA11: =(X11="G")+(Y11="G")+(Z11="G") -> 1 | AB11: =(X11="C")+(Y11="C")+(Z11="C") -> 1 | AC11: =AA11+AB11 -> 2 | AD11: =AC11/3 -> 0.66666667 | AE11: =IF(K11+V11+AC11=E11,"OK","MISMATCH") -> OK | AF11: =B11-42 -> 32 | AG11: =V11+AC11 -> 16 | AH11: =AG11/AF11 -> 0.5 | AI11: =L11 -> 0.88095238 | AJ11: =AI11-AH11 -> 0.38095238
A12: tdbR00000584 Pro-GGG | B12: =COUNTIF(Positions!$B$2:$B$14531,A12) -> 74 | C12: =COUNTIFS(Positions!$B$2:$B$14531,A12,Positions!$E$2:$E$14531,"G") -> 29 | D12: =COUNTIFS(Positions!$B$2:$B$14531,A12,Positions!$E$2:$E$14531,"C") -> 25 | E12: =C12+D12 -> 54 | F12: =E12/B12 -> 0.72972973 | G12: =SUMIFS(Stems_3D_BP!$K$2:$K$5573,Stems_3D_BP!$A$2:$A$5573,$A12,Stems_3D_BP!$B$2:$B$5573,"Acceptor stem") -> 14 | H12: =SUMIFS(Stems_3D_BP!$K$2:$K$5573,Stems_3D_BP!$A$2:$A$5573,$A12,Stems_3D_BP!$B$2:$B$5573,"D-stem") -> 4 | I12: =SUMIFS(Stems_3D_BP!$K$2:$K$5573,Stems_3D_BP!$A$2:$A$5573,$A12,Stems_3D_BP!$B$2:$B$5573,"Anticodon stem") -> 8 | J12: =SUMIFS(Stems_3D_BP!$K$2:$K$5573,Stems_3D_BP!$A$2:$A$5573,$A12,Stems_3D_BP!$B$2:$B$5573,"T-stem") -> 10 | K12: =SUM(G12:J12) -> 36 | L12: =K12/42 -> 0.85714286 | M12: =SUMIFS(Stems_3D_BP!$K$2:$K$5573,Stems_3D_BP!$A$2:$A$5573,$A12,Stems_3D_BP!$B$2:$B$5573,"3D (tertiary) BP") -> 8 | N12: =M12/14 -> 0.57142857 | O12: =K12+M12 -> 44 | P12: =O12/56 -> 0.78571429 | Q12: =SUMIFS(Loops!$I$2:$I$996,Loops!$A$2:$A$996,$A12,Loops!$B$2:$B$996,"D-loop") -> 6 | R12: =SUMIFS(Loops!$I$2:$I$996,Loops!$A$2:$A$996,$A12,Loops!$B$2:$B$996,"Anticodon loop") -> 6 | S12: =SUMIFS(Loops!$I$2:$I$996,Loops!$A$2:$A$996,$A12,Loops!$B$2:$B$996,"Variable loop") -> 3 | T12: =SUMIFS(Loops!$I$2:$I$996,Loops!$A$2:$A$996,$A12,Loops!$B$2:$B$996,"TΨC-loop") -> 1 | U12: =SUMIFS(Loops!$F$2:$F$996,Loops!$A$2:$A$996,$A12)-SUMIFS(Loops!$F$2:$F$996,Loops!$A$2:$A$996,$A12,Loops!$B$2:$B$996,"Positions 8, 9, 26") -> 29 | V12: =SUM(Q12:T12) -> 16 | W12: =V12/U12 -> 0.55172414 | X12: =INDEX(Positions!$E$2:$E$14531,MATCH($A12&"|8",Positions!$A$2:$A$14531,0)) -> U | Y12: =INDEX(Positions!$E$2:$E$14531,MATCH($A12&"|9",Positions!$A$2:$A$14531,0)) -> C | Z12: =INDEX(Positions!$E$2:$E$14531,MATCH($A12&"|26",Positions!$A$2:$A$14531,0)) -> G | AA12: =(X12="G")+(Y12="G")+(Z12="G") -> 1 | AB12: =(X12="C")+(Y12="C")+(Z12="C") -> 1 | AC12: =AA12+AB12 -> 2 | AD12: =AC12/3 -> 0.66666667 | AE12: =IF(K12+V12+AC12=E12,"OK","MISMATCH") -> OK | AF12: =B12-42 -> 32 | AG12: =V12+AC12 -> 18 | AH12: =AG12/AF12 -> 0.5625 | AI12: =L12 -> 0.85714286 | AJ12: =AI12-AH12 -> 0.29464286
A13: tdbR00000585 Thr-CGU | B13: =COUNTIF(Positions!$B$2:$B$14531,A13) -> 71 | C13: =COUNTIFS(Positions!$B$2:$B$14531,A13,Positions!$E$2:$E$14531,"G") -> 28 | D13: =COUNTIFS(Positions!$B$2:$B$14531,A13,Positions!$E$2:$E$14531,"C") -> 25 | E13: =C13+D13 -> 53 | F13: =E13/B13 -> 0.74647887 | G13: =SUMIFS(Stems_3D_BP!$K$2:$K$5573,Stems_3D_BP!$A$2:$A$5573,$A13,Stems_3D_BP!$B$2:$B$5573,"Acceptor stem") -> 14 | H13: =SUMIFS(Stems_3D_BP!$K$2:$K$5573,Stems_3D_BP!$A$2:$A$5573,$A13,Stems_3D_BP!$B$2:$B$5573,"D-stem") -> 6 | I13: =SUMIFS(Stems_3D_BP!$K$2:$K$5573,Stems_3D_BP!$A$2:$A$5573,$A13,Stems_3D_BP!$B$2:$B$5573,"Anticodon stem") -> 10 | J13: =SUMIFS(Stems_3D_BP!$K$2:$K$5573,Stems_3D_BP!$A$2:$A$5573,$A13,Stems_3D_BP!$B$2:$B$5573,"T-stem") -> 10 | K13: =SUM(G13:J13) -> 40 | L13: =K13/42 -> 0.95238095 | M13: =SUMIFS(Stems_3D_BP!$K$2:$K$5573,Stems_3D_BP!$A$2:$A$5573,$A13,Stems_3D_BP!$B$2:$B$5573,"3D (tertiary) BP") -> 7 | N13: =M13/14 -> 0.5 | O13: =K13+M13 -> 47 | P13: =O13/56 -> 0.83928571 | Q13: =SUMIFS(Loops!$I$2:$I$996,Loops!$A$2:$A$996,$A13,Loops!$B$2:$B$996,"D-loop") -> 4 | R13: =SUMIFS(Loops!$I$2:$I$996,Loops!$A$2:$A$996,$A13,Loops!$B$2:$B$996,"Anticodon loop") -> 3 | S13: =SUMIFS(Loops!$I$2:$I$996,Loops!$A$2:$A$996,$A13,Loops!$B$2:$B$996,"Variable loop") -> 3 | T13: =SUMIFS(Loops!$I$2:$I$996,Loops!$A$2:$A$996,$A13,Loops!$B$2:$B$996,"TΨC-loop") -> 2 | U13: =SUMIFS(Loops!$F$2:$F$996,Loops!$A$2:$A$996,$A13)-SUMIFS(Loops!$F$2:$F$996,Loops!$A$2:$A$996,$A13,Loops!$B$2:$B$996,"Positions 8, 9, 26") -> 26 | V13: =SUM(Q13:T13) -> 12 | W13: =V13/U13 -> 0.46153846 | X13: =INDEX(Positions!$E$2:$E$14531,MATCH($A13&"|8",Positions!$A$2:$A$14531,0)) -> U | Y13: =INDEX(Positions!$E$2:$E$14531,MATCH($A13&"|9",Positions!$A$2:$A$14531,0)) -> A | Z13: =INDEX(Positions!$E$2:$E$14531,MATCH($A13&"|26",Positions!$A$2:$A$14531,0)) -> G | AA13: =(X13="G")+(Y13="G")+(Z13="G") -> 1 | AB13: =(X13="C")+(Y13="C")+(Z13="C") -> 0 | AC13: =AA13+AB13 -> 1 | AD13: =AC13/3 -> 0.33333333 | AE13: =IF(K13+V13+AC13=E13,"OK","MISMATCH") -> OK | AF13: =B13-42 -> 29 | AG13: =V13+AC13 -> 13 | AH13: =AG13/AF13 -> 0.44827586 | AI13: =L13 -> 0.95238095 | AJ13: =AI13-AH13 -> 0.50410509
A14: tdbR00000582 Tyr-GUA | B14: =COUNTIF(Positions!$B$2:$B$14531,A14) -> 71 | C14: =COUNTIFS(Positions!$B$2:$B$14531,A14,Positions!$E$2:$E$14531,"G") -> 28 | D14: =COUNTIFS(Positions!$B$2:$B$14531,A14,Positions!$E$2:$E$14531,"C") -> 26 | E14: =C14+D14 -> 54 | F14: =E14/B14 -> 0.76056338 | G14: =SUMIFS(Stems_3D_BP!$K$2:$K$5573,Stems_3D_BP!$A$2:$A$5573,$A14,Stems_3D_BP!$B$2:$B$5573,"Acceptor stem") -> 14 | H14: =SUMIFS(Stems_3D_BP!$K$2:$K$5573,Stems_3D_BP!$A$2:$A$5573,$A14,Stems_3D_BP!$B$2:$B$5573,"D-stem") -> 6 | I14: =SUMIFS(Stems_3D_BP!$K$2:$K$5573,Stems_3D_BP!$A$2:$A$5573,$A14,Stems_3D_BP!$B$2:$B$5573,"Anticodon stem") -> 10 | J14: =SUMIFS(Stems_3D_BP!$K$2:$K$5573,Stems_3D_BP!$A$2:$A$5573,$A14,Stems_3D_BP!$B$2:$B$5573,"T-stem") -> 10 | K14: =SUM(G14:J14) -> 40 | L14: =K14/42 -> 0.95238095 | M14: =SUMIFS(Stems_3D_BP!$K$2:$K$5573,Stems_3D_BP!$A$2:$A$5573,$A14,Stems_3D_BP!$B$2:$B$5573,"3D (tertiary) BP") -> 7 | N14: =M14/14 -> 0.5 | O14: =K14+M14 -> 47 | P14: =O14/56 -> 0.83928571 | Q14: =SUMIFS(Loops!$I$2:$I$996,Loops!$A$2:$A$996,$A14,Loops!$B$2:$B$996,"D-loop") -> 5 | R14: =SUMIFS(Loops!$I$2:$I$996,Loops!$A$2:$A$996,$A14,Loops!$B$2:$B$996,"Anticodon loop") -> 3 | S14: =SUMIFS(Loops!$I$2:$I$996,Loops!$A$2:$A$996,$A14,Loops!$B$2:$B$996,"Variable loop") -> 3 | T14: =SUMIFS(Loops!$I$2:$I$996,Loops!$A$2:$A$996,$A14,Loops!$B$2:$B$996,"TΨC-loop") -> 2 | U14: =SUMIFS(Loops!$F$2:$F$996,Loops!$A$2:$A$996,$A14)-SUMIFS(Loops!$F$2:$F$996,Loops!$A$2:$A$996,$A14,Loops!$B$2:$B$996,"Positions 8, 9, 26") -> 26 | V14: =SUM(Q14:T14) -> 13 | W14: =V14/U14 -> 0.5 | X14: =INDEX(Positions!$E$2:$E$14531,MATCH($A14&"|8",Positions!$A$2:$A$14531,0)) -> U | Y14: =INDEX(Positions!$E$2:$E$14531,MATCH($A14&"|9",Positions!$A$2:$A$14531,0)) -> A | Z14: =INDEX(Positions!$E$2:$E$14531,MATCH($A14&"|26",Positions!$A$2:$A$14531,0)) -> G | AA14: =(X14="G")+(Y14="G")+(Z14="G") -> 1 | AB14: =(X14="C")+(Y14="C")+(Z14="C") -> 0 | AC14: =AA14+AB14 -> 1 | AD14: =AC14/3 -> 0.33333333 | AE14: =IF(K14+V14+AC14=E14,"OK","MISMATCH") -> OK | AF14: =B14-42 -> 29 | AG14: =V14+AC14 -> 14 | AH14: =AG14/AF14 -> 0.48275862 | AI14: =L14 -> 0.95238095 | AJ14: =AI14-AH14 -> 0.46962233
A15: tdbR00000007 Ala-UGC | B15: =COUNTIF(Positions!$B$2:$B$14531,A15) -> 72 | C15: =COUNTIFS(Positions!$B$2:$B$14531,A15,Positions!$E$2:$E$14531,"G") -> 25 | D15: =COUNTIFS(Positions!$B$2:$B$14531,A15,Positions!$E$2:$E$14531,"C") -> 22 | E15: =C15+D15 -> 47 | F15: =E15/B15 -> 0.65277778 | G15: =SUMIFS(Stems_3D_BP!$K$2:$K$5573,Stems_3D_BP!$A$2:$A$5573,$A15,Stems_3D_BP!$B$2:$B$5573,"Acceptor stem") -> 10 | H15: =SUMIFS(Stems_3D_BP!$K$2:$K$5573,Stems_3D_BP!$A$2:$A$5573,$A15,Stems_3D_BP!$B$2:$B$5573,"D-stem") -> 6 | I15: =SUMIFS(Stems_3D_BP!$K$2:$K$5573,Stems_3D_BP!$A$2:$A$5573,$A15,Stems_3D_BP!$B$2:$B$5573,"Anticodon stem") -> 8 | J15: =SUMIFS(Stems_3D_BP!$K$2:$K$5573,Stems_3D_BP!$A$2:$A$5573,$A15,Stems_3D_BP!$B$2:$B$5573,"T-stem") -> 8 | K15: =SUM(G15:J15) -> 32 | L15: =K15/42 -> 0.76190476 | M15: =SUMIFS(Stems_3D_BP!$K$2:$K$5573,Stems_3D_BP!$A$2:$A$5573,$A15,Stems_3D_BP!$B$2:$B$5573,"3D (tertiary) BP") -> 7 | N15: =M15/14 -> 0.5 | O15: =K15+M15 -> 39 | P15: =O15/56 -> 0.69642857 | Q15: =SUMIFS(Loops!$I$2:$I$996,Loops!$A$2:$A$996,$A15,Loops!$B$2:$B$996,"D-loop") -> 5 | R15: =SUMIFS(Loops!$I$2:$I$996,Loops!$A$2:$A$996,$A15,Loops!$B$2:$B$996,"Anticodon loop") -> 3 | S15: =SUMIFS(Loops!$I$2:$I$996,Loops!$A$2:$A$996,$A15,Loops!$B$2:$B$996,"Variable loop") -> 3 | T15: =SUMIFS(Loops!$I$2:$I$996,Loops!$A$2:$A$996,$A15,Loops!$B$2:$B$996,"TΨC-loop") -> 3 | U15: =SUMIFS(Loops!$F$2:$F$996,Loops!$A$2:$A$996,$A15)-SUMIFS(Loops!$F$2:$F$996,Loops!$A$2:$A$996,$A15,Loops!$B$2:$B$996,"Positions 8, 9, 26") -> 27 | V15: =SUM(Q15:T15) -> 14 | W15: =V15/U15 -> 0.51851852 | X15: =INDEX(Positions!$E$2:$E$14531,MATCH($A15&"|8",Positions!$A$2:$A$14531,0)) -> U | Y15: =INDEX(Positions!$E$2:$E$14531,MATCH($A15&"|9",Positions!$A$2:$A$14531,0)) -> A | Z15: =INDEX(Positions!$E$2:$E$14531,MATCH($A15&"|26",Positions!$A$2:$A$14531,0)) -> G | AA15: =(X15="G")+(Y15="G")+(Z15="G") -> 1 | AB15: =(X15="C")+(Y15="C")+(Z15="C") -> 0 | AC15: =AA15+AB15 -> 1 | AD15: =AC15/3 -> 0.33333333 | AE15: =IF(K15+V15+AC15=E15,"OK","MISMATCH") -> OK | AF15: =B15-42 -> 30 | AG15: =V15+AC15 -> 15 | AH15: =AG15/AF15 -> 0.5 | AI15: =L15 -> 0.76190476 | AJ15: =AI15-AH15 -> 0.26190476
... A202: tdbR00000502 Ile-CAU | B202: =COUNTIF(Positions!$B$2:$B$14531,A202) -> 74 | C202: =COUNTIFS(Positions!$B$2:$B$14531,A202,Positions!$E$2:$E$14531,"G") -> 24 | D202: =COUNTIFS(Positions!$B$2:$B$14531,A202,Positions!$E$2:$E$14531,"C") -> 22 | E202: =C202+D202 -> 46 | F202: =E202/B202 -> 0.62162162 | G202: =SUMIFS(Stems_3D_BP!$K$2:$K$5573,Stems_3D_BP!$A$2:$A$5573,$A202,Stems_3D_BP!$B$2:$B$5573,"Acceptor stem") -> 12 | H202: =SUMIFS(Stems_3D_BP!$K$2:$K$5573,Stems_3D_BP!$A$2:$A$5573,$A202,Stems_3D_BP!$B$2:$B$5573,"D-stem") -> 6 | I202: =SUMIFS(Stems_3D_BP!$K$2:$K$5573,Stems_3D_BP!$A$2:$A$5573,$A202,Stems_3D_BP!$B$2:$B$5573,"Anticodon stem") -> 8 | J202: =SUMIFS(Stems_3D_BP!$K$2:$K$5573,Stems_3D_BP!$A$2:$A$5573,$A202,Stems_3D_BP!$B$2:$B$5573,"T-stem") -> 8 | K202: =SUM(G202:J202) -> 34 | L202: =K202/42 -> 0.80952381 | M202: =SUMIFS(Stems_3D_BP!$K$2:$K$5573,Stems_3D_BP!$A$2:$A$5573,$A202,Stems_3D_BP!$B$2:$B$5573,"3D (tertiary) BP") -> 7 | N202: =M202/14 -> 0.5 | O202: =K202+M202 -> 41 | P202: =O202/56 -> 0.73214286 | Q202: =SUMIFS(Loops!$I$2:$I$996,Loops!$A$2:$A$996,$A202,Loops!$B$2:$B$996,"D-loop") -> 5 | R202: =SUMIFS(Loops!$I$2:$I$996,Loops!$A$2:$A$996,$A202,Loops!$B$2:$B$996,"Anticodon loop") -> 2 | S202: =SUMIFS(Loops!$I$2:$I$996,Loops!$A$2:$A$996,$A202,Loops!$B$2:$B$996,"Variable loop") -> 3 | T202: =SUMIFS(Loops!$I$2:$I$996,Loops!$A$2:$A$996,$A202,Loops!$B$2:$B$996,"TΨC-loop") -> 1 | U202: =SUMIFS(Loops!$F$2:$F$996,Loops!$A$2:$A$996,$A202)-SUMIFS(Loops!$F$2:$F$996,Loops!$A$2:$A$996,$A202,Loops!$B$2:$B$996,"Positions 8, 9, 26") -> 29 | V202: =SUM(Q202:T202) -> 11 | W202: =V202/U202 -> 0.37931034 | X202: =INDEX(Positions!$E$2:$E$14531,MATCH($A202&"|8",Positions!$A$2:$A$14531,0)) -> U | Y202: =INDEX(Positions!$E$2:$E$14531,MATCH($A202&"|9",Positions!$A$2:$A$14531,0)) -> A | Z202: =INDEX(Positions!$E$2:$E$14531,MATCH($A202&"|26",Positions!$A$2:$A$14531,0)) -> G | AA202: =(X202="G")+(Y202="G")+(Z202="G") -> 1 | AB202: =(X202="C")+(Y202="C")+(Z202="C") -> 0 | AC202: =AA202+AB202 -> 1 | AD202: =AC202/3 -> 0.33333333 | AE202: =IF(K202+V202+AC202=E202,"OK","MISMATCH") -> OK | AF202: =B202-42 -> 32 | AG202: =V202+AC202 -> 12 | AH202: =AG202/AF202 -> 0.375 | AI202: =L202 -> 0.80952381 | AJ202: =AI202-AH202 -> 0.43452381
A203: Mean | B203: =AVERAGE(B4:B202) -> 73.015075 | C203: =AVERAGE(C4:C202) -> 23.467337 | D203: =AVERAGE(D4:D202) -> 20.025126 | E203: =AVERAGE(E4:E202) -> 43.492462 | F203: =AVERAGE(F4:F202) -> 0.59541202 | G203: =AVERAGE(G4:G202) -> 10.407035 | H203: =AVERAGE(H4:H202) -> 5.6080402 | I203: =AVERAGE(I4:I202) -> 6.758794 | ... W203: =AVERAGE(W4:W202) -> 0.42587012 | AA203: =AVERAGE(AA4:AA202) -> 0.8040201 | AB203: =AVERAGE(AB4:AB202) -> 0.060301508 | AC203: =AVERAGE(AC4:AC202) -> 0.86432161 | AD203: =AVERAGE(AD4:AD202) -> 0.2881072 | AF203: =AVERAGE(AF4:AF202) -> 31.015075 | AG203: =AVERAGE(AG4:AG202) -> 12.829146 | AH203: =AVERAGE(AH4:AH202) -> 0.41236729 | AI203: =AVERAGE(AI4:AI202) -> 0.73007897 | AJ203: =AVERAGE(AJ4:AJ202) -> 0.31771167
A205: Percentages: overall = G+C / full length; stems = /42 nt (21 bp); 3D = /14 nt (7 tertiary pairs); stems+3D = /56 nt; positions 8, 9, 26 = /3 nt; loops = / total nt of D, AC, variable and TΨC loops.
A206: 3D pairs 14, 15, 18, 19, 32, 38, 44, 48, 54, 55, 58 lie inside loops, so "4 stems + 3D" and "4 loops" share those nucleotides. 4 stems + 4 loops + positions 8, 9, 26 together cover every nucleotide once together cover every nucleotide once (column AE checks this).

Sheet tRNA_Info
A1: tRNA (key) | B1: T-psi-C ID | C1: Amino acid | D1: Anticodon | E1: Organism | F1: Database length (nt) | G1: Analysed length 1-72 region (nt) | H1: Excluded 5′ nt | I1: Excluded 3′ nt (73 / CCA) | J1: Analysed sequence | K1: Canonical stem pairs not paired in database structure
A2: tdbR00000589 Arg-UCU | B2: tdbR00000589 | C2: Arg | D2: UCU | E2: Aeropyrum pernix | F2: 78 | G2: 74 | H2: - | I2: GCCA | J2: GGGCCCGUAGCUCAGCCAGGACAGAGCGCCGGCCUUCUAAGCCGGUGCUGCCGGGUUCAAAUCCCGGCGGGCCC | K2: none
A3: tdbR00000588 Asp-GUC | B3: tdbR00000588 | C3: Asp | D3: GUC | E3: Aeropyrum pernix | F3: 78 | G3: 74 | H3: - | I3: GCCA | J3: GCCGCGGUAGUAUAGCCUGGACUAGUAUGCGGGCCUGUCAAGCCCGUGACCCGGGUUCAAAUCCCGGCCGCGGC | K3: none
A4: tdbR00000583 Cys-GCA | B4: tdbR00000583 | C4: Cys | D4: GCA | E4: Aeropyrum pernix | F4: 78 | G4: 74 | H4: - | I4: UCCA | J4: GCCGGGGUGGCCGAGCGGUCUAAGGCGGCGGGCUGCAGACCCGUUAGUUCCCGGGUUCGAAUCCCGGCCCCGGC | K4: 13-22
A5: tdbR00000581 Lys-CUU | B5: tdbR00000581 | C5: Lys | D5: CUU | E5: Aeropyrum pernix | F5: 85 | G5: 81 | H5: - | I5: GCCA | J5: GGGCCCGUAGCUCAGCCUGGUAGAGCGGCGGGCUCUUAACCCGCGAGGGAGGAAGUCCCGGGUUCAAAUCCCGGCGGGCCC | K5: none
A6: tdbR00000580 Lys-UUU | B6: tdbR00000580 | C6: Lys | D6: UUU | E6: Aeropyrum pernix | F6: 80 | G6: 76 | H6: - | I6: GCCA | J6: GGGCCCGUAGCUCAGCCCGGCAGAGCGGCGGGCUUUUACCCCGCGGAAGGUCCCGGGUUCAAAUCCCGGCGGGCCC | K6: none
A7: tdbR00000586 Met-CAU | B7: tdbR00000586 | C7: Met | D7: CAU | E7: Aeropyrum pernix | F7: 77 | G7: 73 | H7: - | I7: ACCA | J7: GGGCCCGUAGCUCAGCCAGGUAGAGCGCCCGGCUCAUAACCGGGUGGUCGGGGGUUCAAAUCCCCCCGGGCCC | K7: none
A8: tdbR00000587 Met-CAU | B8: tdbR00000587 | C8: Met | D8: CAU | E8: Aeropyrum pernix | F8: 77 | G8: 73 | H8: - | I8: ACCA | J8: GCCGCCGUAGCUCAGCCUGGCAGAGCGCCGGACUCAUAAUCCGGAGGUCCCGGGUUCGAAUCCCGGCGGCGGC | K8: none
A9: tdbR00000579 Pro-CGG | B9: tdbR00000579 | C9: Pro | D9: CGG | E9: Aeropyrum pernix | F9: 78 | G9: 74 | H9: - | I9: ACCA | J9: GGGCCCGUCGUCUAGCCUGGCUAAGAUGCGGGGUACGGGACCCCGUGGUCCGGGGUUCAAAUCCCCGCGGGCCC | K9: none
A10: tdbR00000584 Pro-GGG | B10: tdbR00000584 | C10: Pro | D10: GGG | E10: Aeropyrum pernix | F10: 78 | G10: 74 | H10: - | I10: ACCA | J10: GGGGCCGUCGUCUAGCCUGGCUAGGAUGCCAGCCUGGGGCGCUGGUGGUCCCGGGUUCAAAUCCCGGCGGCCCC | K10: none
A11: tdbR00000585 Thr-CGU | B11: tdbR00000585 | C11: Thr | D11: CGU | E11: Aeropyrum pernix | F11: 75 | G11: 71 | H11: - | I11: UCCA | J11: GCCGCCGUAGCUCAGCGGUAGAGCGCCGGCCUCGUAAGCCGGUGGUCGCGGGUUCGAAUCCCGCCGGCGGC | K11: none
A12: tdbR00000582 Tyr-GUA | B12: tdbR00000582 | C12: Tyr | D12: GUA | E12: Aeropyrum pernix | F12: 75 | G12: 71 | H12: - | I12: ACCA | J12: CCCGCCGUAGCUCAGCGGCAGAGCGCCCGGCUGUACACCGGGUGGUCCGGGGUUCGAAUCCCCGCGGCGGG | K12: none
A13: tdbR00000007 Ala-UGC | B13: tdbR00000007 | C13: Ala | D13: UGC | E13: Bacillus subtilis | F13: 76 | G13: 72 | H13: - | I13: ACCA | J13: GGAGCCUUAGCUCAGCUGGGAGAGCGCCUGCUUUGCACGCAGGAGGUCAGCGGUUCGAUCCCGCUAGGCUCC | K13: none
... A200: tdbR00000502 Ile-CAU | B200: tdbR00000502 | C200: Ile | D200: CAU | E200: Sulfolobus acidocaldarius | F200: 78 | G200: 74 | H200: - | I200: ACCA | J200: AGCGGCGUAGGGAACUGGGAGUAUCCCGCAGGGCUCAUAACCCUGAGGUCCCUGGUUCAAAUCCAGGCGCCGCU | K200: none

Sheet Positions
A1: Key | B1: tRNA | C1: Canonical position | D1: Actual position | E1: Nucleotide | F1: Region
A2: =B2&"|"&C2 -> tdbR00000589 Arg-UCU|1 | B2: tdbR00000589 Arg-UCU | C2: 1 | D2: 1 | E2: G | F2: Acceptor stem
A3: =B3&"|"&C3 -> tdbR00000589 Arg-UCU|2 | B3: tdbR00000589 Arg-UCU | C3: 2 | D3: 2 | E3: G | F3: Acceptor stem
A4: =B4&"|"&C4 -> tdbR00000589 Arg-UCU|3 | B4: tdbR00000589 Arg-UCU | C4: 3 | D4: 3 | E4: G | F4: Acceptor stem
A5: =B5&"|"&C5 -> tdbR00000589 Arg-UCU|4 | B5: tdbR00000589 Arg-UCU | C5: 4 | D5: 4 | E5: C | F5: Acceptor stem
A6: =B6&"|"&C6 -> tdbR00000589 Arg-UCU|5 | B6: tdbR00000589 Arg-UCU | C6: 5 | D6: 5 | E6: C | F6: Acceptor stem
A7: =B7&"|"&C7 -> tdbR00000589 Arg-UCU|6 | B7: tdbR00000589 Arg-UCU | C7: 6 | D7: 6 | E7: C | F7: Acceptor stem
A8: =B8&"|"&C8 -> tdbR00000589 Arg-UCU|7 | B8: tdbR00000589 Arg-UCU | C8: 7 | D8: 7 | E8: G | F8: Acceptor stem
A9: =B9&"|"&C9 -> tdbR00000589 Arg-UCU|8 | B9: tdbR00000589 Arg-UCU | C9: 8 | D9: 8 | E9: U | F9: Position 8
A10: =B10&"|"&C10 -> tdbR00000589 Arg-UCU|9 | B10: tdbR00000589 Arg-UCU | C10: 9 | D10: 9 | E10: A | F10: Position 9
A11: =B11&"|"&C11 -> tdbR00000589 Arg-UCU|10 | B11: tdbR00000589 Arg-UCU | C11: 10 | D11: 10 | E11: G | F11: D-stem
A12: =B12&"|"&C12 -> tdbR00000589 Arg-UCU|11 | B12: tdbR00000589 Arg-UCU | C12: 11 | D12: 11 | E12: C | F12: D-stem
A13: =B13&"|"&C13 -> tdbR00000589 Arg-UCU|12 | B13: tdbR00000589 Arg-UCU | C13: 12 | D13: 12 | E13: U | F13: D-stem
... A14531: =B14531&"|"&C14531 -> tdbR00000502 Ile-CAU|72 | B14531: tdbR00000502 Ile-CAU | C14531: 72 | D14531: 74 | E14531: U | F14531: Acceptor stem

Sheet Stems_3D_BP
A1: tRNA | B1: Element | C1: Canonical pair | D1: Actual pos (5′) | E1: Actual pos (3′) | F1: Nt (5′) | G1: Nt (3′) | H1: Pair | I1: G count | J1: C count | K1: G+C count
A2: tdbR00000589 Arg-UCU | B2: Acceptor stem | C2: 1-72 | D2: =IFERROR(INDEX(Positions!$D$2:$D$14531,MATCH($A2&"|1",Positions!$A$2:$A$14531,0)),"-") -> 1 | E2: =IFERROR(INDEX(Positions!$D$2:$D$14531,MATCH($A2&"|72",Positions!$A$2:$A$14531,0)),"-") -> 74 | F2: =IFERROR(INDEX(Positions!$E$2:$E$14531,MATCH($A2&"|1",Positions!$A$2:$A$14531,0)),"-") -> G | G2: =IFERROR(INDEX(Positions!$E$2:$E$14531,MATCH($A2&"|72",Positions!$A$2:$A$14531,0)),"-") -> C | H2: =F2&"-"&G2 -> G-C | I2: =(F2="G")+(G2="G") -> 1 | J2: =(F2="C")+(G2="C") -> 1 | K2: =I2+J2 -> 2
A3: tdbR00000589 Arg-UCU | B3: Acceptor stem | C3: 2-71 | D3: =IFERROR(INDEX(Positions!$D$2:$D$14531,MATCH($A3&"|2",Positions!$A$2:$A$14531,0)),"-") -> 2 | E3: =IFERROR(INDEX(Positions!$D$2:$D$14531,MATCH($A3&"|71",Positions!$A$2:$A$14531,0)),"-") -> 73 | F3: =IFERROR(INDEX(Positions!$E$2:$E$14531,MATCH($A3&"|2",Positions!$A$2:$A$14531,0)),"-") -> G | G3: =IFERROR(INDEX(Positions!$E$2:$E$14531,MATCH($A3&"|71",Positions!$A$2:$A$14531,0)),"-") -> C | H3: =F3&"-"&G3 -> G-C | I3: =(F3="G")+(G3="G") -> 1 | J3: =(F3="C")+(G3="C") -> 1 | K3: =I3+J3 -> 2
A4: tdbR00000589 Arg-UCU | B4: Acceptor stem | C4: 3-70 | D4: =IFERROR(INDEX(Positions!$D$2:$D$14531,MATCH($A4&"|3",Positions!$A$2:$A$14531,0)),"-") -> 3 | E4: =IFERROR(INDEX(Positions!$D$2:$D$14531,MATCH($A4&"|70",Positions!$A$2:$A$14531,0)),"-") -> 72 | F4: =IFERROR(INDEX(Positions!$E$2:$E$14531,MATCH($A4&"|3",Positions!$A$2:$A$14531,0)),"-") -> G | G4: =IFERROR(INDEX(Positions!$E$2:$E$14531,MATCH($A4&"|70",Positions!$A$2:$A$14531,0)),"-") -> C | H4: =F4&"-"&G4 -> G-C | I4: =(F4="G")+(G4="G") -> 1 | J4: =(F4="C")+(G4="C") -> 1 | K4: =I4+J4 -> 2
A5: tdbR00000589 Arg-UCU | B5: Acceptor stem | C5: 4-69 | D5: =IFERROR(INDEX(Positions!$D$2:$D$14531,MATCH($A5&"|4",Positions!$A$2:$A$14531,0)),"-") -> 4 | E5: =IFERROR(INDEX(Positions!$D$2:$D$14531,MATCH($A5&"|69",Positions!$A$2:$A$14531,0)),"-") -> 71 | F5: =IFERROR(INDEX(Positions!$E$2:$E$14531,MATCH($A5&"|4",Positions!$A$2:$A$14531,0)),"-") -> C | G5: =IFERROR(INDEX(Positions!$E$2:$E$14531,MATCH($A5&"|69",Positions!$A$2:$A$14531,0)),"-") -> G | H5: =F5&"-"&G5 -> C-G | I5: =(F5="G")+(G5="G") -> 1 | J5: =(F5="C")+(G5="C") -> 1 | K5: =I5+J5 -> 2
A6: tdbR00000589 Arg-UCU | B6: Acceptor stem | C6: 5-68 | D6: =IFERROR(INDEX(Positions!$D$2:$D$14531,MATCH($A6&"|5",Positions!$A$2:$A$14531,0)),"-") -> 5 | E6: =IFERROR(INDEX(Positions!$D$2:$D$14531,MATCH($A6&"|68",Positions!$A$2:$A$14531,0)),"-") -> 70 | F6: =IFERROR(INDEX(Positions!$E$2:$E$14531,MATCH($A6&"|5",Positions!$A$2:$A$14531,0)),"-") -> C | G6: =IFERROR(INDEX(Positions!$E$2:$E$14531,MATCH($A6&"|68",Positions!$A$2:$A$14531,0)),"-") -> G | H6: =F6&"-"&G6 -> C-G | I6: =(F6="G")+(G6="G") -> 1 | J6: =(F6="C")+(G6="C") -> 1 | K6: =I6+J6 -> 2
A7: tdbR00000589 Arg-UCU | B7: Acceptor stem | C7: 6-67 | D7: =IFERROR(INDEX(Positions!$D$2:$D$14531,MATCH($A7&"|6",Positions!$A$2:$A$14531,0)),"-") -> 6 | E7: =IFERROR(INDEX(Positions!$D$2:$D$14531,MATCH($A7&"|67",Positions!$A$2:$A$14531,0)),"-") -> 69 | F7: =IFERROR(INDEX(Positions!$E$2:$E$14531,MATCH($A7&"|6",Positions!$A$2:$A$14531,0)),"-") -> C | G7: =IFERROR(INDEX(Positions!$E$2:$E$14531,MATCH($A7&"|67",Positions!$A$2:$A$14531,0)),"-") -> G | H7: =F7&"-"&G7 -> C-G | I7: =(F7="G")+(G7="G") -> 1 | J7: =(F7="C")+(G7="C") -> 1 | K7: =I7+J7 -> 2
A8: tdbR00000589 Arg-UCU | B8: Acceptor stem | C8: 7-66 | D8: =IFERROR(INDEX(Positions!$D$2:$D$14531,MATCH($A8&"|7",Positions!$A$2:$A$14531,0)),"-") -> 7 | E8: =IFERROR(INDEX(Positions!$D$2:$D$14531,MATCH($A8&"|66",Positions!$A$2:$A$14531,0)),"-") -> 68 | F8: =IFERROR(INDEX(Positions!$E$2:$E$14531,MATCH($A8&"|7",Positions!$A$2:$A$14531,0)),"-") -> G | G8: =IFERROR(INDEX(Positions!$E$2:$E$14531,MATCH($A8&"|66",Positions!$A$2:$A$14531,0)),"-") -> C | H8: =F8&"-"&G8 -> G-C | I8: =(F8="G")+(G8="G") -> 1 | J8: =(F8="C")+(G8="C") -> 1 | K8: =I8+J8 -> 2
A9: tdbR00000589 Arg-UCU | B9: D-stem | C9: 10-25 | D9: =IFERROR(INDEX(Positions!$D$2:$D$14531,MATCH($A9&"|10",Positions!$A$2:$A$14531,0)),"-") -> 10 | E9: =IFERROR(INDEX(Positions!$D$2:$D$14531,MATCH($A9&"|25",Positions!$A$2:$A$14531,0)),"-") -> 27 | F9: =IFERROR(INDEX(Positions!$E$2:$E$14531,MATCH($A9&"|10",Positions!$A$2:$A$14531,0)),"-") -> G | G9: =IFERROR(INDEX(Positions!$E$2:$E$14531,MATCH($A9&"|25",Positions!$A$2:$A$14531,0)),"-") -> C | H9: =F9&"-"&G9 -> G-C | I9: =(F9="G")+(G9="G") -> 1 | J9: =(F9="C")+(G9="C") -> 1 | K9: =I9+J9 -> 2
A10: tdbR00000589 Arg-UCU | B10: D-stem | C10: 11-24 | D10: =IFERROR(INDEX(Positions!$D$2:$D$14531,MATCH($A10&"|11",Positions!$A$2:$A$14531,0)),"-") -> 11 | E10: =IFERROR(INDEX(Positions!$D$2:$D$14531,MATCH($A10&"|24",Positions!$A$2:$A$14531,0)),"-") -> 26 | F10: =IFERROR(INDEX(Positions!$E$2:$E$14531,MATCH($A10&"|11",Positions!$A$2:$A$14531,0)),"-") -> C | G10: =IFERROR(INDEX(Positions!$E$2:$E$14531,MATCH($A10&"|24",Positions!$A$2:$A$14531,0)),"-") -> G | H10: =F10&"-"&G10 -> C-G | I10: =(F10="G")+(G10="G") -> 1 | J10: =(F10="C")+(G10="C") -> 1 | K10: =I10+J10 -> 2
A11: tdbR00000589 Arg-UCU | B11: D-stem | C11: 12-23 | D11: =IFERROR(INDEX(Positions!$D$2:$D$14531,MATCH($A11&"|12",Positions!$A$2:$A$14531,0)),"-") -> 12 | E11: =IFERROR(INDEX(Positions!$D$2:$D$14531,MATCH($A11&"|23",Positions!$A$2:$A$14531,0)),"-") -> 25 | F11: =IFERROR(INDEX(Positions!$E$2:$E$14531,MATCH($A11&"|12",Positions!$A$2:$A$14531,0)),"-") -> U | G11: =IFERROR(INDEX(Positions!$E$2:$E$14531,MATCH($A11&"|23",Positions!$A$2:$A$14531,0)),"-") -> A | H11: =F11&"-"&G11 -> U-A | I11: =(F11="G")+(G11="G") -> 0 | J11: =(F11="C")+(G11="C") -> 0 | K11: =I11+J11 -> 0
A12: tdbR00000589 Arg-UCU | B12: D-stem | C12: 13-22 | D12: =IFERROR(INDEX(Positions!$D$2:$D$14531,MATCH($A12&"|13",Positions!$A$2:$A$14531,0)),"-") -> 13 | E12: =IFERROR(INDEX(Positions!$D$2:$D$14531,MATCH($A12&"|22",Positions!$A$2:$A$14531,0)),"-") -> 24 | F12: =IFERROR(INDEX(Positions!$E$2:$E$14531,MATCH($A12&"|13",Positions!$A$2:$A$14531,0)),"-") -> C | G12: =IFERROR(INDEX(Positions!$E$2:$E$14531,MATCH($A12&"|22",Positions!$A$2:$A$14531,0)),"-") -> G | H12: =F12&"-"&G12 -> C-G | I12: =(F12="G")+(G12="G") -> 1 | J12: =(F12="C")+(G12="C") -> 1 | K12: =I12+J12 -> 2
A13: tdbR00000589 Arg-UCU | B13: Anticodon stem | C13: 27-43 | D13: =IFERROR(INDEX(Positions!$D$2:$D$14531,MATCH($A13&"|27",Positions!$A$2:$A$14531,0)),"-") -> 29 | E13: =IFERROR(INDEX(Positions!$D$2:$D$14531,MATCH($A13&"|43",Positions!$A$2:$A$14531,0)),"-") -> 45 | F13: =IFERROR(INDEX(Positions!$E$2:$E$14531,MATCH($A13&"|27",Positions!$A$2:$A$14531,0)),"-") -> C | G13: =IFERROR(INDEX(Positions!$E$2:$E$14531,MATCH($A13&"|43",Positions!$A$2:$A$14531,0)),"-") -> G | H13: =F13&"-"&G13 -> C-G | I13: =(F13="G")+(G13="G") -> 1 | J13: =(F13="C")+(G13="C") -> 1 | K13: =I13+J13 -> 2
A14: tdbR00000589 Arg-UCU | B14: Anticodon stem | C14: 28-42 | D14: =IFERROR(INDEX(Positions!$D$2:$D$14531,MATCH($A14&"|28",Positions!$A$2:$A$14531,0)),"-") -> 30 | E14: =IFERROR(INDEX(Positions!$D$2:$D$14531,MATCH($A14&"|42",Positions!$A$2:$A$14531,0)),"-") -> 44 | F14: =IFERROR(INDEX(Positions!$E$2:$E$14531,MATCH($A14&"|28",Positions!$A$2:$A$14531,0)),"-") -> C | G14: =IFERROR(INDEX(Positions!$E$2:$E$14531,MATCH($A14&"|42",Positions!$A$2:$A$14531,0)),"-") -> G | H14: =F14&"-"&G14 -> C-G | I14: =(F14="G")+(G14="G") -> 1 | J14: =(F14="C")+(G14="C") -> 1 | K14: =I14+J14 -> 2
A15: tdbR00000589 Arg-UCU | B15: Anticodon stem | C15: 29-41 | D15: =IFERROR(INDEX(Positions!$D$2:$D$14531,MATCH($A15&"|29",Positions!$A$2:$A$14531,0)),"-") -> 31 | E15: =IFERROR(INDEX(Positions!$D$2:$D$14531,MATCH($A15&"|41",Positions!$A$2:$A$14531,0)),"-") -> 43 | F15: =IFERROR(INDEX(Positions!$E$2:$E$14531,MATCH($A15&"|29",Positions!$A$2:$A$14531,0)),"-") -> G | G15: =IFERROR(INDEX(Positions!$E$2:$E$14531,MATCH($A15&"|41",Positions!$A$2:$A$14531,0)),"-") -> C | H15: =F15&"-"&G15 -> G-C | I15: =(F15="G")+(G15="G") -> 1 | J15: =(F15="C")+(G15="C") -> 1 | K15: =I15+J15 -> 2
A16: tdbR00000589 Arg-UCU | B16: Anticodon stem | C16: 30-40 | D16: =IFERROR(INDEX(Positions!$D$2:$D$14531,MATCH($A16&"|30",Positions!$A$2:$A$14531,0)),"-") -> 32 | E16: =IFERROR(INDEX(Positions!$D$2:$D$14531,MATCH($A16&"|40",Positions!$A$2:$A$14531,0)),"-") -> 42 | F16: =IFERROR(INDEX(Positions!$E$2:$E$14531,MATCH($A16&"|30",Positions!$A$2:$A$14531,0)),"-") -> G | G16: =IFERROR(INDEX(Positions!$E$2:$E$14531,MATCH($A16&"|40",Positions!$A$2:$A$14531,0)),"-") -> C | H16: =F16&"-"&G16 -> G-C | I16: =(F16="G")+(G16="G") -> 1 | J16: =(F16="C")+(G16="C") -> 1 | K16: =I16+J16 -> 2
A17: tdbR00000589 Arg-UCU | B17: Anticodon stem | C17: 31-39 | D17: =IFERROR(INDEX(Positions!$D$2:$D$14531,MATCH($A17&"|31",Positions!$A$2:$A$14531,0)),"-") -> 33 | E17: =IFERROR(INDEX(Positions!$D$2:$D$14531,MATCH($A17&"|39",Positions!$A$2:$A$14531,0)),"-") -> 41 | F17: =IFERROR(INDEX(Positions!$E$2:$E$14531,MATCH($A17&"|31",Positions!$A$2:$A$14531,0)),"-") -> C | G17: =IFERROR(INDEX(Positions!$E$2:$E$14531,MATCH($A17&"|39",Positions!$A$2:$A$14531,0)),"-") -> G | H17: =F17&"-"&G17 -> C-G | I17: =(F17="G")+(G17="G") -> 1 | J17: =(F17="C")+(G17="C") -> 1 | K17: =I17+J17 -> 2
A18: tdbR00000589 Arg-UCU | B18: T-stem | C18: 49-65 | D18: =IFERROR(INDEX(Positions!$D$2:$D$14531,MATCH($A18&"|49",Positions!$A$2:$A$14531,0)),"-") -> 51 | E18: =IFERROR(INDEX(Positions!$D$2:$D$14531,MATCH($A18&"|65",Positions!$A$2:$A$14531,0)),"-") -> 67 | F18: =IFERROR(INDEX(Positions!$E$2:$E$14531,MATCH($A18&"|49",Positions!$A$2:$A$14531,0)),"-") -> C | G18: =IFERROR(INDEX(Positions!$E$2:$E$14531,MATCH($A18&"|65",Positions!$A$2:$A$14531,0)),"-") -> G | H18: =F18&"-"&G18 -> C-G | I18: =(F18="G")+(G18="G") -> 1 | J18: =(F18="C")+(G18="C") -> 1 | K18: =I18+J18 -> 2
A19: tdbR00000589 Arg-UCU | B19: T-stem | C19: 50-64 | D19: =IFERROR(INDEX(Positions!$D$2:$D$14531,MATCH($A19&"|50",Positions!$A$2:$A$14531,0)),"-") -> 52 | E19: =IFERROR(INDEX(Positions!$D$2:$D$14531,MATCH($A19&"|64",Positions!$A$2:$A$14531,0)),"-") -> 66 | F19: =IFERROR(INDEX(Positions!$E$2:$E$14531,MATCH($A19&"|50",Positions!$A$2:$A$14531,0)),"-") -> C | G19: =IFERROR(INDEX(Positions!$E$2:$E$14531,MATCH($A19&"|64",Positions!$A$2:$A$14531,0)),"-") -> G | H19: =F19&"-"&G19 -> C-G | I19: =(F19="G")+(G19="G") -> 1 | J19: =(F19="C")+(G19="C") -> 1 | K19: =I19+J19 -> 2
A20: tdbR00000589 Arg-UCU | B20: T-stem | C20: 51-63 | D20: =IFERROR(INDEX(Positions!$D$2:$D$14531,MATCH($A20&"|51",Positions!$A$2:$A$14531,0)),"-") -> 53 | E20: =IFERROR(INDEX(Positions!$D$2:$D$14531,MATCH($A20&"|63",Positions!$A$2:$A$14531,0)),"-") -> 65 | F20: =IFERROR(INDEX(Positions!$E$2:$E$14531,MATCH($A20&"|51",Positions!$A$2:$A$14531,0)),"-") -> G | G20: =IFERROR(INDEX(Positions!$E$2:$E$14531,MATCH($A20&"|63",Positions!$A$2:$A$14531,0)),"-") -> C | H20: =F20&"-"&G20 -> G-C | I20: =(F20="G")+(G20="G") -> 1 | J20: =(F20="C")+(G20="C") -> 1 | K20: =I20+J20 -> 2
A21: tdbR00000589 Arg-UCU | B21: T-stem | C21: 52-62 | D21: =IFERROR(INDEX(Positions!$D$2:$D$14531,MATCH($A21&"|52",Positions!$A$2:$A$14531,0)),"-") -> 54 | E21: =IFERROR(INDEX(Positions!$D$2:$D$14531,MATCH($A21&"|62",Positions!$A$2:$A$14531,0)),"-") -> 64 | F21: =IFERROR(INDEX(Positions!$E$2:$E$14531,MATCH($A21&"|52",Positions!$A$2:$A$14531,0)),"-") -> G | G21: =IFERROR(INDEX(Positions!$E$2:$E$14531,MATCH($A21&"|62",Positions!$A$2:$A$14531,0)),"-") -> C | H21: =F21&"-"&G21 -> G-C | I21: =(F21="G")+(G21="G") -> 1 | J21: =(F21="C")+(G21="C") -> 1 | K21: =I21+J21 -> 2
A22: tdbR00000589 Arg-UCU | B22: T-stem | C22: 53-61 | D22: =IFERROR(INDEX(Positions!$D$2:$D$14531,MATCH($A22&"|53",Positions!$A$2:$A$14531,0)),"-") -> 55 | E22: =IFERROR(INDEX(Positions!$D$2:$D$14531,MATCH($A22&"|61",Positions!$A$2:$A$14531,0)),"-") -> 63 | F22: =IFERROR(INDEX(Positions!$E$2:$E$14531,MATCH($A22&"|53",Positions!$A$2:$A$14531,0)),"-") -> G | G22: =IFERROR(INDEX(Positions!$E$2:$E$14531,MATCH($A22&"|61",Positions!$A$2:$A$14531,0)),"-") -> C | H22: =F22&"-"&G22 -> G-C | I22: =(F22="G")+(G22="G") -> 1 | J22: =(F22="C")+(G22="C") -> 1 | K22: =I22+J22 -> 2
A23: tdbR00000589 Arg-UCU | B23: 3D (tertiary) BP | C23: 8-14 | D23: =IFERROR(INDEX(Positions!$D$2:$D$14531,MATCH($A23&"|8",Positions!$A$2:$A$14531,0)),"-") -> 8 | E23: =IFERROR(INDEX(Positions!$D$2:$D$14531,MATCH($A23&"|14",Positions!$A$2:$A$14531,0)),"-") -> 14 | F23: =IFERROR(INDEX(Positions!$E$2:$E$14531,MATCH($A23&"|8",Positions!$A$2:$A$14531,0)),"-") -> U | G23: =IFERROR(INDEX(Positions!$E$2:$E$14531,MATCH($A23&"|14",Positions!$A$2:$A$14531,0)),"-") -> A | H23: =F23&"-"&G23 -> U-A | I23: =(F23="G")+(G23="G") -> 0 | J23: =(F23="C")+(G23="C") -> 0 | K23: =I23+J23 -> 0
A24: tdbR00000589 Arg-UCU | B24: 3D (tertiary) BP | C24: 15-48 | D24: =IFERROR(INDEX(Positions!$D$2:$D$14531,MATCH($A24&"|15",Positions!$A$2:$A$14531,0)),"-") -> 15 | E24: =IFERROR(INDEX(Positions!$D$2:$D$14531,MATCH($A24&"|48",Positions!$A$2:$A$14531,0)),"-") -> 50 | F24: =IFERROR(INDEX(Positions!$E$2:$E$14531,MATCH($A24&"|15",Positions!$A$2:$A$14531,0)),"-") -> G | G24: =IFERROR(INDEX(Positions!$E$2:$E$14531,MATCH($A24&"|48",Positions!$A$2:$A$14531,0)),"-") -> G | H24: =F24&"-"&G24 -> G-G | I24: =(F24="G")+(G24="G") -> 2 | J24: =(F24="C")+(G24="C") -> 0 | K24: =I24+J24 -> 2
A25: tdbR00000589 Arg-UCU | B25: 3D (tertiary) BP | C25: 18-55 | D25: =IFERROR(INDEX(Positions!$D$2:$D$14531,MATCH($A25&"|18",Positions!$A$2:$A$14531,0)),"-") -> 19 | E25: =IFERROR(INDEX(Positions!$D$2:$D$14531,MATCH($A25&"|55",Positions!$A$2:$A$14531,0)),"-") -> 57 | F25: =IFERROR(INDEX(Positions!$E$2:$E$14531,MATCH($A25&"|18",Positions!$A$2:$A$14531,0)),"-") -> G | G25: =IFERROR(INDEX(Positions!$E$2:$E$14531,MATCH($A25&"|55",Positions!$A$2:$A$14531,0)),"-") -> U | H25: =F25&"-"&G25 -> G-U | I25: =(F25="G")+(G25="G") -> 1 | J25: =(F25="C")+(G25="C") -> 0 | K25: =I25+J25 -> 1
A26: tdbR00000589 Arg-UCU | B26: 3D (tertiary) BP | C26: 19-56 | D26: =IFERROR(INDEX(Positions!$D$2:$D$14531,MATCH($A26&"|19",Positions!$A$2:$A$14531,0)),"-") -> 20 | E26: =IFERROR(INDEX(Positions!$D$2:$D$14531,MATCH($A26&"|56",Positions!$A$2:$A$14531,0)),"-") -> 58 | F26: =IFERROR(INDEX(Positions!$E$2:$E$14531,MATCH($A26&"|19",Positions!$A$2:$A$14531,0)),"-") -> G | G26: =IFERROR(INDEX(Positions!$E$2:$E$14531,MATCH($A26&"|56",Positions!$A$2:$A$14531,0)),"-") -> C | H26: =F26&"-"&G26 -> G-C | I26: =(F26="G")+(G26="G") -> 1 | J26: =(F26="C")+(G26="C") -> 1 | K26: =I26+J26 -> 2
A27: tdbR00000589 Arg-UCU | B27: 3D (tertiary) BP | C27: 26-44 | D27: =IFERROR(INDEX(Positions!$D$2:$D$14531,MATCH($A27&"|26",Positions!$A$2:$A$14531,0)),"-") -> 28 | E27: =IFERROR(INDEX(Positions!$D$2:$D$14531,MATCH($A27&"|44",Positions!$A$2:$A$14531,0)),"-") -> 46 | F27: =IFERROR(INDEX(Positions!$E$2:$E$14531,MATCH($A27&"|26",Positions!$A$2:$A$14531,0)),"-") -> G | G27: =IFERROR(INDEX(Positions!$E$2:$E$14531,MATCH($A27&"|44",Positions!$A$2:$A$14531,0)),"-") -> U | H27: =F27&"-"&G27 -> G-U | I27: =(F27="G")+(G27="G") -> 1 | J27: =(F27="C")+(G27="C") -> 0 | K27: =I27+J27 -> 1
A28: tdbR00000589 Arg-UCU | B28: 3D (tertiary) BP | C28: 32-38 | D28: =IFERROR(INDEX(Positions!$D$2:$D$14531,MATCH($A28&"|32",Positions!$A$2:$A$14531,0)),"-") -> 34 | E28: =IFERROR(INDEX(Positions!$D$2:$D$14531,MATCH($A28&"|38",Positions!$A$2:$A$14531,0)),"-") -> 40 | F28: =IFERROR(INDEX(Positions!$E$2:$E$14531,MATCH($A28&"|32",Positions!$A$2:$A$14531,0)),"-") -> C | G28: =IFERROR(INDEX(Positions!$E$2:$E$14531,MATCH($A28&"|38",Positions!$A$2:$A$14531,0)),"-") -> A | H28: =F28&"-"&G28 -> C-A | I28: =(F28="G")+(G28="G") -> 0 | J28: =(F28="C")+(G28="C") -> 1 | K28: =I28+J28 -> 1
A29: tdbR00000589 Arg-UCU | B29: 3D (tertiary) BP | C29: 54-58 | D29: =IFERROR(INDEX(Positions!$D$2:$D$14531,MATCH($A29&"|54",Positions!$A$2:$A$14531,0)),"-") -> 56 | E29: =IFERROR(INDEX(Positions!$D$2:$D$14531,MATCH($A29&"|58",Positions!$A$2:$A$14531,0)),"-") -> 60 | F29: =IFERROR(INDEX(Positions!$E$2:$E$14531,MATCH($A29&"|54",Positions!$A$2:$A$14531,0)),"-") -> U | G29: =IFERROR(INDEX(Positions!$E$2:$E$14531,MATCH($A29&"|58",Positions!$A$2:$A$14531,0)),"-") -> A | H29: =F29&"-"&G29 -> U-A | I29: =(F29="G")+(G29="G") -> 0 | J29: =(F29="C")+(G29="C") -> 0 | K29: =I29+J29 -> 0
A30: tdbR00000588 Asp-GUC | B30: Acceptor stem | C30: 1-72 | D30: =IFERROR(INDEX(Positions!$D$2:$D$14531,MATCH($A30&"|1",Positions!$A$2:$A$14531,0)),"-") -> 1 | E30: =IFERROR(INDEX(Positions!$D$2:$D$14531,MATCH($A30&"|72",Positions!$A$2:$A$14531,0)),"-") -> 74 | F30: =IFERROR(INDEX(Positions!$E$2:$E$14531,MATCH($A30&"|1",Positions!$A$2:$A$14531,0)),"-") -> G | G30: =IFERROR(INDEX(Positions!$E$2:$E$14531,MATCH($A30&"|72",Positions!$A$2:$A$14531,0)),"-") -> C | H30: =F30&"-"&G30 -> G-C | I30: =(F30="G")+(G30="G") -> 1 | J30: =(F30="C")+(G30="C") -> 1 | K30: =I30+J30 -> 2
A31: tdbR00000588 Asp-GUC | B31: Acceptor stem | C31: 2-71 | D31: =IFERROR(INDEX(Positions!$D$2:$D$14531,MATCH($A31&"|2",Positions!$A$2:$A$14531,0)),"-") -> 2 | E31: =IFERROR(INDEX(Positions!$D$2:$D$14531,MATCH($A31&"|71",Positions!$A$2:$A$14531,0)),"-") -> 73 | F31: =IFERROR(INDEX(Positions!$E$2:$E$14531,MATCH($A31&"|2",Positions!$A$2:$A$14531,0)),"-") -> C | G31: =IFERROR(INDEX(Positions!$E$2:$E$14531,MATCH($A31&"|71",Positions!$A$2:$A$14531,0)),"-") -> G | H31: =F31&"-"&G31 -> C-G | I31: =(F31="G")+(G31="G") -> 1 | J31: =(F31="C")+(G31="C") -> 1 | K31: =I31+J31 -> 2
A32: tdbR00000588 Asp-GUC | B32: Acceptor stem | C32: 3-70 | D32: =IFERROR(INDEX(Positions!$D$2:$D$14531,MATCH($A32&"|3",Positions!$A$2:$A$14531,0)),"-") -> 3 | E32: =IFERROR(INDEX(Positions!$D$2:$D$14531,MATCH($A32&"|70",Positions!$A$2:$A$14531,0)),"-") -> 72 | F32: =IFERROR(INDEX(Positions!$E$2:$E$14531,MATCH($A32&"|3",Positions!$A$2:$A$14531,0)),"-") -> C | G32: =IFERROR(INDEX(Positions!$E$2:$E$14531,MATCH($A32&"|70",Positions!$A$2:$A$14531,0)),"-") -> G | H32: =F32&"-"&G32 -> C-G | I32: =(F32="G")+(G32="G") -> 1 | J32: =(F32="C")+(G32="C") -> 1 | K32: =I32+J32 -> 2
A33: tdbR00000588 Asp-GUC | B33: Acceptor stem | C33: 4-69 | D33: =IFERROR(INDEX(Positions!$D$2:$D$14531,MATCH($A33&"|4",Positions!$A$2:$A$14531,0)),"-") -> 4 | E33: =IFERROR(INDEX(Positions!$D$2:$D$14531,MATCH($A33&"|69",Positions!$A$2:$A$14531,0)),"-") -> 71 | F33: =IFERROR(INDEX(Positions!$E$2:$E$14531,MATCH($A33&"|4",Positions!$A$2:$A$14531,0)),"-") -> G | G33: =IFERROR(INDEX(Positions!$E$2:$E$14531,MATCH($A33&"|69",Positions!$A$2:$A$14531,0)),"-") -> C | H33: =F33&"-"&G33 -> G-C | I33: =(F33="G")+(G33="G") -> 1 | J33: =(F33="C")+(G33="C") -> 1 | K33: =I33+J33 -> 2
A34: tdbR00000588 Asp-GUC | B34: Acceptor stem | C34: 5-68 | D34: =IFERROR(INDEX(Positions!$D$2:$D$14531,MATCH($A34&"|5",Positions!$A$2:$A$14531,0)),"-") -> 5 | E34: =IFERROR(INDEX(Positions!$D$2:$D$14531,MATCH($A34&"|68",Positions!$A$2:$A$14531,0)),"-") -> 70 | F34: =IFERROR(INDEX(Positions!$E$2:$E$14531,MATCH($A34&"|5",Positions!$A$2:$A$14531,0)),"-") -> C | G34: =IFERROR(INDEX(Positions!$E$2:$E$14531,MATCH($A34&"|68",Positions!$A$2:$A$14531,0)),"-") -> G | H34: =F34&"-"&G34 -> C-G | I34: =(F34="G")+(G34="G") -> 1 | J34: =(F34="C")+(G34="C") -> 1 | K34: =I34+J34 -> 2
A35: tdbR00000588 Asp-GUC | B35: Acceptor stem | C35: 6-67 | D35: =IFERROR(INDEX(Positions!$D$2:$D$14531,MATCH($A35&"|6",Positions!$A$2:$A$14531,0)),"-") -> 6 | E35: =IFERROR(INDEX(Positions!$D$2:$D$14531,MATCH($A35&"|67",Positions!$A$2:$A$14531,0)),"-") -> 69 | F35: =IFERROR(INDEX(Positions!$E$2:$E$14531,MATCH($A35&"|6",Positions!$A$2:$A$14531,0)),"-") -> G | G35: =IFERROR(INDEX(Positions!$E$2:$E$14531,MATCH($A35&"|67",Positions!$A$2:$A$14531,0)),"-") -> C | H35: =F35&"-"&G35 -> G-C | I35: =(F35="G")+(G35="G") -> 1 | J35: =(F35="C")+(G35="C") -> 1 | K35: =I35+J35 -> 2
A36: tdbR00000588 Asp-GUC | B36: Acceptor stem | C36: 7-66 | D36: =IFERROR(INDEX(Positions!$D$2:$D$14531,MATCH($A36&"|7",Positions!$A$2:$A$14531,0)),"-") -> 7 | E36: =IFERROR(INDEX(Positions!$D$2:$D$14531,MATCH($A36&"|66",Positions!$A$2:$A$14531,0)),"-") -> 68 | F36: =IFERROR(INDEX(Positions!$E$2:$E$14531,MATCH($A36&"|7",Positions!$A$2:$A$14531,0)),"-") -> G | G36: =IFERROR(INDEX(Positions!$E$2:$E$14531,MATCH($A36&"|66",Positions!$A$2:$A$14531,0)),"-") -> C | H36: =F36&"-"&G36 -> G-C | I36: =(F36="G")+(G36="G") -> 1 | J36: =(F36="C")+(G36="C") -> 1 | K36: =I36+J36 -> 2
A37: tdbR00000588 Asp-GUC | B37: D-stem | C37: 10-25 | D37: =IFERROR(INDEX(Positions!$D$2:$D$14531,MATCH($A37&"|10",Positions!$A$2:$A$14531,0)),"-") -> 10 | E37: =IFERROR(INDEX(Positions!$D$2:$D$14531,MATCH($A37&"|25",Positions!$A$2:$A$14531,0)),"-") -> 28 | F37: =IFERROR(INDEX(Positions!$E$2:$E$14531,MATCH($A37&"|10",Positions!$A$2:$A$14531,0)),"-") -> G | G37: =IFERROR(INDEX(Positions!$E$2:$E$14531,MATCH($A37&"|25",Positions!$A$2:$A$14531,0)),"-") -> U | H37: =F37&"-"&G37 -> G-U | I37: =(F37="G")+(G37="G") -> 1 | J37: =(F37="C")+(G37="C") -> 0 | K37: =I37+J37 -> 1
A38: tdbR00000588 Asp-GUC | B38: D-stem | C38: 11-24 | D38: =IFERROR(INDEX(Positions!$D$2:$D$14531,MATCH($A38&"|11",Positions!$A$2:$A$14531,0)),"-") -> 11 | E38: =IFERROR(INDEX(Positions!$D$2:$D$14531,MATCH($A38&"|24",Positions!$A$2:$A$14531,0)),"-") -> 27 | F38: =IFERROR(INDEX(Positions!$E$2:$E$14531,MATCH($A38&"|11",Positions!$A$2:$A$14531,0)),"-") -> U | G38: =IFERROR(INDEX(Positions!$E$2:$E$14531,MATCH($A38&"|24",Positions!$A$2:$A$14531,0)),"-") -> A | H38: =F38&"-"&G38 -> U-A | I38: =(F38="G")+(G38="G") -> 0 | J38: =(F38="C")+(G38="C") -> 0 | K38: =I38+J38 -> 0
A39: tdbR00000588 Asp-GUC | B39: D-stem | C39: 12-23 | D39: =IFERROR(INDEX(Positions!$D$2:$D$14531,MATCH($A39&"|12",Positions!$A$2:$A$14531,0)),"-") -> 12 | E39: =IFERROR(INDEX(Positions!$D$2:$D$14531,MATCH($A39&"|23",Positions!$A$2:$A$14531,0)),"-") -> 26 | F39: =IFERROR(INDEX(Positions!$E$2:$E$14531,MATCH($A39&"|12",Positions!$A$2:$A$14531,0)),"-") -> A | G39: =IFERROR(INDEX(Positions!$E$2:$E$14531,MATCH($A39&"|23",Positions!$A$2:$A$14531,0)),"-") -> U | H39: =F39&"-"&G39 -> A-U | I39: =(F39="G")+(G39="G") -> 0 | J39: =(F39="C")+(G39="C") -> 0 | K39: =I39+J39 -> 0
A40: tdbR00000588 Asp-GUC | B40: D-stem | C40: 13-22 | D40: =IFERROR(INDEX(Positions!$D$2:$D$14531,MATCH($A40&"|13",Positions!$A$2:$A$14531,0)),"-") -> 13 | E40: =IFERROR(INDEX(Positions!$D$2:$D$14531,MATCH($A40&"|22",Positions!$A$2:$A$14531,0)),"-") -> 25 | F40: =IFERROR(INDEX(Positions!$E$2:$E$14531,MATCH($A40&"|13",Positions!$A$2:$A$14531,0)),"-") -> U | G40: =IFERROR(INDEX(Positions!$E$2:$E$14531,MATCH($A40&"|22",Positions!$A$2:$A$14531,0)),"-") -> G | H40: =F40&"-"&G40 -> U-G | I40: =(F40="G")+(G40="G") -> 1 | J40: =(F40="C")+(G40="C") -> 0 | K40: =I40+J40 -> 1
...

Sheet Loops
A1: tRNA | B1: Loop / region | C1: Canonical positions | D1: Actual positions | E1: Loop sequence (5′→3′) | F1: Length | G1: G count | H1: C count | I1: G+C count | J1: G+C %
A2: tdbR00000589 Arg-UCU | B2: D-loop | C2: 14–21 | D2: 14–23 | E2: AGCCAGGACA | F2: =COUNTIFS(Positions!$B$2:$B$14531,A2,Positions!$F$2:$F$14531,B2) -> 10 | G2: =COUNTIFS(Positions!$B$2:$B$14531,A2,Positions!$F$2:$F$14531,B2,Positions!$E$2:$E$14531,"G") -> 3 | H2: =COUNTIFS(Positions!$B$2:$B$14531,A2,Positions!$F$2:$F$14531,B2,Positions!$E$2:$E$14531,"C") -> 3 | I2: =G2+H2 -> 6 | J2: =IF(F2=0,0,I2/F2) -> 0.6
A3: tdbR00000589 Arg-UCU | B3: Anticodon loop | C3: 32–38 | D3: 34–40 | E3: CUUCUAA | F3: =COUNTIFS(Positions!$B$2:$B$14531,A3,Positions!$F$2:$F$14531,B3) -> 7 | G3: =COUNTIFS(Positions!$B$2:$B$14531,A3,Positions!$F$2:$F$14531,B3,Positions!$E$2:$E$14531,"G") -> 0 | H3: =COUNTIFS(Positions!$B$2:$B$14531,A3,Positions!$F$2:$F$14531,B3,Positions!$E$2:$E$14531,"C") -> 2 | I3: =G3+H3 -> 2 | J3: =IF(F3=0,0,I3/F3) -> 0.28571429
A4: tdbR00000589 Arg-UCU | B4: Variable loop | C4: 44–48 | D4: 46–50 | E4: UGCUG | F4: =COUNTIFS(Positions!$B$2:$B$14531,A4,Positions!$F$2:$F$14531,B4) -> 5 | G4: =COUNTIFS(Positions!$B$2:$B$14531,A4,Positions!$F$2:$F$14531,B4,Positions!$E$2:$E$14531,"G") -> 2 | H4: =COUNTIFS(Positions!$B$2:$B$14531,A4,Positions!$F$2:$F$14531,B4,Positions!$E$2:$E$14531,"C") -> 1 | I4: =G4+H4 -> 3 | J4: =IF(F4=0,0,I4/F4) -> 0.6
A5: tdbR00000589 Arg-UCU | B5: TΨC-loop | C5: 54–60 | D5: 56–62 | E5: UUCAAAU | F5: =COUNTIFS(Positions!$B$2:$B$14531,A5,Positions!$F$2:$F$14531,B5) -> 7 | G5: =COUNTIFS(Positions!$B$2:$B$14531,A5,Positions!$F$2:$F$14531,B5,Positions!$E$2:$E$14531,"G") -> 0 | H5: =COUNTIFS(Positions!$B$2:$B$14531,A5,Positions!$F$2:$F$14531,B5,Positions!$E$2:$E$14531,"C") -> 1 | I5: =G5+H5 -> 1 | J5: =IF(F5=0,0,I5/F5) -> 0.14285714
